Workbook

Sheet Year_2025
B1: Lenght
C2: 11 | D2: 12 | E2: 13 | F2: 14 | G2: 18
B3: Length | C3: 2.2 | D3: 2.5 | E3: 2.8 | F3: 3.3 | G3: 0.8
B5: TollLights | N5: ML PCE.Miles | AA5: GP PCE.Miles | AN5: Highway PCE.Miles
B6: Direction | C6: NB | D6: SB | E6: NB | F6: SB | G6: NB | H6: SB | I6: NB | J6: SB | K6: NB | L6: SB | N6: Direction | O6: NB | P6: SB | Q6: NB | R6: SB | S6: NB | T6: SB | U6: NB | V6: SB | W6: NB | X6: SB | AA6: Direction | AB6: NB | AC6: SB | AD6: NB | AE6: SB | AF6: NB | AG6: SB | AH6: NB | AI6: SB | AJ6: NB | AK6: SB | AN6: Direction | AO6: NB | AP6: SB | AQ6: NB | AR6: SB | AS6: NB | AT6: SB | AU6: NB | AV6: SB | AW6: NB | AX6: SB
B7: Segment | C7: 11 | D7: 11 | E7: 12 | F7: 12 | G7: 13 | H7: 13 | I7: 14 | J7: 14 | K7: 18 | L7: 18 | N7: Segment | O7: 11 | P7: 11 | Q7: 12 | R7: 12 | S7: 13 | T7: 13 | U7: 14 | V7: 14 | W7: 18 | X7: 18 | AA7: Segment | AB7: 11 | AC7: 11 | AD7: 12 | AE7: 12 | AF7: 13 | AG7: 13 | AH7: 14 | AI7: 14 | AJ7: 18 | AK7: 18 | AN7: Segment | AO7: 11 | AP7: 11 | AQ7: 12 | AR7: 12 | AS7: 13 | AT7: 13 | AU7: 14 | AV7: 14 | AW7: 18 | AX7: 18
B8: Period | N8: Period | AA8: Period | AN8: Period
B9: Night | C9: 0.2 | D9: 0.2 | E9: 0.2 | F9: 0.2 | G9: 0.2 | H9: 0.2 | I9: 0.2 | J9: 0.2 | K9: 0.2 | L9: 0.2 | N9: Night | O9: 2137.97 | P9: 2128.78 | Q9: 2957.58 | R9: 2252.97 | S9: 1803.05 | T9: 1595.26 | U9: 2162.97 | V9: 1528.98 | W9: 1804.93 | X9: 1445.71 | AA9: Night | AB9: 34390.83 | AC9: 34153.62 | AD9: 45972.42 | AE9: 35354.53 | AF9: 32869.35 | AG9: 29255.14 | AH9: 33665.13 | AI9: 28939.92 | AJ9: 16417.47 | AK9: 13383.09 | AN9: Night | AO9: 36528.8 | AP9: 36282.4 | AQ9: 48930 | AR9: 37607.5 | AS9: 34672.4 | AT9: 30850.4 | AU9: 35828.1 | AV9: 30468.9 | AW9: 18222.4 | AX9: 14828.8
B10: AM-Early | C10: 1.04 | D10: 0.5 | E10: 0.4 | F10: 1.56 | G10: 0.7 | H10: 0.75 | I10: 0.78 | J10: 0.9 | K10: 1.26 | L10: 0.94 | N10: AM-Early | O10: 2208.27 | P10: 1410.28 | Q10: 2871.94 | R10: 1593.07 | S10: 3529.67 | T10: 1754.67 | U10: 3758.12 | V10: 613.39 | W10: 964.94 | X10: 763.32 | AA10: AM-Early | AB10: 12696.73 | AC10: 8274.12 | AD10: 17213.06 | AE10: 9822.05 | AF10: 19007.53 | AG10: 9543.33 | AH10: 20189.98 | AI10: 12022.31 | AJ10: 5275.06 | AK10: 4507.08 | AN10: AM-Early | AO10: 14905 | AP10: 9684.4 | AQ10: 20085 | AR10: 11415.12 | AS10: 22537.2 | AT10: 11298 | AU10: 23948.1 | AV10: 12635.7 | AW10: 6240 | AX10: 5270.4
B11: AM-Peak | C11: 1.6 | D11: 1.29 | E11: 0.82 | F11: 1.6 | G11: 1.6 | H11: 0.86 | I11: 1.22 | J11: 0.38 | K11: 1.17 | L11: 1.6 | N11: AM-Peak | O11: 10205.93 | P11: 4049.2 | Q11: 10513.25 | R11: 9835.31 | S11: 13206.74 | T11: 9313.28 | U11: 13342.95 | V11: 9874.86 | W11: 1973.91 | X11: 2596.03 | AA11: AM-Peak | AB11: 46034.7 | AC11: 24360.17 | AD11: 67096.75 | AE11: 37740.19 | AF11: 71717.96 | AG11: 52133.84 | AH11: 76880.87 | AI11: 57358.17 | AJ11: 11194.89 | AK11: 12965.57 | AN11: AM-Peak | AO11: 56240.63 | AP11: 28409.37 | AQ11: 77610 | AR11: 47575.5 | AS11: 84924.7 | AT11: 61447.12 | AU11: 90223.83 | AV11: 67233.02 | AW11: 13168.8 | AX11: 15561.6
B12: AM-Shoulder | C12: 1.3 | D12: 0.86 | E12: 0.6 | F12: 1.42 | G12: 1.02 | H12: 0.75 | I12: 0.43 | J12: 0.24 | K12: 1.04 | L12: 1.15 | N12: AM-Shoulder | O12: 2324.19 | P12: 1371.83 | Q12: 3023 | R12: 3080.56 | S12: 3752.48 | T12: 3250.94 | U12: 3698.55 | V12: 3146.91 | W12: 592.11 | X12: 608.98 | AA12: AM-Shoulder | AB12: 14934.81 | AC12: 8727.93 | AD12: 21112 | AE12: 20241.44 | AF12: 21836.72 | AG12: 19135.06 | AH12: 21232.95 | AI12: 18501.09 | AJ12: 3763.09 | AK12: 3774.86 | AN12: AM-Shoulder | AO12: 17259 | AP12: 10099.76 | AQ12: 24135 | AR12: 23322 | AS12: 25589.2 | AT12: 22386 | AU12: 24931.5 | AV12: 21648 | AW12: 4355.2 | AX12: 4383.84
B13: MD | C13: 1.4 | D13: 1.26 | E13: 0.9 | F13: 1.05 | G13: 0.72 | H13: 0.67 | I13: 0.38 | J13: 0.2 | K13: 1.42 | L13: 1.47 | N13: MD | O13: 8272.5 | P13: 9488.68 | Q13: 11445.31 | R13: 12128.17 | S13: 12932.57 | T13: 15215.44 | U13: 12964.95 | V13: 15875.48 | W13: 4396.52 | X13: 4207.25 | AA13: MD | AB13: 51248.5 | AC13: 56511.32 | AD13: 76842.19 | AE13: 77071.83 | AF13: 73727.43 | AG13: 82812.56 | AH13: 72307.05 | AI13: 87381.52 | AJ13: 27155.48 | AK13: 25530.72 | AN13: MD | AO13: 59521 | AP13: 66000 | AQ13: 88287.5 | AR13: 89200 | AS13: 86660 | AT13: 98028 | AU13: 85272 | AV13: 103257 | AW13: 31552 | AX13: 29737.97
B14: PM-Shoulder | C14: 1.21 | D14: 1.19 | E14: 0.72 | F14: 0.53 | G14: 0.67 | H14: 1 | I14: 0.32 | J14: 0.24 | K14: 1.3 | L14: 1.38 | N14: PM-Shoulder | O14: 2704.9 | P14: 2501.57 | Q14: 3386.1 | R14: 4266.78 | S14: 4491.75 | T14: 5481.41 | U14: 4171.02 | V14: 6273.97 | W14: 1062.16 | X14: 708.66 | AA14: PM-Shoulder | AB14: 13398.64 | AC14: 11600.76 | AD14: 18497.52 | AE14: 20778.22 | AF14: 20328.28 | AG14: 25083.82 | AH14: 18460.38 | AI14: 27736.82 | AJ14: 5273.56 | AK14: 3177.67 | AN14: PM-Shoulder | AO14: 16103.54 | AP14: 14102.33 | AQ14: 21883.62 | AR14: 25045 | AS14: 24820.03 | AT14: 30565.23 | AU14: 22631.4 | AV14: 34010.79 | AW14: 6335.73 | AX14: 3886.33
B15: PM-Peak | C15: 1.54 | D15: 1.43 | E15: 1.07 | F15: 0.72 | G15: 0.75 | H15: 0.82 | I15: 0.48 | J15: 0.2 | K15: 1.6 | L15: 1.42 | N15: PM-Peak | O15: 8819.44 | P15: 8929.23 | Q15: 8368.8 | R15: 10537.48 | S15: 12150.78 | T15: 13393.05 | U15: 11843 | V15: 13342.55 | W15: 1889.72 | X15: 2306.6 | AA15: PM-Peak | AB15: 43125.18 | AC15: 42438.57 | AD15: 44554.2 | AE15: 54832.52 | AF15: 55688.31 | AG15: 59226.32 | AH15: 54050.48 | AI15: 59576.35 | AJ15: 9274.48 | AK15: 11184.28 | AN15: PM-Peak | AO15: 51944.62 | AP15: 51367.8 | AQ15: 52923 | AR15: 65370 | AS15: 67839.09 | AT15: 72619.37 | AU15: 65893.48 | AV15: 72918.89 | AW15: 11164.2 | AX15: 13490.88
B16: PM-Late | C16: 0.5 | D16: 0.43 | E16: 0.6 | F16: 0.2 | G16: 0.67 | H16: 0.59 | I16: 0.5 | J16: 0.9 | K16: 0.71 | L16: 1.14 | N16: PM-Late | O16: 4101.05 | P16: 5366.79 | Q16: 4082.13 | R16: 4355.99 | S16: 4207 | T16: 5093.21 | U16: 3921.81 | V16: 1411.19 | W16: 1654.3 | X16: 1821.58 | AA16: PM-Late | AB16: 20827.15 | AC16: 25158.21 | AD16: 24545.37 | AE16: 26851.51 | AF16: 19959.8 | AG16: 22643.59 | AH16: 18749.19 | AI16: 27536.41 | AJ16: 9181.7 | AK16: 9392.21 | AN16: PM-Late | AO16: 24928.2 | AP16: 30525 | AQ16: 28627.5 | AR16: 31207.5 | AS16: 24166.8 | AT16: 27736.8 | AU16: 22671 | AV16: 28947.6 | AW16: 10836 | AX16: 11213.79
B19: CaptureRateLights | N19: ML Volume (PCE/Period) | AA19: GP Volume (PCE/Period) | AN19: Highway Volume
B20: Direction | C20: NB | D20: SB | E20: NB | F20: SB | G20: NB | H20: SB | I20: NB | J20: SB | K20: NB | L20: SB | N20: Direction | O20: NB | P20: SB | Q20: NB | R20: SB | S20: NB | T20: SB | U20: NB | V20: SB | W20: NB | X20: SB | AA20: Direction | AB20: NB | AC20: SB | AD20: NB | AE20: SB | AF20: NB | AG20: SB | AH20: NB | AI20: SB | AJ20: NB | AK20: SB | AN20: Direction | AO20: NB | AP20: SB | AQ20: NB | AR20: SB | AS20: NB | AT20: SB | AU20: NB | AV20: SB | AW20: NB | AX20: SB
B21: Segment | C21: 11 | D21: 11 | E21: 12 | F21: 12 | G21: 13 | H21: 13 | I21: 14 | J21: 14 | K21: 18 | L21: 18 | N21: Segment | O21: 11 | P21: 11 | Q21: 12 | R21: 12 | S21: 13 | T21: 13 | U21: 14 | V21: 14 | W21: 18 | X21: 18 | AA21: Segment | AB21: 11 | AC21: 11 | AD21: 12 | AE21: 12 | AF21: 13 | AG21: 13 | AH21: 14 | AI21: 14 | AJ21: 18 | AK21: 18 | AN21: Segment | AO21: 11 | AP21: 11 | AQ21: 12 | AR21: 12 | AS21: 13 | AT21: 13 | AU21: 14 | AV21: 14 | AW21: 18 | AX21: 18
B22: Period | N22: Period | AA22: Period | AN22: Period
B23: Night | C23: 0.06 | D23: 0.06 | E23: 0.06 | F23: 0.06 | G23: 0.05 | H23: 0.05 | I23: 0.06 | J23: 0.05 | K23: 0.1 | L23: 0.1 | N23: Night | O23: 971.81 | P23: 967.63 | Q23: 1183.03 | R23: 901.19 | S23: 643.95 | T23: 569.74 | U23: 655.44 | V23: 463.33 | W23: 2256.16 | X23: 1807.14 | AA23: Night | AB23: 15632.19 | AC23: 15524.37 | AD23: 18388.97 | AE23: 14141.81 | AF23: 11739.05 | AG23: 10448.26 | AH23: 10201.56 | AI23: 8769.67 | AJ23: 20521.84 | AK23: 16728.86 | AN23: Night | AO23: 16604 | AP23: 16492 | AQ23: 19572 | AR23: 15043 | AS23: 12383 | AT23: 11018 | AU23: 10857 | AV23: 9233 | AW23: 22778 | AX23: 18536
B24: AM-Early | C24: 0.16 | D24: 0.17 | E24: 0.16 | F24: 0.17 | G24: 0.17 | H24: 0.17 | I24: 0.17 | J24: 0.05 | K24: 0.17 | L24: 0.18 | N24: AM-Early | O24: 1003.76 | P24: 641.04 | Q24: 1148.78 | R24: 637.23 | S24: 1260.6 | T24: 626.67 | U24: 1138.82 | V24: 185.87 | W24: 1206.17 | X24: 954.15 | AA24: AM-Early | AB24: 5771.24 | AC24: 3760.96 | AD24: 6885.22 | AE24: 3928.82 | AF24: 6788.4 | AG24: 3408.33 | AH24: 6118.18 | AI24: 3643.13 | AJ24: 6593.83 | AK24: 5633.85 | AN24: AM-Early | AO24: 6775 | AP24: 4402 | AQ24: 8034 | AR24: 4566.05 | AS24: 8049 | AT24: 4035 | AU24: 7257 | AV24: 3829 | AW24: 7800 | AX24: 6588
B25: AM-Peak | C25: 0.21 | D25: 0.17 | E25: 0.16 | F25: 0.26 | G25: 0.17 | H25: 0.17 | I25: 0.16 | J25: 0.17 | K25: 0.18 | L25: 0.2 | N25: AM-Peak | O25: 4639.06 | P25: 1840.55 | Q25: 4205.3 | R25: 3934.12 | S25: 4716.69 | T25: 3326.17 | U25: 4043.32 | V25: 2992.38 | W25: 2467.39 | X25: 3245.03 | AA25: AM-Peak | AB25: 20924.86 | AC25: 11072.8 | AD25: 26838.7 | AE25: 15096.08 | AF25: 25613.56 | AG25: 18619.23 | AH25: 23297.23 | AI25: 17381.26 | AJ25: 13993.61 | AK25: 16206.97 | AN25: AM-Peak | AO25: 25563.92 | AP25: 12913.35 | AQ25: 31044 | AR25: 19030.2 | AS25: 30330.25 | AT25: 21945.4 | AU25: 27340.55 | AV25: 20373.64 | AW25: 16461 | AX25: 19452
B26: AM-Shoulder | C26: 0.16 | D26: 0.17 | E26: 0.16 | F26: 0.17 | G26: 0.16 | H26: 0.17 | I26: 0.17 | J26: 0.17 | K26: 0.18 | L26: 0.18 | N26: AM-Shoulder | O26: 1056.45 | P26: 623.56 | Q26: 1209.2 | R26: 1232.22 | S26: 1340.17 | T26: 1161.05 | U26: 1120.77 | V26: 953.61 | W26: 740.13 | X26: 761.22 | AA26: AM-Shoulder | AB26: 6788.55 | AC26: 3967.24 | AD26: 8444.8 | AE26: 8096.58 | AF26: 7798.83 | AG26: 6833.95 | AH26: 6434.23 | AI26: 5606.39 | AJ26: 4703.87 | AK26: 4718.58 | AN26: AM-Shoulder | AO26: 7845 | AP26: 4590.8 | AQ26: 9654 | AR26: 9328.8 | AS26: 9139 | AT26: 7995 | AU26: 7555 | AV26: 6560 | AW26: 5444 | AX26: 5479.8
B27: MD | C27: 0.16 | D27: 0.17 | E27: 0.16 | F27: 0.17 | G27: 0.17 | H27: 0.17 | I27: 0.17 | J27: 0.17 | K27: 0.18 | L27: 0.18 | N27: MD | O27: 3760.23 | P27: 4313.04 | Q27: 4578.12 | R27: 4851.27 | S27: 4618.77 | T27: 5434.09 | U27: 3928.77 | V27: 4810.75 | W27: 5495.65 | X27: 5259.06 | AA27: MD | AB27: 23294.77 | AC27: 25686.96 | AD27: 30736.88 | AE27: 30828.73 | AF27: 26331.23 | AG27: 29575.91 | AH27: 21911.23 | AI27: 26479.25 | AJ27: 33944.35 | AK27: 31913.4 | AN27: MD | AO27: 27055 | AP27: 30000 | AQ27: 35315 | AR27: 35680 | AS27: 30950 | AT27: 35010 | AU27: 25840 | AV27: 31290 | AW27: 39440 | AX27: 37172.46
B28: PM-Shoulder | C28: 0.2 | D28: 0.21 | E28: 0.2 | F28: 0.2 | G28: 0.2 | H28: 0.19 | I28: 0.2 | J28: 0.2 | K28: 0.22 | L28: 0.22 | N28: PM-Shoulder | O28: 1229.5 | P28: 1137.08 | Q28: 1354.44 | R28: 1706.71 | S28: 1604.2 | T28: 1957.65 | U28: 1263.94 | V28: 1901.2 | W28: 1327.7 | X28: 885.83 | AA28: PM-Shoulder | AB28: 6090.29 | AC28: 5273.07 | AD28: 7399.01 | AE28: 8311.29 | AF28: 7260.1 | AG28: 8958.51 | AH28: 5594.06 | AI28: 8405.1 | AJ28: 6591.95 | AK28: 3972.09 | AN28: PM-Shoulder | AO28: 7319.79 | AP28: 6410.15 | AQ28: 8753.45 | AR28: 10018 | AS28: 8864.3 | AT28: 10916.15 | AU28: 6858 | AV28: 10306.3 | AW28: 7919.66 | AX28: 4857.92
B29: PM-Peak | C29: 0.2 | D29: 0.2 | E29: 0.2 | F29: 0.2 | G29: 0.2 | H29: 0.2 | I29: 0.2 | J29: 0.2 | K29: 0.22 | L29: 0.22 | N29: PM-Peak | O29: 4008.84 | P29: 4058.74 | Q29: 3347.52 | R29: 4214.99 | S29: 4339.56 | T29: 4783.23 | U29: 3588.79 | V29: 4043.2 | W29: 2362.15 | X29: 2883.25 | AA29: PM-Peak | AB29: 19602.35 | AC29: 19290.26 | AD29: 17821.68 | AE29: 21933.01 | AF29: 19888.68 | AG29: 21152.26 | AH29: 16378.93 | AI29: 18053.44 | AJ29: 11593.1 | AK29: 13980.35 | AN29: PM-Peak | AO29: 23611.19 | AP29: 23349 | AQ29: 21169.2 | AR29: 26148 | AS29: 24228.25 | AT29: 25935.49 | AU29: 19967.72 | AV29: 22096.63 | AW29: 13955.25 | AX29: 16863.6
B30: PM-Late | C30: 0.2 | D30: 0.21 | E30: 0.2 | F30: 0.18 | G30: 0.21 | H30: 0.21 | I30: 0.21 | J30: 0.05 | K30: 0.22 | L30: 0.22 | N30: PM-Late | O30: 1864.12 | P30: 2439.45 | Q30: 1632.85 | R30: 1742.4 | S30: 1502.5 | T30: 1819 | U30: 1188.43 | V30: 427.63 | W30: 2067.88 | X30: 2276.98 | AA30: PM-Late | AB30: 9466.88 | AC30: 11435.55 | AD30: 9818.15 | AE30: 10740.6 | AF30: 7128.5 | AG30: 8087 | AH30: 5681.57 | AI30: 8344.37 | AJ30: 11477.12 | AK30: 11740.27 | AN30: PM-Late | AO30: 11331 | AP30: 13875 | AQ30: 11451 | AR30: 12483 | AS30: 8631 | AT30: 9906 | AU30: 6870 | AV30: 8772 | AW30: 13545 | AX30: 14017.24
B33: Revenue Per Period | N33: ML Flow (PCE/hr) | AA33: GP Flow (PCE/hr) | AN33: Highway Flow
B34: Direction | C34: NB | D34: SB | E34: NB | F34: SB | G34: NB | H34: SB | I34: NB | J34: SB | K34: NB | L34: SB | N34: Direction | O34: NB | P34: SB | Q34: NB | R34: SB | S34: NB | T34: SB | U34: NB | V34: SB | W34: NB | X34: SB | AA34: Direction | AB34: NB | AC34: SB | AD34: NB | AE34: SB | AF34: NB | AG34: SB | AH34: NB | AI34: SB | AJ34: NB | AK34: SB | AN34: Direction | AO34: NB | AP34: SB | AQ34: NB | AR34: SB | AS34: NB | AT34: SB | AU34: NB | AV34: SB | AW34: NB | AX34: SB
B35: Segment | C35: 11 | D35: 11 | E35: 12 | F35: 12 | G35: 13 | H35: 13 | I35: 14 | J35: 14 | K35: 18 | L35: 18 | N35: Segment | O35: 11 | P35: 11 | Q35: 12 | R35: 12 | S35: 13 | T35: 13 | U35: 14 | V35: 14 | W35: 18 | X35: 18 | AA35: Segment | AB35: 11 | AC35: 11 | AD35: 12 | AE35: 12 | AF35: 13 | AG35: 13 | AH35: 14 | AI35: 14 | AJ35: 18 | AK35: 18 | AN35: Segment | AO35: 11 | AP35: 11 | AQ35: 12 | AR35: 12 | AS35: 13 | AT35: 13 | AU35: 14 | AV35: 14 | AW35: 18 | AX35: 18
B36: Period | N36: Period | AA36: Period | AN36: Period
B37: Night | C37: 427.59 | D37: 425.76 | E37: 591.52 | F37: 450.59 | G37: 360.61 | H37: 319.05 | I37: 432.59 | J37: 305.8 | K37: 360.99 | L37: 289.14 | N37: Night | O37: 138.83 | P37: 138.23 | Q37: 169 | R37: 128.74 | S37: 91.99 | T37: 81.39 | U37: 93.63 | V37: 66.19 | W37: 322.31 | X37: 258.16 | AA37: Night | AB37: 2233.17 | AC37: 2217.77 | AD37: 2627 | AE37: 2020.26 | AF37: 1677.01 | AG37: 1492.61 | AH37: 1457.37 | AI37: 1252.81 | AJ37: 2931.69 | AK37: 2389.84 | AN37: Night | AO37: 2372 | AP37: 2356 | AQ37: 2796 | AR37: 2149 | AS37: 1769 | AT37: 1574 | AU37: 1551 | AV37: 1319 | AW37: 3254 | AX37: 2648
B38: AM-Early | C38: 2301.17 | D38: 699.57 | E38: 1160.57 | F38: 2479.66 | G38: 2472.74 | H38: 1314.62 | I38: 2922.02 | J38: 552.05 | K38: 1211.45 | L38: 721.26 | N38: AM-Early | O38: 1003.76 | P38: 641.04 | Q38: 1148.78 | R38: 637.23 | S38: 1260.6 | T38: 626.67 | U38: 1138.82 | V38: 185.87 | W38: 1206.17 | X38: 954.15 | AA38: AM-Early | AB38: 5771.24 | AC38: 3760.96 | AD38: 6885.22 | AE38: 3928.82 | AF38: 6788.4 | AG38: 3408.33 | AH38: 6118.18 | AI38: 3643.13 | AJ38: 6593.83 | AK38: 5633.85 | AN38: AM-Early | AO38: 6775 | AP38: 4402 | AQ38: 8034 | AR38: 4566.05 | AS38: 8049 | AT38: 4035 | AU38: 7257 | AV38: 3829 | AW38: 7800 | AX38: 6588
B39: AM-Peak | C39: 16329.49 | D39: 5213.71 | E39: 8588.65 | F39: 15736.5 | G39: 21130.78 | H39: 8010.06 | I39: 16319.12 | J39: 3777.09 | K39: 2303.25 | L39: 4153.64 | N39: AM-Peak | O39: 1546.35 | P39: 613.52 | Q39: 1401.77 | R39: 1311.37 | S39: 1572.23 | T39: 1108.72 | U39: 1347.77 | V39: 997.46 | W39: 822.46 | X39: 1081.68 | AA39: AM-Peak | AB39: 6974.95 | AC39: 3690.93 | AD39: 8946.23 | AE39: 5032.03 | AF39: 8537.85 | AG39: 6206.41 | AH39: 7765.74 | AI39: 5793.75 | AJ39: 4664.54 | AK39: 5402.32 | AN39: AM-Peak | AO39: 8521.31 | AP39: 4304.45 | AQ39: 10348 | AR39: 6343.4 | AS39: 10110.08 | AT39: 7315.13 | AU39: 9113.52 | AV39: 6791.21 | AW39: 5487 | AX39: 6484
B40: AM-Shoulder | C40: 3012.89 | D40: 1175.26 | E40: 1820.81 | F40: 4376.28 | G40: 3826.33 | H40: 2440.99 | I40: 1583.25 | J40: 763.79 | K40: 617.13 | L40: 702.45 | N40: AM-Shoulder | O40: 1056.45 | P40: 623.56 | Q40: 1209.2 | R40: 1232.22 | S40: 1340.17 | T40: 1161.05 | U40: 1120.77 | V40: 953.61 | W40: 740.13 | X40: 761.22 | AA40: AM-Shoulder | AB40: 6788.55 | AC40: 3967.24 | AD40: 8444.8 | AE40: 8096.58 | AF40: 7798.83 | AG40: 6833.95 | AH40: 6434.23 | AI40: 5606.39 | AJ40: 4703.87 | AK40: 4718.58 | AN40: AM-Shoulder | AO40: 7845 | AP40: 4590.8 | AQ40: 9654 | AR40: 9328.8 | AS40: 9139 | AT40: 7995 | AU40: 7555 | AV40: 6560 | AW40: 5444 | AX40: 5479.8
B41: MD | C41: 11581.86 | D41: 11977.86 | E41: 10295.66 | F41: 12753.01 | G41: 9300.54 | H41: 10163.58 | I41: 4948.15 | J41: 3197.98 | K41: 6253.22 | L41: 6192.58 | N41: MD | O41: 752.05 | P41: 862.61 | Q41: 915.62 | R41: 970.25 | S41: 923.75 | T41: 1086.82 | U41: 785.75 | V41: 962.15 | W41: 1099.13 | X41: 1051.81 | AA41: MD | AB41: 4658.95 | AC41: 5137.39 | AD41: 6147.38 | AE41: 6165.75 | AF41: 5266.25 | AG41: 5915.18 | AH41: 4382.25 | AI41: 5295.85 | AJ41: 6788.87 | AK41: 6382.68 | AN41: MD | AO41: 5411 | AP41: 6000 | AQ41: 7063 | AR41: 7136 | AS41: 6190 | AT41: 7002 | AU41: 5168 | AV41: 6258 | AW41: 7888 | AX41: 7434.49
B42: PM-Shoulder | C42: 3263.85 | D42: 2984.58 | E42: 2424.96 | F42: 2277.69 | G42: 3029.88 | H42: 5467.7 | I42: 1338.36 | J42: 1529.81 | K42: 1381.67 | L42: 978.27 | N42: PM-Shoulder | O42: 1229.5 | P42: 1137.08 | Q42: 1354.44 | R42: 1706.71 | S42: 1604.2 | T42: 1957.65 | U42: 1263.94 | V42: 1901.2 | W42: 1327.7 | X42: 885.83 | AA42: PM-Shoulder | AB42: 6090.29 | AC42: 5273.07 | AD42: 7399.01 | AE42: 8311.29 | AF42: 7260.1 | AG42: 8958.51 | AH42: 5594.06 | AI42: 8405.1 | AJ42: 6591.95 | AK42: 3972.09 | AN42: PM-Shoulder | AO42: 7319.79 | AP42: 6410.15 | AQ42: 8753.45 | AR42: 10018 | AS42: 8864.3 | AT42: 10916.15 | AU42: 6858 | AV42: 10306.3 | AW42: 7919.66 | AX42: 4857.92
B43: PM-Peak | C43: 13606.64 | D43: 12783.77 | E43: 8921.19 | F43: 7548.29 | G43: 9173.31 | H43: 10951.54 | I43: 5743.55 | J43: 2668.53 | K43: 3017.88 | L43: 3285.74 | N43: PM-Peak | O43: 1336.28 | P43: 1352.91 | Q43: 1115.84 | R43: 1405 | S43: 1446.52 | T43: 1594.41 | U43: 1196.26 | V43: 1347.73 | W43: 787.38 | X43: 961.08 | AA43: PM-Peak | AB43: 6534.12 | AC43: 6430.09 | AD43: 5940.56 | AE43: 7311 | AF43: 6629.56 | AG43: 7050.75 | AH43: 5459.64 | AI43: 6017.81 | AJ43: 3864.37 | AK43: 4660.12 | AN43: PM-Peak | AO43: 7870.4 | AP43: 7783 | AQ43: 7056.4 | AR43: 8716 | AS43: 8076.08 | AT43: 8645.16 | AU43: 6655.91 | AV43: 7365.54 | AW43: 4651.75 | AX43: 5621.2
B44: PM-Late | C44: 2055.98 | D44: 2315.17 | E44: 2434.7 | F44: 871.2 | G44: 2799.09 | H44: 3014.52 | I44: 1955.64 | J44: 1270.07 | K44: 1171.21 | L44: 2068.08 | N44: PM-Late | O44: 621.37 | P44: 813.15 | Q44: 544.28 | R44: 580.8 | S44: 500.83 | T44: 606.33 | U44: 396.14 | V44: 142.54 | W44: 689.29 | X44: 758.99 | AA44: PM-Late | AB44: 3155.63 | AC44: 3811.85 | AD44: 3272.72 | AE44: 3580.2 | AF44: 2376.17 | AG44: 2695.67 | AH44: 1893.86 | AI44: 2781.46 | AJ44: 3825.71 | AK44: 3913.42 | AN44: PM-Late | AO44: 3777 | AP44: 4625 | AQ44: 3817 | AR44: 4161 | AS44: 2877 | AT44: 3302 | AU44: 2290 | AV44: 2924 | AW44: 4515 | AX44: 4672.41
B47: Revenue Per Period Lights | N47: ML V/C | AA47: GP V/C real | AN47: Highway Vol / GP Capacity
...

Sheet Year_2032
B1: Lenght
C2: 11 | D2: 12 | E2: 13 | F2: 14 | G2: 18
B3: Length | C3: 2.2 | D3: 2.5 | E3: 2.8 | F3: 3.3 | G3: 0.8
B5: TollLights | N5: ML PCE.Miles | AA5: GP PCE.Miles | AN5: Highway PCE.Miles
B6: Direction | C6: NB | D6: SB | E6: NB | F6: SB | G6: NB | H6: SB | I6: NB | J6: SB | K6: NB | L6: SB | N6: Direction | O6: NB | P6: SB | Q6: NB | R6: SB | S6: NB | T6: SB | U6: NB | V6: SB | W6: NB | X6: SB | AA6: Direction | AB6: NB | AC6: SB | AD6: NB | AE6: SB | AF6: NB | AG6: SB | AH6: NB | AI6: SB | AJ6: NB | AK6: SB | AN6: Direction | AO6: NB | AP6: SB | AQ6: NB | AR6: SB | AS6: NB | AT6: SB | AU6: NB | AV6: SB | AW6: NB | AX6: SB
B7: Segment | C7: 11 | D7: 11 | E7: 12 | F7: 12 | G7: 13 | H7: 13 | I7: 14 | J7: 14 | K7: 18 | L7: 18 | N7: Segment | O7: 11 | P7: 11 | Q7: 12 | R7: 12 | S7: 13 | T7: 13 | U7: 14 | V7: 14 | W7: 18 | X7: 18 | AA7: Segment | AB7: 11 | AC7: 11 | AD7: 12 | AE7: 12 | AF7: 13 | AG7: 13 | AH7: 14 | AI7: 14 | AJ7: 18 | AK7: 18 | AN7: Segment | AO7: 11 | AP7: 11 | AQ7: 12 | AR7: 12 | AS7: 13 | AT7: 13 | AU7: 14 | AV7: 14 | AW7: 18 | AX7: 18
B8: Period | N8: Period | AA8: Period | AN8: Period
B9: Night | C9: 0.2 | D9: 0.2 | E9: 0.2 | F9: 0.2 | G9: 0.2 | H9: 0.2 | I9: 0.2 | J9: 0.2 | K9: 0.2 | L9: 0.2 | N9: Night | O9: 4218.48 | P9: 4156.06 | Q9: 5771.7 | R9: 2708.68 | S9: 2330.76 | T9: 2069.94 | U9: 2620.72 | V9: 1852.56 | W9: 1786.25 | X9: 1439.49 | AA9: Night | AB9: 39702.32 | AC9: 39467.52 | AD9: 53058.05 | AE9: 42504.32 | AF9: 39672.04 | AG9: 35305.3 | AH9: 40786.49 | AI9: 35065.86 | AJ9: 16436.15 | AK9: 13389.31 | AN9: Night | AO9: 43920.8 | AP9: 43623.58 | AQ9: 58829.75 | AR9: 45213 | AS9: 42002.8 | AT9: 37375.24 | AU9: 43407.21 | AV9: 36918.42 | AW9: 18222.4 | AX9: 14828.8
B10: AM-Early | C10: 1.8 | D10: 0.89 | E10: 0.82 | F10: 1.8 | G10: 1.66 | H10: 1.44 | I10: 1.8 | J10: 0.9 | K10: 1.8 | L10: 1.3 | N10: AM-Early | O10: 2683.06 | P10: 1691.17 | Q10: 3397 | R10: 2022.46 | S10: 4120.83 | T10: 2115.09 | U10: 4559.13 | V10: 743.13 | W10: 1030.22 | X10: 762.68 | AA10: AM-Early | AB10: 14056.39 | AC10: 9952.11 | AD10: 20750.75 | AE10: 9735.11 | AF10: 23183.65 | AG10: 11572.43 | AH10: 24301.7 | AI10: 14565.24 | AJ10: 5396.98 | AK10: 4507.72 | AN10: AM-Early | AO10: 16739.45 | AP10: 11643.28 | AQ10: 24147.75 | AR10: 11757.57 | AS10: 27304.48 | AT10: 13687.52 | AU10: 28860.83 | AV10: 15308.37 | AW10: 6427.2 | AX10: 5270.4
B11: AM-Peak | C11: 3.95 | D11: 1.8 | E11: 1.8 | F11: 1.8 | G11: 3.72 | H11: 1.73 | I11: 3.27 | J11: 0.71 | K11: 1.61 | L11: 1.8 | N11: AM-Peak | O11: 12148.22 | P11: 6015.37 | Q11: 12411.5 | R11: 13943.54 | S11: 17271.98 | T11: 10986.03 | U11: 14976.19 | V11: 11700.32 | W11: 1972.33 | X11: 2947.95 | AA11: AM-Peak | AB11: 54907.78 | AC11: 28141.91 | AD11: 80899 | AE11: 39032.62 | AF11: 85619.15 | AG11: 63459.03 | AH11: 94330.76 | AI11: 69755.03 | AJ11: 11196.47 | AK11: 12613.65 | AN11: AM-Peak | AO11: 67056 | AP11: 34157.28 | AQ11: 93310.5 | AR11: 52976.16 | AS11: 102891.13 | AT11: 74445.06 | AU11: 109306.96 | AV11: 81455.35 | AW11: 13168.8 | AX11: 15561.6
B12: AM-Shoulder | C12: 1.8 | D12: 1.79 | E12: 1.36 | F12: 1.8 | G12: 2.29 | H12: 1.73 | I12: 0.89 | J12: 0.44 | K12: 1.44 | L12: 1.59 | N12: AM-Shoulder | O12: 2959.71 | P12: 1644.59 | Q12: 3582.77 | R12: 3710.07 | S12: 4162.8 | T12: 3847.94 | U12: 4385.13 | V12: 3764.36 | W12: 591.96 | X12: 608.79 | AA12: AM-Shoulder | AB12: 15671.07 | AC12: 10497.9 | AD12: 25434.98 | AE12: 20555.58 | AF12: 25237.2 | AG12: 23273.42 | AH12: 25819.44 | AI12: 22462.39 | AJ12: 3763.24 | AK12: 3775.05 | AN12: AM-Shoulder | AO12: 18630.78 | AP12: 12142.48 | AQ12: 29017.75 | AR12: 24265.65 | AS12: 29400 | AT12: 27121.36 | AU12: 30204.57 | AV12: 26226.75 | AW12: 4355.2 | AX12: 4383.84
B13: MD | C13: 1.8 | D13: 1.8 | E13: 1.8 | F13: 1.8 | G13: 1.5 | H13: 1.44 | I13: 0.69 | J13: 0.37 | K13: 1.8 | L13: 1.8 | N13: MD | O13: 11019.89 | P13: 12302.52 | Q13: 15249.7 | R13: 16469.84 | S13: 15469.36 | T13: 18053.7 | U13: 15582.85 | V13: 18963.64 | W13: 4672.9 | X13: 5331.59 | AA13: MD | AB13: 52911.55 | AC13: 59875.78 | AD13: 90902.8 | AE13: 86881.7 | AF13: 89519.44 | AG13: 100711.1 | AH13: 87722 | AI13: 106134.41 | AJ13: 26879.1 | AK13: 25864.12 | AN13: MD | AO13: 63931.44 | AP13: 72178.3 | AQ13: 106152.5 | AR13: 103351.54 | AS13: 104988.8 | AT13: 118764.8 | AU13: 103304.85 | AV13: 125098.05 | AW13: 31552 | AX13: 31195.71
B14: PM-Shoulder | C14: 1.8 | D14: 1.8 | E14: 1.8 | F14: 1.58 | G14: 1.78 | H14: 1.71 | I14: 0.7 | J14: 0.97 | K14: 1.8 | L14: 1.8 | N14: PM-Shoulder | O14: 2838.84 | P14: 2600.99 | Q14: 4023.86 | R14: 4835.95 | S14: 5018.2 | T14: 5395.59 | U14: 4913.4 | V14: 6772.12 | W14: 1209.05 | X14: 877.86 | AA14: PM-Shoulder | AB14: 13738.33 | AC14: 11916.11 | AD14: 22226.14 | AE14: 25255.62 | AF14: 24381.8 | AG14: 26068.61 | AH14: 22505.31 | AI14: 34433.23 | AJ14: 5383.75 | AK14: 3230.55 | AN14: PM-Shoulder | AO14: 16577.17 | AP14: 14517.1 | AQ14: 26250 | AR14: 30091.57 | AS14: 29400 | AT14: 31464.21 | AU14: 27418.71 | AV14: 41205.35 | AW14: 6592.8 | AX14: 4108.41
B15: PM-Peak | C15: 1.8 | D15: 1.8 | E15: 1.8 | F15: 1.63 | G15: 1.79 | H15: 1.8 | I15: 0.99 | J15: 0.44 | K15: 1.8 | L15: 2 | N15: PM-Peak | O15: 14524.27 | P15: 14105.24 | Q15: 11631.62 | R15: 12245.04 | S15: 13938.32 | T15: 16460.66 | U15: 13879.43 | V15: 15641.17 | W15: 2223.96 | X15: 2303.83 | AA15: PM-Peak | AB15: 47927.37 | AC15: 47655.58 | AD15: 51995.01 | AE15: 66351.21 | AF15: 68248.26 | AG15: 71519.49 | AH15: 65955 | AI15: 72701.37 | AJ15: 8940.24 | AK15: 11187.05 | AN15: PM-Peak | AO15: 62451.65 | AP15: 61760.82 | AQ15: 63626.63 | AR15: 78596.25 | AS15: 82186.57 | AT15: 87980.14 | AU15: 79834.43 | AV15: 88342.54 | AW15: 11164.2 | AX15: 13490.88
B16: PM-Late | C16: 0.92 | D16: 0.81 | E16: 1.12 | F16: 0.27 | G16: 1.23 | H16: 1.08 | I16: 0.89 | J16: 1.35 | K16: 0.99 | L16: 1.73 | N16: PM-Late | O16: 4920.78 | P16: 6419.78 | Q16: 4893.78 | R16: 5857.5 | S16: 5055 | T16: 6151.03 | U16: 4748.66 | V16: 1709.58 | W16: 1654.18 | X16: 1877.62 | AA16: PM-Late | AB16: 25050.48 | AC16: 30282.16 | AD16: 29524.47 | AE16: 31662.75 | AF16: 24224.04 | AG16: 27450.65 | AH16: 22718.89 | AI16: 33358.2 | AJ16: 9181.82 | AK16: 9690.29 | AN16: PM-Late | AO16: 29971.26 | AP16: 36701.94 | AQ16: 34418.25 | AR16: 37520.25 | AS16: 29279.04 | AT16: 33601.68 | AU16: 27467.55 | AV16: 35067.78 | AW16: 10836 | AX16: 11567.91
B19: CaptureRateLights | N19: ML Volume (PCE/Period) | AA19: GP Volume (PCE/Period) | AN19: Highway Volume
B20: Direction | C20: NB | D20: SB | E20: NB | F20: SB | G20: NB | H20: SB | I20: NB | J20: SB | K20: NB | L20: SB | N20: Direction | O20: NB | P20: SB | Q20: NB | R20: SB | S20: NB | T20: SB | U20: NB | V20: SB | W20: NB | X20: SB | AA20: Direction | AB20: NB | AC20: SB | AD20: NB | AE20: SB | AF20: NB | AG20: SB | AH20: NB | AI20: SB | AJ20: NB | AK20: SB | AN20: Direction | AO20: NB | AP20: SB | AQ20: NB | AR20: SB | AS20: NB | AT20: SB | AU20: NB | AV20: SB | AW20: NB | AX20: SB
B21: Segment | C21: 11 | D21: 11 | E21: 12 | F21: 12 | G21: 13 | H21: 13 | I21: 14 | J21: 14 | K21: 18 | L21: 18 | N21: Segment | O21: 11 | P21: 11 | Q21: 12 | R21: 12 | S21: 13 | T21: 13 | U21: 14 | V21: 14 | W21: 18 | X21: 18 | AA21: Segment | AB21: 11 | AC21: 11 | AD21: 12 | AE21: 12 | AF21: 13 | AG21: 13 | AH21: 14 | AI21: 14 | AJ21: 18 | AK21: 18 | AN21: Segment | AO21: 11 | AP21: 11 | AQ21: 12 | AR21: 12 | AS21: 13 | AT21: 13 | AU21: 14 | AV21: 14 | AW21: 18 | AX21: 18
B22: Period | N22: Period | AA22: Period | AN22: Period
B23: Night | C23: 0.1 | D23: 0.1 | E23: 0.1 | F23: 0.06 | G23: 0.06 | H23: 0.06 | I23: 0.06 | J23: 0.05 | K23: 0.1 | L23: 0.1 | N23: Night | O23: 1917.49 | P23: 1889.12 | Q23: 2308.68 | R23: 1083.47 | S23: 832.41 | T23: 739.27 | U23: 794.16 | V23: 561.38 | W23: 2232.82 | X23: 1799.37 | AA23: Night | AB23: 18046.51 | AC23: 17939.78 | AD23: 21223.22 | AE23: 17001.73 | AF23: 14168.59 | AG23: 12609.03 | AH23: 12359.54 | AI23: 10626.02 | AJ23: 20545.18 | AK23: 16736.63 | AN23: Night | AO23: 19964 | AP23: 19828.9 | AQ23: 23531.9 | AR23: 18085.2 | AS23: 15001 | AT23: 13348.3 | AU23: 13153.7 | AV23: 11187.4 | AW23: 22778 | AX23: 18536
B24: AM-Early | C24: 0.18 | D24: 0.17 | E24: 0.16 | F24: 0.21 | G24: 0.16 | H24: 0.17 | I24: 0.17 | J24: 0.05 | K24: 0.18 | L24: 0.18 | N24: AM-Early | O24: 1219.57 | P24: 768.72 | Q24: 1358.8 | R24: 808.98 | S24: 1471.73 | T24: 755.39 | U24: 1381.56 | V24: 225.19 | W24: 1287.78 | X24: 953.35 | AA24: AM-Early | AB24: 6389.27 | AC24: 4523.68 | AD24: 8300.3 | AE24: 3894.04 | AF24: 8279.87 | AG24: 4133.01 | AH24: 7364.15 | AI24: 4413.71 | AJ24: 6746.22 | AK24: 5634.65 | AN24: AM-Early | AO24: 7608.84 | AP24: 5292.4 | AQ24: 9659.1 | AR24: 4703.03 | AS24: 9751.6 | AT24: 4888.4 | AU24: 8745.71 | AV24: 4638.9 | AW24: 8034 | AX24: 6588
B25: AM-Peak | C25: 0.21 | D25: 0.21 | E25: 0.15 | F25: 0.29 | G25: 0.18 | H25: 0.16 | I25: 0.15 | J25: 0.16 | K25: 0.18 | L25: 0.23 | N25: AM-Peak | O25: 5521.92 | P25: 2734.26 | Q25: 4964.6 | R25: 5577.42 | S25: 6168.56 | T25: 3923.58 | U25: 4538.24 | V25: 3545.55 | W25: 2465.41 | X25: 3684.93 | AA25: AM-Peak | AB25: 24958.08 | AC25: 12791.78 | AD25: 32359.6 | AE25: 15613.05 | AF25: 30578.27 | AG25: 22663.94 | AH25: 28585.08 | AI25: 21137.89 | AJ25: 13995.59 | AK25: 15767.07 | AN25: AM-Peak | AO25: 30480 | AP25: 15526.03 | AQ25: 37324.2 | AR25: 21190.46 | AS25: 36746.83 | AT25: 26587.52 | AU25: 33123.32 | AV25: 24683.44 | AW25: 16461 | AX25: 19452
B26: AM-Shoulder | C26: 0.19 | D26: 0.17 | E26: 0.16 | F26: 0.19 | G26: 0.16 | H26: 0.17 | I26: 0.16 | J26: 0.17 | K26: 0.18 | L26: 0.18 | N26: AM-Shoulder | O26: 1345.32 | P26: 747.54 | Q26: 1433.11 | R26: 1484.03 | S26: 1486.71 | T26: 1374.26 | U26: 1328.83 | V26: 1140.72 | W26: 739.95 | X26: 760.99 | AA26: AM-Shoulder | AB26: 7123.21 | AC26: 4771.77 | AD26: 10173.99 | AE26: 8222.23 | AF26: 9013.29 | AG26: 8311.94 | AH26: 7824.07 | AI26: 6806.78 | AJ26: 4704.05 | AK26: 4718.81 | AN26: AM-Shoulder | AO26: 8468.53 | AP26: 5519.31 | AQ26: 11607.1 | AR26: 9706.26 | AS26: 10500 | AT26: 9686.2 | AU26: 9152.9 | AV26: 7947.5 | AW26: 5444 | AX26: 5479.8
B27: MD | C27: 0.2 | D27: 0.2 | E27: 0.18 | F27: 0.2 | G27: 0.17 | H27: 0.17 | I27: 0.17 | J27: 0.17 | K27: 0.19 | L27: 0.21 | N27: MD | O27: 5009.04 | P27: 5592.06 | Q27: 6099.88 | R27: 6587.94 | S27: 5524.77 | T27: 6447.75 | U27: 4722.07 | V27: 5746.56 | W27: 5841.13 | X27: 6664.49 | AA27: MD | AB27: 24050.71 | AC27: 27216.26 | AD27: 36361.12 | AE27: 34752.68 | AF27: 31971.23 | AG27: 35968.25 | AH27: 26582.43 | AI27: 32161.94 | AJ27: 33598.87 | AK27: 32330.16 | AN27: MD | AO27: 29059.75 | AP27: 32808.32 | AQ27: 42461 | AR27: 41340.61 | AS27: 37496 | AT27: 42416 | AU27: 31304.5 | AV27: 37908.5 | AW27: 39440 | AX27: 38994.64
B28: PM-Shoulder | C28: 0.2 | D28: 0.21 | E28: 0.2 | F28: 0.19 | G28: 0.19 | H28: 0.19 | I28: 0.2 | J28: 0.17 | K28: 0.24 | L28: 0.25 | N28: PM-Shoulder | O28: 1290.38 | P28: 1182.27 | Q28: 1609.55 | R28: 1934.38 | S28: 1792.21 | T28: 1927 | U28: 1488.91 | V28: 2052.16 | W28: 1511.31 | X28: 1097.33 | AA28: PM-Shoulder | AB28: 6244.69 | AC28: 5416.41 | AD28: 8890.45 | AE28: 10102.25 | AF28: 8707.79 | AG28: 9310.22 | AH28: 6819.79 | AI28: 10434.31 | AJ28: 6729.69 | AK28: 4038.18 | AN28: PM-Shoulder | AO28: 7535.08 | AP28: 6598.68 | AQ28: 10500 | AR28: 12036.63 | AS28: 10500 | AT28: 11237.22 | AU28: 8308.7 | AV28: 12486.47 | AW28: 8241 | AX28: 5135.51
B29: PM-Peak | C29: 0.27 | D29: 0.27 | E29: 0.23 | F29: 0.2 | G29: 0.19 | H29: 0.2 | I29: 0.2 | J29: 0.19 | K29: 0.25 | L29: 0.22 | N29: PM-Peak | O29: 6601.94 | P29: 6411.47 | Q29: 4652.65 | R29: 4898.02 | S29: 4977.97 | T29: 5878.81 | U29: 4205.89 | V29: 4739.75 | W29: 2779.95 | X29: 2879.78 | AA29: PM-Peak | AB29: 21785.17 | AC29: 21661.63 | AD29: 20798 | AE29: 26540.48 | AF29: 24374.38 | AG29: 25542.67 | AH29: 19986.36 | AI29: 22030.72 | AJ29: 11175.3 | AK29: 13983.82 | AN29: PM-Peak | AO29: 28387.11 | AP29: 28073.1 | AQ29: 25450.65 | AR29: 31438.5 | AS29: 29352.35 | AT29: 31421.48 | AU29: 24192.25 | AV29: 26770.47 | AW29: 13955.25 | AX29: 16863.6
B30: PM-Late | C30: 0.2 | D30: 0.21 | E30: 0.2 | F30: 0.21 | G30: 0.21 | H30: 0.21 | I30: 0.21 | J30: 0.05 | K30: 0.22 | L30: 0.22 | N30: PM-Late | O30: 2236.72 | P30: 2918.08 | Q30: 1957.51 | R30: 2343 | S30: 1805.36 | T30: 2196.8 | U30: 1438.99 | V30: 518.06 | W30: 2067.73 | X30: 2347.03 | AA30: PM-Late | AB30: 11386.58 | AC30: 13764.62 | AD30: 11809.79 | AE30: 12665.1 | AF30: 8651.44 | AG30: 9803.8 | AH30: 6884.51 | AI30: 10108.54 | AJ30: 11477.27 | AK30: 12112.86 | AN30: PM-Late | AO30: 13623.3 | AP30: 16682.7 | AQ30: 13767.3 | AR30: 15008.1 | AS30: 10456.8 | AT30: 12000.6 | AU30: 8323.5 | AV30: 10626.6 | AW30: 13545 | AX30: 14459.89
B33: Revenue Per Period | N33: ML Flow (PCE/hr) | AA33: GP Flow (PCE/hr) | AN33: Highway Flow
B34: Direction | C34: NB | D34: SB | E34: NB | F34: SB | G34: NB | H34: SB | I34: NB | J34: SB | K34: NB | L34: SB | N34: Direction | O34: NB | P34: SB | Q34: NB | R34: SB | S34: NB | T34: SB | U34: NB | V34: SB | W34: NB | X34: SB | AA34: Direction | AB34: NB | AC34: SB | AD34: NB | AE34: SB | AF34: NB | AG34: SB | AH34: NB | AI34: SB | AJ34: NB | AK34: SB | AN34: Direction | AO34: NB | AP34: SB | AQ34: NB | AR34: SB | AS34: NB | AT34: SB | AU34: NB | AV34: SB | AW34: NB | AX34: SB
B35: Segment | C35: 11 | D35: 11 | E35: 12 | F35: 12 | G35: 13 | H35: 13 | I35: 14 | J35: 14 | K35: 18 | L35: 18 | N35: Segment | O35: 11 | P35: 11 | Q35: 12 | R35: 12 | S35: 13 | T35: 13 | U35: 14 | V35: 14 | W35: 18 | X35: 18 | AA35: Segment | AB35: 11 | AC35: 11 | AD35: 12 | AE35: 12 | AF35: 13 | AG35: 13 | AH35: 14 | AI35: 14 | AJ35: 18 | AK35: 18 | AN35: Segment | AO35: 11 | AP35: 11 | AQ35: 12 | AR35: 12 | AS35: 13 | AT35: 13 | AU35: 14 | AV35: 14 | AW35: 18 | AX35: 18
B36: Period | N36: Period | AA36: Period | AN36: Period
B37: Night | C37: 843.7 | D37: 831.21 | E37: 1154.34 | F37: 541.74 | G37: 466.15 | H37: 413.99 | I37: 524.14 | J37: 370.51 | K37: 357.25 | L37: 287.9 | N37: Night | O37: 273.93 | P37: 269.87 | Q37: 329.81 | R37: 154.78 | S37: 118.92 | T37: 105.61 | U37: 113.45 | V37: 80.2 | W37: 318.97 | X37: 257.05 | AA37: Night | AB37: 2578.07 | AC37: 2562.83 | AD37: 3031.89 | AE37: 2428.82 | AF37: 2024.08 | AG37: 1801.29 | AH37: 1765.65 | AI37: 1518 | AJ37: 2935.03 | AK37: 2390.95 | AN37: Night | AO37: 2852 | AP37: 2832.7 | AQ37: 3361.7 | AR37: 2583.6 | AS37: 2143 | AT37: 1906.9 | AU37: 1879.1 | AV37: 1598.2 | AW37: 3254 | AX37: 2648
B38: AM-Early | C38: 4829.51 | D38: 1508.83 | E38: 2787.44 | F38: 3640.43 | G38: 6856.87 | H38: 3039.03 | I38: 8206.44 | J38: 668.82 | K38: 1854.4 | L38: 993.41 | N38: AM-Early | O38: 1219.57 | P38: 768.72 | Q38: 1358.8 | R38: 808.98 | S38: 1471.73 | T38: 755.39 | U38: 1381.56 | V38: 225.19 | W38: 1287.78 | X38: 953.35 | AA38: AM-Early | AB38: 6389.27 | AC38: 4523.68 | AD38: 8300.3 | AE38: 3894.04 | AF38: 8279.87 | AG38: 4133.01 | AH38: 7364.15 | AI38: 4413.71 | AJ38: 6746.22 | AK38: 5634.65 | AN38: AM-Early | AO38: 7608.84 | AP38: 5292.4 | AQ38: 9659.1 | AR38: 4703.03 | AS38: 9751.6 | AT38: 4888.4 | AU38: 8745.71 | AV38: 4638.9 | AW38: 8034 | AX38: 6588
B39: AM-Peak | C39: 48002.51 | D39: 10827.66 | E39: 22340.68 | F39: 25098.37 | G39: 64186.32 | H39: 19017.3 | I39: 49041.25 | J39: 8251.83 | K39: 3172.02 | L39: 5306.27 | N39: AM-Peak | O39: 1840.64 | P39: 911.42 | Q39: 1654.87 | R39: 1859.14 | S39: 2056.19 | T39: 1307.86 | U39: 1512.75 | V39: 1181.85 | W39: 821.8 | X39: 1228.31 | AA39: AM-Peak | AB39: 8319.36 | AC39: 4263.93 | AD39: 10786.53 | AE39: 5204.35 | AF39: 10192.76 | AG39: 7554.65 | AH39: 9528.36 | AI39: 7045.96 | AJ39: 4665.2 | AK39: 5255.69 | AN39: AM-Peak | AO39: 10160 | AP39: 5175.34 | AQ39: 12441.4 | AR39: 7063.49 | AS39: 12248.94 | AT39: 8862.51 | AU39: 11041.11 | AV39: 8227.81 | AW39: 5487 | AX39: 6484
B40: AM-Shoulder | C40: 5327.48 | D40: 2949.67 | E40: 4876.72 | F40: 6678.12 | G40: 9528.72 | H40: 6653.53 | I40: 3922.36 | J40: 1667.06 | K40: 849.79 | L40: 967.28 | N40: AM-Shoulder | O40: 1345.32 | P40: 747.54 | Q40: 1433.11 | R40: 1484.03 | S40: 1486.71 | T40: 1374.26 | U40: 1328.83 | V40: 1140.72 | W40: 739.95 | X40: 760.99 | AA40: AM-Shoulder | AB40: 7123.21 | AC40: 4771.77 | AD40: 10173.99 | AE40: 8222.23 | AF40: 9013.29 | AG40: 8311.94 | AH40: 7824.07 | AI40: 6806.78 | AJ40: 4704.05 | AK40: 4718.81 | AN40: AM-Shoulder | AO40: 8468.53 | AP40: 5519.31 | AQ40: 11607.1 | AR40: 9706.26 | AS40: 10500 | AT40: 9686.2 | AU40: 9152.9 | AV40: 7947.5 | AW40: 5444 | AX40: 5479.8
B41: MD | C41: 19835.8 | D41: 22144.48 | E41: 27449.46 | F41: 29645.71 | G41: 23137.66 | H41: 26017.79 | I41: 10809.97 | J41: 6964.67 | K41: 8411.22 | L41: 9596.86 | N41: MD | O41: 1001.81 | P41: 1118.41 | Q41: 1219.98 | R41: 1317.59 | S41: 1104.95 | T41: 1289.55 | U41: 944.41 | V41: 1149.31 | W41: 1168.23 | X41: 1332.9 | AA41: MD | AB41: 4810.14 | AC41: 5443.25 | AD41: 7272.22 | AE41: 6950.54 | AF41: 6394.25 | AG41: 7193.65 | AH41: 5316.49 | AI41: 6432.39 | AJ41: 6719.77 | AK41: 6466.03 | AN41: MD | AO41: 5811.95 | AP41: 6561.66 | AQ41: 8492.2 | AR41: 8268.12 | AS41: 7499.2 | AT41: 8483.2 | AU41: 6260.9 | AV41: 7581.7 | AW41: 7888 | AX41: 7798.93
B42: PM-Shoulder | C42: 5109.92 | D42: 4681.78 | E42: 7242.94 | F42: 7658.71 | G42: 8918.1 | H42: 9200.44 | I42: 3457.56 | J42: 6601.94 | K42: 2176.28 | L42: 1580.15 | N42: PM-Shoulder | O42: 1290.38 | P42: 1182.27 | Q42: 1609.55 | R42: 1934.38 | S42: 1792.21 | T42: 1927 | U42: 1488.91 | V42: 2052.16 | W42: 1511.31 | X42: 1097.33 | AA42: PM-Shoulder | AB42: 6244.69 | AC42: 5416.41 | AD42: 8890.45 | AE42: 10102.25 | AF42: 8707.79 | AG42: 9310.22 | AH42: 6819.79 | AI42: 10434.31 | AJ42: 6729.69 | AK42: 4038.18 | AN42: PM-Shoulder | AO42: 7535.08 | AP42: 6598.68 | AQ42: 10500 | AR42: 12036.63 | AS42: 10500 | AT42: 11237.22 | AU42: 8308.7 | AV42: 12486.47 | AW42: 8241 | AX42: 5135.51
B43: PM-Peak | C43: 26143.61 | D43: 25389.41 | E43: 20936.91 | F43: 20012.26 | G43: 24996.4 | H43: 29629.18 | I43: 13807.66 | J43: 6819.38 | K43: 4003.12 | L43: 4597.32 | N43: PM-Peak | O43: 2200.65 | P43: 2137.16 | Q43: 1550.88 | R43: 1632.67 | S43: 1659.32 | T43: 1959.6 | U43: 1401.96 | V43: 1579.92 | W43: 926.65 | X43: 959.93 | AA43: PM-Peak | AB43: 7261.72 | AC43: 7220.54 | AD43: 6932.67 | AE43: 8846.83 | AF43: 8124.79 | AG43: 8514.22 | AH43: 6662.12 | AI43: 7343.57 | AJ43: 3725.1 | AK43: 4661.27 | AN43: PM-Peak | AO43: 9462.37 | AP43: 9357.7 | AQ43: 8483.55 | AR43: 10479.5 | AS43: 9784.12 | AT43: 10473.83 | AU43: 8064.08 | AV43: 8923.49 | AW43: 4651.75 | AX43: 5621.2
B44: PM-Late | C44: 4537.66 | D44: 5192.18 | E44: 5499.88 | F44: 1560.86 | G44: 6239.49 | H44: 6633.32 | I44: 4220.75 | J44: 2307.94 | K44: 1638.17 | L44: 3241.9 | N44: PM-Late | O44: 745.57 | P44: 972.69 | Q44: 652.5 | R44: 781 | S44: 601.79 | T44: 732.27 | U44: 479.66 | V44: 172.69 | W44: 689.24 | X44: 782.34 | AA44: PM-Late | AB44: 3795.53 | AC44: 4588.21 | AD44: 3936.6 | AE44: 4221.7 | AF44: 2883.81 | AG44: 3267.93 | AH44: 2294.84 | AI44: 3369.51 | AJ44: 3825.76 | AK44: 4037.62 | AN44: PM-Late | AO44: 4541.1 | AP44: 5560.9 | AQ44: 4589.1 | AR44: 5002.7 | AS44: 3485.6 | AT44: 4000.2 | AU44: 2774.5 | AV44: 3542.2 | AW44: 4515 | AX44: 4819.96
B47: Revenue Per Period Lights | N47: ML V/C | AA47: GP V/C real | AN47: Highway Vol / GP Capacity
...

Sheet Year_2040
B1: Lenght
C2: 11 | D2: 12 | E2: 13 | F2: 14 | G2: 18
B3: Length | C3: 2.2 | D3: 2.5 | E3: 2.8 | F3: 3.3 | G3: 0.8
B5: TollLights | N5: ML PCE.Miles | AA5: GP PCE.Miles | AN5: Highway PCE.Miles
B6: Direction | C6: NB | D6: SB | E6: NB | F6: SB | G6: NB | H6: SB | I6: NB | J6: SB | K6: NB | L6: SB | N6: Direction | O6: NB | P6: SB | Q6: NB | R6: SB | S6: NB | T6: SB | U6: NB | V6: SB | W6: NB | X6: SB | AA6: Direction | AB6: NB | AC6: SB | AD6: NB | AE6: SB | AF6: NB | AG6: SB | AH6: NB | AI6: SB | AJ6: NB | AK6: SB | AN6: Direction | AO6: NB | AP6: SB | AQ6: NB | AR6: SB | AS6: NB | AT6: SB | AU6: NB | AV6: SB | AW6: NB | AX6: SB
B7: Segment | C7: 11 | D7: 11 | E7: 12 | F7: 12 | G7: 13 | H7: 13 | I7: 14 | J7: 14 | K7: 18 | L7: 18 | N7: Segment | O7: 11 | P7: 11 | Q7: 12 | R7: 12 | S7: 13 | T7: 13 | U7: 14 | V7: 14 | W7: 18 | X7: 18 | AA7: Segment | AB7: 11 | AC7: 11 | AD7: 12 | AE7: 12 | AF7: 13 | AG7: 13 | AH7: 14 | AI7: 14 | AJ7: 18 | AK7: 18 | AN7: Segment | AO7: 11 | AP7: 11 | AQ7: 12 | AR7: 12 | AS7: 13 | AT7: 13 | AU7: 14 | AV7: 14 | AW7: 18 | AX7: 18
B8: Period | N8: Period | AA8: Period | AN8: Period
B9: Night | C9: 0.2 | D9: 0.2 | E9: 0.2 | F9: 0.2 | G9: 0.2 | H9: 0.2 | I9: 0.2 | J9: 0.2 | K9: 0.2 | L9: 0.2 | N9: Night | O9: 4641.72 | P9: 4653.94 | Q9: 6439.75 | R9: 3007.44 | S9: 4096.36 | T9: 3579.09 | U9: 2929.91 | V9: 2070.83 | W9: 1798.9 | X9: 1435.62 | AA9: Night | AB9: 44117.76 | AC9: 43782.14 | AD9: 58873.75 | AE9: 47194.81 | AF9: 42865.24 | AG9: 38202.23 | AH9: 45600.88 | AI9: 39197.32 | AJ9: 16423.5 | AK9: 13393.18 | AN9: Night | AO9: 48759.48 | AP9: 48436.08 | AQ9: 65313.5 | AR9: 50202.25 | AS9: 46961.6 | AT9: 41781.32 | AU9: 48530.79 | AV9: 41268.15 | AW9: 18222.4 | AX9: 14828.8
B10: AM-Early | C10: 2.1 | D10: 1.58 | E10: 1.65 | F10: 2.1 | G10: 2.1 | H10: 2.1 | I10: 2.1 | J10: 0.9 | K10: 2.1 | L10: 1.9 | N10: AM-Early | O10: 3483.19 | P10: 1868.6 | Q10: 3664.58 | R10: 2669.42 | S10: 5829.56 | T10: 2852.73 | U10: 5863.87 | V10: 1434.52 | W10: 1266.81 | X10: 761.6 | AA10: AM-Early | AB10: 14068.85 | AC10: 11058.82 | AD10: 23146.92 | AE10: 9658.9 | AF10: 24410.44 | AG10: 12450.67 | AH10: 24397.98 | AI10: 15680.27 | AJ10: 5347.59 | AK10: 4508.8 | AN10: AM-Early | AO10: 17552.05 | AP10: 12927.42 | AQ10: 26811.5 | AR10: 12328.32 | AS10: 30240 | AT10: 15303.4 | AU10: 30261.84 | AV10: 17114.79 | AW10: 6614.4 | AX10: 5270.4
B11: AM-Peak | C11: 6.3 | D11: 2.1 | E11: 4.2 | F11: 6.3 | G11: 6.3 | H11: 2.1 | I11: 6.2 | J11: 1.31 | K11: 2.1 | L11: 2.1 | N11: AM-Peak | O11: 16125.21 | P11: 8512.94 | Q11: 12631.54 | R11: 13350.41 | S11: 22390.39 | T11: 15452.6 | U11: 18458.33 | V11: 12618.84 | W11: 2139.29 | X11: 3315.05 | AA11: AM-Peak | AB11: 58948.82 | AC11: 29410.5 | AD11: 90971.21 | AE11: 46299.91 | AF11: 92636.27 | AG11: 67775.13 | AH11: 103744.54 | AI11: 78446.34 | AJ11: 11029.51 | AK11: 12246.55 | AN11: AM-Peak | AO11: 75074.03 | AP11: 37923.44 | AQ11: 103602.75 | AR11: 59650.32 | AS11: 115026.66 | AT11: 83227.72 | AU11: 122202.88 | AV11: 91065.17 | AW11: 13168.8 | AX11: 15561.6
B12: AM-Shoulder | C12: 2.1 | D12: 2.1 | E12: 2.1 | F12: 2.1 | G12: 3.74 | H12: 2.1 | I12: 1.87 | J12: 0.81 | K12: 2.09 | L12: 2.1 | N12: AM-Shoulder | O12: 3537.98 | P12: 2638.88 | Q12: 4701.99 | R12: 4416.89 | S12: 4105.88 | T12: 5604.27 | U12: 4713.3 | V12: 4120.28 | W12: 591.76 | X12: 659 | AA12: AM-Shoulder | AB12: 15447.67 | AC12: 10843.74 | AD12: 27515.26 | AE12: 20310.96 | AF12: 25854.12 | AG12: 24355.73 | AH12: 29055.6 | AI12: 25201.21 | AJ12: 3763.44 | AK12: 3724.84 | AN12: AM-Shoulder | AO12: 18985.65 | AP12: 13482.62 | AQ12: 32217.25 | AR12: 24727.85 | AS12: 29960 | AT12: 29960 | AU12: 33768.9 | AV12: 29321.49 | AW12: 4355.2 | AX12: 4383.84
B13: MD | C13: 2.1 | D13: 3.62 | E13: 2.1 | F13: 2.1 | G13: 2.1 | H13: 2.1 | I13: 1.25 | J13: 0.67 | K13: 2.1 | L13: 2.1 | N13: MD | O13: 13316.35 | P13: 10406.91 | Q13: 20347.25 | R13: 19731.12 | S13: 21544.47 | T13: 24379.22 | U13: 17181.14 | V13: 20709.22 | W13: 5383.12 | X13: 6203.69 | AA13: MD | AB13: 51832.84 | AC13: 63146.21 | AD13: 91447.5 | AE13: 85589.01 | AF13: 95834.33 | AG13: 108393.98 | AH13: 98322.16 | AI13: 119156.33 | AJ13: 26168.88 | AK13: 25324.31 | AN13: MD | AO13: 65149.18 | AP13: 73553.12 | AQ13: 111794.75 | AR13: 105320.14 | AS13: 117378.8 | AT13: 132773.2 | AU13: 115503.3 | AV13: 139865.55 | AW13: 31552 | AX13: 31528
B14: PM-Shoulder | C14: 2.1 | D14: 2.99 | E14: 2.1 | F14: 2.1 | G14: 2.1 | H14: 3.09 | I14: 1.58 | J14: 3.22 | K14: 2.1 | L14: 2.1 | N14: PM-Shoulder | O14: 3427.66 | P14: 2563.97 | Q14: 4808.44 | R14: 5335.17 | S14: 5847.27 | T14: 5135.3 | U14: 5208.3 | V14: 6333.2 | W14: 1364.16 | X14: 1115.03 | AA14: PM-Shoulder | AB14: 13465.26 | AC14: 12229.65 | AD14: 21941.56 | AE14: 25329.57 | AF14: 24112.73 | AG14: 26928.23 | AH14: 25445.73 | AI14: 39569.8 | AJ14: 5228.64 | AK14: 3178.44 | AN14: PM-Shoulder | AO14: 16892.93 | AP14: 14793.62 | AQ14: 26750 | AR14: 30664.74 | AS14: 29960 | AT14: 32063.53 | AU14: 30654.03 | AV14: 45903 | AW14: 6592.8 | AX14: 4293.47
B15: PM-Peak | C15: 6.3 | D15: 6.3 | E15: 2.1 | F15: 2.1 | G15: 4.2 | H15: 4.2 | I15: 2.1 | J15: 1.09 | K15: 2.1 | L15: 2.1 | N15: PM-Peak | O15: 13401.22 | P15: 12833.81 | Q15: 16279.31 | R15: 16451.91 | S15: 14552.85 | T15: 17848.23 | U15: 14637.72 | V15: 16039.66 | W15: 2581.21 | X15: 2870.21 | AA15: PM-Peak | AB15: 55938.91 | AC15: 55735.57 | AD15: 54368.93 | AE15: 70808.34 | AF15: 77332.34 | AG15: 80513.38 | AH15: 74612.46 | AI15: 82724.49 | AJ15: 8582.99 | AK15: 10620.67 | AN15: PM-Peak | AO15: 69340.12 | AP15: 68569.38 | AQ15: 70648.24 | AR15: 87260.25 | AS15: 91885.19 | AT15: 98361.61 | AU15: 89250.18 | AV15: 98764.15 | AW15: 11164.2 | AX15: 13490.88
B16: PM-Late | C16: 1.67 | D16: 1.5 | E16: 2.07 | F16: 0.45 | G16: 2.1 | H16: 1.98 | I16: 1.56 | J16: 1.35 | K16: 1.47 | L16: 2.1 | N16: PM-Late | O16: 5441.49 | P16: 7059.89 | Q16: 5429.41 | R16: 6471.76 | S16: 6027.77 | T16: 6828.21 | U16: 5302.18 | V16: 1911.44 | W16: 1653.96 | X16: 2294.96 | AA16: PM-Late | AB16: 27834.39 | AC16: 33687.85 | AD16: 32786.09 | AE16: 35188.49 | AF16: 26706.19 | AG16: 30742.47 | AH16: 25407.62 | AI16: 37297.51 | AJ16: 9182.04 | AK16: 9486.64 | AN16: PM-Late | AO16: 33275.88 | AP16: 40747.74 | AQ16: 38215.5 | AR16: 41660.25 | AS16: 32733.96 | AT16: 37570.68 | AU16: 30709.8 | AV16: 39208.95 | AW16: 10836 | AX16: 11781.6
B19: CaptureRateLights | N19: ML Volume (PCE/Period) | AA19: GP Volume (PCE/Period) | AN19: Highway Volume
B20: Direction | C20: NB | D20: SB | E20: NB | F20: SB | G20: NB | H20: SB | I20: NB | J20: SB | K20: NB | L20: SB | N20: Direction | O20: NB | P20: SB | Q20: NB | R20: SB | S20: NB | T20: SB | U20: NB | V20: SB | W20: NB | X20: SB | AA20: Direction | AB20: NB | AC20: SB | AD20: NB | AE20: SB | AF20: NB | AG20: SB | AH20: NB | AI20: SB | AJ20: NB | AK20: SB | AN20: Direction | AO20: NB | AP20: SB | AQ20: NB | AR20: SB | AS20: NB | AT20: SB | AU20: NB | AV20: SB | AW20: NB | AX20: SB
B21: Segment | C21: 11 | D21: 11 | E21: 12 | F21: 12 | G21: 13 | H21: 13 | I21: 14 | J21: 14 | K21: 18 | L21: 18 | N21: Segment | O21: 11 | P21: 11 | Q21: 12 | R21: 12 | S21: 13 | T21: 13 | U21: 14 | V21: 14 | W21: 18 | X21: 18 | AA21: Segment | AB21: 11 | AC21: 11 | AD21: 12 | AE21: 12 | AF21: 13 | AG21: 13 | AH21: 14 | AI21: 14 | AJ21: 18 | AK21: 18 | AN21: Segment | AO21: 11 | AP21: 11 | AQ21: 12 | AR21: 12 | AS21: 13 | AT21: 13 | AU21: 14 | AV21: 14 | AW21: 18 | AX21: 18
B22: Period | N22: Period | AA22: Period | AN22: Period
B23: Night | C23: 0.1 | D23: 0.1 | E23: 0.1 | F23: 0.06 | G23: 0.1 | H23: 0.1 | I23: 0.06 | J23: 0.05 | K23: 0.1 | L23: 0.1 | N23: Night | O23: 2109.87 | P23: 2115.43 | Q23: 2575.9 | R23: 1202.98 | S23: 1462.99 | T23: 1278.25 | U23: 887.85 | V23: 627.53 | W23: 2248.63 | X23: 1794.53 | AA23: Night | AB23: 20053.53 | AC23: 19900.97 | AD23: 23549.5 | AE23: 18877.92 | AF23: 15309.01 | AG23: 13643.65 | AH23: 13818.45 | AI23: 11877.97 | AJ23: 20529.37 | AK23: 16741.47 | AN23: Night | AO23: 22163.4 | AP23: 22016.4 | AQ23: 26125.4 | AR23: 20080.9 | AS23: 16772 | AT23: 14921.9 | AU23: 14706.3 | AV23: 12505.5 | AW23: 22778 | AX23: 18536
B24: AM-Early | C24: 0.22 | D24: 0.17 | E24: 0.15 | F24: 0.26 | G24: 0.2 | H24: 0.21 | I24: 0.2 | J24: 0.09 | K24: 0.22 | L24: 0.18 | N24: AM-Early | O24: 1583.27 | P24: 849.36 | Q24: 1465.83 | R24: 1067.77 | S24: 2081.99 | T24: 1018.83 | U24: 1776.93 | V24: 434.7 | W24: 1583.51 | X24: 952 | AA24: AM-Early | AB24: 6394.93 | AC24: 5026.74 | AD24: 9258.77 | AE24: 3863.56 | AF24: 8718.01 | AG24: 4446.67 | AH24: 7393.33 | AI24: 4751.6 | AJ24: 6684.49 | AK24: 5636 | AN24: AM-Early | AO24: 7978.2 | AP24: 5876.1 | AQ24: 10724.6 | AR24: 4931.33 | AS24: 10800 | AT24: 5465.5 | AU24: 9170.26 | AV24: 5186.3 | AW24: 8268 | AX24: 6588
B25: AM-Peak | C25: 0.24 | D25: 0.26 | E25: 0.14 | F25: 0.28 | G25: 0.21 | H25: 0.21 | I25: 0.16 | J25: 0.16 | K25: 0.19 | L25: 0.26 | N25: AM-Peak | O25: 7329.64 | P25: 3869.52 | Q25: 5052.62 | R25: 5340.16 | S25: 7996.57 | T25: 5518.79 | U25: 5593.43 | V25: 3823.89 | W25: 2674.11 | X25: 4143.82 | AA25: AM-Peak | AB25: 26794.92 | AC25: 13368.41 | AD25: 36388.48 | AE25: 18519.96 | AF25: 33084.38 | AG25: 24205.4 | AH25: 31437.74 | AI25: 23771.62 | AJ25: 13786.89 | AK25: 15308.18 | AN25: AM-Peak | AO25: 34124.56 | AP25: 17237.92 | AQ25: 41441.1 | AR25: 23860.13 | AS25: 41080.95 | AT25: 29724.19 | AU25: 37031.17 | AV25: 27595.51 | AW25: 16461 | AX25: 19452
B26: AM-Shoulder | C26: 0.22 | D26: 0.24 | E26: 0.19 | F26: 0.22 | G26: 0.15 | H26: 0.22 | I26: 0.16 | J26: 0.16 | K26: 0.18 | L26: 0.19 | N26: AM-Shoulder | O26: 1608.17 | P26: 1199.49 | Q26: 1880.8 | R26: 1766.76 | S26: 1466.38 | T26: 2001.53 | U26: 1428.27 | V26: 1248.57 | W26: 739.7 | X26: 823.75 | AA26: AM-Shoulder | AB26: 7021.67 | AC26: 4928.97 | AD26: 11006.1 | AE26: 8124.38 | AF26: 9233.62 | AG26: 8698.47 | AH26: 8804.73 | AI26: 7636.73 | AJ26: 4704.3 | AK26: 4656.05 | AN26: AM-Shoulder | AO26: 8629.84 | AP26: 6128.46 | AQ26: 12886.9 | AR26: 9891.14 | AS26: 10700 | AT26: 10700 | AU26: 10233 | AV26: 8885.3 | AW26: 5444 | AX26: 5479.8
B27: MD | C27: 0.24 | D27: 0.17 | E27: 0.23 | F27: 0.23 | G27: 0.21 | H27: 0.2 | I27: 0.17 | J27: 0.16 | K27: 0.22 | L27: 0.24 | N27: MD | O27: 6052.88 | P27: 4730.41 | Q27: 8138.9 | R27: 7892.45 | S27: 7694.45 | T27: 8706.86 | U27: 5206.41 | V27: 6275.52 | W27: 6728.9 | X27: 7754.61 | AA27: MD | AB27: 23560.38 | AC27: 28702.82 | AD27: 36579 | AE27: 34235.6 | AF27: 34226.55 | AG27: 38712.14 | AH27: 29794.59 | AI27: 36107.98 | AJ27: 32711.1 | AK27: 31655.39 | AN27: MD | AO27: 29613.27 | AP27: 33433.24 | AQ27: 44717.9 | AR27: 42128.05 | AS27: 41921 | AT27: 47419 | AU27: 35001 | AV27: 42383.5 | AW27: 39440 | AX27: 39410
B28: PM-Shoulder | C28: 0.24 | D28: 0.2 | E28: 0.23 | F28: 0.21 | G28: 0.22 | H28: 0.17 | I28: 0.19 | J28: 0.15 | K28: 0.26 | L28: 0.3 | N28: PM-Shoulder | O28: 1558.03 | P28: 1165.44 | Q28: 1923.37 | R28: 2134.07 | S28: 2088.31 | T28: 1834.03 | U28: 1578.27 | V28: 1919.15 | W28: 1705.2 | X28: 1393.79 | AA28: PM-Shoulder | AB28: 6120.57 | AC28: 5558.93 | AD28: 8776.63 | AE28: 10131.83 | AF28: 8611.69 | AG28: 9617.23 | AH28: 7710.83 | AI28: 11990.85 | AJ28: 6535.8 | AK28: 3973.05 | AN28: PM-Shoulder | AO28: 7678.6 | AP28: 6724.37 | AQ28: 10700 | AR28: 12265.9 | AS28: 10700 | AT28: 11451.26 | AU28: 9289.1 | AV28: 13910 | AW28: 8241 | AX28: 5366.84
B29: PM-Peak | C29: 0.22 | D29: 0.22 | E29: 0.29 | F29: 0.24 | G29: 0.18 | H29: 0.2 | I29: 0.18 | J29: 0.18 | K29: 0.29 | L29: 0.27 | N29: PM-Peak | O29: 6091.46 | P29: 5833.55 | Q29: 6511.72 | R29: 6580.76 | S29: 5197.45 | T29: 6374.37 | U29: 4435.67 | V29: 4860.5 | W29: 3226.51 | X29: 3587.76 | AA29: PM-Peak | AB29: 25426.78 | AC29: 25334.35 | AD29: 21747.57 | AE29: 28323.34 | AF29: 27618.69 | AG29: 28754.78 | AH29: 22609.84 | AI29: 25068.03 | AJ29: 10728.74 | AK29: 13275.84 | AN29: PM-Peak | AO29: 31518.24 | AP29: 31167.9 | AQ29: 28259.3 | AR29: 34904.1 | AS29: 32816.14 | AT29: 35129.14 | AU29: 27045.51 | AV29: 29928.53 | AW29: 13955.25 | AX29: 16863.6
B30: PM-Late | C30: 0.2 | D30: 0.21 | E30: 0.2 | F30: 0.21 | G30: 0.22 | H30: 0.21 | I30: 0.21 | J30: 0.05 | K30: 0.22 | L30: 0.26 | N30: PM-Late | O30: 2473.4 | P30: 3209.04 | Q30: 2171.76 | R30: 2588.7 | S30: 2152.77 | T30: 2438.65 | U30: 1606.72 | V30: 579.22 | W30: 2067.46 | X30: 2868.71 | AA30: PM-Late | AB30: 12652 | AC30: 15312.66 | AD30: 13114.44 | AE30: 14075.4 | AF30: 9537.93 | AG30: 10979.45 | AH30: 7699.28 | AI30: 11302.28 | AJ30: 11477.54 | AK30: 11858.29 | AN30: PM-Late | AO30: 15125.4 | AP30: 18521.7 | AQ30: 15286.2 | AR30: 16664.1 | AS30: 11690.7 | AT30: 13418.1 | AU30: 9306 | AV30: 11881.5 | AW30: 13545 | AX30: 14727
B33: Revenue Per Period | N33: ML Flow (PCE/hr) | AA33: GP Flow (PCE/hr) | AN33: Highway Flow
B34: Direction | C34: NB | D34: SB | E34: NB | F34: SB | G34: NB | H34: SB | I34: NB | J34: SB | K34: NB | L34: SB | N34: Direction | O34: NB | P34: SB | Q34: NB | R34: SB | S34: NB | T34: SB | U34: NB | V34: SB | W34: NB | X34: SB | AA34: Direction | AB34: NB | AC34: SB | AD34: NB | AE34: SB | AF34: NB | AG34: SB | AH34: NB | AI34: SB | AJ34: NB | AK34: SB | AN34: Direction | AO34: NB | AP34: SB | AQ34: NB | AR34: SB | AS34: NB | AT34: SB | AU34: NB | AV34: SB | AW34: NB | AX34: SB
B35: Segment | C35: 11 | D35: 11 | E35: 12 | F35: 12 | G35: 13 | H35: 13 | I35: 14 | J35: 14 | K35: 18 | L35: 18 | N35: Segment | O35: 11 | P35: 11 | Q35: 12 | R35: 12 | S35: 13 | T35: 13 | U35: 14 | V35: 14 | W35: 18 | X35: 18 | AA35: Segment | AB35: 11 | AC35: 11 | AD35: 12 | AE35: 12 | AF35: 13 | AG35: 13 | AH35: 14 | AI35: 14 | AJ35: 18 | AK35: 18 | AN35: Segment | AO35: 11 | AP35: 11 | AQ35: 12 | AR35: 12 | AS35: 13 | AT35: 13 | AU35: 14 | AV35: 14 | AW35: 18 | AX35: 18
B36: Period | N36: Period | AA36: Period | AN36: Period
B37: Night | C37: 928.34 | D37: 930.79 | E37: 1287.95 | F37: 601.49 | G37: 819.27 | H37: 715.82 | I37: 585.98 | J37: 414.17 | K37: 359.78 | L37: 287.12 | N37: Night | O37: 301.41 | P37: 302.2 | Q37: 367.99 | R37: 171.85 | S37: 209 | T37: 182.61 | U37: 126.84 | V37: 89.65 | W37: 321.23 | X37: 256.36 | AA37: Night | AB37: 2864.79 | AC37: 2843 | AD37: 3364.21 | AE37: 2696.85 | AF37: 2187 | AG37: 1949.09 | AH37: 1974.06 | AI37: 1696.85 | AJ37: 2932.77 | AK37: 2391.64 | AN37: Night | AO37: 3166.2 | AP37: 3145.2 | AQ37: 3732.2 | AR37: 2868.7 | AS37: 2396 | AT37: 2131.7 | AU37: 2100.9 | AV37: 1786.5 | AW37: 3254 | AX37: 2648
B38: AM-Early | C38: 7314.7 | D38: 2947.82 | E38: 6037.22 | F38: 5605.78 | G38: 12242.08 | H38: 5990.72 | I38: 12314.12 | J38: 1291.07 | K38: 2660.28 | L38: 1446.71 | N38: AM-Early | O38: 1583.27 | P38: 849.36 | Q38: 1465.83 | R38: 1067.77 | S38: 2081.99 | T38: 1018.83 | U38: 1776.93 | V38: 434.7 | W38: 1583.51 | X38: 952 | AA38: AM-Early | AB38: 6394.93 | AC38: 5026.74 | AD38: 9258.77 | AE38: 3863.56 | AF38: 8718.01 | AG38: 4446.67 | AH38: 7393.33 | AI38: 4751.6 | AJ38: 6684.49 | AK38: 5636 | AN38: AM-Early | AO38: 7978.2 | AP38: 5876.1 | AQ38: 10724.6 | AR38: 4931.33 | AS38: 10800 | AT38: 5465.5 | AU38: 9170.26 | AV38: 5186.3 | AW38: 8268 | AX38: 6588
B39: AM-Peak | C39: 101588.82 | D39: 17877.17 | E39: 53052.49 | F39: 84107.57 | G39: 141059.43 | H39: 32450.46 | I39: 114426.42 | J39: 16530.14 | K39: 4492.5 | L39: 6961.61 | N39: AM-Peak | O39: 2443.21 | P39: 1289.84 | Q39: 1684.21 | R39: 1780.05 | S39: 2665.52 | T39: 1839.6 | U39: 1864.48 | V39: 1274.63 | W39: 891.37 | X39: 1381.27 | AA39: AM-Peak | AB39: 8931.64 | AC39: 4456.14 | AD39: 12129.49 | AE39: 6173.32 | AF39: 11028.13 | AG39: 8068.47 | AH39: 10479.25 | AI39: 7923.87 | AJ39: 4595.63 | AK39: 5102.73 | AN39: AM-Peak | AO39: 11374.85 | AP39: 5745.98 | AQ39: 13813.7 | AR39: 7953.38 | AS39: 13693.65 | AT39: 9908.06 | AU39: 12343.72 | AV39: 9198.5 | AW39: 5487 | AX39: 6484
B40: AM-Shoulder | C40: 7429.72 | D40: 5541.64 | E40: 9874.18 | F40: 9275.47 | G40: 15340.05 | H40: 11768.98 | I40: 8828 | J40: 3329.13 | K40: 1237.03 | L40: 1383.9 | N40: AM-Shoulder | O40: 1608.17 | P40: 1199.49 | Q40: 1880.8 | R40: 1766.76 | S40: 1466.38 | T40: 2001.53 | U40: 1428.27 | V40: 1248.57 | W40: 739.7 | X40: 823.75 | AA40: AM-Shoulder | AB40: 7021.67 | AC40: 4928.97 | AD40: 11006.1 | AE40: 8124.38 | AF40: 9233.62 | AG40: 8698.47 | AH40: 8804.73 | AI40: 7636.73 | AJ40: 4704.3 | AK40: 4656.05 | AN40: AM-Shoulder | AO40: 8629.84 | AP40: 6128.46 | AQ40: 12886.9 | AR40: 9891.14 | AS40: 10700 | AT40: 10700 | AU40: 10233 | AV40: 8885.3 | AW40: 5444 | AX40: 5479.8
B41: MD | C41: 27964.33 | D41: 37672.91 | E41: 42729.22 | F41: 41435.36 | G41: 45243.33 | H41: 51196.36 | I41: 21517.21 | J41: 13914.05 | K41: 11304.55 | L41: 13027.74 | N41: MD | O41: 1210.58 | P41: 946.08 | Q41: 1627.78 | R41: 1578.49 | S41: 1538.89 | T41: 1741.37 | U41: 1041.28 | V41: 1255.1 | W41: 1345.78 | X41: 1550.92 | AA41: MD | AB41: 4712.08 | AC41: 5740.56 | AD41: 7315.8 | AE41: 6847.12 | AF41: 6845.31 | AG41: 7742.43 | AH41: 5958.92 | AI41: 7221.6 | AJ41: 6542.22 | AK41: 6331.08 | AN41: MD | AO41: 5922.65 | AP41: 6686.65 | AQ41: 8943.58 | AR41: 8425.61 | AS41: 8384.2 | AT41: 9483.8 | AU41: 7000.2 | AV41: 8476.7 | AW41: 7888 | AX41: 7882
B42: PM-Shoulder | C42: 7198.09 | D42: 7656.12 | E42: 10097.72 | F42: 11203.86 | G42: 12279.25 | H42: 15850.16 | I42: 8216.76 | J42: 20389.82 | K42: 2864.74 | L42: 2341.57 | N42: PM-Shoulder | O42: 1558.03 | P42: 1165.44 | Q42: 1923.37 | R42: 2134.07 | S42: 2088.31 | T42: 1834.03 | U42: 1578.27 | V42: 1919.15 | W42: 1705.2 | X42: 1393.79 | AA42: PM-Shoulder | AB42: 6120.57 | AC42: 5558.93 | AD42: 8776.63 | AE42: 10131.83 | AF42: 8611.69 | AG42: 9617.23 | AH42: 7710.83 | AI42: 11990.85 | AJ42: 6535.8 | AK42: 3973.05 | AN42: PM-Shoulder | AO42: 7678.6 | AP42: 6724.37 | AQ42: 10700 | AR42: 12265.9 | AS42: 10700 | AT42: 11451.26 | AU42: 9289.1 | AV42: 13910 | AW42: 8241 | AX42: 5366.84
B43: PM-Peak | C43: 84427.67 | D43: 80852.98 | E43: 34186.54 | F43: 34548.92 | G43: 61121.97 | H43: 74962.55 | I43: 30683.65 | J43: 17520.26 | K43: 5420.53 | L43: 6027.43 | N43: PM-Peak | O43: 2030.49 | P43: 1944.52 | Q43: 2170.57 | R43: 2193.59 | S43: 1732.48 | T43: 2124.79 | U43: 1478.56 | V43: 1620.17 | W43: 1075.5 | X43: 1195.92 | AA43: PM-Peak | AB43: 8475.59 | AC43: 8444.78 | AD43: 7249.19 | AE43: 9441.11 | AF43: 9206.23 | AG43: 9584.93 | AH43: 7536.61 | AI43: 8356.01 | AJ43: 3576.25 | AK43: 4425.28 | AN43: PM-Peak | AO43: 10506.08 | AP43: 10389.3 | AQ43: 9419.76 | AR43: 11634.7 | AS43: 10938.71 | AT43: 11709.71 | AU43: 9015.17 | AV43: 9976.18 | AW43: 4651.75 | AX43: 5621.2
B44: PM-Late | C44: 9092.78 | D44: 10581.13 | E44: 11256.45 | F44: 2902.74 | G44: 12658.3 | H44: 13493.79 | I44: 8284.11 | J44: 2580.45 | K44: 2428.9 | L44: 4819.42 | N44: PM-Late | O44: 824.47 | P44: 1069.68 | Q44: 723.92 | R44: 862.9 | S44: 717.59 | T44: 812.88 | U44: 535.57 | V44: 193.07 | W44: 689.15 | X44: 956.24 | AA44: PM-Late | AB44: 4217.33 | AC44: 5104.22 | AD44: 4371.48 | AE44: 4691.8 | AF44: 3179.31 | AG44: 3659.82 | AH44: 2566.43 | AI44: 3767.43 | AJ44: 3825.85 | AK44: 3952.76 | AN44: PM-Late | AO44: 5041.8 | AP44: 6173.9 | AQ44: 5095.4 | AR44: 5554.7 | AS44: 3896.9 | AT44: 4472.7 | AU44: 3102 | AV44: 3960.5 | AW44: 4515 | AX44: 4909
B47: Revenue Per Period Lights | N47: ML V/C | AA47: GP V/C real | AN47: Highway Vol / GP Capacity
...

Sheet Year_2050
B1: Lenght
C2: 11 | D2: 12 | E2: 13 | F2: 14 | G2: 18
B3: Length | C3: 2.2 | D3: 2.5 | E3: 2.8 | F3: 3.3 | G3: 0.8
B5: TollLights | N5: ML PCE.Miles | AA5: GP PCE.Miles | AN5: Highway PCE.Miles
B6: Direction | C6: NB | D6: SB | E6: NB | F6: SB | G6: NB | H6: SB | I6: NB | J6: SB | K6: NB | L6: SB | N6: Direction | O6: NB | P6: SB | Q6: NB | R6: SB | S6: NB | T6: SB | U6: NB | V6: SB | W6: NB | X6: SB | AA6: Direction | AB6: NB | AC6: SB | AD6: NB | AE6: SB | AF6: NB | AG6: SB | AH6: NB | AI6: SB | AJ6: NB | AK6: SB | AN6: Direction | AO6: NB | AP6: SB | AQ6: NB | AR6: SB | AS6: NB | AT6: SB | AU6: NB | AV6: SB | AW6: NB | AX6: SB
B7: Segment | C7: 11 | D7: 11 | E7: 12 | F7: 12 | G7: 13 | H7: 13 | I7: 14 | J7: 14 | K7: 18 | L7: 18 | N7: Segment | O7: 11 | P7: 11 | Q7: 12 | R7: 12 | S7: 13 | T7: 13 | U7: 14 | V7: 14 | W7: 18 | X7: 18 | AA7: Segment | AB7: 11 | AC7: 11 | AD7: 12 | AE7: 12 | AF7: 13 | AG7: 13 | AH7: 14 | AI7: 14 | AJ7: 18 | AK7: 18 | AN7: Segment | AO7: 11 | AP7: 11 | AQ7: 12 | AR7: 12 | AS7: 13 | AT7: 13 | AU7: 14 | AV7: 14 | AW7: 18 | AX7: 18
B8: Period | N8: Period | AA8: Period | AN8: Period
B9: Night | C9: 0.2 | D9: 0.2 | E9: 0.2 | F9: 0.2 | G9: 0.2 | H9: 0.2 | I9: 0.2 | J9: 0.2 | K9: 0.2 | L9: 0.2 | N9: Night | O9: 5287.66 | P9: 5254.73 | Q9: 7324.96 | R9: 4438 | S9: 5192.3 | T9: 4587.91 | U9: 3350.84 | V9: 2368.74 | W9: 1800.46 | X9: 1446.92 | AA9: Night | AB9: 50015.28 | AC9: 49675.53 | AD9: 66759.54 | AE9: 52500 | AF9: 48519.54 | AG9: 43206.69 | AH9: 52153.84 | AI9: 44831.49 | AJ9: 16421.94 | AK9: 13381.88 | AN9: Night | AO9: 55302.94 | AP9: 54930.26 | AQ9: 74084.5 | AR9: 56938 | AS9: 53711.84 | AT9: 47794.6 | AU9: 55504.68 | AV9: 47200.23 | AW9: 18222.4 | AX9: 14828.8
B10: AM-Early | C10: 2.57 | D10: 2.57 | E10: 4.12 | F10: 2.57 | G10: 2.57 | H10: 2.57 | I10: 2.57 | J10: 0.9 | K10: 5.15 | L10: 2.57 | N10: AM-Early | O10: 3883.87 | P10: 2426.69 | Q10: 3874.19 | R10: 3021.8 | S10: 6368.11 | T10: 4317.04 | U10: 6488.05 | V10: 2448.38 | W10: 1036.09 | X10: 815.83 | AA10: AM-Early | AB10: 13830.7 | AC10: 12236.09 | AD10: 26534.31 | AE10: 9420.68 | AF10: 24151.89 | AG10: 13025.75 | AH10: 24053.99 | AI10: 17128.87 | AJ10: 5765.51 | AK10: 4454.57 | AN10: AM-Early | AO10: 17714.57 | AP10: 14662.78 | AQ10: 30408.5 | AR10: 12442.48 | AS10: 30520 | AT10: 17342.78 | AU10: 30542.05 | AV10: 19577.25 | AW10: 6801.6 | AX10: 5270.4
