Workbook

Sheet Year_2025
B1: Lenght
C2: 11 | D2: 12 | E2: 13 | F2: 14 | G2: 15 | H2: 16 | I2: 17 | J2: 18
B3: Length | C3: 2.4 | D3: 2.5 | E3: 2 | F3: 4 | G3: 2.6 | H3: 2.6 | I3: 2.1 | J3: 0.3
B5: TollLights | T5: ML PCE.Miles | AM5: GP PCE.Miles | BF5: Highway PCE.Miles
B6: Direction | C6: NB | D6: SB | E6: NB | F6: SB | G6: NB | H6: SB | I6: NB | J6: SB | K6: NB | L6: SB | M6: NB | N6: SB | O6: NB | P6: SB | Q6: NB | R6: SB | T6: Direction | U6: NB | V6: SB | W6: NB | X6: SB | Y6: NB | Z6: SB | AA6: NB | AB6: SB | AC6: NB | AD6: SB | AE6: NB | AF6: SB | AG6: NB | AH6: SB | AI6: NB | AJ6: SB | AM6: Direction | AN6: NB | AO6: SB | AP6: NB | AQ6: SB | AR6: NB | AS6: SB | AT6: NB | AU6: SB | AV6: NB | AW6: SB | AX6: NB | AY6: SB | AZ6: NB | BA6: SB | BB6: NB | BC6: SB | BF6: Direction | BG6: NB | BH6: SB | BI6: NB | BJ6: SB | BK6: NB | BL6: SB | BM6: NB | BN6: SB | BO6: NB | BP6: SB | BQ6: NB | BR6: SB | BS6: NB | BT6: SB | BU6: NB | BV6: SB
B7: Segment | C7: 11 | D7: 11 | E7: 12 | F7: 12 | G7: 13 | H7: 13 | I7: 14 | J7: 14 | K7: 15 | L7: 15 | M7: 16 | N7: 16 | O7: 17 | P7: 17 | Q7: 18 | R7: 18 | T7: Segment | U7: 11 | V7: 11 | W7: 12 | X7: 12 | Y7: 13 | Z7: 13 | AA7: 14 | AB7: 14 | AC7: 15 | AD7: 15 | AE7: 16 | AF7: 16 | AG7: 17 | AH7: 17 | AI7: 18 | AJ7: 18 | AM7: Segment | AN7: 11 | AO7: 11 | AP7: 12 | AQ7: 12 | AR7: 13 | AS7: 13 | AT7: 14 | AU7: 14 | AV7: 15 | AW7: 15 | AX7: 16 | AY7: 16 | AZ7: 17 | BA7: 17 | BB7: 18 | BC7: 18 | BF7: Segment | BG7: 11 | BH7: 11 | BI7: 12 | BJ7: 12 | BK7: 13 | BL7: 13 | BM7: 14 | BN7: 14 | BO7: 15 | BP7: 15 | BQ7: 16 | BR7: 16 | BS7: 17 | BT7: 17 | BU7: 18 | BV7: 18
B8: Period | T8: Period | AM8: Period | BF8: Period
B9: Night | C9: 0.2 | D9: 0.2 | E9: 0.2 | F9: 0.2 | G9: 0.2 | H9: 0.2 | I9: 0.2 | J9: 0.2 | K9: 0.2 | L9: 0.2 | M9: 0.2 | N9: 0.2 | O9: 0.2 | P9: 0.2 | Q9: 0.2 | R9: 0.2 | T9: Night | U9: 2308.31 | V9: 2294.2 | W9: 2930.96 | X9: 2221.03 | Y9: 1205.92 | Z9: 1122.3 | AA9: 2597.08 | AB9: 1828.32 | AC9: 1552.86 | AD9: 1914.02 | AE9: 1552.65 | AF9: 1850.67 | AG9: 512.24 | AH9: 471.81 | AI9: 671.64 | AJ9: 535.09 | AM9: Night | AN9: 37146.49 | AO9: 36824.6 | AP9: 45561.54 | AQ9: 34861.47 | AR9: 23301.08 | AS9: 20626.7 | AT9: 40424.92 | AU9: 34613.68 | AV9: 28003.94 | AW9: 34422.28 | AX9: 28004.15 | AY9: 33266.23 | AZ9: 9211.81 | BA9: 8487.84 | BB9: 6100.86 | BC9: 4946.96 | BF9: Night | BG9: 39454.8 | BH9: 39118.8 | BI9: 48492.5 | BJ9: 37082.5 | BK9: 24507 | BL9: 21749 | BM9: 43022 | BN9: 36442 | BO9: 29556.8 | BP9: 36336.3 | BQ9: 29556.8 | BR9: 35116.9 | BS9: 9724.05 | BT9: 8959.65 | BU9: 6772.5 | BV9: 5482.05
B10: AM-Early | C10: 0.8 | D10: 0.6 | E10: 0.71 | F10: 0.8 | G10: 0.8 | H10: 0.79 | I10: 0.8 | J10: 0.65 | K10: 0.62 | L10: 0.67 | M10: 0.62 | N10: 0.66 | O10: 0.6 | P10: 0.55 | Q10: 0.96 | R10: 0.8 | T10: AM-Early | U10: 2723.35 | V10: 1242.78 | W10: 1896.24 | X10: 2531.11 | Y10: 2233.23 | Z10: 1124.06 | AA10: 4299.36 | AB10: 2011.84 | AC10: 1444.6 | AD10: 1582.27 | AE10: 1444.61 | AF10: 1574.93 | AG10: 1030.18 | AH10: 919.69 | AI10: 423.27 | AJ10: 299.57 | AM10: AM-Early | AN10: 13260.65 | AO10: 9115.62 | AP10: 17870.01 | AQ10: 8884 | AR10: 13646.77 | AS10: 6777.94 | AT10: 24338.64 | AU10: 12986.16 | AV10: 9953.8 | AW10: 13488.63 | AX10: 9953.79 | AY10: 13313.97 | AZ10: 6103.52 | BA10: 4927.76 | BB10: 1916.73 | BC10: 1629.13 | BF10: AM-Early | BG10: 15984 | BH10: 10358.4 | BI10: 19766.25 | BJ10: 11415.12 | BK10: 15880 | BL10: 7902 | BM10: 28638 | BN10: 14998 | BO10: 11398.4 | BP10: 15070.9 | BQ10: 11398.4 | BR10: 14888.9 | BS10: 7133.7 | BT10: 5847.45 | BU10: 2340 | BV10: 1928.7
B11: AM-Peak | C11: 1.6 | D11: 0.8 | E11: 0.8 | F11: 1.26 | G11: 0.98 | H11: 0.8 | I11: 1.04 | J11: 0.8 | K11: 0.71 | L11: 0.8 | M11: 0.68 | N11: 0.77 | O11: 0.73 | P11: 0.2 | Q11: 0.8 | R11: 0.92 | T11: AM-Peak | U11: 10616.05 | V11: 6022.75 | W11: 10239.63 | X11: 10515.46 | Y11: 8448.16 | Z11: 6580.65 | AA11: 16894.87 | AB11: 10585.05 | AC11: 3532.48 | AD11: 4032.03 | AE11: 3296.65 | AF11: 3684.87 | AG11: 2635.26 | AH11: 1341.27 | AI11: 917.41 | AJ11: 1262.03 | AM11: AM-Peak | AN11: 49660.35 | AO11: 24344.15 | AP11: 66012.87 | AQ11: 36025.04 | AR11: 43196.69 | AS11: 36293.12 | AT11: 90510.42 | AU11: 68911.44 | AV11: 30010.06 | AW11: 34050.22 | AX11: 24397.25 | AY11: 27203.13 | AZ11: 15935.4 | BA11: 12128.13 | BB11: 3934.49 | BC11: 4452.07 | BF11: AM-Peak | BG11: 60276.4 | BH11: 30366.9 | BI11: 76252.5 | BJ11: 46540.5 | BK11: 51644.85 | BL11: 42873.77 | BM11: 107405.3 | BN11: 79496.49 | BO11: 33542.54 | BP11: 38082.25 | BQ11: 27693.9 | BR11: 30888 | BS11: 18570.66 | BT11: 13469.4 | BU11: 4851.9 | BV11: 5714.1
B12: AM-Shoulder | C12: 0.8 | D12: 0.8 | E12: 0.8 | F12: 1.04 | G12: 0.84 | H12: 0.8 | I12: 0.74 | J12: 0.72 | K12: 0.59 | L12: 0.2 | M12: 0.56 | N12: 0.49 | O12: 0.53 | P12: 0.53 | Q12: 0.8 | R12: 0.8 | T12: AM-Shoulder | U12: 3270.84 | V12: 1521.41 | W12: 2361.77 | X12: 3502.19 | Y12: 2837.16 | Z12: 2080.36 | AA12: 2853.22 | AB12: 2557 | AC12: 1490.48 | AD12: 865.41 | AE12: 1370.29 | AF12: 620.1 | AG12: 304.62 | AH12: 304.83 | AI12: 260.26 | AJ12: 281.01 | AM12: AM-Shoulder | AN12: 15209.16 | AO12: 9304.69 | AP12: 21304.48 | AQ12: 19276.43 | AR12: 15084.84 | AS12: 13535.64 | AT12: 26612.78 | AU12: 23145 | AV12: 12543.64 | AW12: 7866.69 | AX12: 9857.81 | AY12: 8112 | AZ12: 3780 | BA12: 3781.77 | BB12: 1341.29 | BC12: 1324.52 | BF12: AM-Shoulder | BG12: 18480 | BH12: 10826.1 | BI12: 23666.25 | BJ12: 22778.62 | BK12: 17922 | BL12: 15616 | BM12: 29466 | BN12: 25702 | BO12: 14034.12 | BP12: 8732.1 | BQ12: 11228.1 | BR12: 8732.1 | BS12: 4084.62 | BT12: 4086.6 | BU12: 1601.55 | BV12: 1605.54
B13: MD | C13: 0.8 | D13: 0.8 | E13: 0.8 | F13: 0.8 | G13: 0.8 | H13: 0.8 | I13: 0.59 | J13: 0.67 | K13: 0.64 | L13: 0.57 | M13: 0.66 | N13: 0.56 | O13: 0.45 | P13: 0.44 | Q13: 0.86 | R13: 0.94 | T13: MD | U13: 12809.38 | V13: 13554.52 | W13: 11909.5 | X13: 13981.81 | Y13: 8088.66 | Z13: 9082.46 | AA13: 10692.4 | AB13: 12539.03 | AC13: 8169.08 | AD13: 7211.54 | AE13: 8102.78 | AF13: 7158.83 | AG13: 4014.55 | AH13: 3899.23 | AI13: 2141 | AJ13: 3167.86 | AM13: MD | AN13: 51114.62 | AO13: 57359.48 | AP13: 74721.75 | AQ13: 73586.94 | AR13: 52721.34 | AS13: 59702.54 | AT13: 90617.6 | AU13: 110370.97 | AV13: 71891.42 | AW13: 61382.96 | AX13: 70566.72 | AY13: 59999.17 | AZ13: 21038.45 | BA13: 20245.52 | BB13: 9470.5 | BC13: 7983.88 | BF13: MD | BG13: 63924 | BH13: 70914 | BI13: 86631.25 | BJ13: 87568.75 | BK13: 60810 | BL13: 68785 | BM13: 101310 | BN13: 122910 | BO13: 80060.5 | BP13: 68594.5 | BQ13: 78669.5 | BR13: 67158 | BS13: 25053 | BT13: 24144.75 | BU13: 11611.5 | BV13: 11151.74
B14: PM-Shoulder | C14: 0.96 | D14: 0.82 | E14: 0.8 | F14: 0.8 | G14: 0.81 | H14: 1.6 | I14: 0.67 | J14: 0.8 | K14: 0.54 | L14: 0.47 | M14: 0.58 | N14: 0.47 | O14: 0.5 | P14: 0.44 | Q14: 0.78 | R14: 0.8 | T14: PM-Shoulder | U14: 3383.49 | V14: 3380.04 | W14: 2293.37 | X14: 3405.21 | Y14: 2820.67 | Z14: 2998.23 | AA14: 3176.81 | AB14: 5529.54 | AC14: 1763.03 | AD14: 1458.26 | AE14: 1512.51 | AF14: 1280.97 | AG14: 997.09 | AH14: 896.09 | AI14: 211.05 | AJ14: 77.85 | AM14: PM-Shoulder | AN14: 14184 | AO14: 12004.32 | AP14: 19314.66 | AQ14: 21381.04 | AR14: 14643.54 | AS14: 18834.07 | AT14: 23859.19 | AU14: 29932.46 | AV14: 12584.07 | AW14: 10728.31 | AX14: 10560.59 | AY14: 8468.03 | AZ14: 5472.04 | BA14: 4857.01 | BB14: 1497.83 | BC14: 1482.75 | BF14: PM-Shoulder | BG14: 17567.49 | BH14: 15384.36 | BI14: 21608.02 | BJ14: 24786.25 | BK14: 17464.2 | BL14: 21832.31 | BM14: 27036 | BN14: 35462 | BO14: 14347.1 | BP14: 12186.58 | BQ14: 12073.1 | BR14: 9749 | BS14: 6469.13 | BT14: 5753.11 | BU14: 1708.87 | BV14: 1560.6
B15: PM-Peak | C15: 1.36 | D15: 1.3 | E15: 0.8 | F15: 0.8 | G15: 0.8 | H15: 1.04 | I15: 0.8 | J15: 0.8 | K15: 0.8 | L15: 0.8 | M15: 0.8 | N15: 0.8 | O15: 0.2 | P15: 0.68 | Q15: 1 | R15: 0.8 | T15: PM-Peak | U15: 10159.85 | V15: 10080.55 | W15: 2427.43 | X15: 9882.91 | Y15: 2295.75 | Z15: 8485.74 | AA15: 10753.88 | AB15: 4274.78 | AC15: 5697.03 | AD15: 5051.96 | AE15: 5116.43 | AF15: 4514.77 | AG15: 1059.03 | AH15: 2637.13 | AI15: 1264.45 | AJ15: 1198.37 | AM15: PM-Peak | AN15: 46010.27 | AO15: 45417.05 | AP15: 50003.94 | AQ15: 54939.59 | AR15: 45762.44 | AS15: 42993.6 | AT15: 68187.98 | AU15: 83510.88 | AV15: 39127.74 | AW15: 37330.61 | AX15: 30742.49 | AY15: 29389.86 | AZ15: 9587.97 | BA15: 14696.12 | BB15: 3063.65 | BC15: 3818.28 | BF15: PM-Peak | BG15: 56170.12 | BH15: 55497.6 | BI15: 52431.37 | BJ15: 64822.5 | BK15: 48058.19 | BL15: 51479.34 | BM15: 78941.86 | BN15: 87785.66 | BO15: 44824.77 | BP15: 42382.56 | BQ15: 35858.92 | BR15: 33904.64 | BS15: 10647 | BT15: 17333.25 | BU15: 4328.1 | BV15: 5016.64
B16: PM-Late | C16: 0.59 | D16: 0.64 | E16: 0.59 | F16: 0.31 | G16: 0.65 | H16: 0.66 | I16: 0.49 | J16: 0.5 | K16: 0.59 | L16: 0.6 | M16: 0.59 | N16: 0.6 | O16: 0.44 | P16: 0.33 | Q16: 0.77 | R16: 0.8 | T16: PM-Late | U16: 3855.92 | V16: 4264.24 | W16: 4173.61 | X16: 3264.29 | Y16: 3063.84 | Z16: 3273.01 | AA16: 4824.86 | AB16: 5348.96 | AC16: 4186.46 | AD16: 3787.53 | AE16: 4186.53 | AF16: 3787.61 | AG16: 790.65 | AH16: 1415.12 | AI16: 575.67 | AJ16: 892.56 | AM16: PM-Late | AN16: 23136.88 | AO16: 28862.96 | AP16: 24255.14 | AQ16: 27785.71 | AR16: 14072.16 | AS16: 16403.99 | AT16: 22481.14 | AU16: 29673.04 | AV16: 21885.04 | AW16: 17369.97 | AX16: 21884.97 | AY16: 17369.89 | AZ16: 4536 | BA16: 4563.58 | BB16: 3459.48 | BC16: 3312.61 | BF16: PM-Late | BG16: 26992.8 | BH16: 33127.2 | BI16: 28428.75 | BJ16: 31050 | BK16: 17136 | BL16: 19677 | BM16: 27306 | BN16: 35022 | BO16: 26071.5 | BP16: 21157.5 | BQ16: 26071.5 | BR16: 21157.5 | BS16: 5326.65 | BT16: 5978.7 | BU16: 4035.15 | BV16: 4205.17
B19: CaptureRateLights | T19: ML Volume (PCE/Period) | AM19: GP Volume (PCE/Period) | BF19: Highway Volume
B20: Direction | C20: NB | D20: SB | E20: NB | F20: SB | G20: NB | H20: SB | I20: NB | J20: SB | K20: NB | L20: SB | M20: NB | N20: SB | O20: NB | P20: SB | Q20: NB | R20: SB | T20: Direction | U20: NB | V20: SB | W20: NB | X20: SB | Y20: NB | Z20: SB | AA20: NB | AB20: SB | AC20: NB | AD20: SB | AE20: NB | AF20: SB | AG20: NB | AH20: SB | AI20: NB | AJ20: SB | AM20: Direction | AN20: NB | AO20: SB | AP20: NB | AQ20: SB | AR20: NB | AS20: SB | AT20: NB | AU20: SB | AV20: NB | AW20: SB | AX20: NB | AY20: SB | AZ20: NB | BA20: SB | BB20: NB | BC20: SB | BF20: Direction | BG20: NB | BH20: SB | BI20: NB | BJ20: SB | BK20: NB | BL20: SB | BM20: NB | BN20: SB | BO20: NB | BP20: SB | BQ20: NB | BR20: SB | BS20: NB | BT20: SB | BU20: NB | BV20: SB
B21: Segment | C21: 11 | D21: 11 | E21: 12 | F21: 12 | G21: 13 | H21: 13 | I21: 14 | J21: 14 | K21: 15 | L21: 15 | M21: 16 | N21: 16 | O21: 17 | P21: 17 | Q21: 18 | R21: 18 | T21: Segment | U21: 11 | V21: 11 | W21: 12 | X21: 12 | Y21: 13 | Z21: 13 | AA21: 14 | AB21: 14 | AC21: 15 | AD21: 15 | AE21: 16 | AF21: 16 | AG21: 17 | AH21: 17 | AI21: 18 | AJ21: 18 | AM21: Segment | AN21: 11 | AO21: 11 | AP21: 12 | AQ21: 12 | AR21: 13 | AS21: 13 | AT21: 14 | AU21: 14 | AV21: 15 | AW21: 15 | AX21: 16 | AY21: 16 | AZ21: 17 | BA21: 17 | BB21: 18 | BC21: 18 | BF21: Segment | BG21: 11 | BH21: 11 | BI21: 12 | BJ21: 12 | BK21: 13 | BL21: 13 | BM21: 14 | BN21: 14 | BO21: 15 | BP21: 15 | BQ21: 16 | BR21: 16 | BS21: 17 | BT21: 17 | BU21: 18 | BV21: 18
B22: Period | T22: Period | AM22: Period | BF22: Period
B23: Night | C23: 0.06 | D23: 0.06 | E23: 0.06 | F23: 0.06 | G23: 0.05 | H23: 0.05 | I23: 0.06 | J23: 0.05 | K23: 0.05 | L23: 0.05 | M23: 0.05 | N23: 0.05 | O23: 0.05 | P23: 0.05 | Q23: 0.1 | R23: 0.1 | T23: Night | U23: 961.8 | V23: 955.92 | W23: 1172.38 | X23: 888.41 | Y23: 602.96 | Z23: 561.15 | AA23: 649.27 | AB23: 457.08 | AC23: 597.26 | AD23: 736.16 | AE23: 597.17 | AF23: 711.79 | AG23: 243.92 | AH23: 224.67 | AI23: 2238.79 | AJ23: 1783.62 | AM23: Night | AN23: 15477.7 | AO23: 15343.58 | AP23: 18224.62 | AQ23: 13944.59 | AR23: 11650.54 | AS23: 10313.35 | AT23: 10106.23 | AU23: 8653.42 | AV23: 10770.74 | AW23: 13239.34 | AX23: 10770.83 | AY23: 12794.71 | AZ23: 4386.58 | BA23: 4041.83 | BB23: 20336.21 | BC23: 16489.88 | BF23: Night | BG23: 16439.5 | BH23: 16299.5 | BI23: 19397 | BJ23: 14833 | BK23: 12253.5 | BL23: 10874.5 | BM23: 10755.5 | BN23: 9110.5 | BO23: 11368 | BP23: 13975.5 | BQ23: 11368 | BR23: 13506.5 | BS23: 4630.5 | BT23: 4266.5 | BU23: 22575 | BV23: 18273.5
B24: AM-Early | C24: 0.19 | D24: 0.14 | E24: 0.11 | F24: 0.27 | G24: 0.15 | H24: 0.16 | I24: 0.16 | J24: 0.16 | K24: 0.15 | L24: 0.12 | M24: 0.15 | N24: 0.12 | O24: 0.17 | P24: 0.18 | Q24: 0.21 | R24: 0.19 | T24: AM-Early | U24: 1134.73 | V24: 517.83 | W24: 758.5 | X24: 1012.45 | Y24: 1116.61 | Z24: 562.03 | AA24: 1074.84 | AB24: 502.96 | AC24: 555.61 | AD24: 608.57 | AE24: 555.62 | AF24: 605.74 | AG24: 490.56 | AH24: 437.95 | AI24: 1410.9 | AJ24: 998.55 | AM24: AM-Early | AN24: 5525.27 | AO24: 3798.17 | AP24: 7148 | AQ24: 3553.6 | AR24: 6823.39 | AS24: 3388.97 | AT24: 6084.66 | AU24: 3246.54 | AV24: 3828.39 | AW24: 5187.93 | AX24: 3828.38 | AY24: 5120.76 | AZ24: 2906.44 | BA24: 2346.55 | BB24: 6389.1 | BC24: 5430.45 | BF24: AM-Early | BG24: 6660 | BH24: 4316 | BI24: 7906.5 | BJ24: 4566.05 | BK24: 7940 | BL24: 3951 | BM24: 7159.5 | BN24: 3749.5 | BO24: 4384 | BP24: 5796.5 | BQ24: 4384 | BR24: 5726.5 | BS24: 3397 | BT24: 2784.5 | BU24: 7800 | BV24: 6429
B25: AM-Peak | C25: 0.2 | D25: 0.24 | E25: 0.16 | F25: 0.28 | G25: 0.18 | H25: 0.18 | I25: 0.18 | J25: 0.16 | K25: 0.13 | L25: 0.13 | M25: 0.15 | N25: 0.15 | O25: 0.17 | P25: 0.1 | Q25: 0.22 | R25: 0.27 | T25: AM-Peak | U25: 4423.35 | V25: 2509.48 | W25: 4095.85 | X25: 4206.18 | Y25: 4224.08 | Z25: 3290.32 | AA25: 4223.72 | AB25: 2646.26 | AC25: 1358.65 | AD25: 1550.78 | AE25: 1267.94 | AF25: 1417.26 | AG25: 1254.88 | AH25: 638.7 | AI25: 3058.05 | AJ25: 4206.78 | AM25: AM-Peak | AN25: 20691.81 | AO25: 10143.4 | AP25: 26405.15 | AQ25: 14410.02 | AR25: 21598.35 | AS25: 18146.56 | AT25: 22627.61 | AU25: 17227.86 | AV25: 11542.33 | AW25: 13096.24 | AX25: 9383.56 | AY25: 10462.74 | AZ25: 7588.29 | BA25: 5775.3 | BB25: 13114.95 | BC25: 14840.22 | BF25: AM-Peak | BG25: 25115.17 | BH25: 12652.88 | BI25: 30501 | BJ25: 18616.2 | BK25: 25822.42 | BL25: 21436.88 | BM25: 26851.32 | BN25: 19874.12 | BO25: 12900.98 | BP25: 14647.02 | BQ25: 10651.5 | BR25: 11880 | BS25: 8843.17 | BT25: 6414 | BU25: 16173 | BV25: 19047
B26: AM-Shoulder | C26: 0.21 | D26: 0.17 | E26: 0.13 | F26: 0.2 | G26: 0.18 | H26: 0.16 | I26: 0.11 | J26: 0.12 | K26: 0.13 | L26: 0.1 | M26: 0.15 | N26: 0.08 | O26: 0.09 | P26: 0.09 | Q26: 0.21 | R26: 0.22 | T26: AM-Shoulder | U26: 1362.85 | V26: 633.92 | W26: 944.71 | X26: 1400.88 | Y26: 1418.58 | Z26: 1040.18 | AA26: 713.31 | AB26: 639.25 | AC26: 573.26 | AD26: 332.85 | AE26: 527.03 | AF26: 238.5 | AG26: 145.05 | AH26: 145.16 | AI26: 867.52 | AJ26: 936.71 | AM26: AM-Shoulder | AN26: 6337.15 | AO26: 3876.96 | AP26: 8521.79 | AQ26: 7710.57 | AR26: 7542.42 | AS26: 6767.82 | AT26: 6653.19 | AU26: 5786.25 | AV26: 4824.48 | AW26: 3025.65 | AX26: 3791.47 | AY26: 3120 | AZ26: 1800 | BA26: 1800.84 | BB26: 4470.98 | BC26: 4415.07 | BF26: AM-Shoulder | BG26: 7700 | BH26: 4510.88 | BI26: 9466.5 | BJ26: 9111.45 | BK26: 8961 | BL26: 7808 | BM26: 7366.5 | BN26: 6425.5 | BO26: 5397.74 | BP26: 3358.5 | BQ26: 4318.5 | BR26: 3358.5 | BS26: 1945.05 | BT26: 1946 | BU26: 5338.5 | BV26: 5351.79
B27: MD | C27: 0.24 | D27: 0.22 | E27: 0.17 | F27: 0.2 | G27: 0.15 | H27: 0.15 | I27: 0.12 | J27: 0.12 | K27: 0.12 | L27: 0.13 | M27: 0.12 | N27: 0.13 | O27: 0.19 | P27: 0.19 | Q27: 0.23 | R27: 0.42 | T27: MD | U27: 5337.24 | V27: 5647.72 | W27: 4763.8 | X27: 5592.72 | Y27: 4044.33 | Z27: 4541.23 | AA27: 2673.1 | AB27: 3134.76 | AC27: 3141.95 | AD27: 2773.67 | AE27: 3116.45 | AF27: 2753.4 | AG27: 1911.69 | AH27: 1856.77 | AI27: 7136.66 | AJ27: 10559.53 | AM27: MD | AN27: 21297.76 | AO27: 23899.78 | AP27: 29888.7 | AQ27: 29434.78 | AR27: 26360.67 | AS27: 29851.27 | AT27: 22654.4 | AU27: 27592.74 | AV27: 27650.55 | AW27: 23608.83 | AX27: 27141.05 | AY27: 23076.6 | AZ27: 10018.31 | BA27: 9640.73 | BB27: 31568.34 | BC27: 26612.94 | BF27: MD | BG27: 26635 | BH27: 29547.5 | BI27: 34652.5 | BJ27: 35027.5 | BK27: 30405 | BL27: 34392.5 | BM27: 25327.5 | BN27: 30727.5 | BO27: 30792.5 | BP27: 26382.5 | BQ27: 30257.5 | BR27: 25830 | BS27: 11930 | BT27: 11497.5 | BU27: 38705 | BV27: 37172.46
B28: PM-Shoulder | C28: 0.23 | D28: 0.25 | E28: 0.14 | F28: 0.16 | G28: 0.19 | H28: 0.15 | I28: 0.13 | J28: 0.17 | K28: 0.14 | L28: 0.14 | M28: 0.14 | N28: 0.15 | O28: 0.18 | P28: 0.18 | Q28: 0.16 | R28: 0.05 | T28: PM-Shoulder | U28: 1409.79 | V28: 1408.35 | W28: 917.35 | X28: 1362.08 | Y28: 1410.33 | Z28: 1499.12 | AA28: 794.2 | AB28: 1382.38 | AC28: 678.09 | AD28: 560.87 | AE28: 581.74 | AF28: 492.68 | AG28: 474.81 | AH28: 426.71 | AI28: 703.5 | AJ28: 259.5 | AM28: PM-Shoulder | AN28: 5910 | AO28: 5001.8 | AP28: 7725.86 | AQ28: 8552.42 | AR28: 7321.77 | AS28: 9417.04 | AT28: 5964.8 | AU28: 7483.12 | AV28: 4840.03 | AW28: 4126.27 | AX28: 4061.76 | AY28: 3256.93 | AZ28: 2605.73 | BA28: 2312.86 | BB28: 4992.75 | BC28: 4942.5 | BF28: PM-Shoulder | BG28: 7319.79 | BH28: 6410.15 | BI28: 8643.21 | BJ28: 9914.5 | BK28: 8732.1 | BL28: 10916.15 | BM28: 6759 | BN28: 8865.5 | BO28: 5518.12 | BP28: 4687.15 | BQ28: 4643.5 | BR28: 3749.62 | BS28: 3080.54 | BT28: 2739.58 | BU28: 5696.25 | BV28: 5202
B29: PM-Peak | C29: 0.21 | D29: 0.21 | E29: 0.05 | F29: 0.19 | G29: 0.05 | H29: 0.18 | I29: 0.16 | J29: 0.05 | K29: 0.14 | L29: 0.14 | M29: 0.16 | N29: 0.16 | O29: 0.1 | P29: 0.17 | Q29: 0.35 | R29: 0.29 | T29: PM-Peak | U29: 4233.27 | V29: 4200.23 | W29: 970.97 | X29: 3953.16 | Y29: 1147.87 | Z29: 4242.87 | AA29: 2688.47 | AB29: 1068.7 | AC29: 2191.17 | AD29: 1943.06 | AE29: 1967.86 | AF29: 1736.45 | AG29: 504.3 | AH29: 1255.78 | AI29: 4214.83 | AJ29: 3994.56 | AM29: PM-Peak | AN29: 19170.95 | AO29: 18923.77 | AP29: 20001.58 | AQ29: 21975.84 | AR29: 22881.22 | AS29: 21496.8 | AT29: 17047 | AU29: 20877.72 | AV29: 15049.13 | AW29: 14357.93 | AX29: 11824.03 | AY29: 11303.79 | AZ29: 4565.7 | BA29: 6998.15 | BB29: 10212.17 | BC29: 12727.59 | BF29: PM-Peak | BG29: 23404.22 | BH29: 23124 | BI29: 20972.55 | BJ29: 25929 | BK29: 24029.1 | BL29: 25739.67 | BM29: 19735.47 | BN29: 21946.41 | BO29: 17240.3 | BP29: 16300.99 | BQ29: 13791.89 | BR29: 13040.24 | BS29: 5070 | BT29: 8253.93 | BU29: 14427 | BV29: 16722.15
B30: PM-Late | C30: 0.17 | D30: 0.15 | E30: 0.2 | F30: 0.14 | G30: 0.21 | H30: 0.19 | I30: 0.21 | J30: 0.17 | K30: 0.19 | L30: 0.21 | M30: 0.19 | N30: 0.21 | O30: 0.17 | P30: 0.27 | Q30: 0.19 | R30: 0.26 | T30: PM-Late | U30: 1606.63 | V30: 1776.77 | W30: 1669.44 | X30: 1305.72 | Y30: 1531.92 | Z30: 1636.51 | AA30: 1206.22 | AB30: 1337.24 | AC30: 1610.18 | AD30: 1456.74 | AE30: 1610.2 | AF30: 1456.77 | AG30: 376.5 | AH30: 673.87 | AI30: 1918.89 | AJ30: 2975.2 | AM30: PM-Late | AN30: 9640.37 | AO30: 12026.23 | AP30: 9702.06 | AQ30: 11114.28 | AR30: 7036.08 | AS30: 8201.99 | AT30: 5620.28 | AU30: 7418.26 | AV30: 8417.32 | AW30: 6680.76 | AX30: 8417.3 | AY30: 6680.73 | AZ30: 2160 | BA30: 2173.13 | BB30: 11531.61 | BC30: 11042.04 | BF30: PM-Late | BG30: 11247 | BH30: 13803 | BI30: 11371.5 | BJ30: 12420 | BK30: 8568 | BL30: 9838.5 | BM30: 6826.5 | BN30: 8755.5 | BO30: 10027.5 | BP30: 8137.5 | BQ30: 10027.5 | BR30: 8137.5 | BS30: 2536.5 | BT30: 2847 | BU30: 13450.5 | BV30: 14017.24
B33: Revenue Per Period | T33: ML Flow (PCE/hr) | AM33: GP Flow (PCE/hr) | BF33: Highway Flow
B34: Direction | C34: NB | D34: SB | E34: NB | F34: SB | G34: NB | H34: SB | I34: NB | J34: SB | K34: NB | L34: SB | M34: NB | N34: SB | O34: NB | P34: SB | Q34: NB | R34: SB | T34: Direction | U34: NB | V34: SB | W34: NB | X34: SB | Y34: NB | Z34: SB | AA34: NB | AB34: SB | AC34: NB | AD34: SB | AE34: NB | AF34: SB | AG34: NB | AH34: SB | AI34: NB | AJ34: SB | AM34: Direction | AN34: NB | AO34: SB | AP34: NB | AQ34: SB | AR34: NB | AS34: SB | AT34: NB | AU34: SB | AV34: NB | AW34: SB | AX34: NB | AY34: SB | AZ34: NB | BA34: SB | BB34: NB | BC34: SB | BF34: Direction | BG34: NB | BH34: SB | BI34: NB | BJ34: SB | BK34: NB | BL34: SB | BM34: NB | BN34: SB | BO34: NB | BP34: SB | BQ34: NB | BR34: SB | BS34: NB | BT34: SB | BU34: NB | BV34: SB
B35: Segment | C35: 11 | D35: 11 | E35: 12 | F35: 12 | G35: 13 | H35: 13 | I35: 14 | J35: 14 | K35: 15 | L35: 15 | M35: 16 | N35: 16 | O35: 17 | P35: 17 | Q35: 18 | R35: 18 | T35: Segment | U35: 11 | V35: 11 | W35: 12 | X35: 12 | Y35: 13 | Z35: 13 | AA35: 14 | AB35: 14 | AC35: 15 | AD35: 15 | AE35: 16 | AF35: 16 | AG35: 17 | AH35: 17 | AI35: 18 | AJ35: 18 | AM35: Segment | AN35: 11 | AO35: 11 | AP35: 12 | AQ35: 12 | AR35: 13 | AS35: 13 | AT35: 14 | AU35: 14 | AV35: 15 | AW35: 15 | AX35: 16 | AY35: 16 | AZ35: 17 | BA35: 17 | BB35: 18 | BC35: 18 | BF35: Segment | BG35: 11 | BH35: 11 | BI35: 12 | BJ35: 12 | BK35: 13 | BL35: 13 | BM35: 14 | BN35: 14 | BO35: 15 | BP35: 15 | BQ35: 16 | BR35: 16 | BS35: 17 | BT35: 17 | BU35: 18 | BV35: 18
B36: Period | T36: Period | AM36: Period | BF36: Period
B37: Night | C37: 577.46 | D37: 577.92 | E37: 761.86 | F37: 609.88 | G37: 286.13 | H37: 271.49 | I37: 622.82 | J37: 462.9 | K37: 407.26 | L37: 479.6 | M37: 407.24 | N37: 464.65 | O37: 129.65 | P37: 120.47 | Q37: 175.31 | R37: 146.71 | T37: Night | U37: 137.4 | V37: 136.56 | W37: 167.48 | X37: 126.92 | Y37: 86.14 | Z37: 80.16 | AA37: 92.75 | AB37: 65.3 | AC37: 85.32 | AD37: 105.17 | AE37: 85.31 | AF37: 101.68 | AG37: 34.85 | AH37: 32.1 | AI37: 319.83 | AJ37: 254.8 | AM37: Night | AN37: 2211.1 | AO37: 2191.94 | AP37: 2603.52 | AQ37: 1992.08 | AR37: 1664.36 | AS37: 1473.34 | AT37: 1443.75 | AU37: 1236.2 | AV37: 1538.68 | AW37: 1891.33 | AX37: 1538.69 | AY37: 1827.82 | AZ37: 626.65 | BA37: 577.4 | BB37: 2905.17 | BC37: 2355.7 | BF37: Night | BG37: 2348.5 | BH37: 2328.5 | BI37: 2771 | BJ37: 2119 | BK37: 1750.5 | BL37: 1553.5 | BM37: 1536.5 | BN37: 1301.5 | BO37: 1624 | BP37: 1996.5 | BQ37: 1624 | BR37: 1929.5 | BS37: 661.5 | BT37: 609.5 | BU37: 3225 | BV37: 2610.5
B38: AM-Early | C38: 2336.07 | D38: 817.54 | E38: 1453.1 | F38: 2336.77 | G38: 1869.13 | H38: 953.88 | I38: 3594.9 | J38: 1430.22 | K38: 1001.49 | L38: 1132.98 | M38: 1001.49 | N38: 1124.88 | O38: 676.3 | P38: 561.56 | Q38: 441.39 | R38: 273.81 | T38: AM-Early | U38: 1134.73 | V38: 517.83 | W38: 758.5 | X38: 1012.45 | Y38: 1116.61 | Z38: 562.03 | AA38: 1074.84 | AB38: 502.96 | AC38: 555.61 | AD38: 608.57 | AE38: 555.62 | AF38: 605.74 | AG38: 490.56 | AH38: 437.95 | AI38: 1410.9 | AJ38: 998.55 | AM38: AM-Early | AN38: 5525.27 | AO38: 3798.17 | AP38: 7148 | AQ38: 3553.6 | AR38: 6823.39 | AS38: 3388.97 | AT38: 6084.66 | AU38: 3246.54 | AV38: 3828.39 | AW38: 5187.93 | AX38: 3828.38 | AY38: 5120.76 | AZ38: 2906.44 | BA38: 2346.55 | BB38: 6389.1 | BC38: 5430.45 | BF38: AM-Early | BG38: 6660 | BH38: 4316 | BI38: 7906.5 | BJ38: 4566.05 | BK38: 7940 | BL38: 3951 | BM38: 7159.5 | BN38: 3749.5 | BO38: 4384 | BP38: 5796.5 | BQ38: 4384 | BR38: 5726.5 | BS38: 3397 | BT38: 2784.5 | BU38: 7800 | BV38: 6429
B39: AM-Peak | C39: 18664.48 | D39: 5429.74 | E39: 9054.77 | F39: 15527.09 | G39: 8865.51 | H39: 5746.46 | I39: 18825.03 | J39: 9382.41 | K39: 2805.3 | L39: 3605.79 | M39: 2511.21 | N39: 3179.89 | O39: 2167.94 | P39: 328.23 | Q39: 815.88 | R39: 1339.05 | T39: AM-Peak | U39: 1474.45 | V39: 836.49 | W39: 1365.28 | X39: 1402.06 | Y39: 1408.03 | Z39: 1096.77 | AA39: 1407.91 | AB39: 882.09 | AC39: 452.88 | AD39: 516.93 | AE39: 422.65 | AF39: 472.42 | AG39: 418.29 | AH39: 212.9 | AI39: 1019.35 | AJ39: 1402.26 | AM39: AM-Peak | AN39: 6897.27 | AO39: 3381.13 | AP39: 8801.72 | AQ39: 4803.34 | AR39: 7199.45 | AS39: 6048.85 | AT39: 7542.54 | AU39: 5742.62 | AV39: 3847.44 | AW39: 4365.41 | AX39: 3127.85 | AY39: 3487.58 | AZ39: 2529.43 | BA39: 1925.1 | BB39: 4371.65 | BC39: 4946.74 | BF39: AM-Peak | BG39: 8371.72 | BH39: 4217.62 | BI39: 10167 | BJ39: 6205.4 | BK39: 8607.47 | BL39: 7145.63 | BM39: 8950.44 | BN39: 6624.71 | BO39: 4300.33 | BP39: 4882.34 | BQ39: 3550.5 | BR39: 3960 | BS39: 2947.72 | BT39: 2138 | BU39: 5391 | BV39: 6349
B40: AM-Shoulder | C40: 2955.03 | D40: 1385.79 | E40: 2189.74 | F40: 4253.76 | G40: 2611.07 | H40: 1856.3 | I40: 2313.78 | J40: 2041.68 | K40: 984.73 | L40: 210.6 | M40: 862.31 | N40: 352.35 | O40: 188.92 | P40: 189.07 | Q40: 243.52 | R40: 263.22 | T40: AM-Shoulder | U40: 1362.85 | V40: 633.92 | W40: 944.71 | X40: 1400.88 | Y40: 1418.58 | Z40: 1040.18 | AA40: 713.31 | AB40: 639.25 | AC40: 573.26 | AD40: 332.85 | AE40: 527.03 | AF40: 238.5 | AG40: 145.05 | AH40: 145.16 | AI40: 867.52 | AJ40: 936.71 | AM40: AM-Shoulder | AN40: 6337.15 | AO40: 3876.96 | AP40: 8521.79 | AQ40: 7710.57 | AR40: 7542.42 | AS40: 6767.82 | AT40: 6653.19 | AU40: 5786.25 | AV40: 4824.48 | AW40: 3025.65 | AX40: 3791.47 | AY40: 3120 | AZ40: 1800 | BA40: 1800.84 | BB40: 4470.98 | BC40: 4415.07 | BF40: AM-Shoulder | BG40: 7700 | BH40: 4510.88 | BI40: 9466.5 | BJ40: 9111.45 | BK40: 8961 | BL40: 7808 | BM40: 7366.5 | BN40: 6425.5 | BO40: 5397.74 | BP40: 3358.5 | BQ40: 4318.5 | BR40: 3358.5 | BS40: 1945.05 | BT40: 1946 | BU40: 5338.5 | BV40: 5351.79
B41: MD | C41: 11427.13 | D41: 12057.35 | E41: 10981.71 | F41: 12819.14 | G41: 7037.03 | H41: 7815.22 | I41: 6761.41 | J41: 9047.53 | K41: 5649.4 | L41: 4501.87 | M41: 5823.87 | N41: 4447.9 | O41: 2020.14 | P41: 1906.82 | Q41: 2133.7 | R41: 3151.34 | T41: MD | U41: 1067.45 | V41: 1129.54 | W41: 952.76 | X41: 1118.54 | Y41: 808.87 | Z41: 908.25 | AA41: 534.62 | AB41: 626.95 | AC41: 628.39 | AD41: 554.73 | AE41: 623.29 | AF41: 550.68 | AG41: 382.34 | AH41: 371.35 | AI41: 1427.33 | AJ41: 2111.91 | AM41: MD | AN41: 4259.55 | AO41: 4779.96 | AP41: 5977.74 | AQ41: 5886.96 | AR41: 5272.13 | AS41: 5970.25 | AT41: 4530.88 | AU41: 5518.55 | AV41: 5530.11 | AW41: 4721.77 | AX41: 5428.21 | AY41: 4615.32 | AZ41: 2003.66 | BA41: 1928.15 | BB41: 6313.67 | BC41: 5322.59 | BF41: MD | BG41: 5327 | BH41: 5909.5 | BI41: 6930.5 | BJ41: 7005.5 | BK41: 6081 | BL41: 6878.5 | BM41: 5065.5 | BN41: 6145.5 | BO41: 6158.5 | BP41: 5276.5 | BQ41: 6051.5 | BR41: 5166 | BS41: 2386 | BT41: 2299.5 | BU41: 7741 | BV41: 7434.49
B42: PM-Shoulder | C42: 3530.02 | D42: 2984.35 | E42: 2035.3 | F42: 2933.54 | G42: 2388.21 | H42: 5003.7 | I42: 2248.02 | J42: 4588.72 | K42: 1008.36 | L42: 729.5 | M42: 922.55 | N42: 647.36 | O42: 528.03 | P42: 419.78 | Q42: 183.74 | R42: 72.71 | T42: PM-Shoulder | U42: 1409.79 | V42: 1408.35 | W42: 917.35 | X42: 1362.08 | Y42: 1410.33 | Z42: 1499.12 | AA42: 794.2 | AB42: 1382.38 | AC42: 678.09 | AD42: 560.87 | AE42: 581.74 | AF42: 492.68 | AG42: 474.81 | AH42: 426.71 | AI42: 703.5 | AJ42: 259.5 | AM42: PM-Shoulder | AN42: 5910 | AO42: 5001.8 | AP42: 7725.86 | AQ42: 8552.42 | AR42: 7321.77 | AS42: 9417.04 | AT42: 5964.8 | AU42: 7483.12 | AV42: 4840.03 | AW42: 4126.27 | AX42: 4061.76 | AY42: 3256.93 | AZ42: 2605.73 | BA42: 2312.86 | BB42: 4992.75 | BC42: 4942.5 | BF42: PM-Shoulder | BG42: 7319.79 | BH42: 6410.15 | BI42: 8643.21 | BJ42: 9914.5 | BK42: 8732.1 | BL42: 10916.15 | BM42: 6759 | BN42: 8865.5 | BO42: 5518.12 | BP42: 4687.15 | BQ42: 4643.5 | BR42: 3749.62 | BS42: 3080.54 | BT42: 2739.58 | BU42: 5696.25 | BV42: 5202
B43: PM-Peak | C43: 14758.79 | D43: 14061.24 | E43: 2342.48 | F43: 8708.32 | G43: 2048.6 | H43: 9137.52 | I43: 9101.57 | J43: 3720.58 | K43: 4822.77 | L43: 4385.89 | M43: 4314.28 | N43: 3893.39 | O43: 238.65 | P43: 1891.09 | Q43: 1426.91 | R43: 1067.88 | T43: PM-Peak | U43: 1411.09 | V43: 1400.08 | W43: 323.66 | X43: 1317.72 | Y43: 382.62 | Z43: 1414.29 | AA43: 896.16 | AB43: 356.23 | AC43: 730.39 | AD43: 647.69 | AE43: 655.95 | AF43: 578.82 | AG43: 168.1 | AH43: 418.59 | AI43: 1404.94 | AJ43: 1331.52 | AM43: PM-Peak | AN43: 6390.32 | AO43: 6307.92 | AP43: 6667.19 | AQ43: 7325.28 | AR43: 7627.07 | AS43: 7165.6 | AT43: 5682.33 | AU43: 6959.24 | AV43: 5016.38 | AW43: 4785.98 | AX43: 3941.34 | AY43: 3767.93 | AZ43: 1521.9 | BA43: 2332.72 | BB43: 3404.06 | BC43: 4242.53 | BF43: PM-Peak | BG43: 7801.41 | BH43: 7708 | BI43: 6990.85 | BJ43: 8643 | BK43: 8009.7 | BL43: 8579.89 | BM43: 6578.49 | BN43: 7315.47 | BO43: 5746.77 | BP43: 5433.66 | BQ43: 4597.3 | BR43: 4346.75 | BS43: 1690 | BT43: 2751.31 | BU43: 4809 | BV43: 5574.05
B44: PM-Late | C44: 2439.31 | D44: 2892.7 | E44: 2817.95 | F44: 1109.49 | G44: 2136.66 | H44: 2276.43 | I44: 2547.69 | J44: 2812.66 | K44: 2669.5 | L44: 2426.63 | M44: 2669.5 | N44: 2426.63 | O44: 371.63 | P44: 503.58 | Q44: 509.27 | R44: 804.98 | T44: PM-Late | U44: 535.54 | V44: 592.26 | W44: 556.48 | X44: 435.24 | Y44: 510.64 | Z44: 545.5 | AA44: 402.07 | AB44: 445.75 | AC44: 536.73 | AD44: 485.58 | AE44: 536.73 | AF44: 485.59 | AG44: 125.5 | AH44: 224.62 | AI44: 639.63 | AJ44: 991.73 | AM44: PM-Late | AN44: 3213.46 | AO44: 4008.74 | AP44: 3234.02 | AQ44: 3704.76 | AR44: 2345.36 | AS44: 2734 | AT44: 1873.43 | AU44: 2472.75 | AV44: 2805.77 | AW44: 2226.92 | AX44: 2805.77 | AY44: 2226.91 | AZ44: 720 | BA44: 724.38 | BB44: 3843.87 | BC44: 3680.68 | BF44: PM-Late | BG44: 3749 | BH44: 4601 | BI44: 3790.5 | BJ44: 4140 | BK44: 2856 | BL44: 3279.5 | BM44: 2275.5 | BN44: 2918.5 | BO44: 3342.5 | BP44: 2712.5 | BQ44: 3342.5 | BR44: 2712.5 | BS44: 845.5 | BT44: 949 | BU44: 4483.5 | BV44: 4672.41
B47: Revenue Per Period Lights | T47: ML V/C | AM47: GP V/C real | BF47: Highway Vol / GP Capacity
...

Sheet Year_2032
B1: Lenght
C2: 11 | D2: 12 | E2: 13 | F2: 14 | G2: 15 | H2: 16 | I2: 17 | J2: 18
B3: Length | C3: 2.4 | D3: 2.5 | E3: 2 | F3: 4 | G3: 2.6 | H3: 2.6 | I3: 2.1 | J3: 0.3
B5: TollLights | T5: ML PCE.Miles | AM5: GP PCE.Miles | BF5: Highway PCE.Miles
B6: Direction | C6: NB | D6: SB | E6: NB | F6: SB | G6: NB | H6: SB | I6: NB | J6: SB | K6: NB | L6: SB | M6: NB | N6: SB | O6: NB | P6: SB | Q6: NB | R6: SB | T6: Direction | U6: NB | V6: SB | W6: NB | X6: SB | Y6: NB | Z6: SB | AA6: NB | AB6: SB | AC6: NB | AD6: SB | AE6: NB | AF6: SB | AG6: NB | AH6: SB | AI6: NB | AJ6: SB | AM6: Direction | AN6: NB | AO6: SB | AP6: NB | AQ6: SB | AR6: NB | AS6: SB | AT6: NB | AU6: SB | AV6: NB | AW6: SB | AX6: NB | AY6: SB | AZ6: NB | BA6: SB | BB6: NB | BC6: SB | BF6: Direction | BG6: NB | BH6: SB | BI6: NB | BJ6: SB | BK6: NB | BL6: SB | BM6: NB | BN6: SB | BO6: NB | BP6: SB | BQ6: NB | BR6: SB | BS6: NB | BT6: SB | BU6: NB | BV6: SB
B7: Segment | C7: 11 | D7: 11 | E7: 12 | F7: 12 | G7: 13 | H7: 13 | I7: 14 | J7: 14 | K7: 15 | L7: 15 | M7: 16 | N7: 16 | O7: 17 | P7: 17 | Q7: 18 | R7: 18 | T7: Segment | U7: 11 | V7: 11 | W7: 12 | X7: 12 | Y7: 13 | Z7: 13 | AA7: 14 | AB7: 14 | AC7: 15 | AD7: 15 | AE7: 16 | AF7: 16 | AG7: 17 | AH7: 17 | AI7: 18 | AJ7: 18 | AM7: Segment | AN7: 11 | AO7: 11 | AP7: 12 | AQ7: 12 | AR7: 13 | AS7: 13 | AT7: 14 | AU7: 14 | AV7: 15 | AW7: 15 | AX7: 16 | AY7: 16 | AZ7: 17 | BA7: 17 | BB7: 18 | BC7: 18 | BF7: Segment | BG7: 11 | BH7: 11 | BI7: 12 | BJ7: 12 | BK7: 13 | BL7: 13 | BM7: 14 | BN7: 14 | BO7: 15 | BP7: 15 | BQ7: 16 | BR7: 16 | BS7: 17 | BT7: 17 | BU7: 18 | BV7: 18
B8: Period | T8: Period | AM8: Period | BF8: Period
B9: Night | C9: 0.2 | D9: 0.2 | E9: 0.2 | F9: 0.2 | G9: 0.2 | H9: 0.2 | I9: 0.2 | J9: 0.2 | K9: 0.2 | L9: 0.2 | M9: 0.2 | N9: 0.2 | O9: 0.2 | P9: 0.2 | Q9: 0.2 | R9: 0.2 | T9: Night | U9: 7874.4 | V9: 6714.12 | W9: 5803.88 | X9: 2240.84 | Y9: 1746.44 | Z9: 1472.95 | AA9: 2642.03 | AB9: 2218.16 | AC9: 1855.15 | AD9: 2288.03 | AE9: 1853.98 | AF9: 2209.38 | AG9: 612.24 | AH9: 564.16 | AI9: 2205.02 | AJ9: 1767.34 | AM9: Night | AN9: 39564.6 | AO9: 40320 | AP9: 52500 | AQ9: 42341.28 | AR9: 27941.96 | AS9: 24876.45 | AT9: 49479.97 | AU9: 41937.84 | AV9: 34885.19 | AW9: 42877.09 | AX9: 34886.36 | AY9: 41438.77 | AZ9: 11471.16 | BA9: 10575.5 | BB9: 6157.6 | BC9: 5002.64 | BF9: Night | BG9: 47439 | BH9: 47034.12 | BI9: 58303.88 | BJ9: 44582.12 | BK9: 29688.4 | BL9: 26349.4 | BM9: 52122 | BN9: 44156 | BO9: 36740.34 | BP9: 45165.12 | BQ9: 36740.34 | BR9: 43648.15 | BS9: 12083.4 | BT9: 11139.66 | BU9: 8362.62 | BV9: 6769.98
B10: AM-Early | C10: 1.4 | D10: 0.8 | E10: 0.8 | F10: 0.8 | G10: 1.68 | H10: 0.8 | I10: 1.66 | J10: 0.8 | K10: 0.8 | L10: 0.8 | M10: 0.8 | N10: 0.8 | O10: 0.8 | P10: 0.8 | Q10: 1.54 | R10: 1.42 | T10: AM-Early | U10: 3374.88 | V10: 1903.43 | W10: 3313.75 | X10: 3079.9 | Y10: 2800.01 | Z10: 2126.73 | AA10: 5635.5 | AB10: 3373.22 | AC10: 2382.44 | AD10: 2739.37 | AE10: 2382.44 | AF10: 2721.22 | AG10: 1637.41 | AH10: 1366.35 | AI10: 422.44 | AJ10: 420.4 | AM10: AM-Early | AN10: 14886.34 | AO10: 10550.17 | AP10: 20450.75 | AQ10: 8677.67 | AR10: 16439.09 | AS10: 7446.57 | AT10: 29060.1 | AU10: 14797.18 | AV10: 11785.87 | AW10: 15994.41 | AX10: 11785.87 | AY10: 15785.97 | AZ10: 7230.36 | BA10: 5901.96 | BB10: 1987.76 | BC10: 1897.6 | BF10: AM-Early | BG10: 18261.22 | BH10: 12453.6 | BI10: 23764.5 | BJ10: 11757.57 | BK10: 19239.1 | BL10: 9573.3 | BM10: 34695.6 | BN10: 18170.4 | BO10: 14168.31 | BP10: 18733.78 | BQ10: 14168.31 | BR10: 18507.19 | BS10: 8867.78 | BT10: 7268.31 | BU10: 2410.2 | BV10: 2317.99
B11: AM-Peak | C11: 3.6 | D11: 0.8 | E11: 1.8 | F11: 1.8 | G11: 3 | H11: 1.38 | I11: 3.34 | J11: 0.8 | K11: 0.8 | L11: 0.8 | M11: 0.8 | N11: 0.8 | O11: 0.8 | P11: 0.73 | Q11: 1.34 | R11: 1.8 | T11: AM-Peak | U11: 13462.11 | V11: 9518.09 | W11: 11823.96 | X11: 13995.39 | Y11: 8431.08 | Z11: 8412.44 | AA11: 16808.46 | AB11: 17635.15 | AC11: 6069.6 | AD11: 7490.75 | AE11: 5500.01 | AF11: 6743.24 | AG11: 4637.13 | AH11: 2000.25 | AI11: 1267.16 | AJ11: 1738.58 | AM11: AM-Peak | AN11: 59008.33 | AO11: 26992.57 | AP11: 79854.54 | AQ11: 38980.77 | AR11: 54139.53 | AS11: 43530.29 | AT11: 113313.99 | AU11: 78678.03 | AV11: 35627.08 | AW11: 39846.06 | AX11: 28924.9 | AY11: 31651.09 | AZ11: 18449.29 | BA11: 14742 | BB11: 4724.28 | BC11: 5317.6 | BF11: AM-Peak | BG11: 72470.44 | BH11: 36510.66 | BI11: 91678.5 | BJ11: 52976.16 | BK11: 62570.61 | BL11: 51942.73 | BM11: 130122.45 | BN11: 96313.17 | BO11: 41696.68 | BP11: 47336.81 | BQ11: 34424.91 | BR11: 38394.33 | BS11: 23086.42 | BT11: 16742.25 | BU11: 5991.44 | BV11: 7056.18
B12: AM-Shoulder | C12: 1.68 | D12: 0.8 | E12: 1.28 | F12: 1.8 | G12: 1.8 | H12: 1.48 | I12: 0.8 | J12: 0.8 | K12: 0.8 | L12: 0.2 | M12: 0.8 | N12: 0.6 | O12: 0.53 | P12: 0.53 | Q12: 1.18 | R12: 1.1 | T12: AM-Shoulder | U12: 3362.96 | V12: 2914 | W12: 3523.53 | X12: 3696.4 | Y12: 3415.91 | Z12: 2811.72 | AA12: 5278.05 | AB12: 4678.39 | AC12: 2328.38 | AD12: 1075.67 | AE12: 2047.74 | AF12: 1147.17 | AG12: 745.05 | AH12: 745.22 | AI12: 420.59 | AJ12: 423.2 | AM12: AM-Shoulder | AN12: 16961.52 | AO12: 10101.74 | AP12: 24930.59 | AQ12: 20569.25 | AR12: 17584.09 | AS12: 16107.58 | AT12: 30420.15 | AU12: 26459.81 | AV12: 15117.23 | AW12: 9777.77 | AX12: 11908.67 | AY12: 9706.27 | AZ12: 4332.36 | BA12: 4334.37 | BB12: 1541.38 | BC12: 1466.8 | BF12: AM-Shoulder | BG12: 20324.48 | BH12: 13015.75 | BI12: 28454.12 | BJ12: 24265.65 | BK12: 21000 | BL12: 18919.3 | BM12: 35698.2 | BN12: 31138.2 | BO12: 17445.61 | BP12: 10853.44 | BQ12: 13956.41 | BR12: 10853.44 | BS12: 5077.42 | BT12: 5079.59 | BU12: 1961.97 | BV12: 1890
B13: MD | C13: 0.96 | D13: 1.2 | E13: 1.32 | F13: 1.62 | G13: 0.88 | H13: 1.14 | I13: 0.8 | J13: 0.8 | K13: 0.8 | L13: 0.8 | M13: 0.8 | N13: 0.8 | O13: 0.79 | P13: 0.77 | Q13: 1.62 | R13: 1.5 | T13: MD | U13: 16898.74 | V13: 16869.41 | W13: 17529.59 | X13: 17584.93 | Y13: 14443.25 | Z13: 14104.7 | AA13: 16300.54 | AB13: 21472.64 | AC13: 13597.74 | AD13: 10829.69 | AE13: 13988.54 | AF13: 10705.9 | AG13: 4867.03 | AH13: 4732.82 | AI13: 2110.01 | AJ13: 2101.89 | AM13: MD | AN13: 52844.65 | AO13: 61870.55 | AP13: 86631.03 | AQ13: 85766.6 | AR13: 59228.25 | AS13: 69230.8 | AT13: 106434.46 | AU13: 127435.36 | AV13: 85919.21 | AW13: 74434.71 | AX13: 83800.71 | AY13: 72771 | AZ13: 26275.45 | BA13: 25279.85 | BB13: 10174.99 | BC13: 9377.84 | BF13: MD | BG13: 69743.39 | BH13: 78739.96 | BI13: 104160.62 | BJ13: 103351.54 | BK13: 73671.5 | BL13: 83335.5 | BM13: 122735 | BN13: 148908 | BO13: 99516.95 | BP13: 85264.4 | BQ13: 97789.25 | BR13: 83476.9 | BS13: 31142.48 | BT13: 30012.68 | BU13: 12285 | BV13: 11479.73
B14: PM-Shoulder | C14: 1.56 | D14: 1.28 | E14: 1.26 | F14: 2.49 | G14: 2.59 | H14: 1.8 | I14: 0.8 | J14: 1.8 | K14: 0.8 | L14: 0.8 | M14: 0.8 | N14: 0.8 | O14: 0.8 | P14: 0.78 | Q14: 0.8 | R14: 0.96 | T14: PM-Shoulder | U14: 3378 | V14: 3444.98 | W14: 3501.14 | X14: 3514.39 | Y14: 2810.38 | Z14: 3606.96 | AA14: 5430.49 | AB14: 5807.09 | AC14: 2578.32 | AD14: 1856.7 | AE14: 2354.54 | AF14: 1641.61 | AG14: 1345.45 | AH14: 1090.86 | AI14: 105.24 | AJ14: 422.96 | AM14: PM-Shoulder | AN14: 14706.18 | AO14: 12391.85 | AP14: 22478.79 | AQ14: 26286.73 | AR14: 18189.62 | AS14: 18867.48 | AT14: 27324.51 | AU14: 34192.91 | AV14: 15254.86 | AW14: 13291.63 | AX14: 12652.01 | AY14: 10476.46 | AZ14: 6696.23 | BA14: 6060.17 | BB14: 2004.91 | BC14: 1183.54 | BF14: PM-Shoulder | BG14: 18084.19 | BH14: 15836.84 | BI14: 25979.94 | BJ14: 29801.13 | BK14: 21000 | BL14: 22474.43 | BM14: 32755 | BN14: 40000 | BO14: 17833.18 | BP14: 15148.33 | BQ14: 15006.55 | BR14: 12118.07 | BS14: 8041.67 | BT14: 7151.03 | BU14: 2110.14 | BV14: 1606.5
B15: PM-Peak | C15: 1.8 | D15: 1.8 | E15: 2.08 | F15: 2.07 | G15: 2.31 | H15: 3.13 | I15: 0.8 | J15: 1.48 | K15: 0.8 | L15: 0.8 | M15: 0.8 | N15: 0.8 | O15: 0.2 | P15: 0.8 | Q15: 1.8 | R15: 1.8 | T15: PM-Peak | U15: 15576.59 | V15: 15095.08 | W15: 10544.16 | X15: 10519 | Y15: 8413.78 | Z15: 8435.44 | AA15: 4564.48 | AB15: 16913.95 | AC15: 2769.8 | AD15: 2618.97 | AE15: 2216.97 | AF15: 2095.21 | AG15: 1316.45 | AH15: 4444.73 | AI15: 1425.76 | AJ15: 1521.11 | AM15: PM-Peak | AN15: 51955.23 | AO15: 51630.92 | AP15: 52491.66 | AQ15: 67418.75 | AR15: 49808.65 | AS15: 53932.86 | AT15: 91078.88 | AU15: 89439.93 | AV15: 52947.18 | AW15: 50060.6 | AX15: 42354.51 | AY15: 40047.01 | AZ15: 11917.96 | BA15: 17100.62 | BB15: 3374.84 | BC15: 4673.63 | BF15: PM-Peak | BG15: 67531.82 | BH15: 66726 | BI15: 63035.81 | BJ15: 77937.75 | BK15: 58222.43 | BL15: 62368.3 | BM15: 95643.36 | BN15: 106353.88 | BO15: 55716.98 | BP15: 52679.57 | BQ15: 44571.48 | BR15: 42142.23 | BS15: 13234.41 | BT15: 21545.35 | BU15: 4800.6 | BV15: 6194.73
B16: PM-Late | C16: 0.8 | D16: 0.81 | E16: 0.8 | F16: 0.52 | G16: 0.8 | H16: 0.8 | I16: 0.8 | J16: 0.8 | K16: 0.8 | L16: 0.8 | M16: 0.8 | N16: 0.8 | O16: 0.52 | P16: 0.58 | Q16: 0.8 | R16: 0.8 | T16: PM-Late | U16: 5910.23 | V16: 11569.16 | W16: 6452.86 | X16: 3922.63 | Y16: 4997.77 | Z16: 5393.89 | AA16: 6303.41 | AB16: 7161.93 | AC16: 6646.55 | AD16: 6101.68 | AE16: 6646.59 | AF16: 6101.65 | AG16: 1553.87 | AH16: 1724.46 | AI16: 1160.76 | AJ16: 1139.33 | AM16: PM-Late | AN16: 26543.41 | AO16: 28261.6 | AP16: 27726.52 | AQ16: 33408.24 | AR16: 15763.13 | AS16: 18443.81 | AT16: 26779.99 | AU16: 35264.67 | AV16: 25758.94 | AW16: 20196.02 | AX16: 25758.9 | AY16: 20196.05 | AZ16: 5068.38 | BA16: 5707.33 | BB16: 3822.09 | BC16: 3198.64 | BF16: PM-Late | BG16: 32453.64 | BH16: 39830.76 | BI16: 34179.38 | BJ16: 37330.88 | BK16: 20760.9 | BL16: 23837.7 | BM16: 33083.4 | BN16: 42426.6 | BO16: 32405.49 | BP16: 26297.7 | BQ16: 32405.49 | BR16: 26297.7 | BS16: 6622.24 | BT16: 7431.8 | BU16: 4982.85 | BV16: 4337.97
B19: CaptureRateLights | T19: ML Volume (PCE/Period) | AM19: GP Volume (PCE/Period) | BF19: Highway Volume
B20: Direction | C20: NB | D20: SB | E20: NB | F20: SB | G20: NB | H20: SB | I20: NB | J20: SB | K20: NB | L20: SB | M20: NB | N20: SB | O20: NB | P20: SB | Q20: NB | R20: SB | T20: Direction | U20: NB | V20: SB | W20: NB | X20: SB | Y20: NB | Z20: SB | AA20: NB | AB20: SB | AC20: NB | AD20: SB | AE20: NB | AF20: SB | AG20: NB | AH20: SB | AI20: NB | AJ20: SB | AM20: Direction | AN20: NB | AO20: SB | AP20: NB | AQ20: SB | AR20: NB | AS20: SB | AT20: NB | AU20: SB | AV20: NB | AW20: SB | AX20: NB | AY20: SB | AZ20: NB | BA20: SB | BB20: NB | BC20: SB | BF20: Direction | BG20: NB | BH20: SB | BI20: NB | BJ20: SB | BK20: NB | BL20: SB | BM20: NB | BN20: SB | BO20: NB | BP20: SB | BQ20: NB | BR20: SB | BS20: NB | BT20: SB | BU20: NB | BV20: SB
B21: Segment | C21: 11 | D21: 11 | E21: 12 | F21: 12 | G21: 13 | H21: 13 | I21: 14 | J21: 14 | K21: 15 | L21: 15 | M21: 16 | N21: 16 | O21: 17 | P21: 17 | Q21: 18 | R21: 18 | T21: Segment | U21: 11 | V21: 11 | W21: 12 | X21: 12 | Y21: 13 | Z21: 13 | AA21: 14 | AB21: 14 | AC21: 15 | AD21: 15 | AE21: 16 | AF21: 16 | AG21: 17 | AH21: 17 | AI21: 18 | AJ21: 18 | AM21: Segment | AN21: 11 | AO21: 11 | AP21: 12 | AQ21: 12 | AR21: 13 | AS21: 13 | AT21: 14 | AU21: 14 | AV21: 15 | AW21: 15 | AX21: 16 | AY21: 16 | AZ21: 17 | BA21: 17 | BB21: 18 | BC21: 18 | BF21: Segment | BG21: 11 | BH21: 11 | BI21: 12 | BJ21: 12 | BK21: 13 | BL21: 13 | BM21: 14 | BN21: 14 | BO21: 15 | BP21: 15 | BQ21: 16 | BR21: 16 | BS21: 17 | BT21: 17 | BU21: 18 | BV21: 18
B22: Period | T22: Period | AM22: Period | BF22: Period
B23: Night | C23: 0.17 | D23: 0.15 | E23: 0.11 | F23: 0.05 | G23: 0.06 | H23: 0.06 | I23: 0.05 | J23: 0.05 | K23: 0.05 | L23: 0.05 | M23: 0.05 | N23: 0.05 | O23: 0.05 | P23: 0.05 | Q23: 0.27 | R23: 0.27 | T23: Night | U23: 3281 | V23: 2797.55 | W23: 2321.55 | X23: 896.34 | Y23: 873.22 | Z23: 736.47 | AA23: 660.51 | AB23: 554.54 | AC23: 713.52 | AD23: 880.01 | AE23: 713.07 | AF23: 849.76 | AG23: 291.54 | AH23: 268.65 | AI23: 7350.07 | AJ23: 5891.12 | AM23: Night | AN23: 16485.25 | AO23: 16800 | AP23: 21000 | AQ23: 16936.51 | AR23: 13970.98 | AS23: 12438.23 | AT23: 12369.99 | AU23: 10484.46 | AV23: 13417.38 | AW23: 16491.19 | AX23: 13417.83 | AY23: 15937.99 | AZ23: 5462.46 | BA23: 5035.95 | BB23: 20525.33 | BC23: 16675.48 | BF23: Night | BG23: 19766.25 | BH23: 19597.55 | BI23: 23321.55 | BJ23: 17832.85 | BK23: 14844.2 | BL23: 13174.7 | BM23: 13030.5 | BN23: 11039 | BO23: 14130.9 | BP23: 17371.2 | BQ23: 14130.9 | BR23: 16787.75 | BS23: 5754 | BT23: 5304.6 | BU23: 27875.4 | BV23: 22566.6
B24: AM-Early | C24: 0.21 | D24: 0.18 | E24: 0.16 | F24: 0.29 | G24: 0.16 | H24: 0.25 | I24: 0.18 | J24: 0.21 | K24: 0.2 | L24: 0.17 | M24: 0.2 | N24: 0.17 | O24: 0.21 | P24: 0.22 | Q24: 0.2 | R24: 0.22 | T24: AM-Early | U24: 1406.2 | V24: 793.1 | W24: 1325.5 | X24: 1231.96 | Y24: 1400 | Z24: 1063.37 | AA24: 1408.87 | AB24: 843.3 | AC24: 916.32 | AD24: 1053.6 | AE24: 916.32 | AF24: 1046.62 | AG24: 779.72 | AH24: 650.64 | AI24: 1408.13 | AJ24: 1401.33 | AM24: AM-Early | AN24: 6202.64 | AO24: 4395.9 | AP24: 8180.3 | AQ24: 3471.07 | AR24: 8219.55 | AS24: 3723.28 | AT24: 7265.03 | AU24: 3699.3 | AV24: 4533.03 | AW24: 6151.7 | AX24: 4533.03 | AY24: 6071.53 | AZ24: 3443.03 | BA24: 2810.46 | BB24: 6625.87 | BC24: 6325.32 | BF24: AM-Early | BG24: 7608.84 | BH24: 5189 | BI24: 9505.8 | BJ24: 4703.03 | BK24: 9619.55 | BL24: 4786.65 | BM24: 8673.9 | BN24: 4542.6 | BO24: 5449.35 | BP24: 7205.3 | BQ24: 5449.35 | BR24: 7118.15 | BS24: 4222.75 | BT24: 3461.1 | BU24: 8034 | BV24: 7726.64
B25: AM-Peak | C25: 0.21 | D25: 0.31 | E25: 0.15 | F25: 0.32 | G25: 0.15 | H25: 0.19 | I25: 0.15 | J25: 0.22 | K25: 0.18 | L25: 0.19 | M25: 0.2 | N25: 0.21 | O25: 0.24 | P25: 0.13 | Q25: 0.25 | R25: 0.3 | T25: AM-Peak | U25: 5609.21 | V25: 3965.87 | W25: 4729.58 | X25: 5598.16 | Y25: 4215.54 | Z25: 4206.22 | AA25: 4202.11 | AB25: 4408.79 | AC25: 2334.46 | AD25: 2881.06 | AE25: 2115.39 | AF25: 2593.56 | AG25: 2208.16 | AH25: 952.5 | AI25: 4223.85 | AJ25: 5795.26 | AM25: AM-Peak | AN25: 24586.8 | AO25: 11246.91 | AP25: 31941.82 | AQ25: 15592.31 | AR25: 27069.76 | AS25: 21765.14 | AT25: 28328.5 | AU25: 19669.51 | AV25: 13702.72 | AW25: 15325.41 | AX25: 11124.96 | AY25: 12173.49 | AZ25: 8785.38 | BA25: 7020 | BB25: 15747.6 | BC25: 17725.34 | BF25: AM-Peak | BG25: 30196.02 | BH25: 15212.77 | BI25: 36671.4 | BJ25: 21190.46 | BK25: 31285.31 | BL25: 25971.36 | BM25: 32530.61 | BN25: 24078.29 | BO25: 16037.19 | BP25: 18206.47 | BQ25: 13240.35 | BR25: 14767.05 | BS25: 10993.53 | BT25: 7972.5 | BU25: 19971.45 | BV25: 23520.6
B26: AM-Shoulder | C26: 0.2 | D26: 0.27 | E26: 0.16 | F26: 0.19 | G26: 0.19 | H26: 0.18 | I26: 0.17 | J26: 0.18 | K26: 0.17 | L26: 0.1 | M26: 0.18 | N26: 0.13 | O26: 0.18 | P26: 0.18 | Q26: 0.27 | R26: 0.28 | T26: AM-Shoulder | U26: 1401.23 | V26: 1214.17 | W26: 1409.41 | X26: 1478.56 | Y26: 1707.95 | Z26: 1405.86 | AA26: 1319.51 | AB26: 1169.6 | AC26: 895.53 | AD26: 413.72 | AE26: 787.59 | AF26: 441.22 | AG26: 354.79 | AH26: 354.87 | AI26: 1401.97 | AJ26: 1410.65 | AM26: AM-Shoulder | AN26: 7067.3 | AO26: 4209.06 | AP26: 9972.24 | AQ26: 8227.7 | AR26: 8792.05 | AS26: 8053.79 | AT26: 7605.04 | AU26: 6614.95 | AV26: 5814.32 | AW26: 3760.68 | AX26: 4580.26 | AY26: 3733.18 | AZ26: 2063.03 | BA26: 2063.98 | BB26: 5137.93 | BC26: 4889.35 | BF26: AM-Shoulder | BG26: 8468.53 | BH26: 5423.23 | BI26: 11381.65 | BJ26: 9706.26 | BK26: 10500 | BL26: 9459.65 | BM26: 8924.55 | BN26: 7784.55 | BO26: 6709.85 | BP26: 4174.4 | BQ26: 5367.85 | BR26: 4174.4 | BS26: 2417.82 | BT26: 2418.85 | BU26: 6539.9 | BV26: 6300
B27: MD | C27: 0.28 | D27: 0.25 | E27: 0.21 | F27: 0.21 | G27: 0.23 | H27: 0.19 | I27: 0.15 | J27: 0.17 | K27: 0.16 | L27: 0.15 | M27: 0.17 | N27: 0.15 | O27: 0.19 | P27: 0.19 | Q27: 0.22 | R27: 0.23 | T27: MD | U27: 7041.14 | V27: 7028.92 | W27: 7011.84 | X27: 7033.97 | Y27: 7221.63 | Z27: 7052.35 | AA27: 4075.13 | AB27: 5368.16 | AC27: 5229.9 | AD27: 4165.27 | AE27: 5380.21 | AF27: 4117.65 | AG27: 2317.63 | AH27: 2253.72 | AI27: 7033.35 | AJ27: 7006.32 | AM27: MD | AN27: 22018.6 | AO27: 25779.4 | AP27: 34652.41 | AQ27: 34306.64 | AR27: 29614.12 | AS27: 34615.4 | AT27: 26608.62 | AU27: 31858.84 | AV27: 33045.85 | AW27: 28628.73 | AX27: 32231.04 | AY27: 27988.85 | AZ27: 12512.12 | BA27: 12038.03 | BB27: 33916.65 | BC27: 31259.46 | BF27: MD | BG27: 29059.75 | BH27: 32808.32 | BI27: 41664.25 | BJ27: 41340.61 | BK27: 36835.75 | BL27: 41667.75 | BM27: 30683.75 | BN27: 37227 | BO27: 38275.75 | BP27: 32794 | BQ27: 37611.25 | BR27: 32106.5 | BS27: 14829.75 | BT27: 14291.75 | BU27: 40950 | BV27: 38265.77
B28: PM-Shoulder | C28: 0.22 | D28: 0.25 | E28: 0.17 | F28: 0.14 | G28: 0.15 | H28: 0.17 | I28: 0.19 | J28: 0.16 | K28: 0.16 | L28: 0.14 | M28: 0.18 | N28: 0.16 | O28: 0.19 | P28: 0.18 | Q28: 0.05 | R28: 0.31 | T28: PM-Shoulder | U28: 1407.5 | V28: 1435.41 | W28: 1400.46 | X28: 1405.76 | Y28: 1405.19 | Z28: 1803.48 | AA28: 1357.62 | AB28: 1451.77 | AC28: 991.66 | AD28: 714.11 | AE28: 905.59 | AF28: 631.39 | AG28: 640.69 | AH28: 519.46 | AI28: 350.79 | AJ28: 1409.86 | AM28: PM-Shoulder | AN28: 6127.58 | AO28: 5163.27 | AP28: 8991.52 | AQ28: 10514.69 | AR28: 9094.81 | AS28: 9433.74 | AT28: 6831.13 | AU28: 8548.23 | AV28: 5867.25 | AW28: 5112.17 | AX28: 4866.16 | AY28: 4029.41 | AZ28: 3188.68 | BA28: 2885.8 | BB28: 6683.02 | BC28: 3945.14 | BF28: PM-Shoulder | BG28: 7535.08 | BH28: 6598.68 | BI28: 10391.97 | BJ28: 11920.45 | BK28: 10500 | BL28: 11237.22 | BM28: 8188.75 | BN28: 10000 | BO28: 6858.92 | BP28: 5826.28 | BQ28: 5771.75 | BR28: 4660.79 | BS28: 3829.37 | BT28: 3405.25 | BU28: 7033.81 | BV28: 5355
B29: PM-Peak | C29: 0.26 | D29: 0.26 | E29: 0.21 | F29: 0.17 | G29: 0.16 | H29: 0.15 | I29: 0.05 | J29: 0.17 | K29: 0.05 | L29: 0.05 | M29: 0.05 | N29: 0.05 | O29: 0.1 | P29: 0.23 | Q29: 0.36 | R29: 0.3 | T29: PM-Peak | U29: 6490.25 | V29: 6289.62 | W29: 4217.66 | X29: 4207.6 | Y29: 4206.89 | Z29: 4217.72 | AA29: 1141.12 | AB29: 4228.49 | AC29: 1065.31 | AD29: 1007.29 | AE29: 852.68 | AF29: 805.85 | AG29: 626.88 | AH29: 2116.54 | AI29: 4752.55 | AJ29: 5070.35 | AM29: PM-Peak | AN29: 21648.01 | AO29: 21512.88 | AP29: 20996.66 | AQ29: 26967.5 | AR29: 24904.32 | AS29: 26966.43 | AT29: 22769.72 | AU29: 22359.98 | AV29: 20364.3 | AW29: 19254.08 | AX29: 16290.2 | AY29: 15402.7 | AZ29: 5675.22 | BA29: 8143.15 | BB29: 11249.45 | BC29: 15578.76 | BF29: PM-Peak | BG29: 28138.26 | BH29: 27802.5 | BI29: 25214.32 | BJ29: 31175.1 | BK29: 29111.21 | BL29: 31184.15 | BM29: 23910.84 | BN29: 26588.47 | BO29: 21429.61 | BP29: 20261.37 | BQ29: 17142.88 | BR29: 16208.55 | BS29: 6302.1 | BT29: 10259.69 | BU29: 16002 | BV29: 20649.11
B30: PM-Late | C30: 0.22 | D30: 0.34 | E30: 0.25 | F30: 0.14 | G30: 0.28 | H30: 0.26 | I30: 0.22 | J30: 0.19 | K30: 0.24 | L30: 0.26 | M30: 0.24 | N30: 0.26 | O30: 0.26 | P30: 0.26 | Q30: 0.3 | R30: 0.32 | T30: PM-Late | U30: 2462.6 | V30: 4820.48 | W30: 2581.14 | X30: 1569.05 | Y30: 2498.88 | Z30: 2696.94 | AA30: 1575.85 | AB30: 1790.48 | AC30: 2556.36 | AD30: 2346.8 | AE30: 2556.38 | AF30: 2346.79 | AG30: 739.94 | AH30: 821.17 | AI30: 3869.19 | AJ30: 3797.76 | AM30: PM-Late | AN30: 11059.75 | AO30: 11775.67 | AP30: 11090.61 | AQ30: 13363.3 | AR30: 7881.57 | AS30: 9221.91 | AT30: 6695 | AU30: 8816.17 | AV30: 9907.29 | AW30: 7767.7 | AX30: 9907.27 | AY30: 7767.71 | AZ30: 2413.51 | BA30: 2717.78 | BB30: 12740.31 | BC30: 10662.13 | BF30: PM-Late | BG30: 13522.35 | BH30: 16596.15 | BI30: 13671.75 | BJ30: 14932.35 | BK30: 10380.45 | BL30: 11918.85 | BM30: 8270.85 | BN30: 10606.65 | BO30: 12463.65 | BP30: 10114.5 | BQ30: 12463.65 | BR30: 10114.5 | BS30: 3153.45 | BT30: 3538.95 | BU30: 16609.5 | BV30: 14459.89
B33: Revenue Per Period | T33: ML Flow (PCE/hr) | AM33: GP Flow (PCE/hr) | BF33: Highway Flow
B34: Direction | C34: NB | D34: SB | E34: NB | F34: SB | G34: NB | H34: SB | I34: NB | J34: SB | K34: NB | L34: SB | M34: NB | N34: SB | O34: NB | P34: SB | Q34: NB | R34: SB | T34: Direction | U34: NB | V34: SB | W34: NB | X34: SB | Y34: NB | Z34: SB | AA34: NB | AB34: SB | AC34: NB | AD34: SB | AE34: NB | AF34: SB | AG34: NB | AH34: SB | AI34: NB | AJ34: SB | AM34: Direction | AN34: NB | AO34: SB | AP34: NB | AQ34: SB | AR34: NB | AS34: SB | AT34: NB | AU34: SB | AV34: NB | AW34: SB | AX34: NB | AY34: SB | AZ34: NB | BA34: SB | BB34: NB | BC34: SB | BF34: Direction | BG34: NB | BH34: SB | BI34: NB | BJ34: SB | BK34: NB | BL34: SB | BM34: NB | BN34: SB | BO34: NB | BP34: SB | BQ34: NB | BR34: SB | BS34: NB | BT34: SB | BU34: NB | BV34: SB
B35: Segment | C35: 11 | D35: 11 | E35: 12 | F35: 12 | G35: 13 | H35: 13 | I35: 14 | J35: 14 | K35: 15 | L35: 15 | M35: 16 | N35: 16 | O35: 17 | P35: 17 | Q35: 18 | R35: 18 | T35: Segment | U35: 11 | V35: 11 | W35: 12 | X35: 12 | Y35: 13 | Z35: 13 | AA35: 14 | AB35: 14 | AC35: 15 | AD35: 15 | AE35: 16 | AF35: 16 | AG35: 17 | AH35: 17 | AI35: 18 | AJ35: 18 | AM35: Segment | AN35: 11 | AO35: 11 | AP35: 12 | AQ35: 12 | AR35: 13 | AS35: 13 | AT35: 14 | AU35: 14 | AV35: 15 | AW35: 15 | AX35: 16 | AY35: 16 | AZ35: 17 | BA35: 17 | BB35: 18 | BC35: 18 | BF35: Segment | BG35: 11 | BH35: 11 | BI35: 12 | BJ35: 12 | BK35: 13 | BL35: 13 | BM35: 14 | BN35: 14 | BO35: 15 | BP35: 15 | BQ35: 16 | BR35: 16 | BS35: 17 | BT35: 17 | BU35: 18 | BV35: 18
B36: Period | T36: Period | AM36: Period | BF36: Period
B37: Night | C37: 2000.84 | D37: 1667.8 | E37: 1478.78 | F37: 615.32 | G37: 405.3 | H37: 348.56 | I37: 633.62 | J37: 561.61 | K37: 485.9 | L37: 572.42 | M37: 485.45 | N37: 553.82 | O37: 154.75 | P37: 143.89 | Q37: 575.46 | R37: 484.63 | T37: Night | U37: 468.71 | V37: 399.65 | W37: 331.65 | X37: 128.05 | Y37: 124.75 | Z37: 105.21 | AA37: 94.36 | AB37: 79.22 | AC37: 101.93 | AD37: 125.72 | AE37: 101.87 | AF37: 121.39 | AG37: 41.65 | AH37: 38.38 | AI37: 1050.01 | AJ37: 841.59 | AM37: Night | AN37: 2355.04 | AO37: 2400 | AP37: 3000 | AQ37: 2419.5 | AR37: 1995.85 | AS37: 1776.89 | AT37: 1767.14 | AU37: 1497.78 | AV37: 1916.77 | AW37: 2355.88 | AX37: 1916.83 | AY37: 2276.86 | AZ37: 780.35 | BA37: 719.42 | BB37: 2932.19 | BC37: 2382.21 | BF37: Night | BG37: 2823.75 | BH37: 2799.65 | BI37: 3331.65 | BJ37: 2547.55 | BK37: 2120.6 | BL37: 1882.1 | BM37: 1861.5 | BN37: 1577 | BO37: 2018.7 | BP37: 2481.6 | BQ37: 2018.7 | BR37: 2398.25 | BS37: 822 | BT37: 757.8 | BU37: 3982.2 | BV37: 3223.8
B38: AM-Early | C38: 5072.38 | D38: 1683.95 | E38: 2870.54 | F38: 2940.86 | G38: 4922.37 | H38: 1850.77 | I38: 9785.06 | J38: 2967.38 | K38: 2134.44 | L38: 2370.23 | M38: 2134.43 | N38: 2354.64 | O38: 1446.17 | P38: 1206.95 | Q38: 706.29 | R38: 684.6 | T38: AM-Early | U38: 1406.2 | V38: 793.1 | W38: 1325.5 | X38: 1231.96 | Y38: 1400 | Z38: 1063.37 | AA38: 1408.87 | AB38: 843.3 | AC38: 916.32 | AD38: 1053.6 | AE38: 916.32 | AF38: 1046.62 | AG38: 779.72 | AH38: 650.64 | AI38: 1408.13 | AJ38: 1401.33 | AM38: AM-Early | AN38: 6202.64 | AO38: 4395.9 | AP38: 8180.3 | AQ38: 3471.07 | AR38: 8219.55 | AS38: 3723.28 | AT38: 7265.03 | AU38: 3699.3 | AV38: 4533.03 | AW38: 6151.7 | AX38: 4533.03 | AY38: 6071.53 | AZ38: 3443.03 | BA38: 2810.46 | BB38: 6625.87 | BC38: 6325.32 | BF38: AM-Early | BG38: 7608.84 | BH38: 5189 | BI38: 9505.8 | BJ38: 4703.03 | BK38: 9619.55 | BL38: 4786.65 | BM38: 8673.9 | BN38: 4542.6 | BO38: 5449.35 | BP38: 7205.3 | BQ38: 5449.35 | BR38: 7118.15 | BS38: 4222.75 | BT38: 3461.1 | BU38: 8034 | BV38: 7726.64
B39: AM-Peak | C39: 53334.66 | D39: 8640.35 | E39: 23520.86 | F39: 29668.6 | G39: 27012.5 | H39: 12683.82 | I39: 59985.82 | J39: 15731.11 | K39: 5485.95 | L39: 6706.79 | M39: 4983.98 | N39: 6058.72 | O39: 4234.99 | P39: 1728.4 | Q39: 1892.19 | R39: 3620.33 | T39: AM-Peak | U39: 1869.74 | V39: 1321.96 | W39: 1576.53 | X39: 1866.05 | Y39: 1405.18 | Z39: 1402.07 | AA39: 1400.7 | AB39: 1469.6 | AC39: 778.15 | AD39: 960.35 | AE39: 705.13 | AF39: 864.52 | AG39: 736.05 | AH39: 317.5 | AI39: 1407.95 | AJ39: 1931.75 | AM39: AM-Peak | AN39: 8195.6 | AO39: 3748.97 | AP39: 10647.27 | AQ39: 5197.44 | AR39: 9023.25 | AS39: 7255.05 | AT39: 9442.83 | AU39: 6556.5 | AV39: 4567.57 | AW39: 5108.47 | AX39: 3708.32 | AY39: 4057.83 | AZ39: 2928.46 | BA39: 2340 | BB39: 5249.2 | BC39: 5908.45 | BF39: AM-Peak | BG39: 10065.34 | BH39: 5070.92 | BI39: 12223.8 | BJ39: 7063.49 | BK39: 10428.44 | BL39: 8657.12 | BM39: 10843.54 | BN39: 8026.1 | BO39: 5345.73 | BP39: 6068.82 | BQ39: 4413.45 | BR39: 4922.35 | BS39: 3664.51 | BT39: 2657.5 | BU39: 6657.15 | BV39: 7840.2
B40: AM-Shoulder | C40: 6370.3 | D40: 2685.77 | E40: 5248.47 | F40: 7770.62 | G40: 6712.96 | H40: 4651.71 | I40: 4645.85 | J40: 4164.29 | K40: 2098.43 | L40: 261.76 | M40: 1849.33 | N40: 774.12 | O40: 456.53 | P40: 456.71 | Q40: 585 | R40: 548.85 | T40: AM-Shoulder | U40: 1401.23 | V40: 1214.17 | W40: 1409.41 | X40: 1478.56 | Y40: 1707.95 | Z40: 1405.86 | AA40: 1319.51 | AB40: 1169.6 | AC40: 895.53 | AD40: 413.72 | AE40: 787.59 | AF40: 441.22 | AG40: 354.79 | AH40: 354.87 | AI40: 1401.97 | AJ40: 1410.65 | AM40: AM-Shoulder | AN40: 7067.3 | AO40: 4209.06 | AP40: 9972.24 | AQ40: 8227.7 | AR40: 8792.05 | AS40: 8053.79 | AT40: 7605.04 | AU40: 6614.95 | AV40: 5814.32 | AW40: 3760.68 | AX40: 4580.26 | AY40: 3733.18 | AZ40: 2063.03 | BA40: 2063.98 | BB40: 5137.93 | BC40: 4889.35 | BF40: AM-Shoulder | BG40: 8468.53 | BH40: 5423.23 | BI40: 11381.65 | BJ40: 9706.26 | BK40: 10500 | BL40: 9459.65 | BM40: 8924.55 | BN40: 7784.55 | BO40: 6709.85 | BP40: 4174.4 | BQ40: 5367.85 | BR40: 4174.4 | BS40: 2417.82 | BT40: 2418.85 | BU40: 6539.9 | BV40: 6300
B41: MD | C41: 18173.09 | D41: 22567.46 | E41: 26809.83 | F41: 32700.74 | G41: 13917.96 | H41: 17331.88 | I41: 14126.8 | J41: 18546.35 | K41: 11882.83 | L41: 9595.8 | M41: 12229.76 | N41: 9486.55 | O41: 4312.03 | P41: 4055.49 | Q41: 3953.7 | R41: 3622.35 | T41: MD | U41: 1408.23 | V41: 1405.78 | W41: 1402.37 | X41: 1406.79 | Y41: 1444.33 | Z41: 1410.47 | AA41: 815.03 | AB41: 1073.63 | AC41: 1045.98 | AD41: 833.05 | AE41: 1076.04 | AF41: 823.53 | AG41: 463.53 | AH41: 450.74 | AI41: 1406.67 | AJ41: 1401.26 | AM41: MD | AN41: 4403.72 | AO41: 5155.88 | AP41: 6930.48 | AQ41: 6861.33 | AR41: 5922.82 | AS41: 6923.08 | AT41: 5321.72 | AU41: 6371.77 | AV41: 6609.17 | AW41: 5725.75 | AX41: 6446.21 | AY41: 5597.77 | AZ41: 2502.42 | BA41: 2407.61 | BB41: 6783.33 | BC41: 6251.89 | BF41: MD | BG41: 5811.95 | BH41: 6561.66 | BI41: 8332.85 | BJ41: 8268.12 | BK41: 7367.15 | BL41: 8333.55 | BM41: 6136.75 | BN41: 7445.4 | BO41: 7655.15 | BP41: 6558.8 | BQ41: 7522.25 | BR41: 6421.3 | BS41: 2965.95 | BT41: 2858.35 | BU41: 8190 | BV41: 7653.15
B42: PM-Shoulder | C42: 5723.08 | D42: 4747.02 | E42: 4928.63 | F42: 9397.09 | G42: 7709.2 | H42: 6896.18 | I42: 4604.36 | J42: 10841.34 | K42: 2177.98 | L42: 1583.44 | M42: 1991.49 | N42: 1404.52 | O42: 1149.75 | P42: 904.15 | Q42: 103.74 | R42: 443.14 | T42: PM-Shoulder | U42: 1407.5 | V42: 1435.41 | W42: 1400.46 | X42: 1405.76 | Y42: 1405.19 | Z42: 1803.48 | AA42: 1357.62 | AB42: 1451.77 | AC42: 991.66 | AD42: 714.11 | AE42: 905.59 | AF42: 631.39 | AG42: 640.69 | AH42: 519.46 | AI42: 350.79 | AJ42: 1409.86 | AM42: PM-Shoulder | AN42: 6127.58 | AO42: 5163.27 | AP42: 8991.52 | AQ42: 10514.69 | AR42: 9094.81 | AS42: 9433.74 | AT42: 6831.13 | AU42: 8548.23 | AV42: 5867.25 | AW42: 5112.17 | AX42: 4866.16 | AY42: 4029.41 | AZ42: 3188.68 | BA42: 2885.8 | BB42: 6683.02 | BC42: 3945.14 | BF42: PM-Shoulder | BG42: 7535.08 | BH42: 6598.68 | BI42: 10391.97 | BJ42: 11920.45 | BK42: 10500 | BL42: 11237.22 | BM42: 8188.75 | BN42: 10000 | BO42: 6858.92 | BP42: 5826.28 | BQ42: 5771.75 | BR42: 4660.79 | BS42: 3829.37 | BT42: 3405.25 | BU42: 7033.81 | BV42: 5355
B43: PM-Peak | C43: 30099.45 | D43: 29293.74 | E43: 24247.62 | F43: 23906.88 | G43: 20426.27 | H43: 27451.25 | I43: 4127.55 | J43: 25983.2 | K43: 2480.26 | L43: 2443.87 | M43: 1985.47 | N43: 1955.61 | O43: 296.66 | P43: 3777.2 | Q43: 2897.78 | R43: 3052.37 | T43: PM-Peak | U43: 2163.42 | V43: 2096.54 | W43: 1405.89 | X43: 1402.53 | Y43: 1402.3 | Z43: 1405.91 | AA43: 380.37 | AB43: 1409.5 | AC43: 355.1 | AD43: 335.76 | AE43: 284.23 | AF43: 268.62 | AG43: 208.96 | AH43: 705.51 | AI43: 1584.18 | AJ43: 1690.12 | AM43: PM-Peak | AN43: 7216 | AO43: 7170.96 | AP43: 6998.89 | AQ43: 8989.17 | AR43: 8301.44 | AS43: 8988.81 | AT43: 7589.91 | AU43: 7453.33 | AV43: 6788.1 | AW43: 6418.03 | AX43: 5430.07 | AY43: 5134.23 | AZ43: 1891.74 | BA43: 2714.38 | BB43: 3749.82 | BC43: 5192.92 | BF43: PM-Peak | BG43: 9379.42 | BH43: 9267.5 | BI43: 8404.78 | BJ43: 10391.7 | BK43: 9703.74 | BL43: 10394.72 | BM43: 7970.28 | BN43: 8862.82 | BO43: 7143.2 | BP43: 6753.79 | BQ43: 5714.29 | BR43: 5402.85 | BS43: 2100.7 | BT43: 3419.9 | BU43: 5334 | BV43: 6883.04
B44: PM-Late | C44: 5124.66 | D44: 9912.47 | E44: 5976.94 | F44: 2260.78 | G44: 4339.47 | H44: 4594.05 | I44: 5451.17 | J44: 5988.7 | K44: 5795.12 | L44: 5239.04 | M44: 5795.12 | N44: 5239.03 | O44: 855.11 | P44: 1066.65 | Q44: 1080.55 | R44: 1034.6 | T44: PM-Late | U44: 820.87 | V44: 1606.83 | W44: 860.38 | X44: 523.02 | Y44: 832.96 | Z44: 898.98 | AA44: 525.28 | AB44: 596.83 | AC44: 852.12 | AD44: 782.27 | AE44: 852.13 | AF44: 782.26 | AG44: 246.65 | AH44: 273.72 | AI44: 1289.73 | AJ44: 1265.92 | AM44: PM-Late | AN44: 3686.58 | AO44: 3925.22 | AP44: 3696.87 | AQ44: 4454.43 | AR44: 2627.19 | AS44: 3073.97 | AT44: 2231.67 | AU44: 2938.72 | AV44: 3302.43 | AW44: 2589.23 | AX44: 3302.42 | AY44: 2589.24 | AZ44: 804.5 | BA44: 905.93 | BB44: 4246.77 | BC44: 3554.04 | BF44: PM-Late | BG44: 4507.45 | BH44: 5532.05 | BI44: 4557.25 | BJ44: 4977.45 | BK44: 3460.15 | BL44: 3972.95 | BM44: 2756.95 | BN44: 3535.55 | BO44: 4154.55 | BP44: 3371.5 | BQ44: 4154.55 | BR44: 3371.5 | BS44: 1051.15 | BT44: 1179.65 | BU44: 5536.5 | BV44: 4819.96
B47: Revenue Per Period Lights | T47: ML V/C | AM47: GP V/C real | BF47: Highway Vol / GP Capacity
...

Sheet Year_2040
B1: Lenght
C2: 11 | D2: 12 | E2: 13 | F2: 14 | G2: 15 | H2: 16 | I2: 17 | J2: 18
B3: Length | C3: 2.4 | D3: 2.5 | E3: 2 | F3: 4 | G3: 2.6 | H3: 2.6 | I3: 2.1 | J3: 0.3
B5: TollLights | T5: ML PCE.Miles | AM5: GP PCE.Miles | BF5: Highway PCE.Miles
B6: Direction | C6: NB | D6: SB | E6: NB | F6: SB | G6: NB | H6: SB | I6: NB | J6: SB | K6: NB | L6: SB | M6: NB | N6: SB | O6: NB | P6: SB | Q6: NB | R6: SB | T6: Direction | U6: NB | V6: SB | W6: NB | X6: SB | Y6: NB | Z6: SB | AA6: NB | AB6: SB | AC6: NB | AD6: SB | AE6: NB | AF6: SB | AG6: NB | AH6: SB | AI6: NB | AJ6: SB | AM6: Direction | AN6: NB | AO6: SB | AP6: NB | AQ6: SB | AR6: NB | AS6: SB | AT6: NB | AU6: SB | AV6: NB | AW6: SB | AX6: NB | AY6: SB | AZ6: NB | BA6: SB | BB6: NB | BC6: SB | BF6: Direction | BG6: NB | BH6: SB | BI6: NB | BJ6: SB | BK6: NB | BL6: SB | BM6: NB | BN6: SB | BO6: NB | BP6: SB | BQ6: NB | BR6: SB | BS6: NB | BT6: SB | BU6: NB | BV6: SB
