Workbook

Sheet Year_2025
B1: Lenght
C2: 1 | D2: 2 | E2: 3 | F2: 4 | G2: 5 | H2: 6 | I2: 7 | J2: 8 | K2: 9 | L2: 10
B3: Length | C3: 0.7 | D3: 0.7 | E3: 0.5 | F3: 1.6 | G3: 2 | H3: 3.6 | I3: 2.9 | J3: 3.8 | K3: 3.4 | L3: 4.5
B5: TollLights | X5: ML PCE.Miles | AU5: GP PCE.Miles | BR5: Highway PCE.Miles
B6: Direction | C6: NB | D6: SB | E6: NB | F6: SB | G6: NB | H6: SB | I6: NB | J6: SB | K6: NB | L6: SB | M6: NB | N6: SB | O6: NB | P6: SB | Q6: NB | R6: SB | S6: NB | T6: SB | U6: NB | V6: SB | X6: Direction | Y6: NB | Z6: SB | AA6: NB | AB6: SB | AC6: NB | AD6: SB | AE6: NB | AF6: SB | AG6: NB | AH6: SB | AI6: NB | AJ6: SB | AK6: NB | AL6: SB | AM6: NB | AN6: SB | AO6: NB | AP6: SB | AQ6: NB | AR6: SB | AU6: Direction | AV6: NB | AW6: SB | AX6: NB | AY6: SB | AZ6: NB | BA6: SB | BB6: NB | BC6: SB | BD6: NB | BE6: SB | BF6: NB | BG6: SB | BH6: NB | BI6: SB | BJ6: NB | BK6: SB | BL6: NB | BM6: SB | BN6: NB | BO6: SB | BR6: Direction | BS6: NB | BT6: SB | BU6: NB | BV6: SB | BW6: NB | BX6: SB | BY6: NB | BZ6: SB | CA6: NB | CB6: SB | CC6: NB | CD6: SB | CE6: NB | CF6: SB | CG6: NB | CH6: SB | CI6: NB | CJ6: SB | CK6: NB | CL6: SB
B7: Segment | C7: 1 | D7: 1 | E7: 2 | F7: 2 | G7: 3 | H7: 3 | I7: 4 | J7: 4 | K7: 5 | L7: 5 | M7: 6 | N7: 6 | O7: 7 | P7: 7 | Q7: 8 | R7: 8 | S7: 9 | T7: 9 | U7: 10 | V7: 10 | X7: Segment | Y7: 1 | Z7: 1 | AA7: 2 | AB7: 2 | AC7: 3 | AD7: 3 | AE7: 4 | AF7: 4 | AG7: 5 | AH7: 5 | AI7: 6 | AJ7: 6 | AK7: 7 | AL7: 7 | AM7: 8 | AN7: 8 | AO7: 9 | AP7: 9 | AQ7: 10 | AR7: 10 | AU7: Segment | AV7: 1 | AW7: 1 | AX7: 2 | AY7: 2 | AZ7: 3 | BA7: 3 | BB7: 4 | BC7: 4 | BD7: 5 | BE7: 5 | BF7: 6 | BG7: 6 | BH7: 7 | BI7: 7 | BJ7: 8 | BK7: 8 | BL7: 9 | BM7: 9 | BN7: 10 | BO7: 10 | BR7: Segment | BS7: 1 | BT7: 1 | BU7: 2 | BV7: 2 | BW7: 3 | BX7: 3 | BY7: 4 | BZ7: 4 | CA7: 5 | CB7: 5 | CC7: 6 | CD7: 6 | CE7: 7 | CF7: 7 | CG7: 8 | CH7: 8 | CI7: 9 | CJ7: 9 | CK7: 10 | CL7: 10
B8: Period | X8: Period | AU8: Period | BR8: Period
B9: Night | C9: 0.2 | D9: 0.2 | E9: 0.2 | F9: 0.2 | G9: 0.2 | H9: 0.2 | I9: 0.2 | J9: 1.02 | K9: 0.81 | L9: 0.93 | M9: 1.06 | N9: 0.9 | O9: 1.07 | P9: 0.86 | Q9: 0.95 | R9: 0.88 | S9: 0.84 | T9: 0.65 | U9: 0.86 | V9: 0.68 | X9: Night | Y9: 531.14 | Z9: 528.81 | AA9: 408.66 | AB9: 382.45 | AC9: 270.55 | AD9: 327.51 | AE9: 1102.31 | AF9: 2609.04 | AG9: 3824.1 | AH9: 3288.6 | AI9: 6943.86 | AJ9: 5809.86 | AK9: 5410.96 | AL9: 4445.7 | AM9: 6790.98 | AN9: 6080.76 | AO9: 5408.55 | AP9: 3748.5 | AQ9: 6898.5 | AR9: 5003.77 | AU9: Night | AV9: 10510.52 | AW9: 10438.37 | AX9: 7940.94 | AY9: 7428.15 | AZ9: 5413.45 | BA9: 6452.16 | BB9: 22156.73 | BC9: 20530.16 | BD9: 29257.9 | BE9: 25901.4 | BF9: 52679.34 | BG9: 45724.14 | BH9: 41644.44 | BI9: 35545.3 | BJ9: 52340.82 | BK9: 47757.64 | BL9: 41096.65 | BM9: 32118.1 | BN9: 55503 | BO9: 44451.23 | BR9: Night | BS9: 11041.66 | BT9: 10967.18 | BU9: 8349.6 | BV9: 7810.6 | BW9: 5684 | BX9: 6779.67 | BY9: 23259.04 | BZ9: 23139.2 | CA9: 33082 | CB9: 29190 | CC9: 59623.2 | CD9: 51534 | CE9: 47055.4 | CF9: 39991 | CG9: 59131.8 | CH9: 53838.4 | CI9: 46505.2 | CJ9: 35866.6 | CK9: 62401.5 | CL9: 49455
B10: AM-Early | C10: 0.47 | D10: 0.33 | E10: 0.37 | F10: 0.27 | G10: 0.46 | H10: 0.33 | I10: 0.41 | J10: 0.58 | K10: 0.45 | L10: 0.46 | M10: 0.54 | N10: 0.48 | O10: 0.58 | P10: 0.51 | Q10: 0.55 | R10: 0.42 | S10: 0.53 | T10: 0.4 | U10: 0.4 | V10: 0.27 | X10: AM-Early | Y10: 679.41 | Z10: 416.31 | AA10: 676.03 | AB10: 432.06 | AC10: 318.47 | AD10: 394.04 | AE10: 1724.83 | AF10: 1183.3 | AG10: 2055.65 | AH10: 1393.62 | AI10: 3573.99 | AJ10: 2530 | AK10: 2480.59 | AL10: 2170.37 | AM10: 3090.09 | AN10: 2740.27 | AO10: 2698.09 | AP10: 2022.46 | AQ10: 4115.39 | AR10: 2529.69 | AU10: AM-Early | AV10: 3825.96 | AW10: 2511.02 | AX10: 3363.18 | AY10: 2251.88 | AZ10: 1677.53 | BA10: 2059.81 | BB10: 8810.29 | BC10: 6432.7 | BD10: 11383.05 | BE10: 8158.38 | BF10: 19894.05 | BG10: 14926.4 | BH10: 14063.91 | BI10: 12686.33 | BJ10: 17678.82 | BK10: 15872.89 | BL10: 15472.24 | BM10: 12106.54 | BN10: 24249.24 | BO10: 15502.26 | BR10: AM-Early | BS10: 4505.37 | BT10: 2927.33 | BU10: 4039.21 | BV10: 2683.94 | BW10: 1996 | BX10: 2453.85 | BY10: 10535.12 | BZ10: 7616 | CA10: 13438.7 | CB10: 9552 | CC10: 23468.04 | CD10: 17456.4 | CE10: 16544.5 | CF10: 14856.7 | CG10: 20768.9 | CH10: 18613.16 | CI10: 18170.33 | CJ10: 14129.01 | CK10: 28364.62 | CL10: 18031.95
B11: AM-Peak | C11: 1.6 | D11: 0.5 | E11: 2.65 | F11: 0.2 | G11: 1.6 | H11: 1.6 | I11: 1.5 | J11: 0.9 | K11: 1.6 | L11: 0.87 | M11: 1.6 | N11: 0.88 | O11: 1.6 | P11: 0.89 | Q11: 1.6 | R11: 0.84 | S11: 0.95 | T11: 0.75 | U11: 0.71 | V11: 0.65 | X11: AM-Peak | Y11: 2986.57 | Z11: 915.28 | AA11: 2868.79 | AB11: 303.44 | AC11: 1476.68 | AD11: 2889.22 | AE11: 5684.06 | AF11: 4069 | AG11: 7566.43 | AH11: 4603.66 | AI11: 15974.38 | AJ11: 8199.13 | AK11: 15854.84 | AL11: 6589.03 | AM11: 17094.87 | AN11: 8447.18 | AO11: 8422.63 | AP11: 6576.73 | AQ11: 8575.27 | AR11: 7626.94 | AU11: AM-Peak | AV11: 13782.45 | AW11: 6552 | AX11: 14753.57 | AY11: 5795.28 | AZ11: 7089.75 | BA11: 10399.06 | BB11: 31090.22 | BC11: 22842.93 | BD11: 41429.47 | BE11: 28197.57 | BF11: 77644.3 | BG11: 50878.64 | BH11: 61636.19 | BI11: 41207.9 | BJ11: 73733.49 | BK11: 51835.63 | BL11: 51179.67 | BM11: 41768.22 | BN11: 53456.83 | BO11: 48381.74 | BR11: AM-Peak | BS11: 16769.03 | BT11: 7467.28 | BU11: 17622.36 | BV11: 6098.72 | BW11: 8566.42 | BX11: 13288.28 | BY11: 36774.29 | BZ11: 26911.93 | CA11: 48995.9 | CB11: 32801.23 | CC11: 93618.67 | CD11: 59077.77 | CE11: 77491.03 | CF11: 47796.93 | CG11: 90828.36 | CH11: 60282.81 | CI11: 59602.3 | CJ11: 48344.94 | CK11: 62032.1 | CL11: 56008.68
B12: AM-Shoulder | C12: 1.6 | D12: 0.49 | E12: 1.6 | F12: 0.33 | G12: 1.6 | H12: 2.37 | I12: 0.97 | J12: 0.68 | K12: 1.12 | L12: 0.61 | M12: 1.2 | N12: 0.59 | O12: 1.2 | P12: 0.59 | Q12: 0.79 | R12: 0.55 | S12: 0.55 | T12: 0.52 | U12: 0.5 | V12: 0.47 | X12: AM-Shoulder | Y12: 900.63 | Z12: 370.35 | AA12: 1124.49 | AB12: 340.34 | AC12: 539.16 | AD12: 691.15 | AE12: 1722.25 | AF12: 1358.94 | AG12: 2127.24 | AH12: 1546.32 | AI12: 3882.83 | AJ12: 2661.82 | AK12: 3093.41 | AL12: 2126.11 | AM12: 3439.74 | AN12: 2685.22 | AO12: 2447.13 | AP12: 2173.37 | AQ12: 2873.61 | AR12: 2685.46 | AU12: AM-Shoulder | AV12: 4865.44 | AW12: 2423.63 | AX12: 4730.52 | AY12: 2184 | AZ12: 2771.49 | BA12: 3929.66 | BB12: 9734.47 | BC12: 7957.35 | BD12: 13097.12 | BE12: 9711.36 | BF12: 24129.09 | BG12: 17041.14 | BH12: 19418.51 | BI12: 13700.4 | BJ12: 21460.58 | BK12: 17074.88 | BL12: 15329.58 | BM12: 14463.45 | BN12: 18654.36 | BO12: 17741 | BR12: AM-Shoulder | BS12: 5766.07 | BT12: 2793.98 | BU12: 5855.01 | BV12: 2524.34 | BW12: 3310.65 | BX12: 4620.81 | BY12: 11456.72 | BZ12: 9316.29 | CA12: 15224.36 | CB12: 11257.68 | CC12: 28011.92 | CD12: 19702.96 | CE12: 22511.92 | CF12: 15826.51 | CG12: 24900.32 | CH12: 19760.1 | CI12: 17776.71 | CJ12: 16636.82 | CK12: 21527.97 | CL12: 20426.46
B13: MD | C13: 1.59 | D13: 0.92 | E13: 0.88 | F13: 0.4 | G13: 1.06 | H13: 1.6 | I13: 0.43 | J13: 0.86 | K13: 0.73 | L13: 0.81 | M13: 0.66 | N13: 0.59 | O13: 0.6 | P13: 0.54 | Q13: 0.56 | R13: 0.53 | S13: 0.54 | T13: 0.45 | U13: 0.48 | V13: 0.34 | X13: MD | Y13: 2664.62 | Z13: 2958.42 | AA13: 3412.04 | AB13: 3522.05 | AC13: 1713.69 | AD13: 2727.84 | AE13: 7031.93 | AF13: 7137.12 | AG13: 9379.15 | AH13: 9498.81 | AI13: 15782.7 | AJ13: 15889.78 | AK13: 11859.52 | AL13: 12422.27 | AM13: 14623.64 | AN13: 14181.82 | AO13: 12166.46 | AP13: 11879.65 | AQ13: 15187.11 | AR13: 17004.01 | AU13: MD | AV13: 16273.88 | AW13: 18041.58 | AX13: 17363.96 | AY13: 17910.9 | AZ13: 9476.31 | BA13: 12939.66 | BB13: 38074.07 | BC13: 39278.88 | BD13: 55113.71 | BE13: 56201.19 | BF13: 93442.41 | BG13: 94200.02 | BH13: 70770.04 | BI13: 73726.58 | BJ13: 88339.12 | BK13: 85023.55 | BL13: 74329.54 | BM13: 71987.3 | BN13: 94744.51 | BO13: 105367.87 | BR13: MD | BS13: 18938.5 | BT13: 21000 | BU13: 20776 | BV13: 21432.95 | BW13: 11190 | BX13: 15667.5 | BY13: 45106 | BZ13: 46416 | CA13: 64492.85 | CB13: 65700 | CC13: 109225.11 | CD13: 110089.8 | CE13: 82629.57 | CF13: 86148.85 | CG13: 102962.77 | CH13: 99205.37 | CI13: 86496 | CJ13: 83866.95 | CK13: 109931.62 | CL13: 122371.87
B14: PM-Shoulder | C14: 1.6 | D14: 1.59 | E14: 0.66 | F14: 0.95 | G14: 1.47 | H14: 1.46 | I14: 0.41 | J14: 1.6 | K14: 0.41 | L14: 1.25 | M14: 0.46 | N14: 0.78 | O14: 0.45 | P14: 0.61 | Q14: 0.45 | R14: 0.62 | S14: 0.44 | T14: 0.55 | U14: 0.4 | V14: 0.34 | X14: PM-Shoulder | Y14: 856.01 | Z14: 836.35 | AA14: 988.47 | AB14: 1167.93 | AC14: 515.64 | AD14: 608.6 | AE14: 1638.73 | AF14: 2103.93 | AG14: 1957.41 | AH14: 2966.57 | AI14: 3731.91 | AJ14: 4828.44 | AK14: 2960.85 | AL14: 3596.07 | AM14: 3819.29 | AN14: 4628.03 | AO14: 3265.42 | AP14: 4023.52 | AQ14: 3890.06 | AR14: 3830.11 | AU14: PM-Shoulder | AV14: 3914.88 | AW14: 3957.32 | AX14: 3914.45 | AY14: 4518.78 | AZ14: 2240.61 | BA14: 2574.48 | BB14: 6790.3 | BC14: 7530.52 | BD14: 8847.02 | BE14: 13896.43 | BF14: 17140.91 | BG14: 22127.09 | BH14: 13583.75 | BI14: 16155.17 | BJ14: 17725.76 | BK14: 21209.59 | BL14: 15425.52 | BM14: 18065.26 | BN14: 18782.18 | BO14: 17369.59 | BR14: PM-Shoulder | BS14: 4770.88 | BT14: 4793.67 | BU14: 4902.93 | BV14: 5686.71 | BW14: 2756.25 | BX14: 3183.08 | BY14: 8429.03 | BZ14: 9634.46 | CA14: 10804.42 | CB14: 16863 | CC14: 20872.82 | CD14: 26955.53 | CE14: 16544.6 | CF14: 19751.25 | CG14: 21545.04 | CH14: 25837.62 | CI14: 18690.94 | CJ14: 22088.78 | CK14: 22672.24 | CL14: 21199.7
B15: PM-Peak | C15: 2.12 | D15: 1.6 | E15: 0.85 | F15: 1.12 | G15: 1.6 | H15: 1.83 | I15: 0.77 | J15: 1.6 | K15: 0.71 | L15: 2.08 | M15: 0.76 | N15: 1.6 | O15: 0.75 | P15: 1.22 | Q15: 0.83 | R15: 0.93 | S15: 0.71 | T15: 0.71 | U15: 0.65 | V15: 0.63 | X15: PM-Peak | Y15: 2811.58 | Z15: 3492.33 | AA15: 2760.12 | AB15: 3297.96 | AC15: 1663.13 | AD15: 2088.42 | AE15: 5445.07 | AF15: 7667.99 | AG15: 6258.78 | AH15: 9551.02 | AI15: 11534.41 | AJ15: 16010.57 | AK15: 9221.36 | AL15: 11726.5 | AM15: 12443.17 | AN15: 13421.92 | AO15: 9827.14 | AP15: 10186.66 | AQ15: 11965.71 | AR15: 11910.82 | AU15: PM-Peak | AV15: 13287.12 | AW15: 13669.19 | AX15: 10954.98 | AY15: 13058.99 | AZ15: 6786.74 | BA15: 9016.9 | BB15: 23081.33 | BC15: 24467.59 | BD15: 28882.62 | BE15: 46277.83 | BF15: 54078.73 | BG15: 76683.37 | BH15: 43278.38 | BI15: 55729.46 | BJ15: 59567.02 | BK15: 63967.21 | BL15: 47603.6 | BM15: 48444.55 | BN15: 58556.34 | BO15: 57447.57 | BR15: PM-Peak | BS15: 16098.71 | BT15: 17161.52 | BU15: 13715.1 | BV15: 16356.95 | BW15: 8449.88 | BX15: 11105.33 | BY15: 28526.4 | BZ15: 32135.58 | CA15: 35141.41 | CB15: 55828.85 | CC15: 65613.15 | CD15: 92693.94 | CE15: 52499.74 | CF15: 67455.96 | CG15: 72010.19 | CH15: 77389.13 | CI15: 57430.74 | CJ15: 58631.22 | CK15: 70522.05 | CL15: 69358.39
B16: PM-Late | C16: 0.48 | D16: 0.58 | E16: 0.2 | F16: 0.2 | G16: 0.2 | H16: 0.34 | I16: 0.2 | J16: 0.84 | K16: 0.49 | L16: 0.83 | M16: 0.66 | N16: 0.78 | O16: 0.71 | P16: 0.64 | Q16: 0.65 | R16: 0.59 | S16: 0.6 | T16: 0.52 | U16: 0.53 | V16: 0.43 | X16: PM-Late | Y16: 1318.78 | Z16: 1670.08 | AA16: 316.41 | AB16: 337.16 | AC16: 170.36 | AD16: 725.02 | AE16: 622.21 | AF16: 3788.16 | AG16: 3114.32 | AH16: 4604.7 | AI16: 5483.18 | AJ16: 8300.12 | AK16: 4334.43 | AL16: 5883.63 | AM16: 5435.68 | AN16: 6012.78 | AO16: 4722.59 | AP16: 4686.14 | AQ16: 6259.46 | AR16: 6438.72 | AU16: PM-Late | AV16: 6612.92 | AW16: 8042.42 | AX16: 6065.6 | AY16: 6465.79 | AZ16: 3335.14 | BA16: 4680 | BB16: 12259.79 | BC16: 16597.44 | BD16: 15995.68 | BE16: 21681.3 | BF16: 28050.82 | BG16: 39122.68 | BH16: 22418.07 | BI16: 28385.67 | BJ16: 28091.72 | BK16: 30193.62 | BL16: 23684.41 | BM16: 24251.26 | BN16: 32674.54 | BO16: 34574.28 | BR16: PM-Late | BS16: 7931.7 | BT16: 9712.5 | BU16: 6382 | BV16: 6802.95 | BW16: 3505.5 | BX16: 5405.02 | BY16: 12882 | BZ16: 20385.6 | CA16: 19110 | CB16: 26286 | CC16: 33534 | CD16: 47422.8 | CE16: 26752.5 | CF16: 34269.3 | CG16: 33527.4 | CH16: 36206.4 | CI16: 28407 | CJ16: 28937.4 | CK16: 38934 | CL16: 41013
B19: CaptureRateLights | X19: ML Volume (PCE/Period) | AU19: GP Volume (PCE/Period) | BR19: Highway Volume
B20: Direction | C20: NB | D20: SB | E20: NB | F20: SB | G20: NB | H20: SB | I20: NB | J20: SB | K20: NB | L20: SB | M20: NB | N20: SB | O20: NB | P20: SB | Q20: NB | R20: SB | S20: NB | T20: SB | U20: NB | V20: SB | X20: Direction | Y20: NB | Z20: SB | AA20: NB | AB20: SB | AC20: NB | AD20: SB | AE20: NB | AF20: SB | AG20: NB | AH20: SB | AI20: NB | AJ20: SB | AK20: NB | AL20: SB | AM20: NB | AN20: SB | AO20: NB | AP20: SB | AQ20: NB | AR20: SB | AU20: Direction | AV20: NB | AW20: SB | AX20: NB | AY20: SB | AZ20: NB | BA20: SB | BB20: NB | BC20: SB | BD20: NB | BE20: SB | BF20: NB | BG20: SB | BH20: NB | BI20: SB | BJ20: NB | BK20: SB | BL20: NB | BM20: SB | BN20: NB | BO20: SB | BR20: Direction | BS20: NB | BT20: SB | BU20: NB | BV20: SB | BW20: NB | BX20: SB | BY20: NB | BZ20: SB | CA20: NB | CB20: SB | CC20: NB | CD20: SB | CE20: NB | CF20: SB | CG20: NB | CH20: SB | CI20: NB | CJ20: SB | CK20: NB | CL20: SB
B21: Segment | C21: 1 | D21: 1 | E21: 2 | F21: 2 | G21: 3 | H21: 3 | I21: 4 | J21: 4 | K21: 5 | L21: 5 | M21: 6 | N21: 6 | O21: 7 | P21: 7 | Q21: 8 | R21: 8 | S21: 9 | T21: 9 | U21: 10 | V21: 10 | X21: Segment | Y21: 1 | Z21: 1 | AA21: 2 | AB21: 2 | AC21: 3 | AD21: 3 | AE21: 4 | AF21: 4 | AG21: 5 | AH21: 5 | AI21: 6 | AJ21: 6 | AK21: 7 | AL21: 7 | AM21: 8 | AN21: 8 | AO21: 9 | AP21: 9 | AQ21: 10 | AR21: 10 | AU21: Segment | AV21: 1 | AW21: 1 | AX21: 2 | AY21: 2 | AZ21: 3 | BA21: 3 | BB21: 4 | BC21: 4 | BD21: 5 | BE21: 5 | BF21: 6 | BG21: 6 | BH21: 7 | BI21: 7 | BJ21: 8 | BK21: 8 | BL21: 9 | BM21: 9 | BN21: 10 | BO21: 10 | BR21: Segment | BS21: 1 | BT21: 1 | BU21: 2 | BV21: 2 | BW21: 3 | BX21: 3 | BY21: 4 | BZ21: 4 | CA21: 5 | CB21: 5 | CC21: 6 | CD21: 6 | CE21: 7 | CF21: 7 | CG21: 8 | CH21: 8 | CI21: 9 | CJ21: 9 | CK21: 10 | CL21: 10
B22: Period | X22: Period | AU22: Period | BR22: Period
B23: Night | C23: 0.05 | D23: 0.05 | E23: 0.05 | F23: 0.05 | G23: 0.05 | H23: 0.05 | I23: 0.05 | J23: 0.15 | K23: 0.15 | L23: 0.15 | M23: 0.15 | N23: 0.15 | O23: 0.15 | P23: 0.15 | Q23: 0.15 | R23: 0.15 | S23: 0.15 | T23: 0.15 | U23: 0.15 | V23: 0.15 | X23: Night | Y23: 758.77 | Z23: 755.44 | AA23: 583.8 | AB23: 546.35 | AC23: 541.1 | AD23: 655.03 | AE23: 688.94 | AF23: 1630.65 | AG23: 1912.05 | AH23: 1644.3 | AI23: 1928.85 | AJ23: 1613.85 | AK23: 1865.85 | AL23: 1533 | AM23: 1787.1 | AN23: 1600.2 | AO23: 1590.75 | AP23: 1102.5 | AQ23: 1533 | AR23: 1111.95 | AU23: Night | AV23: 15015.03 | AW23: 14911.96 | AX23: 11344.2 | AY23: 10611.65 | AZ23: 10826.9 | BA23: 12904.32 | BB23: 13847.96 | BC23: 12831.35 | BD23: 14628.95 | BE23: 12950.7 | BF23: 14633.15 | BG23: 12701.15 | BH23: 14360.15 | BI23: 12257 | BJ23: 13773.9 | BK23: 12567.8 | BL23: 12087.25 | BM23: 9446.5 | BN23: 12334 | BO23: 9878.05 | BR23: Night | BS23: 15773.8 | BT23: 15667.4 | BU23: 11928 | BV23: 11158 | BW23: 11368 | BX23: 13559.35 | BY23: 14536.9 | BZ23: 14462 | CA23: 16541 | CB23: 14595 | CC23: 16562 | CD23: 14315 | CE23: 16226 | CF23: 13790 | CG23: 15561 | CH23: 14168 | CI23: 13678 | CJ23: 10549 | CK23: 13867 | CL23: 10990
B24: AM-Early | C24: 0.17 | D24: 0.17 | E24: 0.18 | F24: 0.18 | G24: 0.18 | H24: 0.18 | I24: 0.17 | J24: 0.18 | K24: 0.16 | L24: 0.17 | M24: 0.16 | N24: 0.16 | O24: 0.16 | P24: 0.16 | Q24: 0.16 | R24: 0.16 | S24: 0.16 | T24: 0.16 | U24: 0.16 | V24: 0.16 | X24: AM-Early | Y24: 970.59 | Z24: 594.72 | AA24: 965.76 | AB24: 617.22 | AC24: 636.93 | AD24: 788.09 | AE24: 1078.02 | AF24: 739.56 | AG24: 1027.82 | AH24: 696.81 | AI24: 992.78 | AJ24: 702.78 | AK24: 855.38 | AL24: 748.4 | AM24: 813.18 | AN24: 721.12 | AO24: 793.56 | AP24: 594.84 | AQ24: 914.53 | AR24: 562.15 | AU24: AM-Early | AV24: 5465.66 | AW24: 3587.18 | AX24: 4804.54 | AY24: 3216.98 | AZ24: 3355.07 | BA24: 4119.61 | BB24: 5506.43 | BC24: 4020.44 | BD24: 5691.53 | BE24: 4079.19 | BF24: 5526.12 | BG24: 4146.22 | BH24: 4849.62 | BI24: 4374.6 | BJ24: 4652.32 | BK24: 4177.08 | BL24: 4550.66 | BM24: 3560.75 | BN24: 5388.72 | BO24: 3444.95 | BR24: AM-Early | BS24: 6436.25 | BT24: 4181.9 | BU24: 5770.3 | BV24: 3834.2 | BW24: 3992 | BX24: 4907.7 | BY24: 6584.45 | BZ24: 4760 | CA24: 6719.35 | CB24: 4776 | CC24: 6518.9 | CD24: 4849 | CE24: 5705 | CF24: 5123 | CG24: 5465.5 | CH24: 4898.2 | CI24: 5344.21 | CJ24: 4155.59 | CK24: 6303.25 | CL24: 4007.1
B25: AM-Peak | C25: 0.2 | D25: 0.14 | E25: 0.17 | F25: 0.05 | G25: 0.2 | H25: 0.24 | I25: 0.17 | J25: 0.18 | K25: 0.17 | L25: 0.16 | M25: 0.19 | N25: 0.16 | O25: 0.23 | P25: 0.16 | Q25: 0.22 | R25: 0.16 | S25: 0.16 | T25: 0.16 | U25: 0.16 | V25: 0.16 | X25: AM-Peak | Y25: 4266.53 | Z25: 1307.55 | AA25: 4098.27 | AB25: 433.49 | AC25: 2953.36 | AD25: 5778.44 | AE25: 3552.54 | AF25: 2543.12 | AG25: 3783.21 | AH25: 2301.83 | AI25: 4437.33 | AJ25: 2277.54 | AK25: 5467.18 | AL25: 2272.08 | AM25: 4498.65 | AN25: 2222.94 | AO25: 2477.24 | AP25: 1934.33 | AQ25: 1905.61 | AR25: 1694.88 | AU25: AM-Peak | AV25: 19689.22 | AW25: 9360 | AX25: 21076.53 | AY25: 8278.96 | AZ25: 14179.49 | BA25: 20798.11 | BB25: 19431.39 | BC25: 14276.83 | BD25: 20714.73 | BE25: 14098.78 | BF25: 21567.86 | BG25: 14132.96 | BH25: 21253.86 | BI25: 14209.62 | BJ25: 19403.55 | BK25: 13640.96 | BL25: 15052.85 | BM25: 12284.77 | BN25: 11879.3 | BO25: 10751.5 | BR25: AM-Peak | BS25: 23955.75 | BT25: 10667.55 | BU25: 25174.8 | BV25: 8712.45 | BW25: 17132.85 | BX25: 26576.55 | BY25: 22983.93 | BZ25: 16819.95 | CA25: 24497.95 | CB25: 16400.62 | CC25: 26005.19 | CD25: 16410.49 | CE25: 26721.04 | CF25: 16481.7 | CG25: 23902.2 | CH25: 15863.9 | CI25: 17530.09 | CJ25: 14219.1 | CK25: 13784.91 | CL25: 12446.37
B26: AM-Shoulder | C26: 0.19 | D26: 0.17 | E26: 0.21 | F26: 0.15 | G26: 0.2 | H26: 0.17 | I26: 0.17 | J26: 0.18 | K26: 0.16 | L26: 0.17 | M26: 0.16 | N26: 0.16 | O26: 0.16 | P26: 0.16 | Q26: 0.16 | R26: 0.16 | S26: 0.16 | T26: 0.17 | U26: 0.16 | V26: 0.17 | X26: AM-Shoulder | Y26: 1286.62 | Z26: 529.07 | AA26: 1606.41 | AB26: 486.2 | AC26: 1078.32 | AD26: 1382.31 | AE26: 1076.41 | AF26: 849.34 | AG26: 1063.62 | AH26: 773.16 | AI26: 1078.56 | AJ26: 739.4 | AK26: 1066.69 | AL26: 733.14 | AM26: 905.19 | AN26: 706.64 | AO26: 719.74 | AP26: 639.23 | AQ26: 638.58 | AR26: 596.77 | AU26: AM-Shoulder | AV26: 6950.63 | AW26: 3462.33 | AX26: 6757.89 | AY26: 3120 | AZ26: 5542.98 | BA26: 7859.32 | BB26: 6084.04 | BC26: 4973.35 | BD26: 6548.56 | BE26: 4855.68 | BF26: 6702.52 | BG26: 4733.65 | BH26: 6696.04 | BI26: 4724.28 | BJ26: 5647.52 | BK26: 4493.39 | BL26: 4508.7 | BM26: 4253.96 | BN26: 4145.41 | BO26: 3942.45 | BR26: AM-Shoulder | BS26: 8237.25 | BT26: 3991.4 | BU26: 8364.3 | BV26: 3606.2 | BW26: 6621.3 | BX26: 9241.63 | BY26: 7160.45 | BZ26: 5822.68 | CA26: 7612.18 | CB26: 5628.84 | CC26: 7781.09 | CD26: 5473.04 | CE26: 7762.73 | CF26: 5457.42 | CG26: 6552.71 | CH26: 5200.03 | CI26: 5228.44 | CJ26: 4893.18 | CK26: 4783.99 | CL26: 4539.21
B27: MD | C27: 0.17 | D27: 0.17 | E27: 0.18 | F27: 0.18 | G27: 0.18 | H27: 0.2 | I27: 0.18 | J27: 0.18 | K27: 0.17 | L27: 0.17 | M27: 0.17 | N27: 0.17 | O27: 0.17 | P27: 0.17 | Q27: 0.17 | R27: 0.17 | S27: 0.17 | T27: 0.17 | U27: 0.17 | V27: 0.17 | X27: MD | Y27: 3806.6 | Z27: 4226.32 | AA27: 4874.34 | AB27: 5031.5 | AC27: 3427.38 | AD27: 5455.68 | AE27: 4394.96 | AF27: 4460.7 | AG27: 4689.57 | AH27: 4749.4 | AI27: 4384.08 | AJ27: 4413.83 | AK27: 4089.49 | AL27: 4283.54 | AM27: 3848.33 | AN27: 3732.06 | AO27: 3578.37 | AP27: 3494.01 | AQ27: 3374.91 | AR27: 3778.67 | AU27: MD | AV27: 23248.4 | AW27: 25773.68 | AX27: 24805.66 | AY27: 25587 | AZ27: 18952.62 | BA27: 25879.32 | BB27: 23796.29 | BC27: 24549.3 | BD27: 27556.85 | BE27: 28100.6 | BF27: 25956.23 | BG27: 26166.67 | BH27: 24403.46 | BI27: 25422.96 | BJ27: 23247.14 | BK27: 22374.62 | BL27: 21861.63 | BM27: 21172.74 | BN27: 21054.34 | BO27: 23415.08 | BR27: MD | BS27: 27055 | BT27: 30000 | BU27: 29680 | BV27: 30618.5 | BW27: 22380 | BX27: 31335 | BY27: 28191.25 | BZ27: 29010 | CA27: 32246.43 | CB27: 32850 | CC27: 30340.31 | CD27: 30580.5 | CE27: 28492.95 | CF27: 29706.5 | CG27: 27095.46 | CH27: 26106.68 | CI27: 25440 | CJ27: 24666.75 | CK27: 24429.25 | CL27: 27193.75
B28: PM-Shoulder | C28: 0.21 | D28: 0.2 | E28: 0.22 | F28: 0.21 | G28: 0.22 | H28: 0.22 | I28: 0.22 | J28: 0.25 | K28: 0.2 | L28: 0.2 | M28: 0.2 | N28: 0.2 | O28: 0.2 | P28: 0.2 | Q28: 0.2 | R28: 0.2 | S28: 0.2 | T28: 0.2 | U28: 0.2 | V28: 0.2 | X28: PM-Shoulder | Y28: 1222.87 | Z28: 1194.79 | AA28: 1412.1 | AB28: 1668.47 | AC28: 1031.28 | AD28: 1217.19 | AE28: 1024.21 | AF28: 1314.96 | AG28: 978.7 | AH28: 1483.29 | AI28: 1036.64 | AJ28: 1341.23 | AK28: 1020.98 | AL28: 1240.03 | AM28: 1005.08 | AN28: 1217.9 | AO28: 960.42 | AP28: 1183.39 | AQ28: 864.46 | AR28: 851.14 | AU28: PM-Shoulder | AV28: 5592.68 | AW28: 5653.31 | AX28: 5592.07 | AY28: 6455.4 | AZ28: 4481.22 | BA28: 5148.96 | BB28: 4243.94 | BC28: 4706.58 | BD28: 4423.51 | BE28: 6948.21 | BF28: 4761.36 | BG28: 6146.41 | BH28: 4684.05 | BI28: 5570.75 | BJ28: 4664.67 | BK28: 5581.47 | BL28: 4536.92 | BM28: 5313.31 | BN28: 4173.82 | BO28: 3859.91 | BR28: PM-Shoulder | BS28: 6815.55 | BT28: 6848.1 | BU28: 7004.18 | BV28: 8123.88 | BW28: 5512.5 | BX28: 6366.15 | BY28: 5268.14 | BZ28: 6021.54 | CA28: 5402.21 | CB28: 8431.5 | CC28: 5798 | CD28: 7487.65 | CE28: 5705.03 | CF28: 6810.78 | CG28: 5669.75 | CH28: 6799.37 | CI28: 5497.34 | CJ28: 6496.7 | CK28: 5038.28 | CL28: 4711.05
B29: PM-Peak | C29: 0.2 | D29: 0.24 | E29: 0.22 | F29: 0.21 | G29: 0.22 | H29: 0.22 | I29: 0.21 | J29: 0.27 | K29: 0.2 | L29: 0.19 | M29: 0.2 | N29: 0.19 | O29: 0.2 | P29: 0.2 | Q29: 0.2 | R29: 0.2 | S29: 0.2 | T29: 0.2 | U29: 0.2 | V29: 0.2 | X29: PM-Peak | Y29: 4016.54 | Z29: 4989.04 | AA29: 3943.03 | AB29: 4711.37 | AC29: 3326.27 | AD29: 4176.84 | AE29: 3403.17 | AF29: 4792.49 | AG29: 3129.39 | AH29: 4775.51 | AI29: 3204 | AJ29: 4447.38 | AK29: 3179.78 | AL29: 4043.62 | AM29: 3274.52 | AN29: 3532.08 | AO29: 2890.33 | AP29: 2996.08 | AQ29: 2659.05 | AR29: 2646.85 | AU29: PM-Peak | AV29: 18981.61 | AW29: 19527.41 | AX29: 15649.97 | AY29: 18655.7 | AZ29: 13573.48 | BA29: 18033.81 | BB29: 14425.83 | BC29: 15292.24 | BD29: 14441.31 | BE29: 23138.91 | BF29: 15021.87 | BG29: 21300.94 | BH29: 14923.58 | BI29: 19217.06 | BJ29: 15675.53 | BK29: 16833.48 | BL29: 14001.06 | BM29: 14248.4 | BN29: 13012.52 | BO29: 12766.13 | BR29: PM-Peak | BS29: 22998.15 | BT29: 24516.45 | BU29: 19593 | BV29: 23367.07 | BW29: 16899.75 | BX29: 22210.65 | BY29: 17829 | BZ29: 20084.74 | CA29: 17570.7 | CB29: 27914.42 | CC29: 18225.87 | CD29: 25748.32 | CE29: 18103.36 | CF29: 23260.68 | CG29: 18950.05 | CH29: 20365.56 | CI29: 16891.39 | CJ29: 17244.48 | CK29: 15671.57 | CL29: 15412.98
B30: PM-Late | C30: 0.2 | D30: 0.2 | E30: 0.05 | F30: 0.05 | G30: 0.05 | H30: 0.15 | I30: 0.05 | J30: 0.22 | K30: 0.2 | L30: 0.2 | M30: 0.2 | N30: 0.2 | O30: 0.2 | P30: 0.2 | Q30: 0.2 | R30: 0.2 | S30: 0.21 | T30: 0.2 | U30: 0.2 | V30: 0.2 | X30: PM-Late | Y30: 1883.97 | Z30: 2385.82 | AA30: 452.01 | AB30: 481.65 | AC30: 340.72 | AD30: 1450.05 | AE30: 388.88 | AF30: 2367.6 | AG30: 1557.16 | AH30: 2302.35 | AI30: 1523.11 | AJ30: 2305.59 | AK30: 1494.63 | AL30: 2028.84 | AM30: 1430.44 | AN30: 1582.31 | AO30: 1389 | AP30: 1378.28 | AQ30: 1390.99 | AR30: 1430.83 | AU30: PM-Late | AV30: 9447.03 | AW30: 11489.18 | AX30: 8665.14 | AY30: 9236.85 | AZ30: 6670.28 | BA30: 9360 | BB30: 7662.37 | BC30: 10373.4 | BD30: 7997.84 | BE30: 10840.65 | BF30: 7791.89 | BG30: 10867.41 | BH30: 7730.37 | BI30: 9788.16 | BJ30: 7392.56 | BK30: 7945.69 | BL30: 6966 | BM30: 7132.72 | BN30: 7261.01 | BO30: 7683.17 | BR30: PM-Late | BS30: 11331 | BT30: 13875 | BU30: 9117.15 | BV30: 9718.5 | BW30: 7011 | BX30: 10810.05 | BY30: 8051.25 | BZ30: 12741 | CA30: 9555 | CB30: 13143 | CC30: 9315 | CD30: 13173 | CE30: 9225 | CF30: 11817 | CG30: 8823 | CH30: 9528 | CI30: 8355 | CJ30: 8511 | CK30: 8652 | CL30: 9114
B33: Revenue Per Period | X33: ML Flow (PCE/hr) | AU33: GP Flow (PCE/hr) | BR33: Highway Flow
B34: Direction | C34: NB | D34: SB | E34: NB | F34: SB | G34: NB | H34: SB | I34: NB | J34: SB | K34: NB | L34: SB | M34: NB | N34: SB | O34: NB | P34: SB | Q34: NB | R34: SB | S34: NB | T34: SB | U34: NB | V34: SB | X34: Direction | Y34: NB | Z34: SB | AA34: NB | AB34: SB | AC34: NB | AD34: SB | AE34: NB | AF34: SB | AG34: NB | AH34: SB | AI34: NB | AJ34: SB | AK34: NB | AL34: SB | AM34: NB | AN34: SB | AO34: NB | AP34: SB | AQ34: NB | AR34: SB | AU34: Direction | AV34: NB | AW34: SB | AX34: NB | AY34: SB | AZ34: NB | BA34: SB | BB34: NB | BC34: SB | BD34: NB | BE34: SB | BF34: NB | BG34: SB | BH34: NB | BI34: SB | BJ34: NB | BK34: SB | BL34: NB | BM34: SB | BN34: NB | BO34: SB | BR34: Direction | BS34: NB | BT34: SB | BU34: NB | BV34: SB | BW34: NB | BX34: SB | BY34: NB | BZ34: SB | CA34: NB | CB34: SB | CC34: NB | CD34: SB | CE34: NB | CF34: SB | CG34: NB | CH34: SB | CI34: NB | CJ34: SB | CK34: NB | CL34: SB
B35: Segment | C35: 1 | D35: 1 | E35: 2 | F35: 2 | G35: 3 | H35: 3 | I35: 4 | J35: 4 | K35: 5 | L35: 5 | M35: 6 | N35: 6 | O35: 7 | P35: 7 | Q35: 8 | R35: 8 | S35: 9 | T35: 9 | U35: 10 | V35: 10 | X35: Segment | Y35: 1 | Z35: 1 | AA35: 2 | AB35: 2 | AC35: 3 | AD35: 3 | AE35: 4 | AF35: 4 | AG35: 5 | AH35: 5 | AI35: 6 | AJ35: 6 | AK35: 7 | AL35: 7 | AM35: 8 | AN35: 8 | AO35: 9 | AP35: 9 | AQ35: 10 | AR35: 10 | AU35: Segment | AV35: 1 | AW35: 1 | AX35: 2 | AY35: 2 | AZ35: 3 | BA35: 3 | BB35: 4 | BC35: 4 | BD35: 5 | BE35: 5 | BF35: 6 | BG35: 6 | BH35: 7 | BI35: 7 | BJ35: 8 | BK35: 8 | BL35: 9 | BM35: 9 | BN35: 10 | BO35: 10 | BR35: Segment | BS35: 1 | BT35: 1 | BU35: 2 | BV35: 2 | BW35: 3 | BX35: 3 | BY35: 4 | BZ35: 4 | CA35: 5 | CB35: 5 | CC35: 6 | CD35: 6 | CE35: 7 | CF35: 7 | CG35: 8 | CH35: 8 | CI35: 9 | CJ35: 9 | CK35: 10 | CL35: 10
B36: Period | X36: Period | AU36: Period | BR36: Period
B37: Night | C37: 106.23 | D37: 105.76 | E37: 81.73 | F37: 76.49 | G37: 54.11 | H37: 65.5 | I37: 220.46 | J37: 2651.77 | K37: 3096.7 | L37: 3042.99 | M37: 7335.28 | N37: 5241.18 | O37: 5769.35 | P37: 3841.91 | Q37: 6453.51 | R37: 5347.08 | S37: 4565.65 | T37: 2429.58 | U37: 5961.02 | V37: 3416.34 | X37: Night | Y37: 108.4 | Z37: 107.92 | AA37: 83.4 | AB37: 78.05 | AC37: 77.3 | AD37: 93.58 | AE37: 98.42 | AF37: 232.95 | AG37: 273.15 | AH37: 234.9 | AI37: 275.55 | AJ37: 230.55 | AK37: 266.55 | AL37: 219 | AM37: 255.3 | AN37: 228.6 | AO37: 227.25 | AP37: 157.5 | AQ37: 219 | AR37: 158.85 | AU37: Night | AV37: 2145 | AW37: 2130.28 | AX37: 1620.6 | AY37: 1515.95 | AZ37: 1546.7 | BA37: 1843.47 | BB37: 1978.28 | BC37: 1833.05 | BD37: 2089.85 | BE37: 1850.1 | BF37: 2090.45 | BG37: 1814.45 | BH37: 2051.45 | BI37: 1751 | BJ37: 1967.7 | BK37: 1795.4 | BL37: 1726.75 | BM37: 1349.5 | BN37: 1762 | BO37: 1411.15 | BR37: Night | BS37: 2253.4 | BT37: 2238.2 | BU37: 1704 | BV37: 1594 | BW37: 1624 | BX37: 1937.05 | BY37: 2076.7 | BZ37: 2066 | CA37: 2363 | CB37: 2085 | CC37: 2366 | CD37: 2045 | CE37: 2318 | CF37: 1970 | CG37: 2223 | CH37: 2024 | CI37: 1954 | CJ37: 1507 | CK37: 1981 | CL37: 1570
B38: AM-Early | C38: 319.79 | D38: 138.6 | E38: 247.05 | F38: 118.05 | G38: 145.96 | H38: 131.19 | I38: 706.22 | J38: 684.08 | K38: 915.84 | L38: 647.22 | M38: 1943.35 | N38: 1206.61 | O38: 1436.31 | P38: 1102.34 | Q38: 1690.8 | R38: 1151.05 | S38: 1431.68 | T38: 810.82 | U38: 1626.75 | V38: 674.57 | X38: AM-Early | Y38: 970.59 | Z38: 594.72 | AA38: 965.76 | AB38: 617.22 | AC38: 636.93 | AD38: 788.09 | AE38: 1078.02 | AF38: 739.56 | AG38: 1027.82 | AH38: 696.81 | AI38: 992.78 | AJ38: 702.78 | AK38: 855.38 | AL38: 748.4 | AM38: 813.18 | AN38: 721.12 | AO38: 793.56 | AP38: 594.84 | AQ38: 914.53 | AR38: 562.15 | AU38: AM-Early | AV38: 5465.66 | AW38: 3587.18 | AX38: 4804.54 | AY38: 3216.98 | AZ38: 3355.07 | BA38: 4119.61 | BB38: 5506.43 | BC38: 4020.44 | BD38: 5691.53 | BE38: 4079.19 | BF38: 5526.12 | BG38: 4146.22 | BH38: 4849.62 | BI38: 4374.6 | BJ38: 4652.32 | BK38: 4177.08 | BL38: 4550.66 | BM38: 3560.75 | BN38: 5388.72 | BO38: 3444.95 | BR38: AM-Early | BS38: 6436.25 | BT38: 4181.9 | BU38: 5770.3 | BV38: 3834.2 | BW38: 3992 | BX38: 4907.7 | BY38: 6584.45 | BZ38: 4760 | CA38: 6719.35 | CB38: 4776 | CC38: 6518.9 | CD38: 4849 | CE38: 5705 | CF38: 5123 | CG38: 5465.5 | CH38: 4898.2 | CI38: 5344.21 | CJ38: 4155.59 | CK38: 6303.25 | CL38: 4007.1
B39: AM-Peak | C39: 4778.51 | D39: 458.29 | E39: 7609.13 | F39: 60.69 | G39: 2362.68 | H39: 4622.75 | I39: 8521.39 | J39: 3676.35 | K39: 12106.28 | L39: 4004.61 | M39: 25558.99 | N39: 7211.77 | O39: 25367.74 | P39: 5856.68 | Q39: 27351.8 | R39: 7059.71 | S39: 7985.71 | T39: 4929.7 | U39: 6129.43 | V39: 4926.03 | X39: AM-Peak | Y39: 1422.18 | Z39: 435.85 | AA39: 1366.09 | AB39: 144.5 | AC39: 984.45 | AD39: 1926.15 | AE39: 1184.18 | AF39: 847.71 | AG39: 1261.07 | AH39: 767.28 | AI39: 1479.11 | AJ39: 759.18 | AK39: 1822.39 | AL39: 757.36 | AM39: 1499.55 | AN39: 740.98 | AO39: 825.75 | AP39: 644.78 | AQ39: 635.2 | AR39: 564.96 | AU39: AM-Peak | AV39: 6563.07 | AW39: 3120 | AX39: 7025.51 | AY39: 2759.65 | AZ39: 4726.5 | BA39: 6932.7 | BB39: 6477.13 | BC39: 4758.94 | BD39: 6904.91 | BE39: 4699.59 | BF39: 7189.29 | BG39: 4710.99 | BH39: 7084.62 | BI39: 4736.54 | BJ39: 6467.85 | BK39: 4546.99 | BL39: 5017.62 | BM39: 4094.92 | BN39: 3959.77 | BO39: 3583.83 | BR39: AM-Peak | BS39: 7985.25 | BT39: 3555.85 | BU39: 8391.6 | BV39: 2904.15 | BW39: 5710.95 | BX39: 8858.85 | BY39: 7661.31 | BZ39: 5606.65 | CA39: 8165.98 | CB39: 5466.87 | CC39: 8668.4 | CD39: 5470.16 | CE39: 8907.01 | CF39: 5493.9 | CG39: 7967.4 | CH39: 5287.97 | CI39: 5843.36 | CJ39: 4739.7 | CK39: 4594.97 | CL39: 4148.79
B40: AM-Shoulder | C40: 1441.01 | D40: 181.03 | E40: 1799.18 | F40: 113.17 | G40: 862.65 | H40: 1640.18 | I40: 1668.05 | J40: 917.89 | K40: 2373.28 | L40: 945.49 | M40: 4651.1 | N40: 1582.34 | O40: 3702.18 | P40: 1263.77 | Q40: 2731.05 | R40: 1478.33 | S40: 1343.45 | T40: 1137.4 | U40: 1438.86 | V40: 1275.48 | X40: AM-Shoulder | Y40: 1286.62 | Z40: 529.07 | AA40: 1606.41 | AB40: 486.2 | AC40: 1078.32 | AD40: 1382.31 | AE40: 1076.41 | AF40: 849.34 | AG40: 1063.62 | AH40: 773.16 | AI40: 1078.56 | AJ40: 739.4 | AK40: 1066.69 | AL40: 733.14 | AM40: 905.19 | AN40: 706.64 | AO40: 719.74 | AP40: 639.23 | AQ40: 638.58 | AR40: 596.77 | AU40: AM-Shoulder | AV40: 6950.63 | AW40: 3462.33 | AX40: 6757.89 | AY40: 3120 | AZ40: 5542.98 | BA40: 7859.32 | BB40: 6084.04 | BC40: 4973.35 | BD40: 6548.56 | BE40: 4855.68 | BF40: 6702.52 | BG40: 4733.65 | BH40: 6696.04 | BI40: 4724.28 | BJ40: 5647.52 | BK40: 4493.39 | BL40: 4508.7 | BM40: 4253.96 | BN40: 4145.41 | BO40: 3942.45 | BR40: AM-Shoulder | BS40: 8237.25 | BT40: 3991.4 | BU40: 8364.3 | BV40: 3606.2 | BW40: 6621.3 | BX40: 9241.63 | BY40: 7160.45 | BZ40: 5822.68 | CA40: 7612.18 | CB40: 5628.84 | CC40: 7781.09 | CD40: 5473.04 | CE40: 7762.73 | CF40: 5457.42 | CG40: 6552.71 | CH40: 5200.03 | CI40: 5228.44 | CJ40: 4893.18 | CK40: 4783.99 | CL40: 4539.21
B41: MD | C41: 4244.78 | D41: 2721.81 | E41: 3003.56 | F41: 1393.04 | G41: 1811.96 | H41: 4364.55 | I41: 3007.45 | J41: 6118.05 | K41: 6836.62 | L41: 7718.8 | M41: 10368.18 | N41: 9354.27 | O41: 7067.52 | P41: 6741.79 | Q41: 8160.93 | R41: 7470.21 | S41: 6509.93 | T41: 5366.13 | U41: 7219.59 | V41: 5852.29 | X41: MD | Y41: 761.32 | Z41: 845.26 | AA41: 974.87 | AB41: 1006.3 | AC41: 685.48 | AD41: 1091.14 | AE41: 878.99 | AF41: 892.14 | AG41: 937.91 | AH41: 949.88 | AI41: 876.82 | AJ41: 882.77 | AK41: 817.9 | AL41: 856.71 | AM41: 769.67 | AN41: 746.41 | AO41: 715.67 | AP41: 698.8 | AQ41: 674.98 | AR41: 755.73 | AU41: MD | AV41: 4649.68 | AW41: 5154.74 | AX41: 4961.13 | AY41: 5117.4 | AZ41: 3790.52 | BA41: 5175.86 | BB41: 4759.26 | BC41: 4909.86 | BD41: 5511.37 | BE41: 5620.12 | BF41: 5191.25 | BG41: 5233.33 | BH41: 4880.69 | BI41: 5084.59 | BJ41: 4649.43 | BK41: 4474.92 | BL41: 4372.33 | BM41: 4234.55 | BN41: 4210.87 | BO41: 4683.02 | BR41: MD | BS41: 5411 | BT41: 6000 | BU41: 5936 | BV41: 6123.7 | BW41: 4476 | BX41: 6267 | BY41: 5638.25 | BZ41: 5802 | CA41: 6449.29 | CB41: 6570 | CC41: 6068.06 | CD41: 6116.1 | CE41: 5698.59 | CF41: 5941.3 | CG41: 5419.09 | CH41: 5221.34 | CI41: 5088 | CJ41: 4933.35 | CK41: 4885.85 | CL41: 5438.75
B42: PM-Shoulder | C42: 1369.6 | D42: 1333.37 | E42: 653.05 | F42: 1110.75 | G42: 756.81 | H42: 889.57 | I42: 673.61 | J42: 3366.3 | K42: 799.93 | L42: 3702.56 | M42: 1730.74 | N42: 3772.21 | O42: 1335.76 | P42: 2187.35 | Q42: 1730.38 | R42: 2874.15 | S42: 1438.67 | T42: 2222.39 | U42: 1555.22 | V42: 1315.21 | X42: PM-Shoulder | Y42: 1222.87 | Z42: 1194.79 | AA42: 1412.1 | AB42: 1668.47 | AC42: 1031.28 | AD42: 1217.19 | AE42: 1024.21 | AF42: 1314.96 | AG42: 978.7 | AH42: 1483.29 | AI42: 1036.64 | AJ42: 1341.23 | AK42: 1020.98 | AL42: 1240.03 | AM42: 1005.08 | AN42: 1217.9 | AO42: 960.42 | AP42: 1183.39 | AQ42: 864.46 | AR42: 851.14 | AU42: PM-Shoulder | AV42: 5592.68 | AW42: 5653.31 | AX42: 5592.07 | AY42: 6455.4 | AZ42: 4481.22 | BA42: 5148.96 | BB42: 4243.94 | BC42: 4706.58 | BD42: 4423.51 | BE42: 6948.21 | BF42: 4761.36 | BG42: 6146.41 | BH42: 4684.05 | BI42: 5570.75 | BJ42: 4664.67 | BK42: 5581.47 | BL42: 4536.92 | BM42: 5313.31 | BN42: 4173.82 | BO42: 3859.91 | BR42: PM-Shoulder | BS42: 6815.55 | BT42: 6848.1 | BU42: 7004.18 | BV42: 8123.88 | BW42: 5512.5 | BX42: 6366.15 | BY42: 5268.14 | BZ42: 6021.54 | CA42: 5402.21 | CB42: 8431.5 | CC42: 5798 | CD42: 7487.65 | CE42: 5705.03 | CF42: 6810.78 | CG42: 5669.75 | CH42: 6799.37 | CI42: 5497.34 | CJ42: 6496.7 | CK42: 5038.28 | CL42: 4711.05
B43: PM-Peak | C43: 5971.01 | D43: 5587.72 | E43: 2353.16 | F43: 3699.99 | G43: 2661.01 | H43: 3830.89 | I43: 4169.72 | J43: 12268.77 | K43: 4427.85 | L43: 19908.66 | M43: 8785.06 | N43: 25616.49 | O43: 6949.56 | P43: 14269.07 | Q43: 10287.25 | R43: 12483.14 | S43: 6943.63 | T43: 7267.69 | U43: 7761.04 | V43: 7459.82 | X43: PM-Peak | Y43: 1338.85 | Z43: 1663.01 | AA43: 1314.34 | AB43: 1570.46 | AC43: 1108.76 | AD43: 1392.28 | AE43: 1134.39 | AF43: 1597.5 | AG43: 1043.13 | AH43: 1591.84 | AI43: 1068 | AJ43: 1482.46 | AK43: 1059.93 | AL43: 1347.87 | AM43: 1091.51 | AN43: 1177.36 | AO43: 963.44 | AP43: 998.69 | AQ43: 886.35 | AR43: 882.28 | AU43: PM-Peak | AV43: 6327.2 | AW43: 6509.14 | AX43: 5216.66 | AY43: 6218.57 | AZ43: 4524.49 | BA43: 6011.27 | BB43: 4808.61 | BC43: 5097.41 | BD43: 4813.77 | BE43: 7712.97 | BF43: 5007.29 | BG43: 7100.31 | BH43: 4974.53 | BI43: 6405.69 | BJ43: 5225.18 | BK43: 5611.16 | BL43: 4667.02 | BM43: 4749.47 | BN43: 4337.51 | BO43: 4255.38 | BR43: PM-Peak | BS43: 7666.05 | BT43: 8172.15 | BU43: 6531 | BV43: 7789.02 | BW43: 5633.25 | BX43: 7403.55 | BY43: 5943 | BZ43: 6694.91 | CA43: 5856.9 | CB43: 9304.81 | CC43: 6075.29 | CD43: 8582.77 | CE43: 6034.45 | CF43: 7753.56 | CG43: 6316.68 | CH43: 6788.52 | CI43: 5630.46 | CJ43: 5748.16 | CK43: 5223.86 | CL43: 5137.66
B44: PM-Late | C44: 638.49 | D44: 966.03 | E44: 63.28 | F44: 67.43 | G44: 34.07 | H44: 244.61 | I44: 124.44 | J44: 3167.34 | K44: 1518.57 | L44: 3812.72 | M44: 3624.79 | N44: 6439.32 | O44: 3076.24 | P44: 3750.99 | Q44: 3537.47 | R44: 3520.3 | S44: 2856.42 | T44: 2429.36 | U44: 3314.77 | V44: 2750.68 | X44: PM-Late | Y44: 627.99 | Z44: 795.27 | AA44: 150.67 | AB44: 160.55 | AC44: 113.57 | AD44: 483.35 | AE44: 129.63 | AF44: 789.2 | AG44: 519.05 | AH44: 767.45 | AI44: 507.7 | AJ44: 768.53 | AK44: 498.21 | AL44: 676.28 | AM44: 476.81 | AN44: 527.44 | AO44: 463 | AP44: 459.43 | AQ44: 463.66 | AR44: 476.94 | AU44: PM-Late | AV44: 3149.01 | AW44: 3829.73 | AX44: 2888.38 | AY44: 3078.95 | AZ44: 2223.43 | BA44: 3120 | BB44: 2554.12 | BC44: 3457.8 | BD44: 2665.95 | BE44: 3613.55 | BF44: 2597.3 | BG44: 3622.47 | BH44: 2576.79 | BI44: 3262.72 | BJ44: 2464.19 | BK44: 2648.56 | BL44: 2322 | BM44: 2377.57 | BN44: 2420.34 | BO44: 2561.06 | BR44: PM-Late | BS44: 3777 | BT44: 4625 | BU44: 3039.05 | BV44: 3239.5 | BW44: 2337 | BX44: 3603.35 | BY44: 2683.75 | BZ44: 4247 | CA44: 3185 | CB44: 4381 | CC44: 3105 | CD44: 4391 | CE44: 3075 | CF44: 3939 | CG44: 2941 | CH44: 3176 | CI44: 2785 | CJ44: 2837 | CK44: 2884 | CL44: 3038
B47: Revenue Per Period Lights | X47: ML V/C | AU47: GP V/C real | BR47: Highway Vol / GP Capacity
...

Sheet Year_2032
B1: Lenght
C2: 1 | D2: 2 | E2: 3 | F2: 4 | G2: 5 | H2: 6 | I2: 7 | J2: 8 | K2: 9 | L2: 10
B3: Length | C3: 0.7 | D3: 0.7 | E3: 0.5 | F3: 1.6 | G3: 2 | H3: 3.6 | I3: 2.9 | J3: 3.8 | K3: 3.4 | L3: 4.5
B5: TollLights | X5: ML PCE.Miles | AU5: GP PCE.Miles | BR5: Highway PCE.Miles
B6: Direction | C6: NB | D6: SB | E6: NB | F6: SB | G6: NB | H6: SB | I6: NB | J6: SB | K6: NB | L6: SB | M6: NB | N6: SB | O6: NB | P6: SB | Q6: NB | R6: SB | S6: NB | T6: SB | U6: NB | V6: SB | X6: Direction | Y6: NB | Z6: SB | AA6: NB | AB6: SB | AC6: NB | AD6: SB | AE6: NB | AF6: SB | AG6: NB | AH6: SB | AI6: NB | AJ6: SB | AK6: NB | AL6: SB | AM6: NB | AN6: SB | AO6: NB | AP6: SB | AQ6: NB | AR6: SB | AU6: Direction | AV6: NB | AW6: SB | AX6: NB | AY6: SB | AZ6: NB | BA6: SB | BB6: NB | BC6: SB | BD6: NB | BE6: SB | BF6: NB | BG6: SB | BH6: NB | BI6: SB | BJ6: NB | BK6: SB | BL6: NB | BM6: SB | BN6: NB | BO6: SB | BR6: Direction | BS6: NB | BT6: SB | BU6: NB | BV6: SB | BW6: NB | BX6: SB | BY6: NB | BZ6: SB | CA6: NB | CB6: SB | CC6: NB | CD6: SB | CE6: NB | CF6: SB | CG6: NB | CH6: SB | CI6: NB | CJ6: SB | CK6: NB | CL6: SB
B7: Segment | C7: 1 | D7: 1 | E7: 2 | F7: 2 | G7: 3 | H7: 3 | I7: 4 | J7: 4 | K7: 5 | L7: 5 | M7: 6 | N7: 6 | O7: 7 | P7: 7 | Q7: 8 | R7: 8 | S7: 9 | T7: 9 | U7: 10 | V7: 10 | X7: Segment | Y7: 1 | Z7: 1 | AA7: 2 | AB7: 2 | AC7: 3 | AD7: 3 | AE7: 4 | AF7: 4 | AG7: 5 | AH7: 5 | AI7: 6 | AJ7: 6 | AK7: 7 | AL7: 7 | AM7: 8 | AN7: 8 | AO7: 9 | AP7: 9 | AQ7: 10 | AR7: 10 | AU7: Segment | AV7: 1 | AW7: 1 | AX7: 2 | AY7: 2 | AZ7: 3 | BA7: 3 | BB7: 4 | BC7: 4 | BD7: 5 | BE7: 5 | BF7: 6 | BG7: 6 | BH7: 7 | BI7: 7 | BJ7: 8 | BK7: 8 | BL7: 9 | BM7: 9 | BN7: 10 | BO7: 10 | BR7: Segment | BS7: 1 | BT7: 1 | BU7: 2 | BV7: 2 | BW7: 3 | BX7: 3 | BY7: 4 | BZ7: 4 | CA7: 5 | CB7: 5 | CC7: 6 | CD7: 6 | CE7: 7 | CF7: 7 | CG7: 8 | CH7: 8 | CI7: 9 | CJ7: 9 | CK7: 10 | CL7: 10
B8: Period | X8: Period | AU8: Period | BR8: Period
B9: Night | C9: 0.21 | D9: 0.21 | E9: 0.2 | F9: 0.2 | G9: 0.2 | H9: 0.2 | I9: 0.2 | J9: 1.8 | K9: 1.52 | L9: 1.8 | M9: 1.8 | N9: 1.74 | O9: 1.8 | P9: 1.67 | Q9: 1.8 | R9: 1.7 | S9: 1.59 | T9: 1.15 | U9: 1.67 | V9: 1.24 | X9: Night | Y9: 660.43 | Z9: 657.57 | AA9: 631.87 | AB9: 588.97 | AC9: 400.83 | AD9: 490.32 | AE9: 1397.36 | AF9: 3574.3 | AG9: 4740.54 | AH9: 4076.07 | AI9: 9844.87 | AJ9: 7213.75 | AK9: 7943.51 | AL9: 5571.74 | AM9: 8725.34 | AN9: 7602.55 | AO9: 6701.25 | AP9: 4643.86 | AQ9: 8645.8 | AR9: 6270.54 | AU9: Night | AV9: 13069.03 | AW9: 12979.72 | AX9: 10144.21 | AY9: 9490.33 | AZ9: 6838.22 | BA9: 8145.04 | BB9: 28088.21 | BC9: 25755.14 | BD9: 36269.66 | BE9: 32105.53 | BF9: 64190.21 | BG9: 56771.57 | BH9: 51030.02 | BI9: 44548.96 | BJ9: 65204.04 | BK9: 59708.75 | BL9: 50918.55 | BM9: 39788.36 | BN9: 69556.1 | BO9: 55702.56 | BR9: Night | BS9: 13729.46 | BT9: 13637.29 | BU9: 10776.08 | BV9: 10079.3 | BW9: 7239.05 | BX9: 8635.36 | BY9: 29485.57 | BZ9: 29329.44 | CA9: 41010.2 | CB9: 36181.6 | CC9: 74035.08 | CD9: 63985.32 | CE9: 58973.53 | CF9: 50120.7 | CG9: 73929.38 | CH9: 67311.3 | CI9: 57619.8 | CJ9: 44432.22 | CK9: 78201.9 | CL9: 61973.1
B10: AM-Early | C10: 0.9 | D10: 0.55 | E10: 0.69 | F10: 0.46 | G10: 0.82 | H10: 0.58 | I10: 0.83 | J10: 1.15 | K10: 0.93 | L10: 0.87 | M10: 1.2 | N10: 0.91 | O10: 1.25 | P10: 1.01 | Q10: 1.14 | R10: 0.79 | S10: 1.06 | T10: 0.72 | U10: 0.79 | V10: 0.47 | X10: AM-Early | Y10: 841.91 | Z10: 517.27 | AA10: 868.74 | AB10: 556.86 | AC10: 405.28 | AD10: 501.13 | AE10: 2159.65 | AF10: 1493.67 | AG10: 2516.46 | AH10: 1721.36 | AI10: 4336.08 | AJ10: 3120.56 | AK10: 3069.3 | AL10: 2700.46 | AM10: 3812.25 | AN10: 3398.02 | AO10: 3308.22 | AP10: 2496.62 | AQ10: 5062.54 | AR10: 3154.86 | AU10: AM-Early | AV10: 4760.25 | AW10: 3122.61 | AX10: 4344.19 | AY10: 2906.8 | AZ10: 2137.02 | BA10: 2624.27 | BB10: 11194.77 | BC10: 8160.57 | BD10: 14142.93 | BE10: 10119.64 | BF10: 24801.64 | BG10: 18553.96 | BH10: 17664.25 | BI10: 15918.7 | BJ10: 22152.43 | BK10: 19872.04 | BL10: 19202.33 | BM10: 15007.91 | BN10: 30484.09 | BO10: 19442.36 | BR10: AM-Early | BS10: 5602.16 | BT10: 3639.88 | BU10: 5212.93 | BV10: 3463.65 | BW10: 2542.3 | BX10: 3125.4 | BY10: 13354.42 | BZ10: 9654.24 | CA10: 16659.39 | CB10: 11841 | CC10: 29137.72 | CD10: 21674.52 | CE10: 20733.55 | CF10: 18619.16 | CG10: 25964.68 | CH10: 23270.06 | CI10: 22510.55 | CJ10: 17504.54 | CK10: 35546.62 | CL10: 22597.22
B11: AM-Peak | C11: 1.8 | D11: 0.7 | E11: 3.6 | F11: 0.52 | G11: 1.8 | H11: 1.8 | I11: 1.8 | J11: 1.8 | K11: 1.8 | L11: 1.67 | M11: 1.8 | N11: 1.7 | O11: 1.8 | P11: 1.75 | Q11: 1.8 | R11: 1.61 | S11: 1.8 | T11: 1.36 | U11: 1.31 | V11: 1.16 | X11: AM-Peak | Y11: 4508.74 | Z11: 1290.93 | AA11: 3312.52 | AB11: 1262.65 | AC11: 2701.47 | AD11: 3249.26 | AE11: 10459.41 | AF11: 5148.29 | AG11: 12561.71 | AH11: 5672.57 | AI11: 22592.72 | AJ11: 10077.64 | AK11: 17237.81 | AL11: 8188.75 | AM11: 21813.2 | AN11: 10449.19 | AO11: 10723.73 | AP11: 8107.24 | AQ11: 10667.78 | AR11: 9511.8 | AU11: AM-Peak | AV11: 14623.93 | AW11: 7994 | AX11: 15078.95 | AY11: 6608.23 | AZ11: 7806.83 | BA11: 10287.78 | BB11: 35620.59 | BC11: 28965.77 | BD11: 45038.29 | BE11: 34989.64 | BF11: 81087.28 | BG11: 63271.48 | BH11: 60253.22 | BI11: 51709.31 | BJ11: 74732.9 | BK11: 64916.35 | BL11: 63114.86 | BM11: 51784.73 | BN11: 67069.17 | BO11: 60678.78 | BR11: AM-Peak | BS11: 19132.67 | BT11: 9284.93 | BU11: 18391.46 | BV11: 7870.87 | BW11: 10508.3 | BX11: 13537.04 | BY11: 46080 | BZ11: 34114.06 | CA11: 57600 | CB11: 40662.22 | CC11: 103680 | CD11: 73349.12 | CE11: 77491.03 | CF11: 59898.06 | CG11: 96546.1 | CH11: 75365.53 | CI11: 73838.58 | CJ11: 59891.97 | CK11: 77736.94 | CL11: 70190.58
B12: AM-Shoulder | C12: 1.8 | D12: 0.85 | E12: 1.8 | F12: 0.45 | G12: 1.8 | H12: 3.6 | I12: 2.8 | J12: 1.48 | K12: 3.27 | L12: 1.26 | M12: 1.8 | N12: 1.21 | O12: 1.8 | P12: 1.23 | Q12: 1.8 | R12: 1.1 | S12: 1.08 | T12: 0.99 | U12: 0.96 | V12: 0.89 | X12: AM-Shoulder | Y12: 1417.5 | Z12: 460.28 | AA12: 1409.43 | AB12: 508.27 | AC12: 872.49 | AD12: 747.49 | AE12: 2137.07 | AF12: 1712.36 | AG12: 2573.37 | AH12: 1908.42 | AI12: 6917.28 | AJ12: 3284.25 | AK12: 5557.53 | AL12: 2651 | AM12: 4506.88 | AN12: 3337.46 | AO12: 3014.63 | AP12: 2685.17 | AQ12: 3585.48 | AR12: 3354.83 | AU12: AM-Shoulder | AV12: 5060.1 | AW12: 3013.78 | AX12: 4734.97 | AY12: 2749.37 | AZ12: 2878.16 | BA12: 4052.51 | BB12: 12386.14 | BC12: 10097.4 | BD12: 16299.6 | BE12: 12046.74 | BF12: 27642.72 | BG12: 21178.1 | BH12: 22282.47 | BI12: 17183.88 | BJ12: 26623.64 | BK12: 21365.32 | BL12: 19008.17 | BM12: 17926.56 | BN12: 23393.06 | BO12: 22243.51 | BR12: AM-Shoulder | BS12: 6477.6 | BT12: 3474.07 | BU12: 6144.4 | BV12: 3257.64 | BW12: 3750.64 | BX12: 4800 | BY12: 14523.21 | BZ12: 11809.76 | CA12: 18872.96 | CB12: 13955.16 | CC12: 34560 | CD12: 24462.35 | CE12: 27840 | CF12: 19834.88 | CG12: 31130.53 | CH12: 24702.79 | CI12: 22022.8 | CJ12: 20611.72 | CK12: 26978.54 | CL12: 25598.34
B13: MD | C13: 1.8 | D13: 1.8 | E13: 1.8 | F13: 0.78 | G13: 1.8 | H13: 1.8 | I13: 0.81 | J13: 1.8 | K13: 1.71 | L13: 1.8 | M13: 1.47 | N13: 1.27 | O13: 1.28 | P13: 1.15 | Q13: 1.15 | R13: 1.05 | S13: 1.04 | T13: 0.85 | U13: 0.91 | V13: 0.64 | X13: MD | Y13: 5382.37 | Z13: 4251.08 | AA13: 5278.03 | AB13: 4524.54 | AC13: 2933.47 | AD13: 4162.03 | AE13: 8860.89 | AF13: 10152.92 | AG13: 11492.36 | AH13: 12536.03 | AI13: 19299.58 | AJ13: 19452.39 | AK13: 14724.26 | AL13: 15407.93 | AM13: 18116 | AN13: 17584.06 | AO13: 14986.72 | AP13: 14638.49 | AQ13: 18917.21 | AR13: 21109.71 | AU13: MD | AV13: 17473.49 | AW13: 21860.67 | AX13: 21534.42 | AY13: 23135.47 | AZ13: 11319.03 | BA13: 13284.18 | BB13: 48315.43 | BC13: 48683.88 | BD13: 68453.09 | BE13: 68908.97 | BF13: 116307.44 | BG13: 117231.33 | BH13: 88826.17 | BI13: 92555.01 | BJ13: 110606.45 | BK13: 106443.47 | BL13: 92171.08 | BM13: 89264.15 | BN13: 118846.81 | BO13: 132245.23 | BR13: MD | BS13: 22855.86 | BT13: 26111.75 | BU13: 26812.45 | BV13: 27660.01 | BW13: 14252.5 | BX13: 17446.21 | BY13: 57176.32 | BZ13: 58836.8 | CA13: 79945.45 | CB13: 81445 | CC13: 135607.02 | CD13: 136683.72 | CE13: 103550.43 | CF13: 107962.94 | CG13: 128722.45 | CH13: 124027.53 | CI13: 107157.8 | CJ13: 103902.64 | CK13: 137764.01 | CL13: 153354.94
B14: PM-Shoulder | C14: 1.8 | D14: 1.8 | E14: 2.06 | F14: 1.8 | G14: 1.8 | H14: 1.8 | I14: 0.84 | J14: 1.8 | K14: 0.84 | L14: 1.8 | M14: 1.02 | N14: 2.49 | O14: 1 | P14: 1.68 | Q14: 1 | R14: 1.72 | S14: 0.92 | T14: 1.38 | U14: 0.81 | V14: 0.67 | X14: PM-Shoulder | Y14: 1253.6 | Z14: 1276.84 | AA14: 1250.05 | AB14: 1561.03 | AC14: 790.02 | AD14: 878.27 | AE14: 2058.09 | AF14: 2350.59 | AG14: 2404.2 | AH14: 3942.4 | AI14: 4538.66 | AJ14: 5567.46 | AK14: 3650.05 | AL14: 4330.36 | AM14: 4680.14 | AN14: 5515.01 | AO14: 3988.73 | AP14: 4814.22 | AQ14: 4810.25 | AR14: 4732.98 | AU14: PM-Shoulder | AV14: 3973.18 | AW14: 4049.78 | AX14: 5077.62 | AY14: 5158.97 | AZ14: 2332.54 | BA14: 2665.5 | BB14: 8626.79 | BC14: 7283.87 | BD14: 10989.29 | BE14: 14779.76 | BF14: 21376.23 | BG14: 27900.76 | BH14: 17083.48 | BI14: 20422.95 | BJ14: 22254.58 | BK14: 26787.15 | BL14: 19167.16 | BM14: 22551.25 | BN14: 23603.86 | BO14: 21835.01 | BR14: PM-Shoulder | BS14: 5226.78 | BT14: 5326.62 | BU14: 6327.67 | BV14: 6720 | BW14: 3122.56 | BX14: 3543.77 | BY14: 10684.88 | BZ14: 9634.46 | CA14: 13393.49 | CB14: 18722.16 | CC14: 25914.89 | CD14: 33468.22 | CE14: 20733.54 | CF14: 24753.31 | CG14: 26934.72 | CH14: 32302.16 | CI14: 23155.89 | CJ14: 27365.47 | CK14: 28414.1 | CL14: 26567.99
B15: PM-Peak | C15: 3.6 | D15: 1.8 | E15: 2.24 | F15: 3.17 | G15: 1.8 | H15: 3.6 | I15: 1.69 | J15: 1.8 | K15: 1.46 | L15: 3.39 | M15: 1.65 | N15: 1.8 | O15: 1.65 | P15: 1.8 | Q15: 1.8 | R15: 7.2 | S15: 1.43 | T15: 1.46 | U15: 1.29 | V15: 1.24 | X15: PM-Peak | Y15: 3169.49 | Z15: 4530.26 | AA15: 3496.46 | AB15: 3937.89 | AC15: 2694.77 | AD15: 2282.76 | AE15: 6768.37 | AF15: 8416.62 | AG15: 7637.56 | AH15: 9587.38 | AI15: 13880.52 | AJ15: 23310.84 | AK15: 11265.07 | AL15: 18769.78 | AM15: 15457.06 | AN15: 4513.25 | AO15: 11941.98 | AP15: 12336.69 | AQ15: 14693.37 | AR15: 14620.78 | AU15: PM-Peak | AV15: 14227.74 | AW15: 13918.86 | AX15: 14203.52 | AY15: 16222.11 | AZ15: 7200.81 | BA15: 9977.74 | BB15: 29392.11 | BC15: 23718.96 | BD15: 35925.85 | BE15: 48012.62 | BF15: 67586.49 | BG15: 80369.16 | BH15: 54531.93 | BI15: 64750.22 | BJ15: 74574.02 | BK15: 92240.43 | BL15: 59209.04 | BM15: 60297.02 | BN15: 73680.51 | BO15: 72299.78 | BR15: PM-Peak | BS15: 17397.24 | BT15: 18449.12 | BU15: 17699.98 | BV15: 20160 | BW15: 9895.58 | BX15: 12260.5 | BY15: 36160.49 | BZ15: 32135.58 | CA15: 43563.41 | CB15: 57600 | CC15: 81467.01 | CD15: 103680 | CE15: 65797 | CF15: 83520 | CG15: 90031.08 | CH15: 96753.68 | CI15: 71151.02 | CJ15: 72633.71 | CK15: 88373.88 | CL15: 86920.56
B16: PM-Late | C16: 0.87 | D16: 1.15 | E16: 0.27 | F16: 0.28 | G16: 0.2 | H16: 0.33 | I16: 0.66 | J16: 1.8 | K16: 0.91 | L16: 1.8 | M16: 1.34 | N16: 1.8 | O16: 1.5 | P16: 1.37 | Q16: 1.32 | R16: 1.16 | S16: 1.2 | T16: 0.96 | U16: 1.01 | V16: 0.78 | X16: PM-Late | Y16: 1638.7 | Z16: 2072.8 | AA16: 1629.22 | AB16: 1734.52 | AC16: 216.97 | AD16: 1287.86 | AE16: 1354.27 | AF16: 5246.8 | AG16: 3856.49 | AH16: 6086.55 | AI16: 6791.62 | AJ16: 10326.16 | AK16: 5419.5 | AL16: 7325.6 | AM16: 6781.74 | AN16: 7496.95 | AO16: 5706.37 | AP16: 5799.15 | AQ16: 7836.05 | AR16: 8060.17 | AU16: PM-Late | AV16: 8223.74 | AW16: 10003.88 | AX16: 6607.54 | AY16: 7045.67 | AZ16: 4247.56 | BA16: 5596.74 | BB16: 14976 | BC16: 20595.92 | BD16: 19830.31 | BE16: 26499.45 | BF16: 34842.38 | BG16: 48553.28 | BH16: 28108.56 | BI16: 35621.08 | BJ16: 35133.78 | BK16: 37765.61 | BL16: 29484.65 | BM16: 30050.79 | BN16: 40958.35 | BO16: 43339.73 | BR16: PM-Late | BS16: 9862.44 | BT16: 12076.68 | BU16: 8236.76 | BV16: 8780.19 | BW16: 4464.53 | BX16: 6884.6 | BY16: 16330.27 | BZ16: 25842.72 | CA16: 23686.8 | CB16: 32586 | CC16: 41634 | CD16: 58879.44 | CE16: 33528.06 | CF16: 42946.68 | CG16: 41915.52 | CH16: 45262.56 | CI16: 35191.02 | CJ16: 35849.94 | CK16: 48794.4 | CL16: 51399.9
B19: CaptureRateLights | X19: ML Volume (PCE/Period) | AU19: GP Volume (PCE/Period) | BR19: Highway Volume
B20: Direction | C20: NB | D20: SB | E20: NB | F20: SB | G20: NB | H20: SB | I20: NB | J20: SB | K20: NB | L20: SB | M20: NB | N20: SB | O20: NB | P20: SB | Q20: NB | R20: SB | S20: NB | T20: SB | U20: NB | V20: SB | X20: Direction | Y20: NB | Z20: SB | AA20: NB | AB20: SB | AC20: NB | AD20: SB | AE20: NB | AF20: SB | AG20: NB | AH20: SB | AI20: NB | AJ20: SB | AK20: NB | AL20: SB | AM20: NB | AN20: SB | AO20: NB | AP20: SB | AQ20: NB | AR20: SB | AU20: Direction | AV20: NB | AW20: SB | AX20: NB | AY20: SB | AZ20: NB | BA20: SB | BB20: NB | BC20: SB | BD20: NB | BE20: SB | BF20: NB | BG20: SB | BH20: NB | BI20: SB | BJ20: NB | BK20: SB | BL20: NB | BM20: SB | BN20: NB | BO20: SB | BR20: Direction | BS20: NB | BT20: SB | BU20: NB | BV20: SB | BW20: NB | BX20: SB | BY20: NB | BZ20: SB | CA20: NB | CB20: SB | CC20: NB | CD20: SB | CE20: NB | CF20: SB | CG20: NB | CH20: SB | CI20: NB | CJ20: SB | CK20: NB | CL20: SB
B21: Segment | C21: 1 | D21: 1 | E21: 2 | F21: 2 | G21: 3 | H21: 3 | I21: 4 | J21: 4 | K21: 5 | L21: 5 | M21: 6 | N21: 6 | O21: 7 | P21: 7 | Q21: 8 | R21: 8 | S21: 9 | T21: 9 | U21: 10 | V21: 10 | X21: Segment | Y21: 1 | Z21: 1 | AA21: 2 | AB21: 2 | AC21: 3 | AD21: 3 | AE21: 4 | AF21: 4 | AG21: 5 | AH21: 5 | AI21: 6 | AJ21: 6 | AK21: 7 | AL21: 7 | AM21: 8 | AN21: 8 | AO21: 9 | AP21: 9 | AQ21: 10 | AR21: 10 | AU21: Segment | AV21: 1 | AW21: 1 | AX21: 2 | AY21: 2 | AZ21: 3 | BA21: 3 | BB21: 4 | BC21: 4 | BD21: 5 | BE21: 5 | BF21: 6 | BG21: 6 | BH21: 7 | BI21: 7 | BJ21: 8 | BK21: 8 | BL21: 9 | BM21: 9 | BN21: 10 | BO21: 10 | BR21: Segment | BS21: 1 | BT21: 1 | BU21: 2 | BV21: 2 | BW21: 3 | BX21: 3 | BY21: 4 | BZ21: 4 | CA21: 5 | CB21: 5 | CC21: 6 | CD21: 6 | CE21: 7 | CF21: 7 | CG21: 8 | CH21: 8 | CI21: 9 | CJ21: 9 | CK21: 10 | CL21: 10
B22: Period | X22: Period | AU22: Period | BR22: Period
B23: Night | C23: 0.05 | D23: 0.05 | E23: 0.06 | F23: 0.06 | G23: 0.06 | H23: 0.06 | I23: 0.05 | J23: 0.15 | K23: 0.15 | L23: 0.15 | M23: 0.15 | N23: 0.15 | O23: 0.15 | P23: 0.15 | Q23: 0.15 | R23: 0.15 | S23: 0.15 | T23: 0.15 | U23: 0.15 | V23: 0.15 | X23: Night | Y23: 943.47 | Z23: 939.38 | AA23: 902.68 | AB23: 841.38 | AC23: 801.66 | AD23: 980.64 | AE23: 873.35 | AF23: 2233.94 | AG23: 2370.27 | AH23: 2038.03 | AI23: 2734.69 | AJ23: 2003.82 | AK23: 2739.14 | AL23: 1921.29 | AM23: 2296.14 | AN23: 2000.67 | AO23: 1970.95 | AP23: 1365.84 | AQ23: 1921.29 | AR23: 1393.45 | AU23: Night | AV23: 18670.04 | AW23: 18542.46 | AX23: 14491.72 | AY23: 13557.62 | AZ23: 13676.44 | BA23: 16290.08 | BB23: 17555.13 | BC23: 16096.96 | BD23: 18134.83 | BE23: 16052.77 | BF23: 17830.61 | BG23: 15769.88 | BH23: 17596.56 | BI23: 15361.71 | BJ23: 17158.96 | BK23: 15712.83 | BL23: 14976.05 | BM23: 11702.46 | BN23: 15456.91 | BO23: 12378.35 | BR23: Night | BS23: 19613.51 | BT23: 19481.84 | BU23: 15394.4 | BV23: 14399 | BW23: 14478.1 | BX23: 17270.72 | BY23: 18428.48 | BZ23: 18330.9 | CA23: 20505.1 | CB23: 18090.8 | CC23: 20565.3 | CD23: 17773.7 | CE23: 20335.7 | CF23: 17283 | CG23: 19455.1 | CH23: 17713.5 | CI23: 16947 | CJ23: 13068.3 | CK23: 17378.2 | CL23: 13771.8
B24: AM-Early | C24: 0.16 | D24: 0.17 | E24: 0.17 | F24: 0.18 | G24: 0.18 | H24: 0.18 | I24: 0.17 | J24: 0.17 | K24: 0.16 | L24: 0.16 | M24: 0.16 | N24: 0.16 | O24: 0.16 | P24: 0.16 | Q24: 0.16 | R24: 0.16 | S24: 0.16 | T24: 0.16 | U24: 0.16 | V24: 0.16 | X24: AM-Early | Y24: 1202.72 | Z24: 738.96 | AA24: 1241.06 | AB24: 795.51 | AC24: 810.55 | AD24: 1002.26 | AE24: 1349.78 | AF24: 933.54 | AG24: 1258.23 | AH24: 860.68 | AI24: 1204.47 | AJ24: 866.82 | AK24: 1058.38 | AL24: 931.19 | AM24: 1003.22 | AN24: 894.22 | AO24: 973.01 | AP24: 734.3 | AQ24: 1125.01 | AR24: 701.08 | AU24: AM-Early | AV24: 6800.36 | AW24: 4460.87 | AX24: 6205.99 | AY24: 4152.57 | AZ24: 4274.05 | BA24: 5248.55 | BB24: 6996.73 | BC24: 5100.36 | BD24: 7071.46 | BE24: 5059.82 | BF24: 6889.34 | BG24: 5153.88 | BH24: 6091.12 | BI24: 5489.21 | BJ24: 5829.59 | BK24: 5229.48 | BL24: 5647.74 | BM24: 4414.09 | BN24: 6774.24 | BO24: 4320.53 | BR24: AM-Early | BS24: 8003.08 | BT24: 5199.82 | BU24: 7447.05 | BV24: 4948.08 | BW24: 5084.6 | BX24: 6250.81 | BY24: 8346.51 | BZ24: 6033.9 | CA24: 8329.7 | CB24: 5920.5 | CC24: 8093.81 | CD24: 6020.7 | CE24: 7149.5 | CF24: 6420.4 | CG24: 6832.81 | CH24: 6123.7 | CI24: 6620.75 | CJ24: 5148.39 | CK24: 7899.25 | CL24: 5021.6
B25: AM-Peak | C25: 0.27 | D25: 0.17 | E25: 0.19 | F25: 0.18 | G25: 0.29 | H25: 0.27 | I25: 0.25 | J25: 0.17 | K25: 0.24 | L25: 0.16 | M25: 0.24 | N25: 0.16 | O25: 0.25 | P25: 0.16 | Q25: 0.26 | R25: 0.16 | S25: 0.17 | T25: 0.16 | U25: 0.16 | V25: 0.16 | X25: AM-Peak | Y25: 6441.06 | Z25: 1844.18 | AA25: 4732.17 | AB25: 1803.78 | AC25: 5402.94 | AD25: 6498.52 | AE25: 6537.13 | AF25: 3217.68 | AG25: 6280.86 | AH25: 2836.29 | AI25: 6275.75 | AJ25: 2799.34 | AK25: 5944.07 | AL25: 2823.71 | AM25: 5740.32 | AN25: 2749.79 | AO25: 3154.04 | AP25: 2384.48 | AQ25: 2370.62 | AR25: 2113.73 | AU25: AM-Peak | AV25: 20891.33 | AW25: 11420 | AX25: 21541.35 | AY25: 9440.32 | AZ25: 15613.66 | BA25: 20575.56 | BB25: 22262.87 | BC25: 18103.61 | BD25: 22519.14 | BE25: 17494.82 | BF25: 22524.25 | BG25: 17575.41 | BH25: 20776.97 | BI25: 17830.8 | BJ25: 19666.55 | BK25: 17083.25 | BL25: 18563.19 | BM25: 15230.8 | BN25: 14904.26 | BO25: 13484.17 | BR25: AM-Peak | BS25: 27332.39 | BT25: 13264.18 | BU25: 26273.52 | BV25: 11244.1 | BW25: 21016.6 | BX25: 27074.08 | BY25: 28800 | BZ25: 21321.29 | CA25: 28800 | CB25: 20331.11 | CC25: 28800 | CD25: 20374.76 | CE25: 26721.04 | CF25: 20654.5 | CG25: 25406.87 | CH25: 19833.04 | CI25: 21717.23 | CJ25: 17615.29 | CK25: 17274.88 | CL25: 15597.91
B26: AM-Shoulder | C26: 0.26 | D26: 0.17 | E26: 0.25 | F26: 0.18 | G26: 0.28 | H26: 0.18 | I26: 0.17 | J26: 0.17 | K26: 0.16 | L26: 0.16 | M26: 0.23 | N26: 0.16 | O26: 0.23 | P26: 0.16 | Q26: 0.17 | R26: 0.16 | S26: 0.16 | T26: 0.16 | U26: 0.16 | V26: 0.16 | X26: AM-Shoulder | Y26: 2025 | Z26: 657.55 | AA26: 2013.47 | AB26: 726.09 | AC26: 1744.97 | AD26: 1494.98 | AE26: 1335.67 | AF26: 1070.23 | AG26: 1286.68 | AH26: 954.21 | AI26: 1921.47 | AJ26: 912.29 | AK26: 1916.39 | AL26: 914.14 | AM26: 1186.02 | AN26: 878.28 | AO26: 886.66 | AP26: 789.75 | AQ26: 796.77 | AR26: 745.52 | AU26: AM-Shoulder | AV26: 7228.71 | AW26: 4305.4 | AX26: 6764.24 | AY26: 3927.67 | AZ26: 5756.31 | BA26: 8105.02 | BB26: 7741.33 | BC26: 6310.88 | BD26: 8149.8 | BE26: 6023.37 | BF26: 7678.53 | BG26: 5882.81 | BH26: 7683.61 | BI26: 5925.48 | BJ26: 7006.22 | BK26: 5622.45 | BL26: 5590.64 | BM26: 5272.52 | BN26: 5198.46 | BO26: 4943 | BR26: AM-Shoulder | BS26: 9253.72 | BT26: 4962.95 | BU26: 8777.71 | BV26: 4653.76 | BW26: 7501.28 | BX26: 9600 | BY26: 9077.01 | BZ26: 7381.1 | CA26: 9436.48 | CB26: 6977.58 | CC26: 9600 | CD26: 6795.1 | CE26: 9600 | CF26: 6839.62 | CG26: 8192.24 | CH26: 6500.73 | CI26: 6477.29 | CJ26: 6062.27 | CK26: 5995.23 | CL26: 5688.52
B27: MD | C27: 0.27 | D27: 0.19 | E27: 0.21 | F27: 0.18 | G27: 0.24 | H27: 0.27 | I27: 0.18 | J27: 0.2 | K27: 0.16 | L27: 0.18 | M27: 0.16 | N27: 0.16 | O27: 0.16 | P27: 0.16 | Q27: 0.16 | R27: 0.16 | S27: 0.17 | T27: 0.17 | U27: 0.17 | V27: 0.16 | X27: MD | Y27: 7689.1 | Z27: 6072.97 | AA27: 7540.05 | AB27: 6463.62 | AC27: 5866.94 | AD27: 8324.06 | AE27: 5538.05 | AF27: 6345.58 | AG27: 5746.18 | AH27: 6268.02 | AI27: 5360.99 | AJ27: 5403.44 | AK27: 5077.33 | AL27: 5313.08 | AM27: 4767.37 | AN27: 4627.38 | AO27: 4407.86 | AP27: 4305.44 | AQ27: 4203.82 | AR27: 4691.05 | AU27: MD | AV27: 24962.13 | AW27: 31229.53 | AX27: 30763.45 | AY27: 33050.68 | AZ27: 22638.06 | BA27: 26568.37 | BB27: 30197.15 | BC27: 30427.42 | BD27: 34226.55 | BE27: 34454.48 | BF27: 32307.62 | BG27: 32564.26 | BH27: 30629.72 | BI27: 31915.52 | BJ27: 29106.96 | BK27: 28011.44 | BL27: 27109.14 | BM27: 26254.16 | BN27: 26410.4 | BO27: 29387.83 | BR27: MD | BS27: 32651.23 | BT27: 37302.5 | BU27: 38303.5 | BV27: 39514.3 | BW27: 28505 | BX27: 34892.43 | BY27: 35735.2 | BZ27: 36773 | CA27: 39972.73 | CB27: 40722.5 | CC27: 37668.62 | CD27: 37967.7 | CE27: 35707.05 | CF27: 37228.6 | CG27: 33874.33 | CH27: 32638.82 | CI27: 31517 | CJ27: 30559.6 | CK27: 30614.22 | CL27: 34078.87
B28: PM-Shoulder | C28: 0.28 | D28: 0.28 | E28: 0.21 | F28: 0.24 | G28: 0.29 | H28: 0.28 | I28: 0.21 | J28: 0.28 | K28: 0.2 | L28: 0.24 | M28: 0.2 | N28: 0.18 | O28: 0.2 | P28: 0.19 | Q28: 0.2 | R28: 0.19 | S28: 0.2 | T28: 0.19 | U28: 0.2 | V28: 0.2 | X28: PM-Shoulder | Y28: 1790.85 | Z28: 1824.06 | AA28: 1785.79 | AB28: 2230.05 | AC28: 1580.04 | AD28: 1756.54 | AE28: 1286.31 | AF28: 1469.12 | AG28: 1202.1 | AH28: 1971.2 | AI28: 1260.74 | AJ28: 1546.52 | AK28: 1258.64 | AL28: 1493.23 | AM28: 1231.62 | AN28: 1451.32 | AO28: 1173.16 | AP28: 1415.95 | AQ28: 1068.94 | AR28: 1051.77 | AU28: PM-Shoulder | AV28: 5675.97 | AW28: 5785.4 | AX28: 7253.74 | AY28: 7369.95 | AZ28: 4665.07 | BA28: 5331 | BB28: 5391.74 | BC28: 4552.42 | BD28: 5494.65 | BE28: 7389.88 | BF28: 5937.84 | BG28: 7750.21 | BH28: 5890.86 | BI28: 7042.4 | BJ28: 5856.47 | BK28: 7049.25 | BL28: 5637.4 | BM28: 6632.72 | BN28: 5245.3 | BO28: 4852.22 | BR28: PM-Shoulder | BS28: 7466.82 | BT28: 7609.46 | BU28: 9039.53 | BV28: 9600 | BW28: 6245.12 | BX28: 7087.55 | BY28: 6678.05 | BZ28: 6021.54 | CA28: 6696.74 | CB28: 9361.08 | CC28: 7198.58 | CD28: 9296.73 | CE28: 7149.5 | CF28: 8535.62 | CG28: 7088.08 | CH28: 8500.57 | CI28: 6810.56 | CJ28: 8048.67 | CK28: 6314.25 | CL28: 5904
B29: PM-Peak | C29: 0.21 | D29: 0.28 | E29: 0.21 | F29: 0.21 | G29: 0.31 | H29: 0.21 | I29: 0.21 | J29: 0.3 | K29: 0.2 | L29: 0.19 | M29: 0.19 | N29: 0.25 | O29: 0.2 | P29: 0.25 | Q29: 0.2 | R29: 0.05 | S29: 0.2 | T29: 0.2 | U29: 0.2 | V29: 0.2 | X29: PM-Peak | Y29: 4527.85 | Z29: 6471.79 | AA29: 4994.94 | AB29: 5625.55 | AC29: 5389.53 | AD29: 4565.52 | AE29: 4230.23 | AF29: 5260.39 | AG29: 3818.78 | AH29: 4793.69 | AI29: 3855.7 | AJ29: 6475.23 | AK29: 3884.51 | AL29: 6472.34 | AM29: 4067.65 | AN29: 1187.7 | AO29: 3512.35 | AP29: 3628.44 | AQ29: 3265.19 | AR29: 3249.06 | AU29: PM-Peak | AV29: 20325.35 | AW29: 19884.09 | AX29: 20290.74 | AY29: 23174.45 | AZ29: 14401.62 | BA29: 19955.47 | BB29: 18370.07 | BC29: 14824.35 | BD29: 17962.92 | BE29: 24006.31 | BF29: 18774.02 | BG29: 22324.77 | BH29: 18804.11 | BI29: 22327.66 | BJ29: 19624.74 | BK29: 24273.8 | BL29: 17414.42 | BM29: 17734.42 | BN29: 16373.45 | BO29: 16066.62 | BR29: PM-Peak | BS29: 24853.19 | BT29: 26355.88 | BU29: 25285.68 | BV29: 28800 | BW29: 19791.15 | BX29: 24521 | BY29: 22600.31 | BZ29: 20084.74 | CA29: 21781.7 | CB29: 28800 | CC29: 22629.73 | CD29: 28800 | CE29: 22688.62 | CF29: 28800 | CG29: 23692.39 | CH29: 25461.49 | CI29: 20926.77 | CJ29: 21362.86 | CK29: 19638.64 | CL29: 19315.68
