Workbook

Sheet Year_2025
B1: Lenght
C2: 1 | D2: 2 | E2: 3 | F2: 4 | G2: 5 | H2: 6 | I2: 7 | J2: 8 | K2: 9 | L2: 10
B3: Length | C3: 1.3 | D3: 1.3 | E3: 0.5 | F3: 1.6 | G3: 2 | H3: 3.6 | I3: 2.9 | J3: 3.8 | K3: 3.4 | L3: 4.5
B5: TollLights | X5: ML PCE.Miles | AU5: GP PCE.Miles | BR5: Highway PCE.Miles
B6: Direction | C6: NB | D6: SB | E6: NB | F6: SB | G6: NB | H6: SB | I6: NB | J6: SB | K6: NB | L6: SB | M6: NB | N6: SB | O6: NB | P6: SB | Q6: NB | R6: SB | S6: NB | T6: SB | U6: NB | V6: SB | X6: Direction | Y6: NB | Z6: SB | AA6: NB | AB6: SB | AC6: NB | AD6: SB | AE6: NB | AF6: SB | AG6: NB | AH6: SB | AI6: NB | AJ6: SB | AK6: NB | AL6: SB | AM6: NB | AN6: SB | AO6: NB | AP6: SB | AQ6: NB | AR6: SB | AU6: Direction | AV6: NB | AW6: SB | AX6: NB | AY6: SB | AZ6: NB | BA6: SB | BB6: NB | BC6: SB | BD6: NB | BE6: SB | BF6: NB | BG6: SB | BH6: NB | BI6: SB | BJ6: NB | BK6: SB | BL6: NB | BM6: SB | BN6: NB | BO6: SB | BR6: Direction | BS6: NB | BT6: SB | BU6: NB | BV6: SB | BW6: NB | BX6: SB | BY6: NB | BZ6: SB | CA6: NB | CB6: SB | CC6: NB | CD6: SB | CE6: NB | CF6: SB | CG6: NB | CH6: SB | CI6: NB | CJ6: SB | CK6: NB | CL6: SB
B7: Segment | C7: 1 | D7: 1 | E7: 2 | F7: 2 | G7: 3 | H7: 3 | I7: 4 | J7: 4 | K7: 5 | L7: 5 | M7: 6 | N7: 6 | O7: 7 | P7: 7 | Q7: 8 | R7: 8 | S7: 9 | T7: 9 | U7: 10 | V7: 10 | X7: Segment | Y7: 1 | Z7: 1 | AA7: 2 | AB7: 2 | AC7: 3 | AD7: 3 | AE7: 4 | AF7: 4 | AG7: 5 | AH7: 5 | AI7: 6 | AJ7: 6 | AK7: 7 | AL7: 7 | AM7: 8 | AN7: 8 | AO7: 9 | AP7: 9 | AQ7: 10 | AR7: 10 | AU7: Segment | AV7: 1 | AW7: 1 | AX7: 2 | AY7: 2 | AZ7: 3 | BA7: 3 | BB7: 4 | BC7: 4 | BD7: 5 | BE7: 5 | BF7: 6 | BG7: 6 | BH7: 7 | BI7: 7 | BJ7: 8 | BK7: 8 | BL7: 9 | BM7: 9 | BN7: 10 | BO7: 10 | BR7: Segment | BS7: 1 | BT7: 1 | BU7: 2 | BV7: 2 | BW7: 3 | BX7: 3 | BY7: 4 | BZ7: 4 | CA7: 5 | CB7: 5 | CC7: 6 | CD7: 6 | CE7: 7 | CF7: 7 | CG7: 8 | CH7: 8 | CI7: 9 | CJ7: 9 | CK7: 10 | CL7: 10
B8: Period | X8: Period | AU8: Period | BR8: Period
B9: Night | C9: 0.2 | D9: 0.2 | E9: 0.2 | F9: 0.2 | G9: 0.2 | H9: 0.2 | I9: 0.2 | J9: 0.48 | K9: 0.48 | L9: 0.48 | M9: 0.48 | N9: 0.48 | O9: 0.48 | P9: 0.48 | Q9: 0.48 | R9: 0.48 | S9: 0.48 | T9: 0.48 | U9: 0.48 | V9: 0.48 | X9: Night | Y9: 986.4 | Z9: 982.07 | AA9: 758.94 | AB9: 710.26 | AC9: 270.55 | AD9: 327.52 | AE9: 1102.31 | AF9: 2203.04 | AG9: 3148.6 | AH9: 2772 | AI9: 5727.96 | AJ9: 4911.48 | AK9: 4468.03 | AL9: 3840.76 | AM9: 5681.76 | AN9: 5176.36 | AO9: 4486.3 | AP9: 3422.44 | AQ9: 5985 | AR9: 4747.05 | AU9: Night | AV9: 19519.54 | AW9: 19385.55 | AX9: 14747.46 | AY9: 13795.14 | AZ9: 5413.45 | BA9: 6452.16 | BB9: 22156.73 | BC9: 20936.16 | BD9: 29933.4 | BE9: 26418 | BF9: 53895.24 | BG9: 46622.52 | BH9: 42587.37 | BI9: 36150.24 | BJ9: 53450.04 | BK9: 48662.04 | BL9: 42018.9 | BM9: 32444.16 | BN9: 56416.5 | BO9: 44707.95 | BR9: Night | BS9: 20505.94 | BT9: 20367.62 | BU9: 15506.4 | BV9: 14505.4 | BW9: 5684 | BX9: 6779.67 | BY9: 23259.04 | BZ9: 23139.2 | CA9: 33082 | CB9: 29190 | CC9: 59623.2 | CD9: 51534 | CE9: 47055.4 | CF9: 39991 | CG9: 59131.8 | CH9: 53838.4 | CI9: 46505.2 | CJ9: 35866.6 | CK9: 62401.5 | CL9: 49455
B10: AM-Early | C10: 0.2 | D10: 0.2 | E10: 0.2 | F10: 0.21 | G10: 0.25 | H10: 0.2 | I10: 0.2 | J10: 0.32 | K10: 0.2 | L10: 0.24 | M10: 0.24 | N10: 0.25 | O10: 0.29 | P10: 0.26 | Q10: 0.28 | R10: 0.21 | S10: 0.27 | T10: 0.21 | U10: 0.2 | V10: 0.2 | X10: AM-Early | Y10: 1789.21 | Z10: 1025.67 | AA10: 1588.66 | AB10: 928.46 | AC10: 453.69 | AD10: 496.51 | AE10: 2242.18 | AF10: 1693.84 | AG10: 2790.69 | AH10: 1997.17 | AI10: 5054.92 | AJ10: 3637.26 | AK10: 3525.68 | AL10: 3097.49 | AM10: 4379.06 | AN10: 3895.39 | AO10: 3820.69 | AP10: 2876.59 | AQ10: 5459.11 | AR10: 2962.13 | AU10: AM-Early | AV10: 6577.91 | AW10: 4410.8 | AX10: 5912.73 | AY10: 4056 | AZ10: 1542.31 | BA10: 1957.34 | BB10: 8292.94 | BC10: 5922.16 | BD10: 10648.01 | BE10: 7554.83 | BF10: 18413.12 | BG10: 13819.14 | BH10: 13018.82 | BI10: 11759.21 | BJ10: 16389.84 | BK10: 14717.77 | BL10: 14349.64 | BM10: 11252.41 | BN10: 22905.51 | BO10: 15069.82 | BR10: AM-Early | BS10: 8367.12 | BT10: 5436.47 | BU10: 7501.39 | BV10: 4984.46 | BW10: 1996 | BX10: 2453.85 | BY10: 10535.12 | BZ10: 7616 | CA10: 13438.7 | CB10: 9552 | CC10: 23468.04 | CD10: 17456.4 | CE10: 16544.5 | CF10: 14856.7 | CG10: 20768.9 | CH10: 18613.16 | CI10: 18170.33 | CJ10: 14129.01 | CK10: 28364.63 | CL10: 18031.95
B11: AM-Peak | C11: 1.25 | D11: 0.51 | E11: 1.4 | F11: 0.2 | G11: 1.1 | H11: 1.5 | I11: 0.76 | J11: 0.47 | K11: 0.95 | L11: 1.6 | M11: 1.25 | N11: 0.48 | O11: 1.6 | P11: 0.49 | Q11: 1.55 | R11: 0.46 | S11: 0.52 | T11: 0.41 | U11: 1.29 | V11: 0.36 | X11: AM-Peak | Y11: 6311.96 | Z11: 1699.81 | AA11: 7428.21 | AB11: 563.53 | AC11: 1860.18 | AD11: 2978.58 | AE11: 8049.84 | AF11: 5829.07 | AG11: 10007.23 | AH11: 2591 | AI11: 18214.83 | AJ11: 11776.89 | AK11: 15884.23 | AL11: 9414.84 | AM11: 17431.68 | AN11: 12020.2 | AO11: 11966.48 | AP11: 9436.15 | AQ11: 4907.41 | AR11: 10857.3 | AU11: AM-Peak | AV11: 24830.51 | AW11: 12168 | AX11: 25299.03 | AY11: 10762.65 | AZ11: 6706.25 | BA11: 10309.7 | BB11: 28724.45 | BC11: 21082.85 | BD11: 38988.67 | BE11: 30210.23 | BF11: 75403.84 | BG11: 47300.88 | BH11: 61606.8 | BI11: 38382.09 | BJ11: 73396.68 | BK11: 48262.62 | BL11: 47635.82 | BM11: 38908.79 | BN11: 57124.69 | BO11: 45151.38 | BR11: AM-Peak | BS11: 31142.48 | BT11: 13867.81 | BU11: 32727.24 | BV11: 11326.18 | BW11: 8566.42 | BX11: 13288.28 | BY11: 36774.29 | BZ11: 26911.93 | CA11: 48995.9 | CB11: 32801.23 | CC11: 93618.67 | CD11: 59077.77 | CE11: 77491.03 | CF11: 47796.93 | CG11: 90828.36 | CH11: 60282.81 | CI11: 59602.3 | CJ11: 48344.94 | CK11: 62032.1 | CL11: 56008.68
B12: AM-Shoulder | C12: 1.05 | D12: 0.3 | E12: 0.84 | F12: 0.34 | G12: 1.04 | H12: 0.86 | I12: 0.51 | J12: 0.37 | K12: 0.61 | L12: 0.34 | M12: 0.67 | N12: 0.33 | O12: 0.67 | P12: 0.34 | Q12: 0.44 | R12: 0.31 | S12: 0.31 | T12: 0.31 | U12: 0.29 | V12: 0.28 | X12: AM-Shoulder | Y12: 2030.03 | Z12: 969.6 | AA12: 2256.17 | AB12: 632.06 | AC12: 682.77 | AD12: 896.87 | AE12: 2448.69 | AF12: 1921.89 | AG12: 3009.14 | AH12: 2208.76 | AI12: 5461.52 | AJ12: 3800.27 | AK12: 4365.94 | AL12: 3014.09 | AM12: 4862.51 | AN12: 3808.59 | AO12: 3470.41 | AP12: 3068.47 | AQ12: 4064.1 | AR12: 3779.43 | AU12: AM-Shoulder | AV12: 8496.07 | AW12: 4219.22 | AX12: 7728.47 | AY12: 4056 | AZ12: 2599.04 | BA12: 3303.13 | BB12: 9008.03 | BC12: 7394.4 | BD12: 12215.22 | BE12: 9048.92 | BF12: 22550.4 | BG12: 15902.69 | BH12: 18145.99 | BI12: 12812.41 | BJ12: 20037.81 | BK12: 15951.51 | BL12: 14306.3 | BM12: 13568.36 | BN12: 17463.87 | BO12: 16647.03 | BR12: AM-Shoulder | BS12: 10526.1 | BT12: 5188.82 | BU12: 9984.64 | BV12: 4688.06 | BW12: 3281.81 | BX12: 4200 | BY12: 11456.72 | BZ12: 9316.29 | CA12: 15224.36 | CB12: 11257.68 | CC12: 28011.92 | CD12: 19702.96 | CE12: 22511.92 | CF12: 15826.51 | CG12: 24900.32 | CH12: 19760.1 | CI12: 17776.71 | CJ12: 16636.82 | CK12: 21527.97 | CL12: 20426.46
B13: MD | C13: 0.98 | D13: 0.54 | E13: 0.46 | F13: 0.2 | G13: 0.65 | H13: 0.89 | I13: 0.2 | J13: 0.48 | K13: 0.38 | L13: 0.43 | M13: 0.35 | N13: 0.3 | O13: 0.31 | P13: 0.27 | Q13: 0.3 | R13: 0.28 | S13: 0.29 | T13: 0.24 | U13: 0.26 | V13: 0.2 | X13: MD | Y13: 7020.23 | Z13: 7782.14 | AA13: 9053.8 | AB13: 8534.9 | AC13: 2448.09 | AD13: 3286.77 | AE13: 9798.24 | AF13: 10190.03 | AG13: 13417.34 | AH13: 13523.08 | AI13: 22520.82 | AJ13: 22576.51 | AK13: 16941.03 | AL13: 17646.03 | AM13: 20815.73 | AN13: 20156.46 | AO13: 17343.65 | AP13: 16805.37 | AQ13: 21522.51 | AR13: 21948.21 | AU13: MD | AV13: 28151.27 | AW13: 31217.86 | AX13: 29530.2 | AY13: 31269.15 | AZ13: 8741.91 | BA13: 11542.52 | BB13: 35307.76 | BC13: 36225.97 | BD13: 51075.51 | BE13: 52176.92 | BF13: 86704.29 | BG13: 87513.29 | BH13: 65688.53 | BI13: 68502.82 | BJ13: 82147.03 | BK13: 79048.91 | BL13: 69152.35 | BM13: 67061.58 | BN13: 88409.11 | BO13: 100423.66 | BR13: MD | BS13: 35171.5 | BT13: 39000 | BU13: 38584 | BV13: 39804.05 | BW13: 11190 | BX13: 14829.28 | BY13: 45106 | BZ13: 46416 | CA13: 64492.85 | CB13: 65700 | CC13: 109225.11 | CD13: 110089.8 | CE13: 82629.57 | CF13: 86148.85 | CG13: 102962.77 | CH13: 99205.37 | CI13: 86496 | CJ13: 83866.95 | CK13: 109931.62 | CL13: 122371.87
B14: PM-Shoulder | C14: 1.08 | D14: 1.04 | E14: 0.49 | F14: 0.67 | G14: 1.17 | H14: 1.08 | I14: 0.31 | J14: 1.08 | K14: 0.25 | L14: 0.71 | M14: 0.29 | N14: 0.47 | O14: 0.28 | P14: 0.37 | Q14: 0.28 | R14: 0.38 | S14: 0.28 | T14: 0.34 | U14: 0.26 | V14: 0.21 | X14: PM-Shoulder | Y14: 1774.08 | Z14: 1847.21 | AA14: 2089.31 | AB14: 2494.77 | AC14: 583.68 | AD14: 674.5 | AE14: 1886.03 | AF14: 1821.89 | AG14: 2415.25 | AH14: 3603.08 | AI14: 4640.61 | AJ14: 6061.67 | AK14: 3660.83 | AL14: 4456.63 | AM14: 4734.88 | AN14: 5774.2 | AO14: 4039.78 | AP14: 4982.91 | AQ14: 4799.1 | AR14: 4725.83 | AU14: PM-Shoulder | AV14: 6719.43 | AW14: 6808.55 | AX14: 7016.12 | AY14: 8066.27 | AZ14: 2148.56 | BA14: 2426.31 | BB14: 6543 | BC14: 6608.26 | BD14: 8389.18 | BE14: 12778.81 | BF14: 16232.2 | BG14: 20893.86 | BH14: 12883.77 | BI14: 15294.62 | BJ14: 16810.16 | BK14: 20063.42 | BL14: 14651.17 | BM14: 17105.87 | BN14: 17873.14 | BO14: 16473.87 | BR14: PM-Shoulder | BS14: 8493.51 | BT14: 8655.76 | BU14: 9105.43 | BV14: 10561.04 | BW14: 2732.24 | BX14: 3100.8 | BY14: 8429.03 | BZ14: 8430.15 | CA14: 10804.42 | CB14: 16381.89 | CC14: 20872.82 | CD14: 26955.53 | CE14: 16544.6 | CF14: 19751.25 | CG14: 21545.04 | CH14: 25837.62 | CI14: 18690.94 | CJ14: 22088.78 | CK14: 22672.24 | CL14: 21199.7
B15: PM-Peak | C15: 1.49 | D15: 1.48 | E15: 0.64 | F15: 0.81 | G15: 1.38 | H15: 1.6 | I15: 0.58 | J15: 1.6 | K15: 0.45 | L15: 1.29 | M15: 0.48 | N15: 0.99 | O15: 0.48 | P15: 0.76 | Q15: 0.53 | R15: 0.59 | S15: 0.46 | T15: 0.46 | U15: 0.43 | V15: 0.41 | X15: PM-Peak | Y15: 6372.92 | Z15: 6735.67 | AA15: 5831.06 | AB15: 6990.99 | AC15: 1828.05 | AD15: 2256.96 | AE15: 6244.88 | AF15: 7777.1 | AG15: 7701.4 | AH15: 12077.34 | AI15: 14312.98 | AJ15: 20118.07 | AK15: 11370.79 | AL15: 14619.44 | AM15: 15409.51 | AN15: 16720.07 | AO15: 12100.65 | AP15: 12512.57 | AQ15: 14707.46 | AR15: 14664.89 | AU15: PM-Peak | AV15: 23524.68 | AW15: 25135.72 | AX15: 19639.84 | AY15: 23386.2 | AZ15: 6621.82 | BA15: 8848.36 | BB15: 22281.52 | BC15: 24358.48 | BD15: 27440.01 | BE15: 43751.51 | BF15: 51300.17 | BG15: 72575.88 | BH15: 41128.95 | BI15: 52836.52 | BJ15: 56600.68 | BK15: 60669.06 | BL15: 45330.09 | BM15: 46118.65 | BN15: 55814.59 | BO15: 54693.5 | BR15: PM-Peak | BS15: 29897.6 | BT15: 31871.38 | BU15: 25470.9 | BV15: 30377.19 | BW15: 8449.88 | BX15: 11105.32 | BY15: 28526.4 | BZ15: 32135.58 | CA15: 35141.41 | CB15: 55828.85 | CC15: 65613.15 | CD15: 92693.94 | CE15: 52499.74 | CF15: 67455.96 | CG15: 72010.19 | CH15: 77389.13 | CI15: 57430.74 | CJ15: 58631.22 | CK15: 70522.05 | CL15: 69358.39
B16: PM-Late | C16: 0.37 | D16: 0.44 | E16: 0.2 | F16: 0.2 | G16: 0.2 | H16: 0.34 | I16: 0.2 | J16: 0.71 | K16: 0.38 | L16: 0.64 | M16: 0.53 | N16: 0.59 | O16: 0.57 | P16: 0.49 | Q16: 1.4 | R16: 0.47 | S16: 0.5 | T16: 0.42 | U16: 0.43 | V16: 0.34 | X16: PM-Late | Y16: 2970.49 | Z16: 3736.54 | AA16: 587.61 | AB16: 626.15 | AC16: 170.36 | AD16: 725.02 | AE16: 622.21 | AF16: 4265.07 | AG16: 3768.07 | AH16: 5540.58 | AI16: 6592.39 | AJ16: 10016.96 | AK16: 5215.28 | AL16: 7105.38 | AM16: 1953.43 | AN16: 7244.41 | AO16: 5571.99 | AP16: 5634.4 | AQ16: 7551.64 | AR16: 7725.21 | AU16: PM-Late | AV16: 11759.81 | AW16: 14300.96 | AX16: 11264.68 | AY16: 12007.9 | AZ16: 3335.14 | BA16: 4680 | BB16: 12259.79 | BC16: 16120.53 | BD16: 15341.93 | BE16: 20745.42 | BF16: 26941.61 | BG16: 37405.84 | BH16: 21537.22 | BI16: 27163.92 | BJ16: 31573.97 | BK16: 28961.99 | BL16: 22835.01 | BM16: 23303 | BN16: 31382.36 | BO16: 33287.79 | BR16: PM-Late | BS16: 14730.3 | BT16: 18037.5 | BU16: 11852.29 | BV16: 12634.05 | BW16: 3505.5 | BX16: 5405.02 | BY16: 12882 | BZ16: 20385.6 | CA16: 19110 | CB16: 26286 | CC16: 33534 | CD16: 47422.8 | CE16: 26752.5 | CF16: 34269.3 | CG16: 33527.4 | CH16: 36206.4 | CI16: 28407 | CJ16: 28937.4 | CK16: 38934 | CL16: 41013
B19: CaptureRateLights | X19: ML Volume (PCE/Period) | AU19: GP Volume (PCE/Period) | BR19: Highway Volume
B20: Direction | C20: NB | D20: SB | E20: NB | F20: SB | G20: NB | H20: SB | I20: NB | J20: SB | K20: NB | L20: SB | M20: NB | N20: SB | O20: NB | P20: SB | Q20: NB | R20: SB | S20: NB | T20: SB | U20: NB | V20: SB | X20: Direction | Y20: NB | Z20: SB | AA20: NB | AB20: SB | AC20: NB | AD20: SB | AE20: NB | AF20: SB | AG20: NB | AH20: SB | AI20: NB | AJ20: SB | AK20: NB | AL20: SB | AM20: NB | AN20: SB | AO20: NB | AP20: SB | AQ20: NB | AR20: SB | AU20: Direction | AV20: NB | AW20: SB | AX20: NB | AY20: SB | AZ20: NB | BA20: SB | BB20: NB | BC20: SB | BD20: NB | BE20: SB | BF20: NB | BG20: SB | BH20: NB | BI20: SB | BJ20: NB | BK20: SB | BL20: NB | BM20: SB | BN20: NB | BO20: SB | BR20: Direction | BS20: NB | BT20: SB | BU20: NB | BV20: SB | BW20: NB | BX20: SB | BY20: NB | BZ20: SB | CA20: NB | CB20: SB | CC20: NB | CD20: SB | CE20: NB | CF20: SB | CG20: NB | CH20: SB | CI20: NB | CJ20: SB | CK20: NB | CL20: SB
B21: Segment | C21: 1 | D21: 1 | E21: 2 | F21: 2 | G21: 3 | H21: 3 | I21: 4 | J21: 4 | K21: 5 | L21: 5 | M21: 6 | N21: 6 | O21: 7 | P21: 7 | Q21: 8 | R21: 8 | S21: 9 | T21: 9 | U21: 10 | V21: 10 | X21: Segment | Y21: 1 | Z21: 1 | AA21: 2 | AB21: 2 | AC21: 3 | AD21: 3 | AE21: 4 | AF21: 4 | AG21: 5 | AH21: 5 | AI21: 6 | AJ21: 6 | AK21: 7 | AL21: 7 | AM21: 8 | AN21: 8 | AO21: 9 | AP21: 9 | AQ21: 10 | AR21: 10 | AU21: Segment | AV21: 1 | AW21: 1 | AX21: 2 | AY21: 2 | AZ21: 3 | BA21: 3 | BB21: 4 | BC21: 4 | BD21: 5 | BE21: 5 | BF21: 6 | BG21: 6 | BH21: 7 | BI21: 7 | BJ21: 8 | BK21: 8 | BL21: 9 | BM21: 9 | BN21: 10 | BO21: 10 | BR21: Segment | BS21: 1 | BT21: 1 | BU21: 2 | BV21: 2 | BW21: 3 | BX21: 3 | BY21: 4 | BZ21: 4 | CA21: 5 | CB21: 5 | CC21: 6 | CD21: 6 | CE21: 7 | CF21: 7 | CG21: 8 | CH21: 8 | CI21: 9 | CJ21: 9 | CK21: 10 | CL21: 10
B22: Period | X22: Period | AU22: Period | BR22: Period
B23: Night | C23: 0.05 | D23: 0.05 | E23: 0.05 | F23: 0.05 | G23: 0.05 | H23: 0.05 | I23: 0.05 | J23: 0.1 | K23: 0.1 | L23: 0.1 | M23: 0.1 | N23: 0.1 | O23: 0.1 | P23: 0.1 | Q23: 0.1 | R23: 0.1 | S23: 0.1 | T23: 0.1 | U23: 0.1 | V23: 0.1 | X23: Night | Y23: 758.77 | Z23: 755.44 | AA23: 583.8 | AB23: 546.35 | AC23: 541.11 | AD23: 655.03 | AE23: 688.94 | AF23: 1376.9 | AG23: 1574.3 | AH23: 1386 | AI23: 1591.1 | AJ23: 1364.3 | AK23: 1540.7 | AL23: 1324.4 | AM23: 1495.2 | AN23: 1362.2 | AO23: 1319.5 | AP23: 1006.6 | AQ23: 1330 | AR23: 1054.9 | AU23: Night | AV23: 15015.03 | AW23: 14911.96 | AX23: 11344.2 | AY23: 10611.65 | AZ23: 10826.89 | BA23: 12904.32 | BB23: 13847.96 | BC23: 13085.1 | BD23: 14966.7 | BE23: 13209 | BF23: 14970.9 | BG23: 12950.7 | BH23: 14685.3 | BI23: 12465.6 | BJ23: 14065.8 | BK23: 12805.8 | BL23: 12358.5 | BM23: 9542.4 | BN23: 12537 | BO23: 9935.1 | BR23: Night | BS23: 15773.8 | BT23: 15667.4 | BU23: 11928 | BV23: 11158 | BW23: 11368 | BX23: 13559.35 | BY23: 14536.9 | BZ23: 14462 | CA23: 16541 | CB23: 14595 | CC23: 16562 | CD23: 14315 | CE23: 16226 | CF23: 13790 | CG23: 15561 | CH23: 14168 | CI23: 13678 | CJ23: 10549 | CK23: 13867 | CL23: 10990
B24: AM-Early | C24: 0.23 | D24: 0.22 | E24: 0.22 | F24: 0.2 | G24: 0.25 | H24: 0.22 | I24: 0.23 | J24: 0.25 | K24: 0.22 | L24: 0.23 | M24: 0.23 | N24: 0.23 | O24: 0.23 | P24: 0.23 | Q24: 0.23 | R24: 0.23 | S24: 0.23 | T24: 0.23 | U24: 0.21 | V24: 0.19 | X24: AM-Early | Y24: 1376.32 | Z24: 788.98 | AA24: 1222.04 | AB24: 714.2 | AC24: 907.38 | AD24: 993.03 | AE24: 1401.36 | AF24: 1058.65 | AG24: 1395.34 | AH24: 998.58 | AI24: 1404.14 | AJ24: 1010.35 | AK24: 1215.75 | AL24: 1068.1 | AM24: 1152.38 | AN24: 1025.1 | AO24: 1123.73 | AP24: 846.06 | AQ24: 1213.14 | AR24: 658.25 | AU24: AM-Early | AV24: 5059.93 | AW24: 3392.92 | AX24: 4548.26 | AY24: 3120 | AZ24: 3084.62 | BA24: 3914.67 | BB24: 5183.09 | BC24: 3701.35 | BD24: 5324.01 | BE24: 3777.42 | BF24: 5114.76 | BG24: 3838.65 | BH24: 4489.25 | BI24: 4054.9 | BJ24: 4313.12 | BK24: 3873.1 | BL24: 4220.48 | BM24: 3309.53 | BN24: 5090.11 | BO24: 3348.85 | BR24: AM-Early | BS24: 6436.25 | BT24: 4181.9 | BU24: 5770.3 | BV24: 3834.2 | BW24: 3992 | BX24: 4907.7 | BY24: 6584.45 | BZ24: 4760 | CA24: 6719.35 | CB24: 4776 | CC24: 6518.9 | CD24: 4849 | CE24: 5705 | CF24: 5123 | CG24: 5465.5 | CH24: 4898.2 | CI24: 5344.21 | CJ24: 4155.59 | CK24: 6303.25 | CL24: 4007.1
B25: AM-Peak | C25: 0.23 | D25: 0.14 | E25: 0.24 | F25: 0.05 | G25: 0.25 | H25: 0.24 | I25: 0.24 | J25: 0.25 | K25: 0.23 | L25: 0.08 | M25: 0.22 | N25: 0.23 | O25: 0.23 | P25: 0.23 | Q25: 0.22 | R25: 0.23 | S25: 0.23 | T25: 0.23 | U25: 0.08 | V25: 0.23 | X25: AM-Peak | Y25: 4855.35 | Z25: 1307.55 | AA25: 5714 | AB25: 433.49 | AC25: 3720.35 | AD25: 5957.16 | AE25: 5031.15 | AF25: 3643.17 | AG25: 5003.61 | AH25: 1295.5 | AI25: 5059.68 | AJ25: 3271.36 | AK25: 5477.32 | AL25: 3246.5 | AM25: 4587.28 | AN25: 3163.21 | AO25: 3519.55 | AP25: 2775.34 | AQ25: 1090.53 | AR25: 2412.73 | AU25: AM-Peak | AV25: 19100.4 | AW25: 9360 | AX25: 19460.8 | AY25: 8278.96 | AZ25: 13412.5 | BA25: 20619.39 | BB25: 17952.78 | BC25: 13176.78 | BD25: 19494.34 | BE25: 15105.11 | BF25: 20945.51 | BG25: 13139.13 | BH25: 21243.72 | BI25: 13235.2 | BJ25: 19314.92 | BK25: 12700.69 | BL25: 14010.54 | BM25: 11443.76 | BN25: 12694.38 | BO25: 10033.64 | BR25: AM-Peak | BS25: 23955.75 | BT25: 10667.55 | BU25: 25174.8 | BV25: 8712.45 | BW25: 17132.85 | BX25: 26576.55 | BY25: 22983.93 | BZ25: 16819.95 | CA25: 24497.95 | CB25: 16400.62 | CC25: 26005.19 | CD25: 16410.49 | CE25: 26721.04 | CF25: 16481.7 | CG25: 23902.2 | CH25: 15863.9 | CI25: 17530.09 | CJ25: 14219.1 | CK25: 13784.91 | CL25: 12446.37
B26: AM-Shoulder | C26: 0.23 | D26: 0.23 | E26: 0.24 | F26: 0.15 | G26: 0.25 | H26: 0.25 | I26: 0.25 | J26: 0.25 | K26: 0.23 | L26: 0.23 | M26: 0.23 | N26: 0.23 | O26: 0.23 | P26: 0.23 | Q26: 0.23 | R26: 0.23 | S26: 0.23 | T26: 0.23 | U26: 0.23 | V26: 0.23 | X26: AM-Shoulder | Y26: 1561.56 | Z26: 745.85 | AA26: 1735.52 | AB26: 486.2 | AC26: 1365.55 | AD26: 1793.75 | AE26: 1530.43 | AF26: 1201.18 | AG26: 1504.57 | AH26: 1104.38 | AI26: 1517.09 | AJ26: 1055.63 | AK26: 1505.5 | AL26: 1039.34 | AM26: 1279.61 | AN26: 1002.26 | AO26: 1020.71 | AP26: 902.49 | AQ26: 903.13 | AR26: 839.87 | AU26: AM-Shoulder | AV26: 6535.44 | AW26: 3245.55 | AX26: 5944.97 | AY26: 3120 | AZ26: 5198.07 | BA26: 6606.25 | BB26: 5630.02 | BC26: 4621.5 | BD26: 6107.61 | BE26: 4524.46 | BF26: 6264 | BG26: 4417.41 | BH26: 6257.24 | BI26: 4418.07 | BJ26: 5273.11 | BK26: 4197.77 | BL26: 4207.74 | BM26: 3990.69 | BN26: 3880.86 | BO26: 3699.34 | BR26: AM-Shoulder | BS26: 8097 | BT26: 3991.4 | BU26: 7680.49 | BV26: 3606.2 | BW26: 6563.62 | BX26: 8400 | BY26: 7160.45 | BZ26: 5822.68 | CA26: 7612.18 | CB26: 5628.84 | CC26: 7781.09 | CD26: 5473.04 | CE26: 7762.73 | CF26: 5457.42 | CG26: 6552.71 | CH26: 5200.03 | CI26: 5228.44 | CJ26: 4893.18 | CK26: 4783.99 | CL26: 4539.21
B27: MD | C27: 0.24 | D27: 0.24 | E27: 0.25 | F27: 0.23 | G27: 0.25 | H27: 0.25 | I27: 0.24 | J27: 0.25 | K27: 0.23 | L27: 0.23 | M27: 0.23 | N27: 0.23 | O27: 0.23 | P27: 0.23 | Q27: 0.23 | R27: 0.23 | S27: 0.24 | T27: 0.24 | U27: 0.23 | V27: 0.21 | X27: MD | Y27: 5400.18 | Z27: 5986.26 | AA27: 6964.46 | AB27: 6565.31 | AC27: 4896.18 | AD27: 6573.53 | AE27: 6123.9 | AF27: 6368.77 | AG27: 6708.67 | AH27: 6761.54 | AI27: 6255.78 | AJ27: 6271.25 | AK27: 5841.74 | AL27: 6084.84 | AM27: 5477.82 | AN27: 5304.33 | AO27: 5101.07 | AP27: 4942.76 | AQ27: 4782.78 | AR27: 4877.38 | AU27: MD | AV27: 21654.82 | AW27: 24013.74 | AX27: 22715.54 | AY27: 24053.19 | AZ27: 17483.82 | BA27: 23085.03 | BB27: 22067.35 | BC27: 22641.23 | BD27: 25537.76 | BE27: 26088.46 | BF27: 24084.53 | BG27: 24309.25 | BH27: 22651.22 | BI27: 23621.66 | BJ27: 21617.64 | BK27: 20802.34 | BL27: 20338.93 | BM27: 19723.99 | BN27: 19646.47 | BO27: 22316.37 | BR27: MD | BS27: 27055 | BT27: 30000 | BU27: 29680 | BV27: 30618.5 | BW27: 22380 | BX27: 29658.56 | BY27: 28191.25 | BZ27: 29010 | CA27: 32246.43 | CB27: 32850 | CC27: 30340.31 | CD27: 30580.5 | CE27: 28492.95 | CF27: 29706.5 | CG27: 27095.46 | CH27: 26106.68 | CI27: 25440 | CJ27: 24666.75 | CK27: 24429.25 | CL27: 27193.75
B28: PM-Shoulder | C28: 0.24 | D28: 0.24 | E28: 0.24 | F28: 0.24 | G28: 0.24 | H28: 0.24 | I28: 0.24 | J28: 0.24 | K28: 0.25 | L28: 0.24 | M28: 0.24 | N28: 0.24 | O28: 0.24 | P28: 0.24 | Q28: 0.24 | R28: 0.24 | S28: 0.24 | T28: 0.24 | U28: 0.24 | V28: 0.24 | X28: PM-Shoulder | Y28: 1364.68 | Z28: 1420.93 | AA28: 1607.16 | AB28: 1919.06 | AC28: 1167.37 | AD28: 1348.99 | AE28: 1178.77 | AF28: 1138.68 | AG28: 1207.62 | AH28: 1801.54 | AI28: 1289.06 | AJ28: 1683.8 | AK28: 1262.35 | AL28: 1536.77 | AM28: 1246.02 | AN28: 1519.53 | AO28: 1188.17 | AP28: 1465.56 | AQ28: 1066.47 | AR28: 1050.19 | AU28: PM-Shoulder | AV28: 5168.79 | AW28: 5237.35 | AX28: 5397.02 | AY28: 6204.82 | AZ28: 4297.11 | BA28: 4852.61 | BB28: 4089.37 | BC28: 4130.16 | BD28: 4194.59 | BE28: 6389.4 | BF28: 4508.95 | BG28: 5803.85 | BH28: 4442.68 | BI28: 5274.01 | BJ28: 4423.73 | BK28: 5279.85 | BL28: 4309.17 | BM28: 5031.14 | BN28: 3971.81 | BO28: 3660.86 | BR28: PM-Shoulder | BS28: 6533.47 | BT28: 6658.28 | BU28: 7004.18 | BV28: 8123.88 | BW28: 5464.48 | BX28: 6201.6 | BY28: 5268.14 | BZ28: 5268.84 | CA28: 5402.21 | CB28: 8190.94 | CC28: 5798 | CD28: 7487.65 | CE28: 5705.03 | CF28: 6810.78 | CG28: 5669.75 | CH28: 6799.37 | CI28: 5497.34 | CJ28: 6496.7 | CK28: 5038.28 | CL28: 4711.05
B29: PM-Peak | C29: 0.24 | D29: 0.24 | E29: 0.24 | F29: 0.24 | G29: 0.24 | H29: 0.23 | I29: 0.24 | J29: 0.28 | K29: 0.24 | L29: 0.24 | M29: 0.24 | N29: 0.24 | O29: 0.24 | P29: 0.24 | Q29: 0.24 | R29: 0.24 | S29: 0.24 | T29: 0.24 | U29: 0.24 | V29: 0.24 | X29: PM-Peak | Y29: 4902.24 | Z29: 5181.28 | AA29: 4485.43 | AB29: 5377.68 | AC29: 3656.1 | AD29: 4513.92 | AE29: 3903.05 | AF29: 4860.69 | AG29: 3850.7 | AH29: 6038.67 | AI29: 3975.83 | AJ29: 5588.35 | AK29: 3920.96 | AL29: 5041.19 | AM29: 4055.14 | AN29: 4400.02 | AO29: 3559.01 | AP29: 3680.17 | AQ29: 3268.32 | AR29: 3258.86 | AU29: PM-Peak | AV29: 18095.91 | AW29: 19335.17 | AX29: 15107.57 | AY29: 17989.38 | AZ29: 13243.65 | BA29: 17696.73 | BB29: 13925.95 | BC29: 15224.05 | BD29: 13720 | BE29: 21875.76 | BF29: 14250.05 | BG29: 20159.97 | BH29: 14182.4 | BI29: 18219.49 | BJ29: 14894.92 | BK29: 15965.54 | BL29: 13332.38 | BM29: 13564.31 | BN29: 12403.24 | BO29: 12154.11 | BR29: PM-Peak | BS29: 22998.15 | BT29: 24516.45 | BU29: 19593 | BV29: 23367.07 | BW29: 16899.75 | BX29: 22210.65 | BY29: 17829 | BZ29: 20084.74 | CA29: 17570.7 | CB29: 27914.42 | CC29: 18225.87 | CD29: 25748.32 | CE29: 18103.36 | CF29: 23260.68 | CG29: 18950.05 | CH29: 20365.56 | CI29: 16891.39 | CJ29: 17244.48 | CK29: 15671.57 | CL29: 15412.98
B30: PM-Late | C30: 0.25 | D30: 0.25 | E30: 0.05 | F30: 0.05 | G30: 0.05 | H30: 0.15 | I30: 0.05 | J30: 0.24 | K30: 0.25 | L30: 0.25 | M30: 0.25 | N30: 0.24 | O30: 0.25 | P30: 0.25 | Q30: 0.05 | R30: 0.25 | S30: 0.25 | T30: 0.25 | U30: 0.25 | V30: 0.25 | X30: PM-Late | Y30: 2284.99 | Z30: 2874.26 | AA30: 452.01 | AB30: 481.65 | AC30: 340.72 | AD30: 1450.05 | AE30: 388.88 | AF30: 2665.67 | AG30: 1884.04 | AH30: 2770.29 | AI30: 1831.22 | AJ30: 2782.49 | AK30: 1798.37 | AL30: 2450.13 | AM30: 514.06 | AN30: 1906.42 | AO30: 1638.82 | AP30: 1657.18 | AQ30: 1678.14 | AR30: 1716.71 | AU30: PM-Late | AV30: 9046.01 | AW30: 11000.74 | AX30: 8665.14 | AY30: 9236.85 | AZ30: 6670.28 | BA30: 9360 | BB30: 7662.37 | BC30: 10075.33 | BD30: 7670.96 | BE30: 10372.71 | BF30: 7483.78 | BG30: 10390.51 | BH30: 7426.63 | BI30: 9366.87 | BJ30: 8308.94 | BK30: 7621.58 | BL30: 6716.18 | BM30: 6853.82 | BN30: 6973.86 | BO30: 7397.29 | BR30: PM-Late | BS30: 11331 | BT30: 13875 | BU30: 9117.15 | BV30: 9718.5 | BW30: 7011 | BX30: 10810.05 | BY30: 8051.25 | BZ30: 12741 | CA30: 9555 | CB30: 13143 | CC30: 9315 | CD30: 13173 | CE30: 9225 | CF30: 11817 | CG30: 8823 | CH30: 9528 | CI30: 8355 | CJ30: 8511 | CK30: 8652 | CL30: 9114
B33: Revenue Per Period | X33: ML Flow (PCE/hr) | AU33: GP Flow (PCE/hr) | BR33: Highway Flow
B34: Direction | C34: NB | D34: SB | E34: NB | F34: SB | G34: NB | H34: SB | I34: NB | J34: SB | K34: NB | L34: SB | M34: NB | N34: SB | O34: NB | P34: SB | Q34: NB | R34: SB | S34: NB | T34: SB | U34: NB | V34: SB | X34: Direction | Y34: NB | Z34: SB | AA34: NB | AB34: SB | AC34: NB | AD34: SB | AE34: NB | AF34: SB | AG34: NB | AH34: SB | AI34: NB | AJ34: SB | AK34: NB | AL34: SB | AM34: NB | AN34: SB | AO34: NB | AP34: SB | AQ34: NB | AR34: SB | AU34: Direction | AV34: NB | AW34: SB | AX34: NB | AY34: SB | AZ34: NB | BA34: SB | BB34: NB | BC34: SB | BD34: NB | BE34: SB | BF34: NB | BG34: SB | BH34: NB | BI34: SB | BJ34: NB | BK34: SB | BL34: NB | BM34: SB | BN34: NB | BO34: SB | BR34: Direction | BS34: NB | BT34: SB | BU34: NB | BV34: SB | BW34: NB | BX34: SB | BY34: NB | BZ34: SB | CA34: NB | CB34: SB | CC34: NB | CD34: SB | CE34: NB | CF34: SB | CG34: NB | CH34: SB | CI34: NB | CJ34: SB | CK34: NB | CL34: SB
B35: Segment | C35: 1 | D35: 1 | E35: 2 | F35: 2 | G35: 3 | H35: 3 | I35: 4 | J35: 4 | K35: 5 | L35: 5 | M35: 6 | N35: 6 | O35: 7 | P35: 7 | Q35: 8 | R35: 8 | S35: 9 | T35: 9 | U35: 10 | V35: 10 | X35: Segment | Y35: 1 | Z35: 1 | AA35: 2 | AB35: 2 | AC35: 3 | AD35: 3 | AE35: 4 | AF35: 4 | AG35: 5 | AH35: 5 | AI35: 6 | AJ35: 6 | AK35: 7 | AL35: 7 | AM35: 8 | AN35: 8 | AO35: 9 | AP35: 9 | AQ35: 10 | AR35: 10 | AU35: Segment | AV35: 1 | AW35: 1 | AX35: 2 | AY35: 2 | AZ35: 3 | BA35: 3 | BB35: 4 | BC35: 4 | BD35: 5 | BE35: 5 | BF35: 6 | BG35: 6 | BH35: 7 | BI35: 7 | BJ35: 8 | BK35: 8 | BL35: 9 | BM35: 9 | BN35: 10 | BO35: 10 | BR35: Segment | BS35: 1 | BT35: 1 | BU35: 2 | BV35: 2 | BW35: 3 | BX35: 3 | BY35: 4 | BZ35: 4 | CA35: 5 | CB35: 5 | CC35: 6 | CD35: 6 | CE35: 7 | CF35: 7 | CG35: 8 | CH35: 8 | CI35: 9 | CJ35: 9 | CK35: 10 | CL35: 10
B36: Period | X36: Period | AU36: Period | BR36: Period
B37: Night | C37: 196.11 | D37: 195.42 | E37: 151.02 | F37: 141.28 | G37: 53.76 | H37: 65.04 | I37: 219.82 | J37: 1047.78 | K37: 1504.27 | L37: 1326.19 | M37: 2733.7 | N37: 2344.2 | O37: 2129.55 | P37: 1833.33 | Q37: 2710.65 | R37: 2468.69 | S37: 2135.15 | T37: 1630.2 | U37: 2847.85 | V37: 2257.42 | X37: Night | Y37: 108.4 | Z37: 107.92 | AA37: 83.4 | AB37: 78.05 | AC37: 77.3 | AD37: 93.58 | AE37: 98.42 | AF37: 196.7 | AG37: 224.9 | AH37: 198 | AI37: 227.3 | AJ37: 194.9 | AK37: 220.1 | AL37: 189.2 | AM37: 213.6 | AN37: 194.6 | AO37: 188.5 | AP37: 143.8 | AQ37: 190 | AR37: 150.7 | AU37: Night | AV37: 2145 | AW37: 2130.28 | AX37: 1620.6 | AY37: 1515.95 | AZ37: 1546.7 | BA37: 1843.47 | BB37: 1978.28 | BC37: 1869.3 | BD37: 2138.1 | BE37: 1887 | BF37: 2138.7 | BG37: 1850.1 | BH37: 2097.9 | BI37: 1780.8 | BJ37: 2009.4 | BK37: 1829.4 | BL37: 1765.5 | BM37: 1363.2 | BN37: 1791 | BO37: 1419.3 | BR37: Night | BS37: 2253.4 | BT37: 2238.2 | BU37: 1704 | BV37: 1594 | BW37: 1624 | BX37: 1937.05 | BY37: 2076.7 | BZ37: 2066 | CA37: 2363 | CB37: 2085 | CC37: 2366 | CD37: 2045 | CE37: 2318 | CF37: 1970 | CG37: 2223 | CH37: 2024 | CI37: 1954 | CJ37: 1507 | CK37: 1981 | CL37: 1570
B38: AM-Early | C38: 359.53 | D38: 201.81 | E38: 315.89 | F38: 190.5 | G38: 111.83 | H38: 97.77 | I38: 444.2 | J38: 524.29 | K38: 552.29 | L38: 467.87 | M38: 1220.28 | N38: 874.49 | O38: 1022.67 | P38: 801.7 | Q38: 1220.38 | R38: 788.48 | S38: 1037.19 | T38: 604.57 | U38: 1076.32 | V38: 582.04 | X38: AM-Early | Y38: 1376.32 | Z38: 788.98 | AA38: 1222.04 | AB38: 714.2 | AC38: 907.38 | AD38: 993.03 | AE38: 1401.36 | AF38: 1058.65 | AG38: 1395.34 | AH38: 998.58 | AI38: 1404.14 | AJ38: 1010.35 | AK38: 1215.75 | AL38: 1068.1 | AM38: 1152.38 | AN38: 1025.1 | AO38: 1123.73 | AP38: 846.06 | AQ38: 1213.14 | AR38: 658.25 | AU38: AM-Early | AV38: 5059.93 | AW38: 3392.92 | AX38: 4548.26 | AY38: 3120 | AZ38: 3084.62 | BA38: 3914.67 | BB38: 5183.09 | BC38: 3701.35 | BD38: 5324.01 | BE38: 3777.42 | BF38: 5114.76 | BG38: 3838.65 | BH38: 4489.25 | BI38: 4054.9 | BJ38: 4313.12 | BK38: 3873.1 | BL38: 4220.48 | BM38: 3309.53 | BN38: 5090.11 | BO38: 3348.85 | BR38: AM-Early | BS38: 6436.25 | BT38: 4181.9 | BU38: 5770.3 | BV38: 3834.2 | BW38: 3992 | BX38: 4907.7 | BY38: 6584.45 | BZ38: 4760 | CA38: 6719.35 | CB38: 4776 | CC38: 6518.9 | CD38: 4849 | CE38: 5705 | CF38: 5123 | CG38: 5465.5 | CH38: 4898.2 | CI38: 5344.21 | CJ38: 4155.59 | CK38: 6303.25 | CL38: 4007.1
B39: AM-Peak | C39: 7741.92 | D39: 843.36 | E39: 10230.83 | F39: 111.65 | G39: 2010.33 | H39: 4344.8 | I39: 6040.36 | J39: 2650.72 | K39: 9291.18 | L39: 4022.55 | M39: 22241.64 | N39: 5456.12 | O39: 24838.84 | P39: 4488.07 | Q39: 26415.3 | R39: 5366.87 | S39: 6039.93 | T39: 3799.07 | U39: 6173.25 | V39: 3834.11 | X39: AM-Peak | Y39: 1618.45 | Z39: 435.85 | AA39: 1904.67 | AB39: 144.5 | AC39: 1240.12 | AD39: 1985.72 | AE39: 1677.05 | AF39: 1214.39 | AG39: 1667.87 | AH39: 431.83 | AI39: 1686.56 | AJ39: 1090.45 | AK39: 1825.77 | AL39: 1082.17 | AM39: 1529.09 | AN39: 1054.4 | AO39: 1173.18 | AP39: 925.11 | AQ39: 363.51 | AR39: 804.24 | AU39: AM-Peak | AV39: 6366.8 | AW39: 3120 | AX39: 6486.93 | AY39: 2759.65 | AZ39: 4470.83 | BA39: 6873.13 | BB39: 5984.26 | BC39: 4392.26 | BD39: 6498.11 | BE39: 5035.04 | BF39: 6981.84 | BG39: 4379.71 | BH39: 7081.24 | BI39: 4411.73 | BJ39: 6438.31 | BK39: 4233.56 | BL39: 4670.18 | BM39: 3814.59 | BN39: 4231.46 | BO39: 3344.55 | BR39: AM-Peak | BS39: 7985.25 | BT39: 3555.85 | BU39: 8391.6 | BV39: 2904.15 | BW39: 5710.95 | BX39: 8858.85 | BY39: 7661.31 | BZ39: 5606.65 | CA39: 8165.98 | CB39: 5466.87 | CC39: 8668.4 | CD39: 5470.16 | CE39: 8907.01 | CF39: 5493.9 | CG39: 7967.4 | CH39: 5287.97 | CI39: 5843.36 | CJ39: 4739.7 | CK39: 4594.97 | CL39: 4148.79
B40: AM-Shoulder | C40: 2087.92 | D40: 289.06 | E40: 1865.35 | F40: 208.5 | G40: 694.68 | H40: 760.98 | I40: 1224.25 | J40: 707.44 | K40: 1811.99 | L40: 725.52 | M40: 3600.27 | N40: 1231.72 | O40: 2869.21 | P40: 996.4 | Q40: 2111.37 | R40: 1155.32 | S40: 1039.84 | T40: 919.23 | U40: 1143.92 | V40: 1030.56 | X40: AM-Shoulder | Y40: 1561.56 | Z40: 745.85 | AA40: 1735.52 | AB40: 486.2 | AC40: 1365.55 | AD40: 1793.75 | AE40: 1530.43 | AF40: 1201.18 | AG40: 1504.57 | AH40: 1104.38 | AI40: 1517.09 | AJ40: 1055.63 | AK40: 1505.5 | AL40: 1039.34 | AM40: 1279.61 | AN40: 1002.26 | AO40: 1020.71 | AP40: 902.49 | AQ40: 903.13 | AR40: 839.87 | AU40: AM-Shoulder | AV40: 6535.44 | AW40: 3245.55 | AX40: 5944.97 | AY40: 3120 | AZ40: 5198.07 | BA40: 6606.25 | BB40: 5630.02 | BC40: 4621.5 | BD40: 6107.61 | BE40: 4524.46 | BF40: 6264 | BG40: 4417.41 | BH40: 6257.24 | BI40: 4418.07 | BJ40: 5273.11 | BK40: 4197.77 | BL40: 4207.74 | BM40: 3990.69 | BN40: 3880.86 | BO40: 3699.34 | BR40: AM-Shoulder | BS40: 8097 | BT40: 3991.4 | BU40: 7680.49 | BV40: 3606.2 | BW40: 6563.62 | BX40: 8400 | BY40: 7160.45 | BZ40: 5822.68 | CA40: 7612.18 | CB40: 5628.84 | CC40: 7781.09 | CD40: 5473.04 | CE40: 7762.73 | CF40: 5457.42 | CG40: 6552.71 | CH40: 5200.03 | CI40: 5228.44 | CJ40: 4893.18 | CK40: 4783.99 | CL40: 4539.21
B41: MD | C41: 6763.83 | D41: 4162.45 | E41: 4123.63 | F41: 1680.26 | G41: 1556.9 | H41: 2899.98 | I41: 1923.8 | J41: 4756.07 | K41: 4971.77 | L41: 5779.7 | M41: 7625.09 | N41: 6655.45 | O41: 5222.06 | P41: 4731.41 | Q41: 6123.5 | R41: 5585.26 | S41: 4979.12 | T41: 3943.7 | U41: 5502.24 | V41: 4317.76 | X41: MD | Y41: 1080.04 | Z41: 1197.25 | AA41: 1392.89 | AB41: 1313.06 | AC41: 979.24 | AD41: 1314.71 | AE41: 1224.78 | AF41: 1273.75 | AG41: 1341.73 | AH41: 1352.31 | AI41: 1251.16 | AJ41: 1254.25 | AK41: 1168.35 | AL41: 1216.97 | AM41: 1095.56 | AN41: 1060.87 | AO41: 1020.21 | AP41: 988.55 | AQ41: 956.56 | AR41: 975.48 | AU41: MD | AV41: 4330.96 | AW41: 4802.75 | AX41: 4543.11 | AY41: 4810.64 | AZ41: 3496.76 | BA41: 4617.01 | BB41: 4413.47 | BC41: 4528.25 | BD41: 5107.55 | BE41: 5217.69 | BF41: 4816.91 | BG41: 4861.85 | BH41: 4530.24 | BI41: 4724.33 | BJ41: 4323.53 | BK41: 4160.47 | BL41: 4067.79 | BM41: 3944.8 | BN41: 3929.29 | BO41: 4463.27 | BR41: MD | BS41: 5411 | BT41: 6000 | BU41: 5936 | BV41: 6123.7 | BW41: 4476 | BX41: 5931.71 | BY41: 5638.25 | BZ41: 5802 | CA41: 6449.29 | CB41: 6570 | CC41: 6068.06 | CD41: 6116.1 | CE41: 5698.59 | CF41: 5941.3 | CG41: 5419.09 | CH41: 5221.34 | CI41: 5088 | CJ41: 4933.35 | CK41: 4885.85 | CL41: 5438.75
B42: PM-Shoulder | C42: 1899.3 | D42: 1900.95 | E42: 1015.12 | F42: 1659.96 | G42: 672.61 | H42: 723.99 | I42: 566.64 | J42: 1938.07 | K42: 600.74 | L42: 2529.65 | M42: 1300.13 | N42: 2800.79 | O42: 1013.23 | P42: 1630.6 | Q42: 1318.9 | R42: 2151.39 | S42: 1115.57 | T42: 1656.07 | U42: 1230.99 | V42: 989.83 | X42: PM-Shoulder | Y42: 1364.68 | Z42: 1420.93 | AA42: 1607.16 | AB42: 1919.06 | AC42: 1167.37 | AD42: 1348.99 | AE42: 1178.77 | AF42: 1138.68 | AG42: 1207.62 | AH42: 1801.54 | AI42: 1289.06 | AJ42: 1683.8 | AK42: 1262.35 | AL42: 1536.77 | AM42: 1246.02 | AN42: 1519.53 | AO42: 1188.17 | AP42: 1465.56 | AQ42: 1066.47 | AR42: 1050.19 | AU42: PM-Shoulder | AV42: 5168.79 | AW42: 5237.35 | AX42: 5397.02 | AY42: 6204.82 | AZ42: 4297.11 | BA42: 4852.61 | BB42: 4089.37 | BC42: 4130.16 | BD42: 4194.59 | BE42: 6389.4 | BF42: 4508.95 | BG42: 5803.85 | BH42: 4442.68 | BI42: 5274.01 | BJ42: 4423.73 | BK42: 5279.85 | BL42: 4309.17 | BM42: 5031.14 | BN42: 3971.81 | BO42: 3660.86 | BR42: PM-Shoulder | BS42: 6533.47 | BT42: 6658.28 | BU42: 7004.18 | BV42: 8123.88 | BW42: 5464.48 | BX42: 6201.6 | BY42: 5268.14 | BZ42: 5268.84 | CA42: 5402.21 | CB42: 8190.94 | CC42: 5798 | CD42: 7487.65 | CE42: 5705.03 | CF42: 6810.78 | CG42: 5669.75 | CH42: 6799.37 | CI42: 5497.34 | CJ42: 6496.7 | CK42: 5038.28 | CL42: 4711.05
B43: PM-Peak | C43: 9418.01 | D43: 9865.04 | E43: 3673 | F43: 5639.95 | G43: 2494.19 | H43: 3576.8 | I43: 3560.33 | J43: 12306.65 | K43: 3406.11 | L43: 15339.06 | M43: 6748.91 | N43: 19733.44 | O43: 5403 | P43: 11048.97 | Q43: 8064.88 | R43: 9668.88 | S43: 5531.8 | T43: 5744.23 | U43: 6243 | V43: 5927.06 | X43: PM-Peak | Y43: 1634.08 | Z43: 1727.09 | AA43: 1495.14 | AB43: 1792.56 | AC43: 1218.7 | AD43: 1504.64 | AE43: 1301.02 | AF43: 1620.23 | AG43: 1283.57 | AH43: 2012.89 | AI43: 1325.28 | AJ43: 1862.78 | AK43: 1306.99 | AL43: 1680.4 | AM43: 1351.71 | AN43: 1466.67 | AO43: 1186.34 | AP43: 1226.72 | AQ43: 1089.44 | AR43: 1086.29 | AU43: PM-Peak | AV43: 6031.97 | AW43: 6445.06 | AX43: 5035.86 | AY43: 5996.46 | AZ43: 4414.55 | BA43: 5898.91 | BB43: 4641.98 | BC43: 5074.68 | BD43: 4573.33 | BE43: 7291.92 | BF43: 4750.02 | BG43: 6719.99 | BH43: 4727.47 | BI43: 6073.16 | BJ43: 4964.97 | BK43: 5321.85 | BL43: 4444.13 | BM43: 4521.44 | BN43: 4134.41 | BO43: 4051.37 | BR43: PM-Peak | BS43: 7666.05 | BT43: 8172.15 | BU43: 6531 | BV43: 7789.02 | BW43: 5633.25 | BX43: 7403.55 | BY43: 5943 | BZ43: 6694.91 | CA43: 5856.9 | CB43: 9304.81 | CC43: 6075.29 | CD43: 8582.77 | CE43: 6034.45 | CF43: 7753.56 | CG43: 6316.68 | CH43: 6788.52 | CI43: 5630.46 | CJ43: 5748.16 | CK43: 5223.86 | CL43: 5137.66
B44: PM-Late | C44: 1092.56 | D44: 1621.79 | E44: 117.17 | F44: 124.82 | G44: 33.91 | H44: 246.3 | I44: 123.99 | J44: 3019.15 | K44: 1428.01 | L44: 3507.29 | M44: 3491.94 | N44: 5897.42 | O44: 2975.93 | P44: 3468.04 | Q44: 2708.32 | R44: 3353 | S44: 2770.23 | T44: 2334.75 | U44: 3183.11 | V44: 2595.34 | X44: PM-Late | Y44: 761.66 | Z44: 958.09 | AA44: 150.67 | AB44: 160.55 | AC44: 113.57 | AD44: 483.35 | AE44: 129.63 | AF44: 888.56 | AG44: 628.01 | AH44: 923.43 | AI44: 610.41 | AJ44: 927.5 | AK44: 599.46 | AL44: 816.71 | AM44: 171.35 | AN44: 635.47 | AO44: 546.27 | AP44: 552.39 | AQ44: 559.38 | AR44: 572.24 | AU44: PM-Late | AV44: 3015.34 | AW44: 3666.91 | AX44: 2888.38 | AY44: 3078.95 | AZ44: 2223.43 | BA44: 3120 | BB44: 2554.12 | BC44: 3358.44 | BD44: 2556.99 | BE44: 3457.57 | BF44: 2494.59 | BG44: 3463.5 | BH44: 2475.54 | BI44: 3122.29 | BJ44: 2769.65 | BK44: 2540.53 | BL44: 2238.73 | BM44: 2284.61 | BN44: 2324.62 | BO44: 2465.76 | BR44: PM-Late | BS44: 3777 | BT44: 4625 | BU44: 3039.05 | BV44: 3239.5 | BW44: 2337 | BX44: 3603.35 | BY44: 2683.75 | BZ44: 4247 | CA44: 3185 | CB44: 4381 | CC44: 3105 | CD44: 4391 | CE44: 3075 | CF44: 3939 | CG44: 2941 | CH44: 3176 | CI44: 2785 | CJ44: 2837 | CK44: 2884 | CL44: 3038
B47: Revenue Per Period Lights | X47: ML V/C | AU47: GP V/C real | BR47: Highway Vol / GP Capacity
...

Sheet Year_2032
B1: Lenght
C2: 1 | D2: 2 | E2: 3 | F2: 4 | G2: 5 | H2: 6 | I2: 7 | J2: 8 | K2: 9 | L2: 10
B3: Length | C3: 1.3 | D3: 1.3 | E3: 0.5 | F3: 1.6 | G3: 2 | H3: 3.6 | I3: 2.9 | J3: 3.8 | K3: 3.4 | L3: 4.5
B5: TollLights | X5: ML PCE.Miles | AU5: GP PCE.Miles | BR5: Highway PCE.Miles
B6: Direction | C6: NB | D6: SB | E6: NB | F6: SB | G6: NB | H6: SB | I6: NB | J6: SB | K6: NB | L6: SB | M6: NB | N6: SB | O6: NB | P6: SB | Q6: NB | R6: SB | S6: NB | T6: SB | U6: NB | V6: SB | X6: Direction | Y6: NB | Z6: SB | AA6: NB | AB6: SB | AC6: NB | AD6: SB | AE6: NB | AF6: SB | AG6: NB | AH6: SB | AI6: NB | AJ6: SB | AK6: NB | AL6: SB | AM6: NB | AN6: SB | AO6: NB | AP6: SB | AQ6: NB | AR6: SB | AU6: Direction | AV6: NB | AW6: SB | AX6: NB | AY6: SB | AZ6: NB | BA6: SB | BB6: NB | BC6: SB | BD6: NB | BE6: SB | BF6: NB | BG6: SB | BH6: NB | BI6: SB | BJ6: NB | BK6: SB | BL6: NB | BM6: SB | BN6: NB | BO6: SB | BR6: Direction | BS6: NB | BT6: SB | BU6: NB | BV6: SB | BW6: NB | BX6: SB | BY6: NB | BZ6: SB | CA6: NB | CB6: SB | CC6: NB | CD6: SB | CE6: NB | CF6: SB | CG6: NB | CH6: SB | CI6: NB | CJ6: SB | CK6: NB | CL6: SB
B7: Segment | C7: 1 | D7: 1 | E7: 2 | F7: 2 | G7: 3 | H7: 3 | I7: 4 | J7: 4 | K7: 5 | L7: 5 | M7: 6 | N7: 6 | O7: 7 | P7: 7 | Q7: 8 | R7: 8 | S7: 9 | T7: 9 | U7: 10 | V7: 10 | X7: Segment | Y7: 1 | Z7: 1 | AA7: 2 | AB7: 2 | AC7: 3 | AD7: 3 | AE7: 4 | AF7: 4 | AG7: 5 | AH7: 5 | AI7: 6 | AJ7: 6 | AK7: 7 | AL7: 7 | AM7: 8 | AN7: 8 | AO7: 9 | AP7: 9 | AQ7: 10 | AR7: 10 | AU7: Segment | AV7: 1 | AW7: 1 | AX7: 2 | AY7: 2 | AZ7: 3 | BA7: 3 | BB7: 4 | BC7: 4 | BD7: 5 | BE7: 5 | BF7: 6 | BG7: 6 | BH7: 7 | BI7: 7 | BJ7: 8 | BK7: 8 | BL7: 9 | BM7: 9 | BN7: 10 | BO7: 10 | BR7: Segment | BS7: 1 | BT7: 1 | BU7: 2 | BV7: 2 | BW7: 3 | BX7: 3 | BY7: 4 | BZ7: 4 | CA7: 5 | CB7: 5 | CC7: 6 | CD7: 6 | CE7: 7 | CF7: 7 | CG7: 8 | CH7: 8 | CI7: 9 | CJ7: 9 | CK7: 10 | CL7: 10
B8: Period | X8: Period | AU8: Period | BR8: Period
B9: Night | C9: 0.21 | D9: 0.21 | E9: 0.22 | F9: 0.22 | G9: 0.22 | H9: 0.22 | I9: 0.2 | J9: 0.54 | K9: 0.54 | L9: 0.54 | M9: 0.54 | N9: 0.54 | O9: 0.54 | P9: 0.54 | Q9: 0.54 | R9: 0.54 | S9: 0.54 | T9: 0.54 | U9: 0.54 | V9: 0.54 | X9: Night | Y9: 1542.14 | Z9: 1532.65 | AA9: 1262.57 | AB9: 1177.08 | AC9: 430.22 | AD9: 530.17 | AE9: 1386.02 | AF9: 2769.98 | AG9: 3877.16 | AH9: 3413.62 | AI9: 7063.56 | AJ9: 6056.32 | AK9: 5557.73 | AL9: 4777.81 | AM9: 7051.13 | AN9: 6424.43 | AO9: 5521.12 | AP9: 4211.41 | AQ9: 7445.02 | AR9: 5904.67 | AU9: Night | AV9: 23776.47 | AW9: 23620.84 | AX9: 18559.96 | AY9: 17369.63 | AZ9: 6747.23 | BA9: 8031.37 | BB9: 27860.15 | BC9: 26324.26 | BD9: 36860.04 | BE9: 32532.78 | BF9: 66459.96 | BG9: 57493.04 | BH9: 52973.26 | BI9: 44967.34 | BJ9: 66332.95 | BK9: 60397.43 | BL9: 51710.74 | BM9: 39923.31 | BN9: 70180.43 | BO9: 55608.53 | BR9: Night | BS9: 25318.61 | BT9: 25153.49 | BU9: 19822.53 | BV9: 18546.71 | BW9: 7177.45 | BX9: 8561.54 | BY9: 29246.17 | BZ9: 29094.24 | CA9: 40737.2 | CB9: 35946.4 | CC9: 73523.52 | CD9: 63549.36 | CE9: 58530.99 | CF9: 49745.15 | CG9: 73384.08 | CH9: 66821.86 | CI9: 57231.86 | CJ9: 44134.72 | CK9: 77625.45 | CL9: 61513.2
B10: AM-Early | C10: 0.43 | D10: 0.3 | E10: 0.26 | F10: 0.2 | G10: 0.48 | H10: 0.23 | I10: 0.32 | J10: 0.67 | K10: 0.42 | L10: 0.5 | M10: 0.66 | N10: 0.52 | O10: 0.72 | P10: 0.59 | Q10: 0.67 | R10: 0.44 | S10: 0.62 | T10: 0.43 | U10: 0.4 | V10: 0.24 | X10: AM-Early | Y10: 2180.59 | Z10: 1352.9 | AA10: 2232.63 | AB10: 1451.09 | AC10: 571.87 | AD10: 710.28 | AE10: 3000.94 | AF10: 2110.19 | AG10: 3501.89 | AH10: 2438.28 | AI10: 5951.35 | AJ10: 4414.2 | AK10: 4274.75 | AL10: 3791.29 | AM10: 5285.56 | AN10: 4747.29 | AO10: 4599.41 | AP10: 3507.33 | AQ10: 6944.86 | AR10: 4413.2 | AU10: AM-Early | AV10: 8151.91 | AW10: 5359.81 | AX10: 7358.38 | AY10: 4921.75 | AZ10: 1948.83 | BA10: 2388.67 | BB10: 10244.64 | BC10: 7465.49 | BD10: 13045.78 | BE10: 9323.32 | BF10: 22987.66 | BG10: 17111.64 | BH10: 16305.97 | BI10: 14689.54 | BJ10: 20492.32 | BK10: 18353.82 | BL10: 17761.25 | BM10: 13880.26 | BN10: 28339.28 | BO10: 18018.15 | BR10: AM-Early | BS10: 10332.5 | BT10: 6712.72 | BU10: 9591.01 | BV10: 6372.85 | BW10: 2520.7 | BX10: 3098.95 | BY10: 13245.58 | BZ10: 9575.68 | CA10: 16547.67 | CB10: 11761.6 | CC10: 28939.01 | CD10: 21525.84 | CE10: 20580.72 | CF10: 18480.83 | CG10: 25777.87 | CH10: 23101.11 | CI10: 22360.66 | CJ10: 17387.59 | CK10: 35284.14 | CL10: 22431.35
B11: AM-Peak | C11: 3.6 | D11: 0.37 | E11: 3.19 | F11: 0.57 | G11: 1.8 | H11: 2.86 | I11: 1.8 | J11: 1.04 | K11: 1.8 | L11: 0.99 | M11: 1.8 | N11: 1.05 | O11: 1.8 | P11: 1.09 | Q11: 1.8 | R11: 1.01 | S11: 1.19 | T11: 0.84 | U11: 0.82 | V11: 0.73 | X11: AM-Peak | Y11: 7116.39 | Z11: 3383.64 | AA11: 7550.9 | AB11: 2313.36 | AC11: 3020.6 | AD11: 3082.23 | AE11: 10892.32 | AF11: 7194.6 | AG11: 13965.61 | AH11: 8033.16 | AI11: 25121.24 | AJ11: 14123.23 | AK11: 19269.65 | AL11: 11448.3 | AM11: 24439.69 | AN11: 14503.15 | AO11: 14225.15 | AP11: 11429.6 | AQ11: 14840.79 | AR11: 13293.79 | AU11: AM-Peak | AV11: 29600.12 | AW11: 13741.24 | AX11: 27743.19 | AY11: 12168 | AZ11: 7797.45 | BA11: 10906.04 | BB11: 35342.33 | BC11: 26642.27 | BD11: 45554.39 | BE11: 32355.31 | BF11: 82014.76 | BG11: 58729.97 | BH11: 60804.42 | BI11: 48008.44 | BJ11: 75324.61 | BK11: 60315.29 | BL11: 59122.88 | BM11: 48065.11 | BN11: 62321.98 | BO11: 56375.91 | BR11: AM-Peak | BS11: 36716.51 | BT11: 17124.88 | BU11: 35294.09 | BV11: 14481.36 | BW11: 10818.04 | BX11: 13988.27 | BY11: 46234.65 | BZ11: 33836.87 | CA11: 59520 | CB11: 40388.47 | CC11: 107136 | CD11: 72853.2 | CE11: 80074.06 | CF11: 59456.74 | CG11: 99764.3 | CH11: 74818.44 | CI11: 73348.03 | CJ11: 59494.71 | CK11: 77162.77 | CL11: 69669.7
B12: AM-Shoulder | C12: 1.79 | D12: 0.57 | E12: 1.45 | F12: 0.21 | G12: 1.73 | H12: 1.46 | I12: 1.4 | J12: 0.89 | K12: 1.45 | L12: 0.76 | M12: 1.56 | N12: 0.75 | O12: 1.53 | P12: 0.77 | Q12: 1.26 | R12: 0.69 | S12: 0.67 | T12: 0.64 | U12: 0.61 | V12: 0.58 | X12: AM-Shoulder | Y12: 2064.78 | Z12: 1194.79 | AA12: 2281.54 | AB12: 1335.21 | AC12: 699.87 | AD12: 916.9 | AE12: 2868.03 | AF12: 2384.9 | AG12: 3325.34 | AH12: 2689.6 | AI12: 5790.82 | AJ12: 4606.2 | AK12: 4690.39 | AL12: 3697.55 | AM12: 5782.66 | AN12: 4651.43 | AO12: 4207.7 | AP12: 3740 | AQ12: 4986.64 | AR12: 4650.07 | AU12: AM-Shoulder | AV12: 8762.07 | AW12: 5212.99 | AX12: 7988.37 | AY12: 4658.24 | AZ12: 2675.71 | BA12: 3403.1 | BB12: 10955.97 | BC12: 9328.66 | BD12: 13954.66 | BE12: 11172.33 | BF12: 25313.18 | BG12: 19691.6 | BH12: 20365.61 | BI12: 15990.05 | BJ12: 25122.91 | BK12: 19872.89 | BL12: 17669.34 | BM12: 16733.79 | BN12: 21793.58 | BO12: 20760.12 | BR12: AM-Shoulder | BS12: 10826.85 | BT12: 6407.78 | BU12: 10269.92 | BV12: 5993.46 | BW12: 3375.58 | BX12: 4320 | BY12: 13824 | BZ12: 11713.56 | CA12: 17280 | CB12: 13861.93 | CC12: 31104 | CD12: 24297.8 | CE12: 25056 | CF12: 19687.61 | CG12: 30905.58 | CH12: 24524.32 | CI12: 21877.04 | CJ12: 20473.79 | CK12: 26780.22 | CL12: 25410.19
B13: MD | C13: 1.75 | D13: 1.4 | E13: 1.27 | F13: 0.29 | G13: 1.58 | H13: 1.48 | I13: 0.38 | J13: 1.29 | K13: 1 | L13: 1.2 | M13: 0.88 | N13: 0.74 | O13: 0.76 | P13: 0.66 | Q13: 0.69 | R13: 0.63 | S13: 0.64 | T13: 0.5 | U13: 0.56 | V13: 0.33 | X13: MD | Y13: 7365.65 | Z13: 9482.77 | AA13: 10985.64 | AB13: 11776.81 | AC13: 2982.34 | AD13: 3372.71 | AE13: 12497.27 | AF13: 12541.51 | AG13: 16137.7 | AH13: 16213.42 | AI13: 26872.9 | AJ13: 26993.23 | AK13: 20636.99 | AL13: 21462.37 | AM13: 25277.39 | AN13: 24527.42 | AO13: 21029.61 | AP13: 20406.53 | AQ13: 26334.65 | AR13: 29251.32 | AU13: MD | AV13: 29775.12 | AW13: 38675.08 | AX13: 36970.3 | AY13: 39113.22 | AZ13: 10708.44 | BA13: 11892.72 | BB13: 44215.45 | BC13: 45815.29 | BD13: 63273.42 | BE13: 64683.58 | BF13: 107821.88 | BG13: 108758.54 | BH13: 82146.85 | BI13: 85707.13 | BJ13: 102506.63 | BK13: 98596.92 | BL13: 85419.29 | BM13: 82804.89 | BN13: 110409.78 | BO13: 122977.15 | BR13: MD | BS13: 37140.77 | BT13: 48157.85 | BU13: 47955.94 | BV13: 50890.03 | BW13: 13690.78 | BX13: 15265.44 | BY13: 56712.72 | BZ13: 58356.8 | CA13: 79411.12 | CB13: 80897 | CC13: 134694.79 | CD13: 135751.77 | CE13: 102783.84 | CF13: 107169.5 | CG13: 127784.01 | CH13: 123124.34 | CI13: 106448.9 | CJ13: 103211.42 | CK13: 136744.43 | CL13: 152228.48
B14: PM-Shoulder | C14: 1.8 | D14: 1.77 | E14: 1.39 | F14: 1.29 | G14: 1.8 | H14: 1.8 | I14: 0.66 | J14: 1.8 | K14: 0.56 | L14: 1.22 | M14: 0.67 | N14: 1.15 | O14: 0.67 | P14: 1.07 | Q14: 0.67 | R14: 1.08 | S14: 0.63 | T14: 0.88 | U14: 0.57 | V14: 0.45 | X14: PM-Shoulder | Y14: 1844.73 | Z14: 1896.79 | AA14: 2561.09 | AB14: 2640.62 | AC14: 634.88 | AD14: 700.81 | AE14: 2366.42 | AF14: 1877.38 | AG14: 2967.64 | AH14: 3693.08 | AI14: 5695.66 | AJ14: 6922.15 | AK14: 4537.07 | AL14: 5494.39 | AM14: 5849.58 | AN14: 7090.72 | AO14: 4955.22 | AP14: 6082.54 | AQ14: 5949.76 | AR14: 5858.61 | AU14: PM-Shoulder | AV14: 6891.46 | AW14: 7006.28 | AX14: 8670.91 | AY14: 8591.38 | AZ14: 2175.43 | BA14: 2488.59 | BB14: 8231.12 | BC14: 6793.63 | BD14: 10335.9 | BE14: 13156.86 | BF14: 20042.2 | BG14: 24181.85 | BH14: 16044.19 | BI14: 19074.73 | BJ14: 20890.53 | BK14: 24976.21 | BL14: 18047.29 | BM14: 21099.31 | BN14: 22251.93 | BO14: 20512.85 | BR14: PM-Shoulder | BS14: 8736.19 | BT14: 8903.07 | BU14: 11232 | BV14: 11232 | BW14: 2810.3 | BX14: 3189.4 | BY14: 10597.55 | BZ14: 8671.01 | CA14: 13303.53 | CB14: 16849.94 | CC14: 25737.86 | CD14: 31104 | CE14: 20581.26 | CF14: 24569.11 | CG14: 26740.1 | CH14: 32066.92 | CI14: 23002.51 | CJ14: 27181.85 | CK14: 28201.69 | CL14: 26371.46
B15: PM-Peak | C15: 3.4 | D15: 3.35 | E15: 1.75 | F15: 2.82 | G15: 1.8 | H15: 3.5 | I15: 1.35 | J15: 1.8 | K15: 0.99 | L15: 1.8 | M15: 1.1 | N15: 1.8 | O15: 1.12 | P15: 1.8 | Q15: 1.27 | R15: 1.51 | S15: 1 | T15: 1.02 | U15: 0.92 | V15: 0.87 | X15: PM-Peak | Y15: 7067.85 | Z15: 7429.24 | AA15: 7398.72 | AB15: 8755.63 | AC15: 3049.06 | AD15: 2700.91 | AE15: 7816.12 | AF15: 9560.54 | AG15: 9446.12 | AH15: 14441.98 | AI15: 17510.82 | AJ15: 26004.61 | AK15: 14053.72 | AL15: 19719.73 | AM15: 18944.06 | AN15: 20485.26 | AO15: 14815.44 | AP15: 15304.78 | AQ15: 18190.45 | AR15: 18137.85 | AU15: PM-Peak | AV15: 26318.28 | AW15: 27975.49 | AX15: 25167.18 | AY15: 29932.37 | AZ15: 7176.37 | BA15: 9968.27 | BB15: 28049.53 | BC15: 23646.22 | BD15: 33824.29 | BE15: 45078.02 | BF15: 63399.64 | BG15: 81131.39 | BH15: 51254.35 | BI15: 64194.82 | BJ15: 70426.68 | BK15: 75563.84 | BL15: 55863.94 | BM15: 56850.2 | BN15: 69534.42 | BO15: 68138.82 | BR15: PM-Peak | BS15: 33386.12 | BT15: 35404.74 | BU15: 32565.9 | BV15: 38688 | BW15: 10225.43 | BX15: 12669.18 | BY15: 35865.65 | BZ15: 33206.76 | CA15: 43270.41 | CB15: 59520 | CC15: 80910.47 | CD15: 107136 | CE15: 65308.07 | CF15: 83914.55 | CG15: 89370.74 | CH15: 96049.1 | CI15: 70679.38 | CJ15: 72154.98 | CK15: 87724.87 | CL15: 86276.67
B16: PM-Late | C16: 0.73 | D16: 0.93 | E16: 0.3 | F16: 0.22 | G16: 0.2 | H16: 0.27 | I16: 0.78 | J16: 1.46 | K16: 0.78 | L16: 1.28 | M16: 1.16 | N16: 1.27 | O16: 1.3 | P16: 1.13 | Q16: 1.15 | R16: 1 | S16: 1.05 | T16: 0.84 | U16: 0.88 | V16: 0.68 | X16: PM-Late | Y16: 3666.39 | Z16: 4609.15 | AA16: 2985.45 | AB16: 3595.84 | AC16: 220.23 | AD16: 1436.97 | AE16: 1220.21 | AF16: 4883.98 | AG16: 4637.16 | AH16: 6256.84 | AI16: 8117.84 | AJ16: 11623.95 | AK16: 6479.29 | AL16: 8819.32 | AM16: 8089.91 | AN16: 8978.93 | AO16: 6850.96 | AP16: 6928.46 | AQ16: 9383.46 | AR16: 9599.92 | AU16: PM-Late | AV16: 14523.21 | AW16: 17664.53 | AX16: 12168 | AY16: 12556.85 | AZ16: 4206.53 | BA16: 5389.35 | BB16: 14976 | BC16: 18496.59 | BD16: 18893.04 | BE16: 23477.42 | BF16: 33233.2 | BG16: 43591.25 | BH16: 26797.34 | BI16: 33808.94 | BJ16: 33523.51 | BK16: 35956.45 | BL16: 28106.48 | BM16: 28683.82 | BN16: 39047.79 | BO16: 41416.58 | BR16: PM-Late | BS16: 18189.6 | BT16: 22273.68 | BU16: 15153.45 | BV16: 16152.69 | BW16: 4426.76 | BX16: 6826.32 | BY16: 16196.21 | BZ16: 23380.57 | CA16: 23530.2 | CB16: 29734.25 | CC16: 41351.04 | CD16: 55215.2 | CE16: 33276.63 | CF16: 42628.26 | CG16: 41613.42 | CH16: 44935.38 | CI16: 34957.44 | CJ16: 35612.28 | CK16: 48431.25 | CL16: 51016.5
B19: CaptureRateLights | X19: ML Volume (PCE/Period) | AU19: GP Volume (PCE/Period) | BR19: Highway Volume
B20: Direction | C20: NB | D20: SB | E20: NB | F20: SB | G20: NB | H20: SB | I20: NB | J20: SB | K20: NB | L20: SB | M20: NB | N20: SB | O20: NB | P20: SB | Q20: NB | R20: SB | S20: NB | T20: SB | U20: NB | V20: SB | X20: Direction | Y20: NB | Z20: SB | AA20: NB | AB20: SB | AC20: NB | AD20: SB | AE20: NB | AF20: SB | AG20: NB | AH20: SB | AI20: NB | AJ20: SB | AK20: NB | AL20: SB | AM20: NB | AN20: SB | AO20: NB | AP20: SB | AQ20: NB | AR20: SB | AU20: Direction | AV20: NB | AW20: SB | AX20: NB | AY20: SB | AZ20: NB | BA20: SB | BB20: NB | BC20: SB | BD20: NB | BE20: SB | BF20: NB | BG20: SB | BH20: NB | BI20: SB | BJ20: NB | BK20: SB | BL20: NB | BM20: SB | BN20: NB | BO20: SB | BR20: Direction | BS20: NB | BT20: SB | BU20: NB | BV20: SB | BW20: NB | BX20: SB | BY20: NB | BZ20: SB | CA20: NB | CB20: SB | CC20: NB | CD20: SB | CE20: NB | CF20: SB | CG20: NB | CH20: SB | CI20: NB | CJ20: SB | CK20: NB | CL20: SB
B21: Segment | C21: 1 | D21: 1 | E21: 2 | F21: 2 | G21: 3 | H21: 3 | I21: 4 | J21: 4 | K21: 5 | L21: 5 | M21: 6 | N21: 6 | O21: 7 | P21: 7 | Q21: 8 | R21: 8 | S21: 9 | T21: 9 | U21: 10 | V21: 10 | X21: Segment | Y21: 1 | Z21: 1 | AA21: 2 | AB21: 2 | AC21: 3 | AD21: 3 | AE21: 4 | AF21: 4 | AG21: 5 | AH21: 5 | AI21: 6 | AJ21: 6 | AK21: 7 | AL21: 7 | AM21: 8 | AN21: 8 | AO21: 9 | AP21: 9 | AQ21: 10 | AR21: 10 | AU21: Segment | AV21: 1 | AW21: 1 | AX21: 2 | AY21: 2 | AZ21: 3 | BA21: 3 | BB21: 4 | BC21: 4 | BD21: 5 | BE21: 5 | BF21: 6 | BG21: 6 | BH21: 7 | BI21: 7 | BJ21: 8 | BK21: 8 | BL21: 9 | BM21: 9 | BN21: 10 | BO21: 10 | BR21: Segment | BS21: 1 | BT21: 1 | BU21: 2 | BV21: 2 | BW21: 3 | BX21: 3 | BY21: 4 | BZ21: 4 | CA21: 5 | CB21: 5 | CC21: 6 | CD21: 6 | CE21: 7 | CF21: 7 | CG21: 8 | CH21: 8 | CI21: 9 | CJ21: 9 | CK21: 10 | CL21: 10
B22: Period | X22: Period | AU22: Period | BR22: Period
B23: Night | C23: 0.07 | D23: 0.07 | E23: 0.07 | F23: 0.07 | G23: 0.07 | H23: 0.07 | I23: 0.05 | J23: 0.1 | K23: 0.1 | L23: 0.1 | M23: 0.1 | N23: 0.1 | O23: 0.1 | P23: 0.1 | Q23: 0.1 | R23: 0.1 | S23: 0.1 | T23: 0.1 | U23: 0.1 | V23: 0.1 | X23: Night | Y23: 1186.26 | Z23: 1178.96 | AA23: 971.21 | AB23: 905.45 | AC23: 860.45 | AD23: 1060.34 | AE23: 866.26 | AF23: 1731.24 | AG23: 1938.58 | AH23: 1706.81 | AI23: 1962.1 | AJ23: 1682.31 | AK23: 1916.46 | AL23: 1647.52 | AM23: 1855.56 | AN23: 1690.64 | AO23: 1623.86 | AP23: 1238.65 | AQ23: 1654.45 | AR23: 1312.15 | AU23: Night | AV23: 18289.59 | AW23: 18169.88 | AX23: 14276.89 | AY23: 13361.25 | AZ23: 13494.45 | BA23: 16062.74 | BB23: 17412.59 | BC23: 16452.66 | BD23: 18430.02 | BE23: 16266.39 | BF23: 18461.1 | BG23: 15970.29 | BH23: 18266.64 | BI23: 15505.98 | BJ23: 17456.04 | BK23: 15894.06 | BL23: 15209.04 | BM23: 11742.15 | BN23: 15595.65 | BO23: 12357.45 | BR23: Night | BS23: 19475.86 | BT23: 19348.84 | BU23: 15248.1 | BV23: 14266.7 | BW23: 14354.9 | BX23: 17123.08 | BY23: 18278.85 | BZ23: 18183.9 | CA23: 20368.6 | CB23: 17973.2 | CC23: 20423.2 | CD23: 17652.6 | CE23: 20183.1 | CF23: 17153.5 | CG23: 19311.6 | CH23: 17584.7 | CI23: 16832.9 | CJ23: 12980.8 | CK23: 17250.1 | CL23: 13669.6
B24: AM-Early | C24: 0.23 | D24: 0.23 | E24: 0.24 | F24: 0.25 | G24: 0.25 | H24: 0.25 | I24: 0.24 | J24: 0.25 | K24: 0.23 | L24: 0.23 | M24: 0.22 | N24: 0.23 | O24: 0.23 | P24: 0.23 | Q24: 0.22 | R24: 0.23 | S24: 0.23 | T24: 0.23 | U24: 0.22 | V24: 0.23 | X24: AM-Early | Y24: 1677.38 | Z24: 1040.7 | AA24: 1717.41 | AB24: 1116.23 | AC24: 1143.73 | AD24: 1420.55 | AE24: 1875.59 | AF24: 1318.87 | AG24: 1750.94 | AH24: 1219.14 | AI24: 1653.15 | AJ24: 1226.17 | AK24: 1474.05 | AL24: 1307.34 | AM24: 1390.94 | AN24: 1249.29 | AO24: 1352.77 | AP24: 1031.57 | AQ24: 1543.3 | AR24: 980.71 | AU24: AM-Early | AV24: 6270.7 | AW24: 4122.93 | AX24: 5660.29 | AY24: 3785.96 | AZ24: 3897.67 | BA24: 4777.34 | BB24: 6402.9 | BC24: 4665.93 | BD24: 6522.89 | BE24: 4661.66 | BF24: 6385.46 | BG24: 4753.23 | BH24: 5622.75 | BI24: 5065.36 | BJ24: 5392.71 | BK24: 4829.95 | BL24: 5223.9 | BM24: 4082.43 | BN24: 6297.62 | BO24: 4004.03 | BR24: AM-Early | BS24: 7948.08 | BT24: 5163.63 | BU24: 7377.7 | BV24: 4902.19 | BW24: 5041.4 | BX24: 6197.9 | BY24: 8278.49 | BZ24: 5984.8 | CA24: 8273.83 | CB24: 5880.8 | CC24: 8038.62 | CD24: 5979.4 | CE24: 7096.8 | CF24: 6372.7 | CG24: 6783.65 | CH24: 6079.24 | CI24: 6576.67 | CJ24: 5114 | CK24: 7840.92 | CL24: 4984.74
B25: AM-Peak | C25: 0.22 | D25: 0.23 | E25: 0.22 | F25: 0.17 | G25: 0.33 | H25: 0.24 | I25: 0.26 | J25: 0.24 | K25: 0.26 | L25: 0.23 | M25: 0.26 | N25: 0.22 | O25: 0.28 | P25: 0.23 | Q25: 0.28 | R25: 0.22 | S25: 0.22 | T25: 0.23 | U25: 0.23 | V25: 0.23 | X25: AM-Peak | Y25: 5474.15 | Z25: 2602.8 | AA25: 5808.39 | AB25: 1779.51 | AC25: 6041.19 | AD25: 6164.47 | AE25: 6807.7 | AF25: 4496.62 | AG25: 6982.81 | AH25: 4016.58 | AI25: 6978.12 | AJ25: 3923.12 | AK25: 6644.71 | AL25: 3947.69 | AM25: 6431.5 | AN25: 3816.62 | AO25: 4183.87 | AP25: 3361.65 | AQ25: 3297.95 | AR25: 2954.18 | AU25: AM-Peak | AV25: 22769.32 | AW25: 10570.19 | AX25: 21340.92 | AY25: 9360 | AZ25: 15594.9 | BA25: 21812.08 | BB25: 22088.95 | BC25: 16651.42 | BD25: 22777.19 | BE25: 16177.65 | BF25: 22781.88 | BG25: 16313.88 | BH25: 20967.04 | BI25: 16554.63 | BJ25: 19822.27 | BK25: 15872.45 | BL25: 17389.08 | BM25: 14136.8 | BN25: 13849.33 | BO25: 12527.98 | BR25: AM-Peak | BS25: 28243.47 | BT25: 13172.98 | BU25: 27149.3 | BV25: 11139.51 | BW25: 21636.09 | BX25: 27976.55 | BY25: 28896.66 | BZ25: 21148.05 | CA25: 29760 | CB25: 20194.24 | CC25: 29760 | CD25: 20237 | CE25: 27611.75 | CF25: 20502.32 | CG25: 26253.76 | CH25: 19689.06 | CI25: 21572.95 | CJ25: 17498.45 | CK25: 17147.28 | CL25: 15482.16
B26: AM-Shoulder | C26: 0.23 | D26: 0.23 | E26: 0.24 | F26: 0.25 | G26: 0.25 | H26: 0.25 | I26: 0.24 | J26: 0.24 | K26: 0.22 | L26: 0.23 | M26: 0.21 | N26: 0.23 | O26: 0.22 | P26: 0.23 | Q26: 0.22 | R26: 0.23 | S26: 0.23 | T26: 0.23 | U26: 0.23 | V26: 0.23 | X26: AM-Shoulder | Y26: 1588.29 | Z26: 919.07 | AA26: 1755.03 | AB26: 1027.09 | AC26: 1399.73 | AD26: 1833.8 | AE26: 1792.52 | AF26: 1490.56 | AG26: 1662.67 | AH26: 1344.8 | AI26: 1608.56 | AJ26: 1279.5 | AK26: 1617.37 | AL26: 1275.02 | AM26: 1521.75 | AN26: 1224.06 | AO26: 1237.56 | AP26: 1100 | AQ26: 1108.14 | AR26: 1033.35 | AU26: AM-Shoulder | AV26: 6740.05 | AW26: 4009.99 | AX26: 6144.9 | AY26: 3583.26 | AZ26: 5351.42 | BA26: 6806.2 | BB26: 6847.48 | BC26: 5830.41 | BD26: 6977.33 | BE26: 5586.16 | BF26: 7031.44 | BG26: 5469.89 | BH26: 7022.63 | BI26: 5513.81 | BJ26: 6611.29 | BK26: 5229.71 | BL26: 5196.86 | BM26: 4921.7 | BN26: 4843.02 | BO26: 4613.36 | BR26: AM-Shoulder | BS26: 8328.34 | BT26: 4929.06 | BU26: 7899.94 | BV26: 4610.35 | BW26: 6751.15 | BX26: 8640 | BY26: 8640 | BZ26: 7320.97 | CA26: 8640 | CB26: 6930.96 | CC26: 8640 | CD26: 6749.39 | CE26: 8640 | CF26: 6788.83 | CG26: 8133.05 | CH26: 6453.77 | CI26: 6434.42 | CJ26: 6021.7 | CK26: 5951.16 | CL26: 5646.71
B27: MD | C27: 0.23 | D27: 0.23 | E27: 0.24 | F27: 0.25 | G27: 0.25 | H27: 0.25 | I27: 0.25 | J27: 0.24 | K27: 0.23 | L27: 0.23 | M27: 0.22 | N27: 0.23 | O27: 0.23 | P27: 0.23 | Q27: 0.23 | R27: 0.23 | S27: 0.23 | T27: 0.23 | U27: 0.23 | V27: 0.23 | X27: MD | Y27: 5665.88 | Z27: 7294.44 | AA27: 8450.49 | AB27: 9059.09 | AC27: 5964.67 | AD27: 6745.43 | AE27: 7810.79 | AF27: 7838.44 | AG27: 8068.85 | AH27: 8106.71 | AI27: 7464.7 | AJ27: 7498.12 | AK27: 7116.2 | AL27: 7400.82 | AM27: 6651.94 | AN27: 6454.58 | AO27: 6185.18 | AP27: 6001.92 | AQ27: 5852.14 | AR27: 6500.29 | AU27: MD | AV27: 22903.94 | AW27: 29750.06 | AX27: 28438.69 | AY27: 30087.09 | AZ27: 21416.89 | BA27: 23785.45 | BB27: 27634.66 | BC27: 28634.56 | BD27: 31636.71 | BE27: 32341.79 | BF27: 29950.52 | BG27: 30210.71 | BH27: 28326.5 | BI27: 29554.18 | BJ27: 26975.43 | BK27: 25946.56 | BL27: 25123.32 | BM27: 24354.38 | BN27: 24535.51 | BO27: 27328.26 | BR27: MD | BS27: 28569.82 | BT27: 37044.5 | BU27: 36889.18 | BV27: 39146.17 | BW27: 27381.56 | BX27: 30530.87 | BY27: 35445.45 | BZ27: 36473 | CA27: 39705.56 | CB27: 40448.5 | CC27: 37415.22 | CD27: 37708.83 | CE27: 35442.7 | CF27: 36955 | CG27: 33627.37 | CH27: 32401.14 | CI27: 31308.5 | CJ27: 30356.3 | CK27: 30387.65 | CL27: 33828.55
B28: PM-Shoulder | C28: 0.25 | D28: 0.24 | E28: 0.24 | F28: 0.24 | G28: 0.26 | H28: 0.25 | I28: 0.24 | J28: 0.24 | K28: 0.24 | L28: 0.24 | M28: 0.24 | N28: 0.24 | O28: 0.24 | P28: 0.24 | Q28: 0.24 | R28: 0.24 | S28: 0.24 | T28: 0.24 | U28: 0.24 | V28: 0.24 | X28: PM-Shoulder | Y28: 1419.02 | Z28: 1459.07 | AA28: 1970.07 | AB28: 2031.25 | AC28: 1269.76 | AD28: 1401.61 | AE28: 1479.02 | AF28: 1173.36 | AG28: 1483.82 | AH28: 1846.54 | AI28: 1582.13 | AJ28: 1922.82 | AK28: 1564.51 | AL28: 1894.62 | AM28: 1539.36 | AN28: 1865.98 | AO28: 1457.42 | AP28: 1788.98 | AQ28: 1322.17 | AR28: 1301.91 | AU28: PM-Shoulder | AV28: 5301.12 | AW28: 5389.45 | AX28: 6669.93 | AY28: 6608.75 | AZ28: 4350.85 | BA28: 4977.18 | BB28: 5144.45 | BC28: 4246.02 | BD28: 5167.95 | BE28: 6578.43 | BF28: 5567.28 | BG28: 6717.18 | BH28: 5532.48 | BI28: 6577.49 | BJ28: 5497.51 | BK28: 6572.69 | BL28: 5308.03 | BM28: 6205.68 | BN28: 4944.87 | BO28: 4558.41 | BR28: PM-Shoulder | BS28: 6720.14 | BT28: 6848.52 | BU28: 8640 | BV28: 8640 | BW28: 5620.61 | BX28: 6378.79 | BY28: 6623.47 | BZ28: 5419.38 | CA28: 6651.77 | CB28: 8424.97 | CC28: 7149.41 | CD28: 8640 | CE28: 7096.99 | CF28: 8472.11 | CG28: 7036.87 | CH28: 8438.66 | CI28: 6765.44 | CJ28: 7994.66 | CK28: 6267.04 | CL28: 5860.32
B29: PM-Peak | C29: 0.24 | D29: 0.24 | E29: 0.24 | F29: 0.24 | G29: 0.34 | H29: 0.24 | I29: 0.24 | J29: 0.34 | K29: 0.24 | L29: 0.28 | M29: 0.24 | N29: 0.27 | O29: 0.24 | P29: 0.27 | Q29: 0.24 | R29: 0.24 | S29: 0.24 | T29: 0.24 | U29: 0.24 | V29: 0.24 | X29: PM-Peak | Y29: 5436.8 | Z29: 5714.8 | AA29: 5691.32 | AB29: 6735.1 | AC29: 6098.13 | AD29: 5401.82 | AE29: 4885.07 | AF29: 5975.34 | AG29: 4723.06 | AH29: 7220.99 | AI29: 4864.12 | AJ29: 7223.5 | AK29: 4846.11 | AL29: 6799.91 | AM29: 4985.28 | AN29: 5390.86 | AO29: 4357.48 | AP29: 4501.41 | AQ29: 4042.32 | AR29: 4030.63 | AU29: PM-Peak | AV29: 20244.83 | AW29: 21519.61 | AX29: 19359.37 | AY29: 23024.9 | AZ29: 14352.73 | BA29: 19936.55 | BB29: 17530.96 | BC29: 14778.89 | BD29: 16912.15 | BE29: 22539.01 | BF29: 17611.01 | BG29: 22536.5 | BH29: 17673.91 | BI29: 22136.15 | BJ29: 18533.34 | BK29: 19885.22 | BL29: 16430.57 | BM29: 16720.65 | BN29: 15452.09 | BO29: 15141.96 | BR29: PM-Peak | BS29: 25681.63 | BT29: 27234.41 | BU29: 25050.69 | BV29: 29760 | BW29: 20450.86 | BX29: 25338.37 | BY29: 22416.03 | BZ29: 20754.23 | CA29: 21635.2 | CB29: 29760 | CC29: 22475.13 | CD29: 29760 | CE29: 22520.02 | CF29: 28936.05 | CG29: 23518.62 | CH29: 25276.08 | CI29: 20788.05 | CJ29: 21222.05 | CK29: 19494.42 | CL29: 19172.59
