Workbook

Sheet Year_2025
B1: Lenght
C2: 16
B3: Length | C3: 2.6
B5: TollLights | F5: ML PCE.Miles | K5: GP PCE.Miles | P5: Highway PCE.Miles
B6: Direction | C6: NB | D6: SB | F6: Direction | G6: NB | H6: SB | K6: Direction | L6: NB | M6: SB | P6: Direction | Q6: NB | R6: SB
B7: Segment | C7: 16 | D7: 16 | F7: Segment | G7: 16 | H7: 16 | K7: Segment | L7: 16 | M7: 16 | P7: Segment | Q7: 16 | R7: 16
B8: Period | F8: Period | K8: Period | P8: Period
B9: Night | C9: 0.2 | D9: 0.2 | F9: Night | G9: 1552.65 | H9: 1850.67 | K9: Night | L9: 28004.15 | M9: 33266.23 | P9: Night | Q9: 29556.8 | R9: 35116.9
B10: AM-Early | C10: 0.62 | D10: 0.66 | F10: AM-Early | G10: 1444.61 | H10: 1574.93 | K10: AM-Early | L10: 9953.79 | M10: 13313.97 | P10: AM-Early | Q10: 11398.4 | R10: 14888.9
B11: AM-Peak | C11: 0.68 | D11: 0.77 | F11: AM-Peak | G11: 3296.65 | H11: 3684.87 | K11: AM-Peak | L11: 24397.25 | M11: 27203.13 | P11: AM-Peak | Q11: 27693.9 | R11: 30888
B12: AM-Shoulder | C12: 0.56 | D12: 0.49 | F12: AM-Shoulder | G12: 1370.29 | H12: 620.1 | K12: AM-Shoulder | L12: 9857.81 | M12: 8112 | P12: AM-Shoulder | Q12: 11228.1 | R12: 8732.1
B13: MD | C13: 0.66 | D13: 0.56 | F13: MD | G13: 8102.78 | H13: 7158.83 | K13: MD | L13: 70566.72 | M13: 59999.17 | P13: MD | Q13: 78669.5 | R13: 67158
B14: PM-Shoulder | C14: 0.58 | D14: 0.47 | F14: PM-Shoulder | G14: 1512.51 | H14: 1280.97 | K14: PM-Shoulder | L14: 10560.59 | M14: 8468.03 | P14: PM-Shoulder | Q14: 12073.1 | R14: 9749
B15: PM-Peak | C15: 0.8 | D15: 0.8 | F15: PM-Peak | G15: 5116.43 | H15: 4514.77 | K15: PM-Peak | L15: 30742.49 | M15: 29389.86 | P15: PM-Peak | Q15: 35858.92 | R15: 33904.64
B16: PM-Late | C16: 0.59 | D16: 0.6 | F16: PM-Late | G16: 4186.53 | H16: 3787.61 | K16: PM-Late | L16: 21884.97 | M16: 17369.89 | P16: PM-Late | Q16: 26071.5 | R16: 21157.5
B19: CaptureRateLights | F19: ML Volume (PCE/Period) | K19: GP Volume (PCE/Period) | P19: Highway Volume
B20: Direction | C20: NB | D20: SB | F20: Direction | G20: NB | H20: SB | K20: Direction | L20: NB | M20: SB | P20: Direction | Q20: NB | R20: SB
B21: Segment | C21: 16 | D21: 16 | F21: Segment | G21: 16 | H21: 16 | K21: Segment | L21: 16 | M21: 16 | P21: Segment | Q21: 16 | R21: 16
B22: Period | F22: Period | K22: Period | P22: Period
B23: Night | C23: 0.05 | D23: 0.05 | F23: Night | G23: 597.17 | H23: 711.79 | K23: Night | L23: 10770.83 | M23: 12794.71 | P23: Night | Q23: 11368 | R23: 13506.5
B24: AM-Early | C24: 0.15 | D24: 0.12 | F24: AM-Early | G24: 555.62 | H24: 605.74 | K24: AM-Early | L24: 3828.38 | M24: 5120.76 | P24: AM-Early | Q24: 4384 | R24: 5726.5
B25: AM-Peak | C25: 0.15 | D25: 0.15 | F25: AM-Peak | G25: 1267.94 | H25: 1417.26 | K25: AM-Peak | L25: 9383.56 | M25: 10462.74 | P25: AM-Peak | Q25: 10651.5 | R25: 11880
B26: AM-Shoulder | C26: 0.15 | D26: 0.08 | F26: AM-Shoulder | G26: 527.03 | H26: 238.5 | K26: AM-Shoulder | L26: 3791.47 | M26: 3120 | P26: AM-Shoulder | Q26: 4318.5 | R26: 3358.5
B27: MD | C27: 0.12 | D27: 0.13 | F27: MD | G27: 3116.45 | H27: 2753.4 | K27: MD | L27: 27141.05 | M27: 23076.6 | P27: MD | Q27: 30257.5 | R27: 25830
B28: PM-Shoulder | C28: 0.14 | D28: 0.15 | F28: PM-Shoulder | G28: 581.74 | H28: 492.68 | K28: PM-Shoulder | L28: 4061.76 | M28: 3256.93 | P28: PM-Shoulder | Q28: 4643.5 | R28: 3749.62
B29: PM-Peak | C29: 0.16 | D29: 0.16 | F29: PM-Peak | G29: 1967.86 | H29: 1736.45 | K29: PM-Peak | L29: 11824.03 | M29: 11303.79 | P29: PM-Peak | Q29: 13791.89 | R29: 13040.24
B30: PM-Late | C30: 0.19 | D30: 0.21 | F30: PM-Late | G30: 1610.2 | H30: 1456.77 | K30: PM-Late | L30: 8417.3 | M30: 6680.73 | P30: PM-Late | Q30: 10027.5 | R30: 8137.5
B33: Revenue Per Period | F33: ML Flow (PCE/hr) | K33: GP Flow (PCE/hr) | P33: Highway Flow
B34: Direction | C34: NB | D34: SB | F34: Direction | G34: NB | H34: SB | K34: Direction | L34: NB | M34: SB | P34: Direction | Q34: NB | R34: SB
B35: Segment | C35: 16 | D35: 16 | F35: Segment | G35: 16 | H35: 16 | K35: Segment | L35: 16 | M35: 16 | P35: Segment | Q35: 16 | R35: 16
B36: Period | F36: Period | K36: Period | P36: Period
B37: Night | C37: 407.24 | D37: 464.65 | F37: Night | G37: 85.31 | H37: 101.68 | K37: Night | L37: 1538.69 | M37: 1827.82 | P37: Night | Q37: 1624 | R37: 1929.5
B38: AM-Early | C38: 1001.49 | D38: 1124.88 | F38: AM-Early | G38: 555.62 | H38: 605.74 | K38: AM-Early | L38: 3828.38 | M38: 5120.76 | P38: AM-Early | Q38: 4384 | R38: 5726.5
B39: AM-Peak | C39: 2511.21 | D39: 3179.89 | F39: AM-Peak | G39: 422.65 | H39: 472.42 | K39: AM-Peak | L39: 3127.85 | M39: 3487.58 | P39: AM-Peak | Q39: 3550.5 | R39: 3960
B40: AM-Shoulder | C40: 862.31 | D40: 352.35 | F40: AM-Shoulder | G40: 527.03 | H40: 238.5 | K40: AM-Shoulder | L40: 3791.47 | M40: 3120 | P40: AM-Shoulder | Q40: 4318.5 | R40: 3358.5
B41: MD | C41: 5823.87 | D41: 4447.9 | F41: MD | G41: 623.29 | H41: 550.68 | K41: MD | L41: 5428.21 | M41: 4615.32 | P41: MD | Q41: 6051.5 | R41: 5166
B42: PM-Shoulder | C42: 922.55 | D42: 647.36 | F42: PM-Shoulder | G42: 581.74 | H42: 492.68 | K42: PM-Shoulder | L42: 4061.76 | M42: 3256.93 | P42: PM-Shoulder | Q42: 4643.5 | R42: 3749.62
B43: PM-Peak | C43: 4314.28 | D43: 3893.39 | F43: PM-Peak | G43: 655.95 | H43: 578.82 | K43: PM-Peak | L43: 3941.34 | M43: 3767.93 | P43: PM-Peak | Q43: 4597.3 | R43: 4346.75
B44: PM-Late | C44: 2669.5 | D44: 2426.63 | F44: PM-Late | G44: 536.73 | H44: 485.59 | K44: PM-Late | L44: 2805.77 | M44: 2226.91 | P44: PM-Late | Q44: 3342.5 | R44: 2712.5
B47: Revenue Per Period Lights | F47: ML V/C | K47: GP V/C real | P47: Highway Vol / GP Capacity
...

Sheet Year_2032
B1: Lenght
C2: 16
B3: Length | C3: 2.6
B5: TollLights | F5: ML PCE.Miles | K5: GP PCE.Miles | P5: Highway PCE.Miles
B6: Direction | C6: NB | D6: SB | F6: Direction | G6: NB | H6: SB | K6: Direction | L6: NB | M6: SB | P6: Direction | Q6: NB | R6: SB
B7: Segment | C7: 16 | D7: 16 | F7: Segment | G7: 16 | H7: 16 | K7: Segment | L7: 16 | M7: 16 | P7: Segment | Q7: 16 | R7: 16
B8: Period | F8: Period | K8: Period | P8: Period
B9: Night | C9: 0.2 | D9: 0.2 | F9: Night | G9: 1853.98 | H9: 2209.38 | K9: Night | L9: 34886.36 | M9: 41438.77 | P9: Night | Q9: 36740.34 | R9: 43648.15
B10: AM-Early | C10: 0.8 | D10: 0.8 | F10: AM-Early | G10: 2382.4 | H10: 2721.24 | K10: AM-Early | L10: 11785.91 | M10: 15785.95 | P10: AM-Early | Q10: 14168.31 | R10: 18507.19
B11: AM-Peak | C11: 0.8 | D11: 0.8 | F11: AM-Peak | G11: 5499.95 | H11: 6743.17 | K11: AM-Peak | L11: 28924.96 | M11: 31651.16 | P11: AM-Peak | Q11: 34424.91 | R11: 38394.33
B12: AM-Shoulder | C12: 0.8 | D12: 0.6 | F12: AM-Shoulder | G12: 2047.74 | H12: 1147.17 | K12: AM-Shoulder | L12: 11908.67 | M12: 9706.27 | P12: AM-Shoulder | Q12: 13956.41 | R12: 10853.44
B13: MD | C13: 0.8 | D13: 0.8 | F13: MD | G13: 13988.3 | H13: 10706.17 | K13: MD | L13: 83800.95 | M13: 72770.73 | P13: MD | Q13: 97789.25 | R13: 83476.9
B14: PM-Shoulder | C14: 0.8 | D14: 0.8 | F14: PM-Shoulder | G14: 2354.55 | H14: 1639.81 | K14: PM-Shoulder | L14: 12652 | M14: 10478.26 | P14: PM-Shoulder | Q14: 15006.55 | R14: 12118.07
B15: PM-Peak | C15: 0.8 | D15: 0.8 | F15: PM-Peak | G15: 2216.97 | H15: 2095.21 | K15: PM-Peak | L15: 42354.51 | M15: 40047.01 | P15: PM-Peak | Q15: 44571.48 | R15: 42142.23
B16: PM-Late | C16: 0.8 | D16: 0.8 | F16: PM-Late | G16: 6646.54 | H16: 6101.68 | K16: PM-Late | L16: 25758.95 | M16: 20196.02 | P16: PM-Late | Q16: 32405.49 | R16: 26297.7
B19: CaptureRateLights | F19: ML Volume (PCE/Period) | K19: GP Volume (PCE/Period) | P19: Highway Volume
B20: Direction | C20: NB | D20: SB | F20: Direction | G20: NB | H20: SB | K20: Direction | L20: NB | M20: SB | P20: Direction | Q20: NB | R20: SB
B21: Segment | C21: 16 | D21: 16 | F21: Segment | G21: 16 | H21: 16 | K21: Segment | L21: 16 | M21: 16 | P21: Segment | Q21: 16 | R21: 16
B22: Period | F22: Period | K22: Period | P22: Period
B23: Night | C23: 0.05 | D23: 0.05 | F23: Night | G23: 713.07 | H23: 849.76 | K23: Night | L23: 13417.83 | M23: 15937.99 | P23: Night | Q23: 14130.9 | R23: 16787.75
B24: AM-Early | C24: 0.2 | D24: 0.17 | F24: AM-Early | G24: 916.31 | H24: 1046.63 | K24: AM-Early | L24: 4533.04 | M24: 6071.52 | P24: AM-Early | Q24: 5449.35 | R24: 7118.15
B25: AM-Peak | C25: 0.2 | D25: 0.21 | F25: AM-Peak | G25: 2115.37 | H25: 2593.53 | K25: AM-Peak | L25: 11124.98 | M25: 12173.52 | P25: AM-Peak | Q25: 13240.35 | R25: 14767.05
B26: AM-Shoulder | C26: 0.18 | D26: 0.13 | F26: AM-Shoulder | G26: 787.59 | H26: 441.22 | K26: AM-Shoulder | L26: 4580.26 | M26: 3733.18 | P26: AM-Shoulder | Q26: 5367.85 | R26: 4174.4
B27: MD | C27: 0.17 | D27: 0.15 | F27: MD | G27: 5380.12 | H27: 4117.76 | K27: MD | L27: 32231.13 | M27: 27988.74 | P27: MD | Q27: 37611.25 | R27: 32106.5
B28: PM-Shoulder | C28: 0.18 | D28: 0.16 | F28: PM-Shoulder | G28: 905.59 | H28: 630.7 | K28: PM-Shoulder | L28: 4866.16 | M28: 4030.1 | P28: PM-Shoulder | Q28: 5771.75 | R28: 4660.79
B29: PM-Peak | C29: 0.05 | D29: 0.05 | F29: PM-Peak | G29: 852.68 | H29: 805.85 | K29: PM-Peak | L29: 16290.2 | M29: 15402.7 | P29: PM-Peak | Q29: 17142.88 | R29: 16208.55
B30: PM-Late | C30: 0.24 | D30: 0.26 | F30: PM-Late | G30: 2556.36 | H30: 2346.8 | K30: PM-Late | L30: 9907.29 | M30: 7767.7 | P30: PM-Late | Q30: 12463.65 | R30: 10114.5
B33: Revenue Per Period | F33: ML Flow (PCE/hr) | K33: GP Flow (PCE/hr) | P33: Highway Flow
B34: Direction | C34: NB | D34: SB | F34: Direction | G34: NB | H34: SB | K34: Direction | L34: NB | M34: SB | P34: Direction | Q34: NB | R34: SB
B35: Segment | C35: 16 | D35: 16 | F35: Segment | G35: 16 | H35: 16 | K35: Segment | L35: 16 | M35: 16 | P35: Segment | Q35: 16 | R35: 16
B36: Period | F36: Period | K36: Period | P36: Period
B37: Night | C37: 485.45 | D37: 553.82 | F37: Night | G37: 101.87 | H37: 121.39 | K37: Night | L37: 1916.83 | M37: 2276.86 | P37: Night | Q37: 2018.7 | R37: 2398.25
B38: AM-Early | C38: 2134.45 | D38: 2354.65 | F38: AM-Early | G38: 916.31 | H38: 1046.63 | K38: AM-Early | L38: 4533.04 | M38: 6071.52 | P38: AM-Early | Q38: 5449.35 | R38: 7118.15
B39: AM-Peak | C39: 4983.97 | D39: 6058.79 | F39: AM-Peak | G39: 705.12 | H39: 864.51 | K39: AM-Peak | L39: 3708.33 | M39: 4057.84 | P39: AM-Peak | Q39: 4413.45 | R39: 4922.35
B40: AM-Shoulder | C40: 1849.32 | D40: 774.12 | F40: AM-Shoulder | G40: 787.59 | H40: 441.22 | K40: AM-Shoulder | L40: 4580.26 | M40: 3733.18 | P40: AM-Shoulder | Q40: 5367.85 | R40: 4174.4
B41: MD | C41: 12229.69 | D41: 9486.04 | F41: MD | G41: 1076.02 | H41: 823.55 | K41: MD | L41: 6446.23 | M41: 5597.75 | P41: MD | Q41: 7522.25 | R41: 6421.3
B42: PM-Shoulder | C42: 1991.5 | D42: 1404.65 | F42: PM-Shoulder | G42: 905.59 | H42: 630.7 | K42: PM-Shoulder | L42: 4866.16 | M42: 4030.1 | P42: PM-Shoulder | Q42: 5771.75 | R42: 4660.79
B43: PM-Peak | C43: 1985.47 | D43: 1955.61 | F43: PM-Peak | G43: 284.23 | H43: 268.62 | K43: PM-Peak | L43: 5430.07 | M43: 5134.23 | P43: PM-Peak | Q43: 5714.29 | R43: 5402.85
B44: PM-Late | C44: 5795.13 | D44: 5239.02 | F44: PM-Late | G44: 852.12 | H44: 782.27 | K44: PM-Late | L44: 3302.43 | M44: 2589.23 | P44: PM-Late | Q44: 4154.55 | R44: 3371.5
B47: Revenue Per Period Lights | F47: ML V/C | K47: GP V/C real | P47: Highway Vol / GP Capacity
...

Sheet Year_2040
B1: Lenght
C2: 16
B3: Length | C3: 2.6
B5: TollLights | F5: ML PCE.Miles | K5: GP PCE.Miles | P5: Highway PCE.Miles
B6: Direction | C6: NB | D6: SB | F6: Direction | G6: NB | H6: SB | K6: Direction | L6: NB | M6: SB | P6: Direction | Q6: NB | R6: SB
B7: Segment | C7: 16 | D7: 16 | F7: Segment | G7: 16 | H7: 16 | K7: Segment | L7: 16 | M7: 16 | P7: Segment | Q7: 16 | R7: 16
B8: Period | F8: Period | K8: Period | P8: Period
B9: Night | C9: 0.2 | D9: 0.2 | F9: Night | G9: 2197.4 | H9: 6610.24 | K9: Night | L9: 40128.52 | M9: 43680 | P9: Night | Q9: 42325.92 | R9: 50290.24
B10: AM-Early | C10: 0.85 | D10: 1.14 | F10: AM-Early | G10: 3718.92 | H10: 3642.96 | K10: AM-Early | L10: 12603.1 | M10: 17677.69 | P10: AM-Early | Q10: 16322.02 | R10: 21320.65
B11: AM-Peak | C11: 0.8 | D11: 0.8 | F11: AM-Peak | G11: 8308.16 | H11: 9890.53 | K11: AM-Peak | L11: 31351.72 | M11: 34340.15 | P11: AM-Peak | Q11: 39659.88 | R11: 44230.68
B12: AM-Shoulder | C12: 0.8 | D12: 0.8 | F12: AM-Shoulder | G12: 3313.7 | H12: 1603.9 | K12: AM-Shoulder | L12: 12764.18 | M12: 10900.02 | P12: AM-Shoulder | Q12: 16077.88 | R12: 12503.92
B13: MD | C13: 1.18 | D13: 0.8 | F13: MD | G13: 18451.48 | H13: 17261.7 | K13: MD | L13: 94200.67 | M13: 78905.8 | P13: MD | Q13: 112652.15 | R13: 96167.5
B14: PM-Shoulder | C14: 0.84 | D14: 0.8 | F14: PM-Shoulder | G14: 3662.46 | H14: 2778.79 | K14: PM-Shoulder | L14: 13626.5 | M14: 11181.69 | P14: PM-Shoulder | Q14: 17288.96 | R14: 13960.48
B15: PM-Peak | C15: 0.8 | D15: 0.8 | F15: PM-Peak | G15: 2554.02 | H15: 2413.81 | K15: PM-Peak | L15: 48795.85 | M15: 46138.77 | P15: PM-Peak | Q15: 51349.87 | R15: 48552.58
B16: PM-Late | C16: 0.8 | D16: 0.8 | F16: PM-Late | G16: 10473.91 | H16: 9553.2 | K16: PM-Late | L16: 26858.06 | M16: 20742.78 | P16: PM-Late | Q16: 37331.97 | R16: 30295.98
B19: CaptureRateLights | F19: ML Volume (PCE/Period) | K19: GP Volume (PCE/Period) | P19: Highway Volume
B20: Direction | C20: NB | D20: SB | F20: Direction | G20: NB | H20: SB | K20: Direction | L20: NB | M20: SB | P20: Direction | Q20: NB | R20: SB
B21: Segment | C21: 16 | D21: 16 | F21: Segment | G21: 16 | H21: 16 | K21: Segment | L21: 16 | M21: 16 | P21: Segment | Q21: 16 | R21: 16
B22: Period | F22: Period | K22: Period | P22: Period
B23: Night | C23: 0.05 | D23: 0.17 | F23: Night | G23: 845.15 | H23: 2542.4 | K23: Night | L23: 15434.05 | M23: 16800 | P23: Night | Q23: 16279.2 | R23: 19342.4
B24: AM-Early | C24: 0.3 | D24: 0.2 | F24: AM-Early | G24: 1430.35 | H24: 1401.14 | K24: AM-Early | L24: 4847.35 | M24: 6799.11 | P24: AM-Early | Q24: 6277.7 | R24: 8200.25
B25: AM-Peak | C25: 0.25 | D25: 0.27 | F25: AM-Peak | G25: 3195.45 | H25: 3804.05 | K25: AM-Peak | L25: 12058.35 | M25: 13207.75 | P25: AM-Peak | Q25: 15253.8 | R25: 17011.8
B26: AM-Shoulder | C26: 0.25 | D26: 0.16 | F26: AM-Shoulder | G26: 1274.5 | H26: 616.89 | K26: AM-Shoulder | L26: 4909.3 | M26: 4192.31 | P26: AM-Shoulder | Q26: 6183.8 | R26: 4809.2
B27: MD | C27: 0.19 | D27: 0.21 | F27: MD | G27: 7096.72 | H27: 6639.12 | K27: MD | L27: 36231.03 | M27: 30348.38 | P27: MD | Q27: 43327.75 | R27: 36987.5
B28: PM-Shoulder | C28: 0.24 | D28: 0.23 | F28: PM-Shoulder | G28: 1408.64 | H28: 1068.77 | K28: PM-Shoulder | L28: 5240.96 | M28: 4300.65 | P28: PM-Shoulder | Q28: 6649.6 | R28: 5369.42
B29: PM-Peak | C29: 0.05 | D29: 0.05 | F29: PM-Peak | G29: 982.31 | H29: 928.39 | K29: PM-Peak | L29: 18767.63 | M29: 17745.68 | P29: PM-Peak | Q29: 19749.95 | R29: 18674.07
B30: PM-Late | C30: 0.33 | D30: 0.35 | F30: PM-Late | G30: 4028.43 | H30: 3674.31 | K30: PM-Late | L30: 10330.02 | M30: 7977.99 | P30: PM-Late | Q30: 14358.45 | R30: 11652.3
B33: Revenue Per Period | F33: ML Flow (PCE/hr) | K33: GP Flow (PCE/hr) | P33: Highway Flow
B34: Direction | C34: NB | D34: SB | F34: Direction | G34: NB | H34: SB | K34: Direction | L34: NB | M34: SB | P34: Direction | Q34: NB | R34: SB
B35: Segment | C35: 16 | D35: 16 | F35: Segment | G35: 16 | H35: 16 | K35: Segment | L35: 16 | M35: 16 | P35: Segment | Q35: 16 | R35: 16
B36: Period | F36: Period | K36: Period | P36: Period
B37: Night | C37: 572.37 | D37: 1497.54 | F37: Night | G37: 120.74 | H37: 363.2 | K37: Night | L37: 2204.86 | M37: 2400 | P37: Night | Q37: 2325.6 | R37: 2763.2
B38: AM-Early | C38: 3385.07 | D38: 4502.87 | F38: AM-Early | G38: 1430.35 | H38: 1401.14 | K38: AM-Early | L38: 4847.35 | M38: 6799.11 | P38: AM-Early | Q38: 6277.7 | R38: 8200.25
B39: AM-Peak | C39: 7577.94 | D39: 8936.74 | F39: AM-Peak | G39: 1065.15 | H39: 1268.02 | K39: AM-Peak | L39: 4019.45 | M39: 4402.58 | P39: AM-Peak | Q39: 5084.6 | R39: 5670.6
B40: AM-Shoulder | C40: 3016.59 | D40: 1440.3 | F40: AM-Shoulder | G40: 1274.5 | H40: 616.89 | K40: AM-Shoulder | L40: 4909.3 | M40: 4192.31 | P40: AM-Shoulder | Q40: 6183.8 | R40: 4809.2
B41: MD | C41: 23852.24 | D41: 15398.83 | F41: MD | G41: 1419.34 | H41: 1327.82 | K41: MD | L41: 7246.21 | M41: 6069.68 | P41: MD | Q41: 8665.55 | R41: 7397.5
B42: PM-Shoulder | C42: 3269.07 | D42: 2387.5 | F42: PM-Shoulder | G42: 1408.64 | H42: 1068.77 | K42: PM-Shoulder | L42: 5240.96 | M42: 4300.65 | P42: PM-Shoulder | Q42: 6649.6 | R42: 5369.42
B43: PM-Peak | C43: 2287.35 | D43: 2253.03 | F43: PM-Peak | G43: 327.44 | H43: 309.46 | K43: PM-Peak | L43: 6255.88 | M43: 5915.23 | P43: PM-Peak | Q43: 6583.32 | R43: 6224.69
B44: PM-Late | C44: 9205.93 | D44: 8274.42 | F44: PM-Late | G44: 1342.81 | H44: 1224.77 | K44: PM-Late | L44: 3443.34 | M44: 2659.33 | P44: PM-Late | Q44: 4786.15 | R44: 3884.1
B47: Revenue Per Period Lights | F47: ML V/C | K47: GP V/C real | P47: Highway Vol / GP Capacity
...

Sheet Year_2050
B1: Lenght
C2: 16
B3: Length | C3: 2.6
B5: TollLights | F5: ML PCE.Miles | K5: GP PCE.Miles | P5: Highway PCE.Miles
B6: Direction | C6: NB | D6: SB | F6: Direction | G6: NB | H6: SB | K6: Direction | L6: NB | M6: SB | P6: Direction | Q6: NB | R6: SB
B7: Segment | C7: 16 | D7: 16 | F7: Segment | G7: 16 | H7: 16 | K7: Segment | L7: 16 | M7: 16 | P7: Segment | Q7: 16 | R7: 16
B8: Period | F8: Period | K8: Period | P8: Period
B9: Night | C9: 0.2 | D9: 0.2 | F9: Night | G9: 5661.11 | H9: 14940.38 | K9: Night | L9: 43680 | M9: 43680 | P9: Night | Q9: 49341.11 | R9: 58620.38
B10: AM-Early | C10: 2.49 | D10: 2.57 | F10: AM-Early | G10: 3684.45 | H10: 4141.51 | K10: AM-Early | L10: 15343.13 | M10: 20713.06 | P10: AM-Early | Q10: 19027.58 | R10: 24854.57
B11: AM-Peak | C11: 0.97 | D11: 1.69 | F11: AM-Peak | G11: 10977.87 | H11: 10949.65 | K11: AM-Peak | L11: 35254.29 | M11: 40612.64 | P11: AM-Peak | Q11: 46232.16 | R11: 51562.29
B12: AM-Shoulder | C12: 1.59 | D12: 0.8 | F12: AM-Shoulder | G12: 3860.6 | H12: 722.32 | K12: AM-Shoulder | L12: 14882.41 | M12: 13854.32 | P12: AM-Shoulder | Q12: 18743.01 | R12: 14576.64
B13: MD | C13: 3.43 | D13: 1.95 | F13: MD | G13: 18223.22 | H13: 18212.03 | K13: MD | L13: 113103.43 | M13: 93895.42 | P13: MD | Q13: 131326.65 | R13: 112107.45
B14: PM-Shoulder | C14: 2.43 | D14: 1.15 | F14: PM-Shoulder | G14: 3646.55 | H14: 3640.57 | K14: PM-Shoulder | L14: 16507.22 | M14: 12633.33 | P14: PM-Shoulder | Q14: 20153.77 | R14: 16273.9
B15: PM-Peak | C15: 0.8 | D15: 0.8 | F15: PM-Peak | G15: 10643.56 | H15: 10068.79 | K15: PM-Peak | L15: 49218.06 | M15: 46531.08 | P15: PM-Peak | Q15: 59861.62 | R15: 56599.87
B16: PM-Late | C16: 2.17 | D16: 1.61 | F16: PM-Late | G16: 10956.22 | H16: 10969.31 | K16: PM-Late | L16: 32567.39 | M16: 23949.83 | P16: PM-Late | Q16: 43523.61 | R16: 34919.14
B19: CaptureRateLights | F19: ML Volume (PCE/Period) | K19: GP Volume (PCE/Period) | P19: Highway Volume
B20: Direction | C20: NB | D20: SB | F20: Direction | G20: NB | H20: SB | K20: Direction | L20: NB | M20: SB | P20: Direction | Q20: NB | R20: SB
B21: Segment | C21: 16 | D21: 16 | F21: Segment | G21: 16 | H21: 16 | K21: Segment | L21: 16 | M21: 16 | P21: Segment | Q21: 16 | R21: 16
B22: Period | F22: Period | K22: Period | P22: Period
B23: Night | C23: 0.16 | D23: 0.28 | F23: Night | G23: 2177.35 | H23: 5746.3 | K23: Night | L23: 16800 | M23: 16800 | P23: Night | Q23: 18977.35 | R23: 22546.3
B24: AM-Early | C24: 0.25 | D24: 0.19 | F24: AM-Early | G24: 1417.1 | H24: 1592.89 | K24: AM-Early | L24: 5901.2 | M24: 7966.56 | P24: AM-Early | Q24: 7318.3 | R24: 9559.45
B25: AM-Peak | C25: 0.28 | D25: 0.25 | F25: AM-Peak | G25: 4222.26 | H25: 4211.4 | K25: AM-Peak | L25: 13559.34 | M25: 15620.25 | P25: AM-Peak | Q25: 17781.6 | R25: 19831.65
B26: AM-Shoulder | C26: 0.25 | D26: 0.05 | F26: AM-Shoulder | G26: 1484.84 | H26: 277.82 | K26: AM-Shoulder | L26: 5724.01 | M26: 5328.58 | P26: AM-Shoulder | Q26: 7208.85 | R26: 5606.4
B27: MD | C27: 0.16 | D27: 0.19 | F27: MD | G27: 7008.93 | H27: 7004.63 | K27: MD | L27: 43501.32 | M27: 36113.62 | P27: MD | Q27: 50510.25 | R27: 43118.25
B28: PM-Shoulder | C28: 0.2 | D28: 0.26 | F28: PM-Shoulder | G28: 1402.52 | H28: 1400.22 | K28: PM-Shoulder | L28: 6348.93 | M28: 4858.97 | P28: PM-Shoulder | Q28: 7751.45 | R28: 6259.19
B29: PM-Peak | C29: 0.18 | D29: 0.18 | F29: PM-Peak | G29: 4093.68 | H29: 3872.61 | K29: PM-Peak | L29: 18930.02 | M29: 17896.57 | P29: PM-Peak | Q29: 23023.7 | R29: 21769.18
B30: PM-Late | C30: 0.29 | D30: 0.35 | F30: PM-Late | G30: 4213.93 | H30: 4218.97 | K30: PM-Late | L30: 12525.92 | M30: 9211.47 | P30: PM-Late | Q30: 16739.85 | R30: 13430.44
B33: Revenue Per Period | F33: ML Flow (PCE/hr) | K33: GP Flow (PCE/hr) | P33: Highway Flow
B34: Direction | C34: NB | D34: SB | F34: Direction | G34: NB | H34: SB | K34: Direction | L34: NB | M34: SB | P34: Direction | Q34: NB | R34: SB
B35: Segment | C35: 16 | D35: 16 | F35: Segment | G35: 16 | H35: 16 | K35: Segment | L35: 16 | M35: 16 | P35: Segment | Q35: 16 | R35: 16
B36: Period | F36: Period | K36: Period | P36: Period
B37: Night | C37: 1349.67 | D37: 3644.04 | F37: Night | G37: 311.05 | H37: 820.9 | K37: Night | L37: 2400 | M37: 2400 | P37: Night | Q37: 2711.05 | R37: 3220.9
B38: AM-Early | C38: 9875.84 | D38: 11565.74 | F38: AM-Early | G38: 1417.1 | H38: 1592.89 | K38: AM-Early | L38: 5901.2 | M38: 7966.56 | P38: AM-Early | Q38: 7318.3 | R38: 9559.45
B39: AM-Peak | C39: 12242.93 | D39: 20936.19 | F39: AM-Peak | G39: 1407.42 | H39: 1403.8 | K39: AM-Peak | L39: 4519.78 | M39: 5206.75 | P39: AM-Peak | Q39: 5927.2 | R39: 6610.55
B40: AM-Shoulder | C40: 7006.77 | D40: 703.11 | F40: AM-Shoulder | G40: 1484.84 | H40: 277.82 | K40: AM-Shoulder | L40: 5724.01 | M40: 5328.58 | P40: AM-Shoulder | Q40: 7208.85 | R40: 5606.4
B41: MD | C41: 68232.84 | D41: 39618.88 | F41: MD | G41: 1401.79 | H41: 1400.93 | K41: MD | L41: 8700.26 | M41: 7222.72 | P41: MD | Q41: 10102.05 | R41: 8623.65
B42: PM-Shoulder | C42: 9407.81 | D42: 4526.48 | F42: PM-Shoulder | G42: 1402.52 | H42: 1400.22 | K42: PM-Shoulder | L42: 6348.93 | M42: 4858.97 | P42: PM-Shoulder | Q42: 7751.45 | R42: 6259.19
B43: PM-Peak | C43: 9510.27 | D43: 9378.29 | F43: PM-Peak | G43: 1364.56 | H43: 1290.87 | K43: PM-Peak | L43: 6310.01 | M43: 5965.52 | P43: PM-Peak | Q43: 7674.57 | R43: 7256.39
B44: PM-Late | C44: 26104.59 | D44: 19145.75 | F44: PM-Late | G44: 1404.64 | H44: 1406.32 | K44: PM-Late | L44: 4175.31 | M44: 3070.49 | P44: PM-Late | Q44: 5579.95 | R44: 4476.81
B47: Revenue Per Period Lights | F47: ML V/C | K47: GP V/C real | P47: Highway Vol / GP Capacity
...

Sheet Sheet1
B1: 2025-2032 | F1: 2025-2032
B2: GP Flow (PCE/hr) | F2: CaptureRateLights
B3: Direction | C3: NB | D3: SB | F3: Direction | G3: NB | H3: SB
B4: Segment | C4: 16 | D4: 16 | F4: Segment | G4: 16 | H4: 16
B5: Period | F5: Period
B6: Night | C6: =Year_2032!L37/Year_2025!L37-1 -> 0.24575451 | D6: =Year_2032!M37/Year_2025!M37-1 -> 0.2456697 | F6: Night | G6: =Year_2032!C23/Year_2025!C23-1 -> 0 | H6: =Year_2032!D23/Year_2025!D23-1 -> 0
B7: AM-Early | C7: =Year_2032!L38/Year_2025!L38-1 -> 0.18406219 | D7: =Year_2032!M38/Year_2025!M38-1 -> 0.18566775 | F7: AM-Early | G7: =Year_2032!C24/Year_2025!C24-1 -> 0.33333333 | H7: =Year_2032!D24/Year_2025!D24-1 -> 0.41666667
B8: AM-Peak | C8: =Year_2032!L39/Year_2025!L39-1 -> 0.18558435 | D8: =Year_2032!M39/Year_2025!M39-1 -> 0.16351166 | F8: AM-Peak | G8: =Year_2032!C25/Year_2025!C25-1 -> 0.33333333 | H8: =Year_2032!D25/Year_2025!D25-1 -> 0.4
B9: AM-Shoulder | C9: =Year_2032!L40/Year_2025!L40-1 -> 0.20804332 | D9: =Year_2032!M40/Year_2025!M40-1 -> 0.19653205 | F9: AM-Shoulder | G9: =Year_2032!C26/Year_2025!C26-1 -> 0.2 | H9: =Year_2032!D26/Year_2025!D26-1 -> 0.625
B10: MD | C10: =Year_2032!L41/Year_2025!L41-1 -> 0.18754249 | D10: =Year_2032!M41/Year_2025!M41-1 -> 0.21286281 | F10: MD | G10: =Year_2032!C27/Year_2025!C27-1 -> 0.41666667 | H10: =Year_2032!D27/Year_2025!D27-1 -> 0.15384615
B11: PM-Shoulder | C11: =Year_2032!L42/Year_2025!L42-1 -> 0.19804223 | D11: =Year_2032!M42/Year_2025!M42-1 -> 0.23739227 | F11: PM-Shoulder | G11: =Year_2032!C28/Year_2025!C28-1 -> 0.28571429 | H11: =Year_2032!D28/Year_2025!D28-1 -> 0.066666667
B12: PM-Peak | C12: =Year_2032!L43/Year_2025!L43-1 -> 0.37772179 | D12: =Year_2032!M43/Year_2025!M43-1 -> 0.36261289 | F12: PM-Peak | G12: =Year_2032!C29/Year_2025!C29-1 -> -0.6875 | H12: =Year_2032!D29/Year_2025!D29-1 -> -0.6875
B13: PM-Late | C13: =Year_2032!L44/Year_2025!L44-1 -> 0.1770138 | D13: =Year_2032!M44/Year_2025!M44-1 -> 0.16270078 | F13: PM-Late | G13: =Year_2032!C30/Year_2025!C30-1 -> 0.26315789 | H13: =Year_2032!D30/Year_2025!D30-1 -> 0.23809524
B16: 2032-2040 | F16: 2032-2040
B17: GP Flow (PCE/hr) | F17: CaptureRateLights
B18: Direction | C18: NB | D18: SB | F18: Direction | G18: NB | H18: SB
B19: Segment | C19: 16 | D19: 16 | F19: Segment | G19: 16 | H19: 16
B20: Period | F20: Period
B21: Night | C21: =Year_2040!L37/Year_2032!L37-1 -> 0.15026372 | D21: =Year_2040!M37/Year_2032!M37-1 -> 0.054083255 | F21: Night | G21: =Year_2040!C23/Year_2032!C23-1 -> 0 | H21: =Year_2040!D23/Year_2032!D23-1 -> 2.4
B22: AM-Early | C22: =Year_2040!L38/Year_2032!L38-1 -> 0.069337575 | D22: =Year_2040!M38/Year_2032!M38-1 -> 0.11983655 | F22: AM-Early | G22: =Year_2040!C24/Year_2032!C24-1 -> 0.5 | H22: =Year_2040!D24/Year_2032!D24-1 -> 0.17647059
B23: AM-Peak | C23: =Year_2040!L39/Year_2032!L39-1 -> 0.083897604 | D23: =Year_2040!M39/Year_2032!M39-1 -> 0.084956529 | F23: AM-Peak | G23: =Year_2040!C25/Year_2032!C25-1 -> 0.25 | H23: =Year_2040!D25/Year_2032!D25-1 -> 0.28571429
B24: AM-Shoulder | C24: =Year_2040!L40/Year_2032!L40-1 -> 0.071838717 | D24: =Year_2040!M40/Year_2032!M40-1 -> 0.1229863 | F24: AM-Shoulder | G24: =Year_2040!C26/Year_2032!C26-1 -> 0.38888889 | H24: =Year_2040!D26/Year_2032!D26-1 -> 0.23076923
B25: MD | C25: =Year_2040!L41/Year_2032!L41-1 -> 0.12410044 | D25: =Year_2040!M41/Year_2032!M41-1 -> 0.084307088 | F25: MD | G25: =Year_2040!C27/Year_2032!C27-1 -> 0.11764706 | H25: =Year_2040!D27/Year_2032!D27-1 -> 0.4
B26: PM-Shoulder | C26: =Year_2040!L42/Year_2032!L42-1 -> 0.077021717 | D26: =Year_2040!M42/Year_2032!M42-1 -> 0.067132329 | F26: PM-Shoulder | G26: =Year_2040!C28/Year_2032!C28-1 -> 0.33333333 | H26: =Year_2040!D28/Year_2032!D28-1 -> 0.4375
B27: PM-Peak | C27: =Year_2040!L43/Year_2032!L43-1 -> 0.15208091 | D27: =Year_2040!M43/Year_2032!M43-1 -> 0.15211629 | F27: PM-Peak | G27: =Year_2040!C29/Year_2032!C29-1 -> 0 | H27: =Year_2040!D29/Year_2032!D29-1 -> 0
B28: PM-Late | C28: =Year_2040!L44/Year_2032!L44-1 -> 0.04266858 | D28: =Year_2040!M44/Year_2032!M44-1 -> 0.027073686 | F28: PM-Late | G28: =Year_2040!C30/Year_2032!C30-1 -> 0.375 | H28: =Year_2040!D30/Year_2032!D30-1 -> 0.34615385
B31: 2040-2050 | F31: 2032-2040
B32: GP Flow (PCE/hr) | F32: CaptureRateLights
B33: Direction | C33: NB | D33: SB | F33: Direction | G33: NB | H33: SB
B34: Segment | C34: 16 | D34: 16 | F34: Segment | G34: 16 | H34: 16
B35: Period | F35: Period
B36: Night | C36: =Year_2050!L37/Year_2040!L37-1 -> 0.088504486 | D36: =Year_2050!M37/Year_2040!M37-1 -> 0 | F36: Night | G36: =Year_2050!C23/Year_2040!C23-1 -> 2.2 | H36: =Year_2050!D23/Year_2040!D23-1 -> 0.64705882
B37: AM-Early | C37: =Year_2050!L38/Year_2040!L38-1 -> 0.21740745 | D37: =Year_2050!M38/Year_2040!M38-1 -> 0.1717063 | F37: AM-Early | G37: =Year_2050!C24/Year_2040!C24-1 -> -0.16666667 | H37: =Year_2050!D24/Year_2040!D24-1 -> -0.05
B38: AM-Peak | C38: =Year_2050!L39/Year_2040!L39-1 -> 0.12447723 | D38: =Year_2050!M39/Year_2040!M39-1 -> 0.1826588 | F38: AM-Peak | G38: =Year_2050!C25/Year_2040!C25-1 -> 0.12 | H38: =Year_2050!D25/Year_2040!D25-1 -> -0.074074074
B39: AM-Shoulder | C39: =Year_2050!L40/Year_2040!L40-1 -> 0.16595238 | D39: =Year_2050!M40/Year_2040!M40-1 -> 0.27103673 | F39: AM-Shoulder | G39: =Year_2050!C26/Year_2040!C26-1 -> 0 | H39: =Year_2050!D26/Year_2040!D26-1 -> -0.6875
B40: MD | C40: =Year_2050!L41/Year_2040!L41-1 -> 0.20066352 | D40: =Year_2050!M41/Year_2040!M41-1 -> 0.18996718 | F40: MD | G40: =Year_2050!C27/Year_2040!C27-1 -> -0.15789474 | H40: =Year_2050!D27/Year_2040!D27-1 -> -0.095238095
B41: PM-Shoulder | C41: =Year_2050!L42/Year_2040!L42-1 -> 0.21140593 | D41: =Year_2050!M42/Year_2040!M42-1 -> 0.12982224 | F41: PM-Shoulder | G41: =Year_2050!C28/Year_2040!C28-1 -> -0.16666667 | H41: =Year_2050!D28/Year_2040!D28-1 -> 0.13043478
B42: PM-Peak | C42: =Year_2050!L43/Year_2040!L43-1 -> 0.0086526596 | D42: =Year_2050!M43/Year_2040!M43-1 -> 0.0085017827 | F42: PM-Peak | G42: =Year_2050!C29/Year_2040!C29-1 -> 2.6 | H42: =Year_2050!D29/Year_2040!D29-1 -> 2.6
B43: PM-Late | C43: =Year_2050!L44/Year_2040!L44-1 -> 0.21257558 | D43: =Year_2050!M44/Year_2040!M44-1 -> 0.15461037 | F43: PM-Late | G43: =Year_2050!C30/Year_2040!C30-1 -> -0.12121212 | H43: =Year_2050!D30/Year_2040!D30-1 -> 0
