Workbook

Sheet Year_2025
B1: Lenght
C2: 1 | D2: 2 | E2: 3 | F2: 4 | G2: 5 | H2: 6 | I2: 7 | J2: 8 | K2: 9 | L2: 10
B3: Length | C3: 1.3 | D3: 1.3 | E3: 0.5 | F3: 1.6 | G3: 2 | H3: 3.6 | I3: 2.9 | J3: 3.8 | K3: 3.4 | L3: 4.5
B5: TollLights | X5: ML PCE.Miles | AU5: GP PCE.Miles | BR5: Highway PCE.Miles
B6: Direction | C6: NB | D6: SB | E6: NB | F6: SB | G6: NB | H6: SB | I6: NB | J6: SB | K6: NB | L6: SB | M6: NB | N6: SB | O6: NB | P6: SB | Q6: NB | R6: SB | S6: NB | T6: SB | U6: NB | V6: SB | X6: Direction | Y6: NB | Z6: SB | AA6: NB | AB6: SB | AC6: NB | AD6: SB | AE6: NB | AF6: SB | AG6: NB | AH6: SB | AI6: NB | AJ6: SB | AK6: NB | AL6: SB | AM6: NB | AN6: SB | AO6: NB | AP6: SB | AQ6: NB | AR6: SB | AU6: Direction | AV6: NB | AW6: SB | AX6: NB | AY6: SB | AZ6: NB | BA6: SB | BB6: NB | BC6: SB | BD6: NB | BE6: SB | BF6: NB | BG6: SB | BH6: NB | BI6: SB | BJ6: NB | BK6: SB | BL6: NB | BM6: SB | BN6: NB | BO6: SB | BR6: Direction | BS6: NB | BT6: SB | BU6: NB | BV6: SB | BW6: NB | BX6: SB | BY6: NB | BZ6: SB | CA6: NB | CB6: SB | CC6: NB | CD6: SB | CE6: NB | CF6: SB | CG6: NB | CH6: SB | CI6: NB | CJ6: SB | CK6: NB | CL6: SB
B7: Segment | C7: 1 | D7: 1 | E7: 2 | F7: 2 | G7: 3 | H7: 3 | I7: 4 | J7: 4 | K7: 5 | L7: 5 | M7: 6 | N7: 6 | O7: 7 | P7: 7 | Q7: 8 | R7: 8 | S7: 9 | T7: 9 | U7: 10 | V7: 10 | X7: Segment | Y7: 1 | Z7: 1 | AA7: 2 | AB7: 2 | AC7: 3 | AD7: 3 | AE7: 4 | AF7: 4 | AG7: 5 | AH7: 5 | AI7: 6 | AJ7: 6 | AK7: 7 | AL7: 7 | AM7: 8 | AN7: 8 | AO7: 9 | AP7: 9 | AQ7: 10 | AR7: 10 | AU7: Segment | AV7: 1 | AW7: 1 | AX7: 2 | AY7: 2 | AZ7: 3 | BA7: 3 | BB7: 4 | BC7: 4 | BD7: 5 | BE7: 5 | BF7: 6 | BG7: 6 | BH7: 7 | BI7: 7 | BJ7: 8 | BK7: 8 | BL7: 9 | BM7: 9 | BN7: 10 | BO7: 10 | BR7: Segment | BS7: 1 | BT7: 1 | BU7: 2 | BV7: 2 | BW7: 3 | BX7: 3 | BY7: 4 | BZ7: 4 | CA7: 5 | CB7: 5 | CC7: 6 | CD7: 6 | CE7: 7 | CF7: 7 | CG7: 8 | CH7: 8 | CI7: 9 | CJ7: 9 | CK7: 10 | CL7: 10
B8: Period | X8: Period | AU8: Period | BR8: Period
B9: Night | C9: 0.2 | D9: 0.2 | E9: 0.2 | F9: 0.2 | G9: 0.2 | H9: 0.2 | I9: 0.2 | J9: 0.2 | K9: 0.2 | L9: 0.2 | M9: 0.2 | N9: 0.2 | O9: 0.2 | P9: 0.2 | Q9: 0.2 | R9: 0.2 | S9: 0.2 | T9: 0.2 | U9: 0.2 | V9: 0.2 | X9: Night | Y9: 340.76 | Z9: 338.1 | AA9: 294.72 | AB9: 270.97 | AC9: 96.77 | AD9: 121.72 | AE9: 238.39 | AF9: 243.89 | AG9: 323.32 | AH9: 284.64 | AI9: 588.18 | AJ9: 504.34 | AK9: 458.8 | AL9: 394.39 | AM9: 583.44 | AN9: 531.54 | AO9: 460.68 | AP9: 351.44 | AQ9: 614.57 | AR9: 487.45 | AU9: Night | AV9: 20165.18 | AW9: 20029.52 | AX9: 15211.68 | AY9: 14234.43 | AZ9: 5587.23 | BA9: 6657.95 | BB9: 23020.65 | BC9: 22895.31 | BD9: 32758.68 | BE9: 28905.36 | BF9: 59035.02 | BG9: 51029.66 | BH9: 46596.6 | BI9: 39596.61 | BJ9: 58548.36 | BK9: 53306.86 | BL9: 46044.52 | BM9: 35515.16 | BN9: 61786.93 | BO9: 48967.55 | BR9: Night | BS9: 20505.94 | BT9: 20367.62 | BU9: 15506.4 | BV9: 14505.4 | BW9: 5684 | BX9: 6779.68 | BY9: 23259.04 | BZ9: 23139.2 | CA9: 33082 | CB9: 29190 | CC9: 59623.2 | CD9: 51534 | CE9: 47055.4 | CF9: 39991 | CG9: 59131.8 | CH9: 53838.4 | CI9: 46505.2 | CJ9: 35866.6 | CK9: 62401.5 | CL9: 49455
B10: AM-Early | C10: 0.47 | D10: 0.33 | E10: 0.37 | F10: 0.27 | G10: 0.46 | H10: 0.33 | I10: 0.41 | J10: 0.58 | K10: 0.45 | L10: 0.46 | M10: 0.54 | N10: 0.48 | O10: 0.58 | P10: 0.51 | Q10: 0.55 | R10: 0.42 | S10: 0.53 | T10: 0.4 | U10: 0.4 | V10: 0.27 | X10: AM-Early | Y10: 1259.23 | Z10: 772.69 | AA10: 1252.59 | AB10: 801.78 | AC10: 318.47 | AD10: 394.04 | AE10: 1724.83 | AF10: 1183.3 | AG10: 2055.65 | AH10: 1393.62 | AI10: 3573.99 | AJ10: 2530 | AK10: 2480.59 | AL10: 2170.37 | AM10: 3090.09 | AN10: 2740.27 | AO10: 2698.09 | AP10: 2022.46 | AQ10: 4115.39 | AR10: 2529.69 | AU10: AM-Early | AV10: 7107.89 | AW10: 4663.78 | AX10: 6248.8 | AY10: 4182.68 | AZ10: 1677.53 | BA10: 2059.81 | BB10: 8810.29 | BC10: 6432.7 | BD10: 11383.05 | BE10: 8158.38 | BF10: 19894.05 | BG10: 14926.4 | BH10: 14063.91 | BI10: 12686.33 | BJ10: 17678.82 | BK10: 15872.89 | BL10: 15472.24 | BM10: 12106.54 | BN10: 24249.24 | BO10: 15502.26 | BR10: AM-Early | BS10: 8367.12 | BT10: 5436.47 | BU10: 7501.39 | BV10: 4984.46 | BW10: 1996 | BX10: 2453.85 | BY10: 10535.12 | BZ10: 7616 | CA10: 13438.7 | CB10: 9552 | CC10: 23468.04 | CD10: 17456.4 | CE10: 16544.5 | CF10: 14856.7 | CG10: 20768.9 | CH10: 18613.16 | CI10: 18170.33 | CJ10: 14129.01 | CK10: 28364.62 | CL10: 18031.95
B11: AM-Peak | C11: 1.6 | D11: 0.2 | E11: 2.65 | F11: 0.2 | G11: 1.6 | H11: 1.6 | I11: 1.5 | J11: 0.9 | K11: 1.6 | L11: 0.87 | M11: 1.6 | N11: 0.88 | O11: 1.6 | P11: 0.89 | Q11: 1.6 | R11: 0.84 | S11: 0.95 | T11: 0.75 | U11: 0.71 | V11: 0.65 | X11: AM-Peak | Y11: 5753.96 | Z11: 578.51 | AA11: 5720.99 | AB11: 504.21 | AC11: 1579.57 | AD11: 3016.75 | AE11: 5684.06 | AF11: 4069 | AG11: 7566.43 | AH11: 4603.66 | AI11: 15974.38 | AJ11: 8199.13 | AK11: 16717.76 | AL11: 6589.03 | AM11: 18242.95 | AN11: 8447.18 | AO11: 8422.63 | AP11: 6576.73 | AQ11: 8575.27 | AR11: 7626.94 | AU11: AM-Peak | AV11: 27060.71 | AW11: 11829.54 | AX11: 30123.13 | AY11: 9629.74 | AZ11: 7802.7 | BA11: 11118.63 | BB11: 31090.22 | BC11: 22842.93 | BD11: 41429.47 | BE11: 28197.57 | BF11: 77644.3 | BG11: 50878.64 | BH11: 66802.24 | BI11: 41207.9 | BJ11: 81235.73 | BK11: 51835.63 | BL11: 51179.67 | BM11: 41768.22 | BN11: 53456.83 | BO11: 48381.74 | BR11: AM-Peak | BS11: 32814.67 | BT11: 12408.04 | BU11: 35844.12 | BV11: 10133.96 | BW11: 9382.27 | BX11: 14135.38 | BY11: 36774.29 | BZ11: 26911.93 | CA11: 48995.9 | CB11: 32801.23 | CC11: 93618.67 | CD11: 59077.77 | CE11: 83520 | CF11: 47796.93 | CG11: 99478.68 | CH11: 60282.81 | CI11: 59602.3 | CJ11: 48344.94 | CK11: 62032.1 | CL11: 56008.68
B12: AM-Shoulder | C12: 1.6 | D12: 0.49 | E12: 1.57 | F12: 0.2 | G12: 1.6 | H12: 1.6 | I12: 0.97 | J12: 0.68 | K12: 1.12 | L12: 0.61 | M12: 1.2 | N12: 0.59 | O12: 1.2 | P12: 0.59 | Q12: 0.79 | R12: 0.55 | S12: 0.55 | T12: 0.52 | U12: 0.5 | V12: 0.47 | X12: AM-Shoulder | Y12: 1625.16 | Z12: 687.54 | AA12: 1735.66 | AB12: 208.57 | AC12: 564.18 | AD12: 644.99 | AE12: 1722.25 | AF12: 1358.94 | AG12: 2127.24 | AH12: 1546.32 | AI12: 3882.83 | AJ12: 2661.82 | AK12: 3093.41 | AL12: 2126.11 | AM12: 3439.74 | AN12: 2685.22 | AO12: 2447.13 | AP12: 2173.37 | AQ12: 2873.61 | AR12: 2685.46 | AU12: AM-Shoulder | AV12: 9294.84 | AW12: 4501.28 | AX12: 9184.34 | AY12: 3986.01 | AZ12: 3030.19 | BA12: 3555.01 | BB12: 9734.47 | BC12: 7957.35 | BD12: 13097.12 | BE12: 9711.36 | BF12: 24129.09 | BG12: 17041.14 | BH12: 19418.51 | BI12: 13700.4 | BJ12: 21460.58 | BK12: 17074.88 | BL12: 15329.58 | BM12: 14463.45 | BN12: 18654.36 | BO12: 17741 | BR12: AM-Shoulder | BS12: 10920 | BT12: 5188.82 | BU12: 10920 | BV12: 4194.58 | BW12: 3594.36 | BX12: 4200 | BY12: 11456.72 | BZ12: 9316.29 | CA12: 15224.36 | CB12: 11257.68 | CC12: 28011.92 | CD12: 19702.96 | CE12: 22511.92 | CF12: 15826.51 | CG12: 24900.32 | CH12: 19760.1 | CI12: 17776.71 | CJ12: 16636.82 | CK12: 21527.97 | CL12: 20426.46
B13: MD | C13: 1.59 | D13: 0.92 | E13: 0.88 | F13: 0.4 | G13: 1.06 | H13: 1.57 | I13: 0.43 | J13: 0.86 | K13: 0.73 | L13: 0.81 | M13: 0.66 | N13: 0.59 | O13: 0.6 | P13: 0.54 | Q13: 0.56 | R13: 0.53 | S13: 0.54 | T13: 0.45 | U13: 0.48 | V13: 0.34 | X13: MD | Y13: 4943 | Z13: 5489.05 | AA13: 6321.52 | AB13: 6525.47 | AC13: 1713.69 | AD13: 2308.18 | AE13: 7031.93 | AF13: 7137.12 | AG13: 9379.15 | AH13: 9498.81 | AI13: 15782.7 | AJ13: 15889.78 | AK13: 11859.52 | AL13: 12422.27 | AM13: 14623.64 | AN13: 14181.82 | AO13: 12166.46 | AP13: 11879.65 | AQ13: 15187.11 | AR13: 17004.01 | AU13: MD | AV13: 30228.5 | AW13: 33510.95 | AX13: 32262.48 | AY13: 33278.58 | AZ13: 9476.31 | BA13: 12521.1 | BB13: 38074.07 | BC13: 39278.88 | BD13: 55113.71 | BE13: 56201.19 | BF13: 93442.41 | BG13: 94200.02 | BH13: 70770.04 | BI13: 73726.58 | BJ13: 88339.12 | BK13: 85023.55 | BL13: 74329.54 | BM13: 71987.3 | BN13: 94744.51 | BO13: 105367.87 | BR13: MD | BS13: 35171.5 | BT13: 39000 | BU13: 38584 | BV13: 39804.05 | BW13: 11190 | BX13: 14829.28 | BY13: 45106 | BZ13: 46416 | CA13: 64492.85 | CB13: 65700 | CC13: 109225.11 | CD13: 110089.8 | CE13: 82629.57 | CF13: 86148.85 | CG13: 102962.77 | CH13: 99205.37 | CI13: 86496 | CJ13: 83866.95 | CK13: 109931.62 | CL13: 122371.87
B14: PM-Shoulder | C14: 1.46 | D14: 1.42 | E14: 0.67 | F14: 0.97 | G14: 1.39 | H14: 1.3 | I14: 0.41 | J14: 1.29 | K14: 0.41 | L14: 1.12 | M14: 0.46 | N14: 0.78 | O14: 0.45 | P14: 0.61 | Q14: 0.45 | R14: 0.62 | S14: 0.44 | T14: 0.55 | U14: 0.4 | V14: 0.34 | X14: PM-Shoulder | Y14: 1586.93 | Z14: 1645.21 | AA14: 1825.54 | AB14: 2145.54 | AC14: 559.59 | AD14: 649.22 | AE14: 1638.73 | AF14: 1740.26 | AG14: 1957.41 | AH14: 2960.94 | AI14: 3731.91 | AJ14: 4828.44 | AK14: 2960.85 | AL14: 3596.07 | AM14: 3819.29 | AN14: 4628.03 | AO14: 3265.42 | AP14: 4023.52 | AQ14: 3890.06 | AR14: 3830.11 | AU14: PM-Shoulder | AV14: 7715.49 | AW14: 7834.91 | AX14: 7279.89 | AY14: 8415.5 | AZ14: 2432.86 | BA14: 2746.89 | BB14: 6790.3 | BC14: 7492.76 | BD14: 8847.02 | BE14: 13839.06 | BF14: 17140.91 | BG14: 22127.09 | BH14: 13583.75 | BI14: 16155.17 | BJ14: 17725.76 | BK14: 21209.59 | BL14: 15425.52 | BM14: 18065.26 | BN14: 18782.18 | BO14: 17369.59 | BR14: PM-Shoulder | BS14: 9302.42 | BT14: 9480.12 | BU14: 9105.43 | BV14: 10561.04 | BW14: 2992.45 | BX14: 3396.12 | BY14: 8429.03 | BZ14: 9233.02 | CA14: 10804.42 | CB14: 16800 | CC14: 20872.82 | CD14: 26955.53 | CE14: 16544.6 | CF14: 19751.25 | CG14: 21545.04 | CH14: 25837.62 | CI14: 18690.94 | CJ14: 22088.78 | CK14: 22672.24 | CL14: 21199.7
B15: PM-Peak | C15: 2.09 | D15: 1.6 | E15: 0.84 | F15: 1.15 | G15: 1.6 | H15: 1.76 | I15: 0.75 | J15: 1.6 | K15: 0.71 | L15: 2.08 | M15: 0.76 | N15: 1.6 | O15: 0.75 | P15: 1.22 | Q15: 0.83 | R15: 0.93 | S15: 0.71 | T15: 0.71 | U15: 0.65 | V15: 0.63 | X15: PM-Peak | Y15: 5648.65 | Z15: 6894.94 | AA15: 5237.78 | AB15: 6053.91 | AC15: 1777.5 | AD15: 2283.41 | AE15: 5616.69 | AF15: 8201.21 | AG15: 6258.78 | AH15: 9551.04 | AI15: 11534.41 | AJ15: 16010.57 | AK15: 9221.36 | AL15: 11726.5 | AM15: 12443.17 | AN15: 13421.92 | AO15: 9827.14 | AP15: 10186.66 | AQ15: 11965.71 | AR15: 11910.82 | AU15: PM-Peak | AV15: 27096.34 | AW15: 27932.04 | AX15: 20987.57 | AY15: 24323.28 | AZ15: 7477.12 | BA15: 9879.56 | BB15: 23836.81 | BC15: 26994.9 | BD15: 28882.62 | BE15: 46277.81 | BF15: 54078.73 | BG15: 76683.37 | BH15: 43278.38 | BI15: 55729.46 | BJ15: 59567.02 | BK15: 63967.21 | BL15: 47603.6 | BM15: 48444.55 | BN15: 58556.34 | BO15: 57447.57 | BR15: PM-Peak | BS15: 32744.98 | BT15: 34826.98 | BU15: 26225.35 | BV15: 30377.19 | BW15: 9254.62 | BX15: 12162.98 | BY15: 29453.5 | BZ15: 35196.11 | CA15: 35141.41 | CB15: 55828.85 | CC15: 65613.15 | CD15: 92693.94 | CE15: 52499.74 | CF15: 67455.96 | CG15: 72010.19 | CH15: 77389.13 | CI15: 57430.74 | CJ15: 58631.22 | CK15: 70522.05 | CL15: 69358.39
B16: PM-Late | C16: 0.48 | D16: 0.58 | E16: 0.2 | F16: 0.2 | G16: 0.2 | H16: 0.34 | I16: 0.2 | J16: 0.84 | K16: 0.49 | L16: 0.83 | M16: 0.66 | N16: 0.78 | O16: 0.71 | P16: 0.64 | Q16: 0.65 | R16: 0.59 | S16: 0.6 | T16: 0.52 | U16: 0.53 | V16: 0.43 | X16: PM-Late | Y16: 2448.39 | Z16: 3099.2 | AA16: 587.61 | AB16: 626.15 | AC16: 170.36 | AD16: 725.02 | AE16: 622.21 | AF16: 3788.16 | AG16: 3114.32 | AH16: 4604.7 | AI16: 5483.18 | AJ16: 8300.12 | AK16: 4334.43 | AL16: 5883.63 | AM16: 5435.68 | AN16: 6012.78 | AO16: 4722.59 | AP16: 4686.14 | AQ16: 6259.46 | AR16: 6438.72 | AU16: PM-Late | AV16: 12281.91 | AW16: 14938.3 | AX16: 11264.68 | AY16: 12007.9 | AZ16: 3335.14 | BA16: 4680 | BB16: 12259.79 | BC16: 16597.44 | BD16: 15995.68 | BE16: 21681.3 | BF16: 28050.82 | BG16: 39122.68 | BH16: 22418.07 | BI16: 28385.67 | BJ16: 28091.72 | BK16: 30193.62 | BL16: 23684.41 | BM16: 24251.26 | BN16: 32674.54 | BO16: 34574.28 | BR16: PM-Late | BS16: 14730.3 | BT16: 18037.5 | BU16: 11852.3 | BV16: 12634.05 | BW16: 3505.5 | BX16: 5405.02 | BY16: 12882 | BZ16: 20385.6 | CA16: 19110 | CB16: 26286 | CC16: 33534 | CD16: 47422.8 | CE16: 26752.5 | CF16: 34269.3 | CG16: 33527.4 | CH16: 36206.4 | CI16: 28407 | CJ16: 28937.4 | CK16: 38934 | CL16: 41013
B19: CaptureRateLights | X19: ML Volume (PCE/Period) | AU19: GP Volume (PCE/Period) | BR19: Highway Volume
B20: Direction | C20: NB | D20: SB | E20: NB | F20: SB | G20: NB | H20: SB | I20: NB | J20: SB | K20: NB | L20: SB | M20: NB | N20: SB | O20: NB | P20: SB | Q20: NB | R20: SB | S20: NB | T20: SB | U20: NB | V20: SB | X20: Direction | Y20: NB | Z20: SB | AA20: NB | AB20: SB | AC20: NB | AD20: SB | AE20: NB | AF20: SB | AG20: NB | AH20: SB | AI20: NB | AJ20: SB | AK20: NB | AL20: SB | AM20: NB | AN20: SB | AO20: NB | AP20: SB | AQ20: NB | AR20: SB | AU20: Direction | AV20: NB | AW20: SB | AX20: NB | AY20: SB | AZ20: NB | BA20: SB | BB20: NB | BC20: SB | BD20: NB | BE20: SB | BF20: NB | BG20: SB | BH20: NB | BI20: SB | BJ20: NB | BK20: SB | BL20: NB | BM20: SB | BN20: NB | BO20: SB | BR20: Direction | BS20: NB | BT20: SB | BU20: NB | BV20: SB | BW20: NB | BX20: SB | BY20: NB | BZ20: SB | CA20: NB | CB20: SB | CC20: NB | CD20: SB | CE20: NB | CF20: SB | CG20: NB | CH20: SB | CI20: NB | CJ20: SB | CK20: NB | CL20: SB
B21: Segment | C21: 1 | D21: 1 | E21: 2 | F21: 2 | G21: 3 | H21: 3 | I21: 4 | J21: 4 | K21: 5 | L21: 5 | M21: 6 | N21: 6 | O21: 7 | P21: 7 | Q21: 8 | R21: 8 | S21: 9 | T21: 9 | U21: 10 | V21: 10 | X21: Segment | Y21: 1 | Z21: 1 | AA21: 2 | AB21: 2 | AC21: 3 | AD21: 3 | AE21: 4 | AF21: 4 | AG21: 5 | AH21: 5 | AI21: 6 | AJ21: 6 | AK21: 7 | AL21: 7 | AM21: 8 | AN21: 8 | AO21: 9 | AP21: 9 | AQ21: 10 | AR21: 10 | AU21: Segment | AV21: 1 | AW21: 1 | AX21: 2 | AY21: 2 | AZ21: 3 | BA21: 3 | BB21: 4 | BC21: 4 | BD21: 5 | BE21: 5 | BF21: 6 | BG21: 6 | BH21: 7 | BI21: 7 | BJ21: 8 | BK21: 8 | BL21: 9 | BM21: 9 | BN21: 10 | BO21: 10 | BR21: Segment | BS21: 1 | BT21: 1 | BU21: 2 | BV21: 2 | BW21: 3 | BX21: 3 | BY21: 4 | BZ21: 4 | CA21: 5 | CB21: 5 | CC21: 6 | CD21: 6 | CE21: 7 | CF21: 7 | CG21: 8 | CH21: 8 | CI21: 9 | CJ21: 9 | CK21: 10 | CL21: 10
B22: Period | X22: Period | AU22: Period | BR22: Period
B23: Night | C23: 0.02 | D23: 0.02 | E23: 0.02 | F23: 0.02 | G23: 0.02 | H23: 0.02 | I23: 0.01 | J23: 0.01 | K23: 0.01 | L23: 0.01 | M23: 0.01 | N23: 0.01 | O23: 0.01 | P23: 0.01 | Q23: 0.01 | R23: 0.01 | S23: 0.01 | T23: 0.01 | U23: 0.01 | V23: 0.01 | X23: Night | Y23: 262.12 | Z23: 260.07 | AA23: 226.71 | AB23: 208.44 | AC23: 193.55 | AD23: 243.44 | AE23: 148.99 | AF23: 152.43 | AG23: 161.66 | AH23: 142.32 | AI23: 163.38 | AJ23: 140.09 | AK23: 158.21 | AL23: 136 | AM23: 153.54 | AN23: 139.88 | AO23: 135.49 | AP23: 103.36 | AQ23: 136.57 | AR23: 108.32 | AU23: Night | AV23: 15511.68 | AW23: 15407.33 | AX23: 11701.29 | AY23: 10949.56 | AZ23: 11174.45 | BA23: 13315.91 | BB23: 14387.91 | BC23: 14309.57 | BD23: 16379.34 | BE23: 14452.68 | BF23: 16398.62 | BG23: 14174.91 | BH23: 16067.79 | BI23: 13654 | BJ23: 15407.46 | BK23: 14028.12 | BL23: 13542.51 | BM23: 10445.64 | BN23: 13730.43 | BO23: 10881.68 | BR23: Night | BS23: 15773.8 | BT23: 15667.4 | BU23: 11928 | BV23: 11158 | BW23: 11368 | BX23: 13559.35 | BY23: 14536.9 | BZ23: 14462 | CA23: 16541 | CB23: 14595 | CC23: 16562 | CD23: 14315 | CE23: 16226 | CF23: 13790 | CG23: 15561 | CH23: 14168 | CI23: 13678 | CJ23: 10549 | CK23: 13867 | CL23: 10990
B24: AM-Early | C24: 0.16 | D24: 0.17 | E24: 0.18 | F24: 0.18 | G24: 0.18 | H24: 0.18 | I24: 0.17 | J24: 0.18 | K24: 0.16 | L24: 0.17 | M24: 0.16 | N24: 0.16 | O24: 0.16 | P24: 0.16 | Q24: 0.16 | R24: 0.16 | S24: 0.16 | T24: 0.16 | U24: 0.16 | V24: 0.16 | X24: AM-Early | Y24: 968.64 | Z24: 594.38 | AA24: 963.53 | AB24: 616.75 | AC24: 636.93 | AD24: 788.09 | AE24: 1078.02 | AF24: 739.56 | AG24: 1027.82 | AH24: 696.81 | AI24: 992.78 | AJ24: 702.78 | AK24: 855.38 | AL24: 748.4 | AM24: 813.18 | AN24: 721.12 | AO24: 793.56 | AP24: 594.84 | AQ24: 914.53 | AR24: 562.15 | AU24: AM-Early | AV24: 5467.61 | AW24: 3587.52 | AX24: 4806.77 | AY24: 3217.45 | AZ24: 3355.07 | BA24: 4119.61 | BB24: 5506.43 | BC24: 4020.44 | BD24: 5691.53 | BE24: 4079.19 | BF24: 5526.12 | BG24: 4146.22 | BH24: 4849.62 | BI24: 4374.6 | BJ24: 4652.32 | BK24: 4177.08 | BL24: 4550.66 | BM24: 3560.75 | BN24: 5388.72 | BO24: 3444.95 | BR24: AM-Early | BS24: 6436.25 | BT24: 4181.9 | BU24: 5770.3 | BV24: 3834.2 | BW24: 3992 | BX24: 4907.7 | BY24: 6584.45 | BZ24: 4760 | CA24: 6719.35 | CB24: 4776 | CC24: 6518.9 | CD24: 4849 | CE24: 5705 | CF24: 5123 | CG24: 5465.5 | CH24: 4898.2 | CI24: 5344.21 | CJ24: 4155.59 | CK24: 6303.25 | CL24: 4007.1
B25: AM-Peak | C25: 0.2 | D25: 0.05 | E25: 0.17 | F25: 0.05 | G25: 0.2 | H25: 0.24 | I25: 0.17 | J25: 0.18 | K25: 0.17 | L25: 0.16 | M25: 0.19 | N25: 0.16 | O25: 0.23 | P25: 0.16 | Q25: 0.21 | R25: 0.16 | S25: 0.16 | T25: 0.16 | U25: 0.16 | V25: 0.16 | X25: AM-Peak | Y25: 4426.12 | Z25: 445 | AA25: 4400.76 | AB25: 387.86 | AC25: 3159.14 | AD25: 6033.5 | AE25: 3552.54 | AF25: 2543.12 | AG25: 3783.21 | AH25: 2301.83 | AI25: 4437.33 | AJ25: 2277.54 | AK25: 5764.74 | AL25: 2272.08 | AM25: 4800.78 | AN25: 2222.94 | AO25: 2477.24 | AP25: 1934.33 | AQ25: 1905.61 | AR25: 1694.88 | AU25: AM-Peak | AV25: 20815.93 | AW25: 9099.65 | AX25: 23171.64 | AY25: 7407.49 | AZ25: 15605.41 | BA25: 22237.25 | BB25: 19431.39 | BC25: 14276.83 | BD25: 20714.73 | BE25: 14098.78 | BF25: 21567.86 | BG25: 14132.96 | BH25: 23035.26 | BI25: 14209.62 | BJ25: 21377.82 | BK25: 13640.96 | BL25: 15052.85 | BM25: 12284.77 | BN25: 11879.3 | BO25: 10751.5 | BR25: AM-Peak | BS25: 25242.05 | BT25: 9544.65 | BU25: 27572.4 | BV25: 7795.35 | BW25: 18764.55 | BX25: 28270.75 | BY25: 22983.93 | BZ25: 16819.95 | CA25: 24497.95 | CB25: 16400.62 | CC25: 26005.19 | CD25: 16410.49 | CE25: 28800 | CF25: 16481.7 | CG25: 26178.6 | CH25: 15863.9 | CI25: 17530.09 | CJ25: 14219.1 | CK25: 13784.91 | CL25: 12446.37
B26: AM-Shoulder | C26: 0.18 | D26: 0.17 | E26: 0.17 | F26: 0.05 | G26: 0.19 | H26: 0.18 | I26: 0.17 | J26: 0.18 | K26: 0.16 | L26: 0.17 | M26: 0.16 | N26: 0.16 | O26: 0.16 | P26: 0.16 | Q26: 0.16 | R26: 0.16 | S26: 0.16 | T26: 0.17 | U26: 0.16 | V26: 0.17 | X26: AM-Shoulder | Y26: 1250.12 | Z26: 528.88 | AA26: 1335.12 | AB26: 160.44 | AC26: 1128.35 | AD26: 1289.98 | AE26: 1076.41 | AF26: 849.34 | AG26: 1063.62 | AH26: 773.16 | AI26: 1078.56 | AJ26: 739.4 | AK26: 1066.69 | AL26: 733.14 | AM26: 905.19 | AN26: 706.64 | AO26: 719.74 | AP26: 639.23 | AQ26: 638.58 | AR26: 596.77 | AU26: AM-Shoulder | AV26: 7149.88 | AW26: 3462.52 | AX26: 7064.88 | AY26: 3066.16 | AZ26: 6060.38 | BA26: 7110.02 | BB26: 6084.04 | BC26: 4973.35 | BD26: 6548.56 | BE26: 4855.68 | BF26: 6702.52 | BG26: 4733.65 | BH26: 6696.04 | BI26: 4724.28 | BJ26: 5647.52 | BK26: 4493.39 | BL26: 4508.7 | BM26: 4253.96 | BN26: 4145.41 | BO26: 3942.45 | BR26: AM-Shoulder | BS26: 8400 | BT26: 3991.4 | BU26: 8400 | BV26: 3226.6 | BW26: 7188.73 | BX26: 8400 | BY26: 7160.45 | BZ26: 5822.68 | CA26: 7612.18 | CB26: 5628.84 | CC26: 7781.09 | CD26: 5473.04 | CE26: 7762.73 | CF26: 5457.42 | CG26: 6552.71 | CH26: 5200.03 | CI26: 5228.44 | CJ26: 4893.18 | CK26: 4783.99 | CL26: 4539.21
B27: MD | C27: 0.17 | D27: 0.17 | E27: 0.18 | F27: 0.18 | G27: 0.18 | H27: 0.18 | I27: 0.18 | J27: 0.18 | K27: 0.17 | L27: 0.17 | M27: 0.17 | N27: 0.17 | O27: 0.17 | P27: 0.17 | Q27: 0.17 | R27: 0.17 | S27: 0.17 | T27: 0.17 | U27: 0.17 | V27: 0.17 | X27: MD | Y27: 3802.31 | Z27: 4222.34 | AA27: 4862.71 | AB27: 5019.59 | AC27: 3427.38 | AD27: 4616.36 | AE27: 4394.96 | AF27: 4460.7 | AG27: 4689.57 | AH27: 4749.4 | AI27: 4384.08 | AJ27: 4413.83 | AK27: 4089.49 | AL27: 4283.54 | AM27: 3848.33 | AN27: 3732.06 | AO27: 3578.37 | AP27: 3494.01 | AQ27: 3374.91 | AR27: 3778.67 | AU27: MD | AV27: 23252.69 | AW27: 25777.66 | AX27: 24817.29 | AY27: 25598.91 | AZ27: 18952.62 | BA27: 25042.21 | BB27: 23796.29 | BC27: 24549.3 | BD27: 27556.85 | BE27: 28100.6 | BF27: 25956.23 | BG27: 26166.67 | BH27: 24403.46 | BI27: 25422.96 | BJ27: 23247.14 | BK27: 22374.62 | BL27: 21861.63 | BM27: 21172.74 | BN27: 21054.34 | BO27: 23415.08 | BR27: MD | BS27: 27055 | BT27: 30000 | BU27: 29680 | BV27: 30618.5 | BW27: 22380 | BX27: 29658.56 | BY27: 28191.25 | BZ27: 29010 | CA27: 32246.43 | CB27: 32850 | CC27: 30340.31 | CD27: 30580.5 | CE27: 28492.95 | CF27: 29706.5 | CG27: 27095.46 | CH27: 26106.68 | CI27: 25440 | CJ27: 24666.75 | CK27: 24429.25 | CL27: 27193.75
B28: PM-Shoulder | C28: 0.2 | D28: 0.2 | E28: 0.21 | F28: 0.21 | G28: 0.22 | H28: 0.22 | I28: 0.22 | J28: 0.21 | K28: 0.2 | L28: 0.2 | M28: 0.2 | N28: 0.2 | O28: 0.2 | P28: 0.2 | Q28: 0.2 | R28: 0.2 | S28: 0.2 | T28: 0.2 | U28: 0.2 | V28: 0.2 | X28: PM-Shoulder | Y28: 1220.71 | Z28: 1265.54 | AA28: 1404.26 | AB28: 1650.41 | AC28: 1119.18 | AD28: 1298.45 | AE28: 1024.21 | AF28: 1087.66 | AG28: 978.7 | AH28: 1480.47 | AI28: 1036.64 | AJ28: 1341.23 | AK28: 1020.98 | AL28: 1240.03 | AM28: 1005.08 | AN28: 1217.9 | AO28: 960.42 | AP28: 1183.39 | AQ28: 864.46 | AR28: 851.14 | AU28: PM-Shoulder | AV28: 5934.99 | AW28: 6026.86 | AX28: 5599.92 | AY28: 6473.46 | AZ28: 4865.72 | BA28: 5493.79 | BB28: 4243.94 | BC28: 4682.98 | BD28: 4423.51 | BE28: 6919.53 | BF28: 4761.36 | BG28: 6146.41 | BH28: 4684.05 | BI28: 5570.75 | BJ28: 4664.67 | BK28: 5581.47 | BL28: 4536.92 | BM28: 5313.31 | BN28: 4173.82 | BO28: 3859.91 | BR28: PM-Shoulder | BS28: 7155.71 | BT28: 7292.4 | BU28: 7004.18 | BV28: 8123.88 | BW28: 5984.91 | BX28: 6792.23 | BY28: 5268.14 | BZ28: 5770.64 | CA28: 5402.21 | CB28: 8400 | CC28: 5798 | CD28: 7487.65 | CE28: 5705.03 | CF28: 6810.78 | CG28: 5669.75 | CH28: 6799.37 | CI28: 5497.34 | CJ28: 6496.7 | CK28: 5038.28 | CL28: 4711.05
B29: PM-Peak | C29: 0.2 | D29: 0.23 | E29: 0.21 | F29: 0.21 | G29: 0.22 | H29: 0.21 | I29: 0.21 | J29: 0.27 | K29: 0.2 | L29: 0.19 | M29: 0.2 | N29: 0.19 | O29: 0.2 | P29: 0.2 | Q29: 0.2 | R29: 0.2 | S29: 0.2 | T29: 0.2 | U29: 0.2 | V29: 0.2 | X29: PM-Peak | Y29: 4345.11 | Z29: 5303.8 | AA29: 4029.06 | AB29: 4656.85 | AC29: 3555 | AD29: 4566.83 | AE29: 3510.43 | AF29: 5125.75 | AG29: 3129.39 | AH29: 4775.52 | AI29: 3204 | AJ29: 4447.38 | AK29: 3179.78 | AL29: 4043.62 | AM29: 3274.52 | AN29: 3532.08 | AO29: 2890.33 | AP29: 2996.08 | AQ29: 2659.05 | AR29: 2646.85 | AU29: PM-Peak | AV29: 20843.34 | AW29: 21486.19 | AX29: 16144.29 | AY29: 18710.21 | AZ29: 14954.25 | BA29: 19759.12 | BB29: 14898.01 | BC29: 16871.81 | BD29: 14441.31 | BE29: 23138.91 | BF29: 15021.87 | BG29: 21300.94 | BH29: 14923.58 | BI29: 19217.06 | BJ29: 15675.53 | BK29: 16833.48 | BL29: 14001.06 | BM29: 14248.4 | BN29: 13012.52 | BO29: 12766.13 | BR29: PM-Peak | BS29: 25188.45 | BT29: 26789.99 | BU29: 20173.35 | BV29: 23367.07 | BW29: 18509.25 | BX29: 24325.95 | BY29: 18408.44 | BZ29: 21997.57 | CA29: 17570.7 | CB29: 27914.42 | CC29: 18225.87 | CD29: 25748.32 | CE29: 18103.36 | CF29: 23260.68 | CG29: 18950.05 | CH29: 20365.56 | CI29: 16891.39 | CJ29: 17244.48 | CK29: 15671.57 | CL29: 15412.98
B30: PM-Late | C30: 0.2 | D30: 0.2 | E30: 0.05 | F30: 0.05 | G30: 0.05 | H30: 0.15 | I30: 0.05 | J30: 0.22 | K30: 0.2 | L30: 0.2 | M30: 0.2 | N30: 0.2 | O30: 0.2 | P30: 0.2 | Q30: 0.2 | R30: 0.2 | S30: 0.21 | T30: 0.2 | U30: 0.2 | V30: 0.2 | X30: PM-Late | Y30: 1883.38 | Z30: 2384 | AA30: 452.01 | AB30: 481.65 | AC30: 340.72 | AD30: 1450.05 | AE30: 388.88 | AF30: 2367.6 | AG30: 1557.16 | AH30: 2302.35 | AI30: 1523.11 | AJ30: 2305.59 | AK30: 1494.63 | AL30: 2028.84 | AM30: 1430.44 | AN30: 1582.31 | AO30: 1389 | AP30: 1378.28 | AQ30: 1390.99 | AR30: 1430.83 | AU30: PM-Late | AV30: 9447.62 | AW30: 11491 | AX30: 8665.14 | AY30: 9236.85 | AZ30: 6670.28 | BA30: 9360 | BB30: 7662.37 | BC30: 10373.4 | BD30: 7997.84 | BE30: 10840.65 | BF30: 7791.89 | BG30: 10867.41 | BH30: 7730.37 | BI30: 9788.16 | BJ30: 7392.56 | BK30: 7945.69 | BL30: 6966 | BM30: 7132.72 | BN30: 7261.01 | BO30: 7683.17 | BR30: PM-Late | BS30: 11331 | BT30: 13875 | BU30: 9117.15 | BV30: 9718.5 | BW30: 7011 | BX30: 10810.05 | BY30: 8051.25 | BZ30: 12741 | CA30: 9555 | CB30: 13143 | CC30: 9315 | CD30: 13173 | CE30: 9225 | CF30: 11817 | CG30: 8823 | CH30: 9528 | CI30: 8355 | CJ30: 8511 | CK30: 8652 | CL30: 9114
B33: Revenue Per Period | X33: ML Flow (PCE/hr) | AU33: GP Flow (PCE/hr) | BR33: Highway Flow
B34: Direction | C34: NB | D34: SB | E34: NB | F34: SB | G34: NB | H34: SB | I34: NB | J34: SB | K34: NB | L34: SB | M34: NB | N34: SB | O34: NB | P34: SB | Q34: NB | R34: SB | S34: NB | T34: SB | U34: NB | V34: SB | X34: Direction | Y34: NB | Z34: SB | AA34: NB | AB34: SB | AC34: NB | AD34: SB | AE34: NB | AF34: SB | AG34: NB | AH34: SB | AI34: NB | AJ34: SB | AK34: NB | AL34: SB | AM34: NB | AN34: SB | AO34: NB | AP34: SB | AQ34: NB | AR34: SB | AU34: Direction | AV34: NB | AW34: SB | AX34: NB | AY34: SB | AZ34: NB | BA34: SB | BB34: NB | BC34: SB | BD34: NB | BE34: SB | BF34: NB | BG34: SB | BH34: NB | BI34: SB | BJ34: NB | BK34: SB | BL34: NB | BM34: SB | BN34: NB | BO34: SB | BR34: Direction | BS34: NB | BT34: SB | BU34: NB | BV34: SB | BW34: NB | BX34: SB | BY34: NB | BZ34: SB | CA34: NB | CB34: SB | CC34: NB | CD34: SB | CE34: NB | CF34: SB | CG34: NB | CH34: SB | CI34: NB | CJ34: SB | CK34: NB | CL34: SB
B35: Segment | C35: 1 | D35: 1 | E35: 2 | F35: 2 | G35: 3 | H35: 3 | I35: 4 | J35: 4 | K35: 5 | L35: 5 | M35: 6 | N35: 6 | O35: 7 | P35: 7 | Q35: 8 | R35: 8 | S35: 9 | T35: 9 | U35: 10 | V35: 10 | X35: Segment | Y35: 1 | Z35: 1 | AA35: 2 | AB35: 2 | AC35: 3 | AD35: 3 | AE35: 4 | AF35: 4 | AG35: 5 | AH35: 5 | AI35: 6 | AJ35: 6 | AK35: 7 | AL35: 7 | AM35: 8 | AN35: 8 | AO35: 9 | AP35: 9 | AQ35: 10 | AR35: 10 | AU35: Segment | AV35: 1 | AW35: 1 | AX35: 2 | AY35: 2 | AZ35: 3 | BA35: 3 | BB35: 4 | BC35: 4 | BD35: 5 | BE35: 5 | BF35: 6 | BG35: 6 | BH35: 7 | BI35: 7 | BJ35: 8 | BK35: 8 | BL35: 9 | BM35: 9 | BN35: 10 | BO35: 10 | BR35: Segment | BS35: 1 | BT35: 1 | BU35: 2 | BV35: 2 | BW35: 3 | BX35: 3 | BY35: 4 | BZ35: 4 | CA35: 5 | CB35: 5 | CC35: 6 | CD35: 6 | CE35: 7 | CF35: 7 | CG35: 8 | CH35: 8 | CI35: 9 | CJ35: 9 | CK35: 10 | CL35: 10
B36: Period | X36: Period | AU36: Period | BR36: Period
B37: Night | C37: 76.5 | D37: 76.08 | E37: 63.1 | F37: 58.34 | G37: 21.84 | H37: 26.9 | I37: 56.38 | J37: 58.73 | K37: 76.97 | L37: 68.83 | M37: 140.2 | N37: 122.19 | O37: 109.44 | P37: 96.89 | Q37: 140.4 | R37: 129.36 | S37: 110.22 | T37: 89.25 | U37: 151.38 | V37: 126.47 | X37: Night | Y37: 37.45 | Z37: 37.15 | AA37: 32.39 | AB37: 29.78 | AC37: 27.65 | AD37: 34.78 | AE37: 21.28 | AF37: 21.78 | AG37: 23.09 | AH37: 20.33 | AI37: 23.34 | AJ37: 20.01 | AK37: 22.6 | AL37: 19.43 | AM37: 21.93 | AN37: 19.98 | AO37: 19.36 | AP37: 14.77 | AQ37: 19.51 | AR37: 15.47 | AU37: Night | AV37: 2215.95 | AW37: 2201.05 | AX37: 1671.61 | AY37: 1564.22 | AZ37: 1596.35 | BA37: 1902.27 | BB37: 2055.42 | BC37: 2044.22 | BD37: 2339.91 | BE37: 2064.67 | BF37: 2342.66 | BG37: 2024.99 | BH37: 2295.4 | BI37: 1950.57 | BJ37: 2201.07 | BK37: 2004.02 | BL37: 1934.64 | BM37: 1492.23 | BN37: 1961.49 | BO37: 1554.53 | BR37: Night | BS37: 2253.4 | BT37: 2238.2 | BU37: 1704 | BV37: 1594 | BW37: 1624 | BX37: 1937.05 | BY37: 2076.7 | BZ37: 2066 | CA37: 2363 | CB37: 2085 | CC37: 2366 | CD37: 2045 | CE37: 2318 | CF37: 1970 | CG37: 2223 | CH37: 2024 | CI37: 1954 | CJ37: 1507 | CK37: 1981 | CL37: 1570
B38: AM-Early | C38: 608.66 | D38: 267.81 | E38: 465.46 | F38: 224.54 | G38: 149.65 | H38: 134.26 | I38: 717.61 | J38: 705.73 | K38: 931.99 | L38: 666.61 | M38: 1977.96 | N38: 1245.67 | O38: 1471.03 | P38: 1135.3 | Q38: 1735 | R38: 1184.4 | S38: 1469.23 | T38: 842.46 | U38: 1678.38 | V38: 705.01 | X38: AM-Early | Y38: 968.64 | Z38: 594.38 | AA38: 963.53 | AB38: 616.75 | AC38: 636.93 | AD38: 788.09 | AE38: 1078.02 | AF38: 739.56 | AG38: 1027.82 | AH38: 696.81 | AI38: 992.78 | AJ38: 702.78 | AK38: 855.38 | AL38: 748.4 | AM38: 813.18 | AN38: 721.12 | AO38: 793.56 | AP38: 594.84 | AQ38: 914.53 | AR38: 562.15 | AU38: AM-Early | AV38: 5467.61 | AW38: 3587.52 | AX38: 4806.77 | AY38: 3217.45 | AZ38: 3355.07 | BA38: 4119.61 | BB38: 5506.43 | BC38: 4020.44 | BD38: 5691.53 | BE38: 4079.19 | BF38: 5526.12 | BG38: 4146.22 | BH38: 4849.62 | BI38: 4374.6 | BJ38: 4652.32 | BK38: 4177.08 | BL38: 4550.66 | BM38: 3560.75 | BN38: 5388.72 | BO38: 3444.95 | BR38: AM-Early | BS38: 6436.25 | BT38: 4181.9 | BU38: 5770.3 | BV38: 3834.2 | BW38: 3992 | BX38: 4907.7 | BY38: 6584.45 | BZ38: 4760 | CA38: 6719.35 | CB38: 4776 | CC38: 6518.9 | CD38: 4849 | CE38: 5705 | CF38: 5123 | CG38: 5465.5 | CH38: 4898.2 | CI38: 5344.21 | CJ38: 4155.59 | CK38: 6303.25 | CL38: 4007.1
B39: AM-Peak | C39: 9572.4 | D39: 132.09 | E39: 15405.78 | F39: 108.6 | G39: 2636.43 | H39: 4993.83 | I39: 8792.11 | J39: 3822.63 | K39: 12499.34 | L39: 4172.85 | M39: 26435.94 | N39: 7533.17 | O39: 27926.4 | P39: 6131.6 | Q39: 30440.84 | R39: 7362.73 | S39: 8303.59 | T39: 5188.03 | U39: 6422.19 | V39: 5185.45 | X39: AM-Peak | Y39: 1475.37 | Z39: 148.33 | AA39: 1466.92 | AB39: 129.29 | AC39: 1053.05 | AD39: 2011.17 | AE39: 1184.18 | AF39: 847.71 | AG39: 1261.07 | AH39: 767.28 | AI39: 1479.11 | AJ39: 759.18 | AK39: 1921.58 | AL39: 757.36 | AM39: 1600.26 | AN39: 740.98 | AO39: 825.75 | AP39: 644.78 | AQ39: 635.2 | AR39: 564.96 | AU39: AM-Peak | AV39: 6938.64 | AW39: 3033.22 | AX39: 7723.88 | AY39: 2469.16 | AZ39: 5201.8 | BA39: 7412.42 | BB39: 6477.13 | BC39: 4758.94 | BD39: 6904.91 | BE39: 4699.59 | BF39: 7189.29 | BG39: 4710.99 | BH39: 7678.42 | BI39: 4736.54 | BJ39: 7125.94 | BK39: 4546.99 | BL39: 5017.62 | BM39: 4094.92 | BN39: 3959.77 | BO39: 3583.83 | BR39: AM-Peak | BS39: 8414.02 | BT39: 3181.55 | BU39: 9190.8 | BV39: 2598.45 | BW39: 6254.85 | BX39: 9423.58 | BY39: 7661.31 | BZ39: 5606.65 | CA39: 8165.98 | CB39: 5466.87 | CC39: 8668.4 | CD39: 5470.16 | CE39: 9600 | CF39: 5493.9 | CG39: 8726.2 | CH39: 5287.97 | CI39: 5843.36 | CJ39: 4739.7 | CK39: 4594.97 | CL39: 4148.79
B40: AM-Shoulder | C40: 2740.33 | D40: 357.4 | E40: 2788.17 | F40: 45.89 | G40: 949.52 | H40: 1076.65 | I40: 1736.23 | J40: 965.25 | K40: 2475.21 | L40: 994.01 | M40: 4853.81 | N40: 1671.08 | O40: 3875.71 | P40: 1336.99 | Q40: 2859.8 | R40: 1558.31 | S40: 1409.37 | T40: 1212.94 | U40: 1525.22 | V40: 1357.87 | X40: AM-Shoulder | Y40: 1250.12 | Z40: 528.88 | AA40: 1335.12 | AB40: 160.44 | AC40: 1128.35 | AD40: 1289.98 | AE40: 1076.41 | AF40: 849.34 | AG40: 1063.62 | AH40: 773.16 | AI40: 1078.56 | AJ40: 739.4 | AK40: 1066.69 | AL40: 733.14 | AM40: 905.19 | AN40: 706.64 | AO40: 719.74 | AP40: 639.23 | AQ40: 638.58 | AR40: 596.77 | AU40: AM-Shoulder | AV40: 7149.88 | AW40: 3462.52 | AX40: 7064.88 | AY40: 3066.16 | AZ40: 6060.38 | BA40: 7110.02 | BB40: 6084.04 | BC40: 4973.35 | BD40: 6548.56 | BE40: 4855.68 | BF40: 6702.52 | BG40: 4733.65 | BH40: 6696.04 | BI40: 4724.28 | BJ40: 5647.52 | BK40: 4493.39 | BL40: 4508.7 | BM40: 4253.96 | BN40: 4145.41 | BO40: 3942.45 | BR40: AM-Shoulder | BS40: 8400 | BT40: 3991.4 | BU40: 8400 | BV40: 3226.6 | BW40: 7188.73 | BX40: 8400 | BY40: 7160.45 | BZ40: 5822.68 | CA40: 7612.18 | CB40: 5628.84 | CC40: 7781.09 | CD40: 5473.04 | CE40: 7762.73 | CF40: 5457.42 | CG40: 6552.71 | CH40: 5200.03 | CI40: 5228.44 | CJ40: 4893.18 | CK40: 4783.99 | CL40: 4539.21
B41: MD | C41: 8252.97 | D41: 5292.43 | E41: 5692.05 | F41: 2642.99 | G41: 1885.19 | H41: 3754.97 | I41: 3110.49 | J41: 6351.9 | K41: 7079.81 | L41: 8005.25 | M41: 10750.51 | N41: 9700.61 | O41: 7347 | P41: 6996.9 | Q41: 8508.72 | R41: 7775.83 | S41: 6807.49 | T41: 5600.65 | U41: 7589.24 | V41: 6138.58 | X41: MD | Y41: 760.46 | Z41: 844.47 | AA41: 972.54 | AB41: 1003.92 | AC41: 685.48 | AD41: 923.27 | AE41: 878.99 | AF41: 892.14 | AG41: 937.91 | AH41: 949.88 | AI41: 876.82 | AJ41: 882.77 | AK41: 817.9 | AL41: 856.71 | AM41: 769.67 | AN41: 746.41 | AO41: 715.67 | AP41: 698.8 | AQ41: 674.98 | AR41: 755.73 | AU41: MD | AV41: 4650.54 | AW41: 5155.53 | AX41: 4963.46 | AY41: 5119.78 | AZ41: 3790.52 | BA41: 5008.44 | BB41: 4759.26 | BC41: 4909.86 | BD41: 5511.37 | BE41: 5620.12 | BF41: 5191.25 | BG41: 5233.33 | BH41: 4880.69 | BI41: 5084.59 | BJ41: 4649.43 | BK41: 4474.92 | BL41: 4372.33 | BM41: 4234.55 | BN41: 4210.87 | BO41: 4683.02 | BR41: MD | BS41: 5411 | BT41: 6000 | BU41: 5936 | BV41: 6123.7 | BW41: 4476 | BX41: 5931.71 | BY41: 5638.25 | BZ41: 5802 | CA41: 6449.29 | CB41: 6570 | CC41: 6068.06 | CD41: 6116.1 | CE41: 5698.59 | CF41: 5941.3 | CG41: 5419.09 | CH41: 5221.34 | CI41: 5088 | CJ41: 4933.35 | CK41: 4885.85 | CL41: 5438.75
B42: PM-Shoulder | C42: 2396.28 | D42: 2416.42 | E42: 1236.08 | F42: 2105.19 | G42: 803.44 | H42: 867.15 | I42: 687.88 | J42: 2303.6 | K42: 818.13 | L42: 3384.29 | M42: 1773.09 | N42: 3849.18 | O42: 1369.1 | P42: 2229.31 | Q42: 1775.38 | R42: 2937.37 | S42: 1481.48 | T42: 2265.65 | U42: 1608.49 | V42: 1344.82 | X42: PM-Shoulder | Y42: 1220.71 | Z42: 1265.54 | AA42: 1404.26 | AB42: 1650.41 | AC42: 1119.18 | AD42: 1298.45 | AE42: 1024.21 | AF42: 1087.66 | AG42: 978.7 | AH42: 1480.47 | AI42: 1036.64 | AJ42: 1341.23 | AK42: 1020.98 | AL42: 1240.03 | AM42: 1005.08 | AN42: 1217.9 | AO42: 960.42 | AP42: 1183.39 | AQ42: 864.46 | AR42: 851.14 | AU42: PM-Shoulder | AV42: 5934.99 | AW42: 6026.86 | AX42: 5599.92 | AY42: 6473.46 | AZ42: 4865.72 | BA42: 5493.79 | BB42: 4243.94 | BC42: 4682.98 | BD42: 4423.51 | BE42: 6919.53 | BF42: 4761.36 | BG42: 6146.41 | BH42: 4684.05 | BI42: 5570.75 | BJ42: 4664.67 | BK42: 5581.47 | BL42: 4536.92 | BM42: 5313.31 | BN42: 4173.82 | BO42: 3859.91 | BR42: PM-Shoulder | BS42: 7155.71 | BT42: 7292.4 | BU42: 7004.18 | BV42: 8123.88 | BW42: 5984.91 | BX42: 6792.23 | BY42: 5268.14 | BZ42: 5770.64 | CA42: 5402.21 | CB42: 8400 | CC42: 5798 | CD42: 7487.65 | CE42: 5705.03 | CF42: 6810.78 | CG42: 5669.75 | CH42: 6799.37 | CI42: 5497.34 | CJ42: 6496.7 | CK42: 5038.28 | CL42: 4711.05
B43: PM-Peak | C43: 12153.61 | D43: 11407.67 | E43: 4472.8 | F43: 7038.18 | G43: 2919.63 | H43: 4129.72 | I43: 4287.43 | J43: 13534.74 | K43: 4539.25 | L43: 20441.4 | M43: 9014.1 | N43: 26259.02 | O43: 7137.58 | P43: 14635.26 | Q43: 10594.42 | R43: 12829.38 | S43: 7180.17 | T43: 7480.59 | U43: 8043.32 | V43: 7702.66 | X43: PM-Peak | Y43: 1448.37 | Z43: 1767.93 | AA43: 1343.02 | AB43: 1552.28 | AC43: 1185 | AD43: 1522.28 | AE43: 1170.14 | AF43: 1708.58 | AG43: 1043.13 | AH43: 1591.84 | AI43: 1068 | AJ43: 1482.46 | AK43: 1059.93 | AL43: 1347.87 | AM43: 1091.51 | AN43: 1177.36 | AO43: 963.44 | AP43: 998.69 | AQ43: 886.35 | AR43: 882.28 | AU43: PM-Peak | AV43: 6947.78 | AW43: 7162.06 | AX43: 5381.43 | AY43: 6236.74 | AZ43: 4984.75 | BA43: 6586.37 | BB43: 4966 | BC43: 5623.94 | BD43: 4813.77 | BE43: 7712.97 | BF43: 5007.29 | BG43: 7100.31 | BH43: 4974.53 | BI43: 6405.69 | BJ43: 5225.18 | BK43: 5611.16 | BL43: 4667.02 | BM43: 4749.47 | BN43: 4337.51 | BO43: 4255.38 | BR43: PM-Peak | BS43: 8396.15 | BT43: 8930 | BU43: 6724.45 | BV43: 7789.02 | BW43: 6169.75 | BX43: 8108.65 | BY43: 6136.15 | BZ43: 7332.52 | CA43: 5856.9 | CB43: 9304.81 | CC43: 6075.29 | CD43: 8582.77 | CE43: 6034.45 | CF43: 7753.56 | CG43: 6316.68 | CH43: 6788.52 | CI43: 5630.46 | CJ43: 5748.16 | CK43: 5223.86 | CL43: 5137.66
B44: PM-Late | C44: 1232.83 | D44: 1854.63 | E44: 125.6 | F44: 133.9 | G44: 39.14 | H44: 254.18 | I44: 143.87 | J44: 3258.44 | K44: 1581.27 | L44: 3922.47 | M44: 3780.49 | N44: 6629.13 | O44: 3211.49 | P44: 3876.12 | Q44: 3698.62 | R44: 3665.85 | S44: 2994.05 | T44: 2540.76 | U44: 3475.38 | V44: 2900.86 | X44: PM-Late | Y44: 627.79 | Z44: 794.67 | AA44: 150.67 | AB44: 160.55 | AC44: 113.57 | AD44: 483.35 | AE44: 129.63 | AF44: 789.2 | AG44: 519.05 | AH44: 767.45 | AI44: 507.7 | AJ44: 768.53 | AK44: 498.21 | AL44: 676.28 | AM44: 476.81 | AN44: 527.44 | AO44: 463 | AP44: 459.43 | AQ44: 463.66 | AR44: 476.94 | AU44: PM-Late | AV44: 3149.21 | AW44: 3830.33 | AX44: 2888.38 | AY44: 3078.95 | AZ44: 2223.43 | BA44: 3120 | BB44: 2554.12 | BC44: 3457.8 | BD44: 2665.95 | BE44: 3613.55 | BF44: 2597.3 | BG44: 3622.47 | BH44: 2576.79 | BI44: 3262.72 | BJ44: 2464.19 | BK44: 2648.56 | BL44: 2322 | BM44: 2377.57 | BN44: 2420.34 | BO44: 2561.06 | BR44: PM-Late | BS44: 3777 | BT44: 4625 | BU44: 3039.05 | BV44: 3239.5 | BW44: 2337 | BX44: 3603.35 | BY44: 2683.75 | BZ44: 4247 | CA44: 3185 | CB44: 4381 | CC44: 3105 | CD44: 4391 | CE44: 3075 | CF44: 3939 | CG44: 2941 | CH44: 3176 | CI44: 2785 | CJ44: 2837 | CK44: 2884 | CL44: 3038
B47: Revenue Per Period Lights | X47: ML V/C | AU47: GP V/C real | BR47: Highway Vol / GP Capacity
...

Sheet Year_2032
B1: Lenght
C2: 1 | D2: 2 | E2: 3 | F2: 4 | G2: 5 | H2: 6 | I2: 7 | J2: 8 | K2: 9 | L2: 10
B3: Length | C3: 1.3 | D3: 1.3 | E3: 0.5 | F3: 1.6 | G3: 2 | H3: 3.6 | I3: 2.9 | J3: 3.8 | K3: 3.4 | L3: 4.5
B5: TollLights | X5: ML PCE.Miles | AU5: GP PCE.Miles | BR5: Highway PCE.Miles
B6: Direction | C6: NB | D6: SB | E6: NB | F6: SB | G6: NB | H6: SB | I6: NB | J6: SB | K6: NB | L6: SB | M6: NB | N6: SB | O6: NB | P6: SB | Q6: NB | R6: SB | S6: NB | T6: SB | U6: NB | V6: SB | X6: Direction | Y6: NB | Z6: SB | AA6: NB | AB6: SB | AC6: NB | AD6: SB | AE6: NB | AF6: SB | AG6: NB | AH6: SB | AI6: NB | AJ6: SB | AK6: NB | AL6: SB | AM6: NB | AN6: SB | AO6: NB | AP6: SB | AQ6: NB | AR6: SB | AU6: Direction | AV6: NB | AW6: SB | AX6: NB | AY6: SB | AZ6: NB | BA6: SB | BB6: NB | BC6: SB | BD6: NB | BE6: SB | BF6: NB | BG6: SB | BH6: NB | BI6: SB | BJ6: NB | BK6: SB | BL6: NB | BM6: SB | BN6: NB | BO6: SB | BR6: Direction | BS6: NB | BT6: SB | BU6: NB | BV6: SB | BW6: NB | BX6: SB | BY6: NB | BZ6: SB | CA6: NB | CB6: SB | CC6: NB | CD6: SB | CE6: NB | CF6: SB | CG6: NB | CH6: SB | CI6: NB | CJ6: SB | CK6: NB | CL6: SB
B7: Segment | C7: 1 | D7: 1 | E7: 2 | F7: 2 | G7: 3 | H7: 3 | I7: 4 | J7: 4 | K7: 5 | L7: 5 | M7: 6 | N7: 6 | O7: 7 | P7: 7 | Q7: 8 | R7: 8 | S7: 9 | T7: 9 | U7: 10 | V7: 10 | X7: Segment | Y7: 1 | Z7: 1 | AA7: 2 | AB7: 2 | AC7: 3 | AD7: 3 | AE7: 4 | AF7: 4 | AG7: 5 | AH7: 5 | AI7: 6 | AJ7: 6 | AK7: 7 | AL7: 7 | AM7: 8 | AN7: 8 | AO7: 9 | AP7: 9 | AQ7: 10 | AR7: 10 | AU7: Segment | AV7: 1 | AW7: 1 | AX7: 2 | AY7: 2 | AZ7: 3 | BA7: 3 | BB7: 4 | BC7: 4 | BD7: 5 | BE7: 5 | BF7: 6 | BG7: 6 | BH7: 7 | BI7: 7 | BJ7: 8 | BK7: 8 | BL7: 9 | BM7: 9 | BN7: 10 | BO7: 10 | BR7: Segment | BS7: 1 | BT7: 1 | BU7: 2 | BV7: 2 | BW7: 3 | BX7: 3 | BY7: 4 | BZ7: 4 | CA7: 5 | CB7: 5 | CC7: 6 | CD7: 6 | CE7: 7 | CF7: 7 | CG7: 8 | CH7: 8 | CI7: 9 | CJ7: 9 | CK7: 10 | CL7: 10
B8: Period | X8: Period | AU8: Period | BR8: Period
B9: Night | C9: 0.2 | D9: 0.2 | E9: 0.2 | F9: 0.2 | G9: 0.2 | H9: 0.2 | I9: 0.2 | J9: 0.2 | K9: 0.2 | L9: 0.2 | M9: 0.2 | N9: 0.2 | O9: 0.2 | P9: 0.2 | Q9: 0.2 | R9: 0.2 | S9: 0.2 | T9: 0.2 | U9: 0.2 | V9: 0.2 | X9: Night | Y9: 3478.61 | Z9: 3313.49 | AA9: 1001.51 | AB9: 914.74 | AC9: 305.11 | AD9: 399.02 | AE9: 2366.17 | AF9: 2214.24 | AG9: 7137.2 | AH9: 2346.4 | AI9: 13043.52 | AJ9: 3150.85 | AK9: 9810.99 | AL9: 1025.15 | AM9: 9544.08 | AN9: 2981.86 | AO9: 566.94 | AP9: 432.45 | AQ9: 4346.35 | AR9: 606.33 | AU9: Night | AV9: 21840 | AW9: 21840 | AX9: 18821.02 | AY9: 17631.97 | AZ9: 6872.34 | BA9: 8162.53 | BB9: 26880 | BC9: 26880 | BD9: 33600 | BE9: 33600 | BF9: 60480 | BG9: 60398.51 | BH9: 48720 | BI9: 48720 | BJ9: 63840 | BK9: 63840 | BL9: 56664.92 | BM9: 43702.27 | BN9: 73279.1 | BO9: 60906.87 | BR9: Night | BS9: 25318.61 | BT9: 25153.49 | BU9: 19822.53 | BV9: 18546.71 | BW9: 7177.45 | BX9: 8561.54 | BY9: 29246.17 | BZ9: 29094.24 | CA9: 40737.2 | CB9: 35946.4 | CC9: 73523.52 | CD9: 63549.36 | CE9: 58530.99 | CF9: 49745.15 | CG9: 73384.08 | CH9: 66821.86 | CI9: 57231.86 | CJ9: 44134.72 | CK9: 77625.45 | CL9: 61513.2
B10: AM-Early | C10: 0.89 | D10: 0.55 | E10: 0.69 | F10: 0.46 | G10: 0.81 | H10: 0.58 | I10: 0.82 | J10: 1.13 | K10: 0.91 | L10: 0.86 | M10: 1.18 | N10: 0.89 | O10: 1.23 | P10: 0.99 | Q10: 1.12 | R10: 0.78 | S10: 1.05 | T10: 0.71 | U10: 0.78 | V10: 0.47 | X10: AM-Early | Y10: 1545.56 | Z10: 952.75 | AA10: 1589.4 | AB10: 1022.77 | AC10: 401.86 | AD10: 496.92 | AE10: 2143.03 | AF10: 1481.81 | AG10: 2500.65 | AH10: 1709.99 | AI10: 4310.16 | AJ10: 3099.93 | AK10: 3048.29 | AL10: 2681.05 | AM10: 3786.73 | AN10: 3374.37 | AO10: 3287.42 | AP10: 2480.22 | AQ10: 5028.15 | AR10: 3131.99 | AU10: AM-Early | AV10: 8786.95 | AW10: 5759.97 | AX10: 8001.61 | AY10: 5350.08 | AZ10: 2118.84 | BA10: 2602.02 | BB10: 11102.56 | BC10: 8093.87 | BD10: 14047.02 | BE10: 10051.61 | BF10: 24628.86 | BG10: 18425.91 | BH10: 17532.43 | BI10: 15799.78 | BJ10: 21991.14 | BK10: 19726.74 | BL10: 19073.24 | BM10: 14907.36 | BN10: 30255.99 | BO10: 19299.36 | BR10: AM-Early | BS10: 10332.5 | BT10: 6712.72 | BU10: 9591.01 | BV10: 6372.85 | BW10: 2520.7 | BX10: 3098.95 | BY10: 13245.58 | BZ10: 9575.68 | CA10: 16547.67 | CB10: 11761.6 | CC10: 28939.01 | CD10: 21525.84 | CE10: 20580.72 | CF10: 18480.83 | CG10: 25777.87 | CH10: 23101.11 | CI10: 22360.66 | CJ10: 17387.59 | CK10: 35284.14 | CL10: 22431.35
B11: AM-Peak | C11: 3.76 | D11: 0.63 | E11: 4.45 | F11: 1.25 | G11: 1.8 | H11: 1.8 | I11: 1.8 | J11: 1.79 | K11: 1.8 | L11: 1.65 | M11: 1.8 | N11: 1.68 | O11: 1.8 | P11: 1.72 | Q11: 1.8 | R11: 1.59 | S11: 1.8 | T11: 1.35 | U11: 1.3 | V11: 1.15 | X11: AM-Peak | Y11: 7412.58 | Z11: 2128.72 | AA11: 7016.27 | AB11: 789.01 | AC11: 3076.97 | AD11: 2842.76 | AE11: 10537.03 | AF11: 5076.22 | AG11: 13942.63 | AH11: 5635.61 | AI11: 25655.43 | AJ11: 10012.91 | AK11: 20596.9 | AL11: 8130.79 | AM11: 26386.15 | AN11: 10377.27 | AO11: 10549.36 | AP11: 8054.58 | AQ11: 10591.45 | AR11: 9442.76 | AU11: AM-Peak | AV11: 32211.42 | AW11: 13193.54 | AX11: 32574.37 | AY11: 12168 | AZ11: 8771.37 | BA11: 10477.24 | BB11: 35697.62 | BC11: 28760.66 | BD11: 46389.03 | BE11: 34752.86 | BF11: 84072.57 | BG11: 62840.28 | BH11: 67795.1 | BI11: 51325.95 | BJ11: 85523.04 | BK11: 64441.17 | BL11: 62798.66 | BM11: 51440.13 | BN11: 66571.32 | BO11: 60226.94 | BR11: AM-Peak | BS11: 39624 | BT11: 15322.26 | BU11: 39590.65 | BV11: 12957.01 | BW11: 11848.34 | BX11: 13320 | BY11: 46234.65 | BZ11: 33836.87 | CA11: 60331.66 | CB11: 40388.47 | CC11: 109728 | CD11: 72853.2 | CE11: 88392 | CF11: 59456.74 | CG11: 111909.19 | CH11: 74818.44 | CI11: 73348.03 | CJ11: 59494.71 | CK11: 77162.77 | CL11: 69669.7
B12: AM-Shoulder | C12: 1.8 | D12: 0.84 | E12: 1.8 | F12: 0.41 | G12: 2.97 | H12: 2.8 | I12: 1.8 | J12: 1.45 | K12: 1.8 | L12: 1.24 | M12: 1.8 | N12: 1.19 | O12: 1.8 | P12: 1.21 | Q12: 1.8 | R12: 1.08 | S12: 1.06 | T12: 0.98 | U12: 0.95 | V12: 0.88 | X12: AM-Shoulder | Y12: 2181.24 | Z12: 848.69 | AA12: 2272.28 | AB12: 836.14 | AC12: 553.2 | AD12: 663.57 | AE12: 2609.52 | AF12: 1698.86 | AG12: 3063.6 | AH12: 1896 | AI12: 5510.92 | AJ12: 3262.93 | AK12: 4424.85 | AL12: 2631.82 | AM12: 4402.89 | AN12: 3314.08 | AO12: 2995.21 | AP12: 2667.44 | AQ12: 3559.74 | AR12: 3330.49 | AU12: AM-Shoulder | AV12: 9362.76 | AW12: 5559.09 | AX12: 9271.72 | AY12: 4526.43 | AZ12: 3246.55 | BA12: 3776.43 | BB12: 11598.48 | BC12: 10014.7 | BD12: 14696.4 | BE12: 11965.93 | BF12: 26457.08 | BG12: 21034.87 | BH12: 21327.15 | BI12: 17055.79 | BJ12: 26502.69 | BK12: 21210.24 | BL12: 18881.82 | BM12: 17806.34 | BN12: 23220.48 | BO12: 22079.7 | BR12: AM-Shoulder | BS12: 11544 | BT12: 6407.78 | BU12: 11544 | BV12: 5362.56 | BW12: 3799.76 | BX12: 4440 | BY12: 14208 | BZ12: 11713.56 | CA12: 17760 | CB12: 13861.93 | CC12: 31968 | CD12: 24297.8 | CE12: 25752 | CF12: 19687.61 | CG12: 30905.58 | CH12: 24524.32 | CI12: 21877.04 | CJ12: 20473.79 | CK12: 26780.22 | CL12: 25410.19
B13: MD | C13: 1.8 | D13: 1.8 | E13: 1.8 | F13: 0.78 | G13: 1.8 | H13: 1.8 | I13: 0.8 | J13: 1.8 | K13: 1.68 | L13: 1.8 | M13: 1.44 | N13: 1.24 | O13: 1.26 | P13: 1.13 | Q13: 1.13 | R13: 1.04 | S13: 1.03 | T13: 0.84 | U13: 0.9 | V13: 0.63 | X13: MD | Y13: 7234.78 | Z13: 7725.86 | AA13: 9290.34 | AB13: 8275.45 | AC13: 2759.42 | AD13: 3031.89 | AE13: 8790.82 | AF13: 9907.27 | AG13: 11421.09 | AH13: 12271.43 | AI13: 19181.58 | AJ13: 19330.12 | AK13: 14621.26 | AL13: 15300.41 | AM13: 17991.29 | AN13: 17461.41 | AO13: 14890.22 | AP13: 14543.14 | AQ13: 18781.11 | AR13: 20960.34 | AU13: MD | AV13: 30613.43 | AW13: 40431.99 | AX13: 39579.05 | AY13: 42614.57 | AZ13: 11192.13 | BA13: 12524.32 | BB13: 47921.9 | BC13: 48449.53 | BD13: 67990.03 | BE13: 68625.57 | BF13: 115513.21 | BG13: 116421.65 | BH13: 88162.58 | BI13: 91869.09 | BJ13: 109792.72 | BK13: 105662.93 | BL13: 91558.68 | BM13: 88668.28 | BN13: 117963.32 | BO13: 131268.14 | BR13: MD | BS13: 37848.21 | BT13: 48157.85 | BU13: 48869.39 | BV13: 50890.03 | BW13: 13951.56 | BX13: 15556.21 | BY13: 56712.72 | BZ13: 58356.8 | CA13: 79411.12 | CB13: 80897 | CC13: 134694.79 | CD13: 135751.77 | CE13: 102783.84 | CF13: 107169.5 | CG13: 127784.01 | CH13: 123124.34 | CI13: 106448.9 | CJ13: 103211.42 | CK13: 136744.43 | CL13: 152228.48
B14: PM-Shoulder | C14: 1.8 | D14: 2.44 | E14: 2 | F14: 1.94 | G14: 1.8 | H14: 2.21 | I14: 0.82 | J14: 1.8 | K14: 0.82 | L14: 1.95 | M14: 1 | N14: 2.03 | O14: 0.98 | P14: 1.64 | Q14: 0.98 | R14: 1.67 | S14: 0.9 | T14: 1.35 | U14: 0.8 | V14: 0.67 | X14: PM-Shoulder | Y14: 2020.19 | Z14: 1722.34 | AA14: 2238.3 | AB14: 2284.8 | AC14: 689.68 | AD14: 683.29 | AE14: 2041.99 | AF14: 2044.01 | AG14: 2388.83 | AH14: 3071.05 | AI14: 4511.18 | AJ14: 5427.1 | AK14: 3625.59 | AL14: 4306.09 | AM14: 4649.81 | AN14: 5486.89 | AO14: 3964.18 | AP14: 4788.61 | AQ14: 4776.59 | AR14: 4700.17 | AU14: PM-Shoulder | AV14: 7813.79 | AW14: 8299.5 | AX14: 9305.7 | AY14: 9259.2 | AZ14: 2473.77 | BA14: 2906.89 | BB14: 8555.56 | BC14: 7716.62 | BD14: 10914.7 | BE14: 14688.95 | BF14: 21226.69 | BG14: 26540.9 | BH14: 16955.67 | BI14: 20263.02 | BJ14: 22090.29 | BK14: 26580.04 | BL14: 19038.33 | BM14: 22393.24 | BN14: 23425.11 | BO14: 21671.29 | BR14: PM-Shoulder | BS14: 9833.99 | BT14: 10021.84 | BU14: 11544 | BV14: 11544 | BW14: 3163.45 | BX14: 3590.18 | BY14: 10597.55 | BZ14: 9760.62 | CA14: 13303.53 | CB14: 17760 | CC14: 25737.86 | CD14: 31968 | CE14: 20581.26 | CF14: 24569.11 | CG14: 26740.1 | CH14: 32066.92 | CI14: 23002.51 | CJ14: 27181.85 | CK14: 28201.69 | CL14: 26371.46
B15: PM-Peak | C15: 3.7 | D15: 3.88 | E15: 2.23 | F15: 3.6 | G15: 1.8 | H15: 3.89 | I15: 1.63 | J15: 1.8 | K15: 1.44 | L15: 3.6 | M15: 1.62 | N15: 1.8 | O15: 1.62 | P15: 1.8 | Q15: 1.8 | R15: 2.27 | S15: 1.41 | T15: 1.44 | U15: 1.27 | V15: 1.22 | X15: PM-Peak | Y15: 7411.44 | Z15: 7546.53 | AA15: 6469.67 | AB15: 7626.09 | AC15: 2421.65 | AD15: 2799.42 | AE15: 6920.81 | AF15: 10138.88 | AG15: 7590.21 | AH15: 11078.69 | AI15: 13800.89 | AJ15: 26373.38 | AK15: 11192.38 | AL15: 18968.3 | AM15: 15182.32 | AN15: 15857.01 | AO15: 11870.04 | AP15: 12264.25 | AQ15: 14594.53 | AR15: 14521.96 | AU15: PM-Peak | AV15: 30038.97 | AW15: 32077.47 | AX15: 27060.83 | AY15: 31212.28 | AZ15: 7603.51 | BA15: 11412.06 | BB15: 30110.46 | BC15: 27110.34 | BD15: 35680.2 | BE15: 49881.31 | BF15: 67109.57 | BG15: 83354.62 | BH15: 54115.69 | BI15: 64946.25 | BJ15: 74188.42 | BK15: 80192.09 | BL15: 58809.34 | BM15: 59890.74 | BN15: 73130.34 | BO15: 71754.7 | BR15: PM-Peak | BS15: 37450.41 | BT15: 39624 | BU15: 33530.51 | BV15: 38838.37 | BW15: 10025.16 | BX15: 14211.48 | BY15: 37031.27 | BZ15: 37249.22 | CA15: 43270.41 | CB15: 60960 | CC15: 80910.47 | CD15: 109728 | CE15: 65308.07 | CF15: 83914.55 | CG15: 89370.74 | CH15: 96049.1 | CI15: 70679.38 | CJ15: 72154.98 | CK15: 87724.87 | CL15: 86276.67
B16: PM-Late | C16: 0.87 | D16: 1.14 | E16: 0.27 | F16: 0.28 | G16: 0.2 | H16: 0.34 | I16: 0.7 | J16: 1.57 | K16: 0.9 | L16: 1.54 | M16: 1.32 | N16: 1.53 | O16: 1.48 | P16: 1.35 | Q16: 1.3 | R16: 1.14 | S16: 1.19 | T16: 0.95 | U16: 1 | V16: 0.78 | X16: PM-Late | Y16: 3019.94 | Z16: 3814.59 | AA16: 2985.45 | AB16: 3184.83 | AC16: 215.14 | AD16: 1266.93 | AE16: 1220.21 | AF16: 4323.76 | AG16: 3831.29 | AH16: 5183.06 | AI16: 6746.02 | AJ16: 9567.34 | AK16: 5379.85 | AL16: 7273.93 | AM16: 6734.19 | AN16: 7444.3 | AO16: 5668.86 | AP16: 5760.8 | AQ16: 7778.39 | AR16: 7999.97 | AU16: PM-Late | AV16: 15169.66 | AW16: 18459.09 | AX16: 12168 | AY16: 12967.85 | AZ16: 4211.62 | BA16: 5559.39 | BB16: 14976 | BC16: 19056.81 | BD16: 19698.91 | BE16: 24551.19 | BF16: 34605.02 | BG16: 45647.86 | BH16: 27896.78 | BI16: 35354.33 | BJ16: 34879.23 | BK16: 37491.08 | BL16: 29288.58 | BM16: 29851.48 | BN16: 40652.86 | BO16: 43016.53 | BR16: PM-Late | BS16: 18189.6 | BT16: 22273.68 | BU16: 15153.45 | BV16: 16152.69 | BW16: 4426.76 | BX16: 6826.32 | BY16: 16196.21 | BZ16: 23380.57 | CA16: 23530.2 | CB16: 29734.25 | CC16: 41351.04 | CD16: 55215.2 | CE16: 33276.63 | CF16: 42628.26 | CG16: 41613.42 | CH16: 44935.38 | CI16: 34957.44 | CJ16: 35612.28 | CK16: 48431.25 | CL16: 51016.5
B19: CaptureRateLights | X19: ML Volume (PCE/Period) | AU19: GP Volume (PCE/Period) | BR19: Highway Volume
B20: Direction | C20: NB | D20: SB | E20: NB | F20: SB | G20: NB | H20: SB | I20: NB | J20: SB | K20: NB | L20: SB | M20: NB | N20: SB | O20: NB | P20: SB | Q20: NB | R20: SB | S20: NB | T20: SB | U20: NB | V20: SB | X20: Direction | Y20: NB | Z20: SB | AA20: NB | AB20: SB | AC20: NB | AD20: SB | AE20: NB | AF20: SB | AG20: NB | AH20: SB | AI20: NB | AJ20: SB | AK20: NB | AL20: SB | AM20: NB | AN20: SB | AO20: NB | AP20: SB | AQ20: NB | AR20: SB | AU20: Direction | AV20: NB | AW20: SB | AX20: NB | AY20: SB | AZ20: NB | BA20: SB | BB20: NB | BC20: SB | BD20: NB | BE20: SB | BF20: NB | BG20: SB | BH20: NB | BI20: SB | BJ20: NB | BK20: SB | BL20: NB | BM20: SB | BN20: NB | BO20: SB | BR20: Direction | BS20: NB | BT20: SB | BU20: NB | BV20: SB | BW20: NB | BX20: SB | BY20: NB | BZ20: SB | CA20: NB | CB20: SB | CC20: NB | CD20: SB | CE20: NB | CF20: SB | CG20: NB | CH20: SB | CI20: NB | CJ20: SB | CK20: NB | CL20: SB
B21: Segment | C21: 1 | D21: 1 | E21: 2 | F21: 2 | G21: 3 | H21: 3 | I21: 4 | J21: 4 | K21: 5 | L21: 5 | M21: 6 | N21: 6 | O21: 7 | P21: 7 | Q21: 8 | R21: 8 | S21: 9 | T21: 9 | U21: 10 | V21: 10 | X21: Segment | Y21: 1 | Z21: 1 | AA21: 2 | AB21: 2 | AC21: 3 | AD21: 3 | AE21: 4 | AF21: 4 | AG21: 5 | AH21: 5 | AI21: 6 | AJ21: 6 | AK21: 7 | AL21: 7 | AM21: 8 | AN21: 8 | AO21: 9 | AP21: 9 | AQ21: 10 | AR21: 10 | AU21: Segment | AV21: 1 | AW21: 1 | AX21: 2 | AY21: 2 | AZ21: 3 | BA21: 3 | BB21: 4 | BC21: 4 | BD21: 5 | BE21: 5 | BF21: 6 | BG21: 6 | BH21: 7 | BI21: 7 | BJ21: 8 | BK21: 8 | BL21: 9 | BM21: 9 | BN21: 10 | BO21: 10 | BR21: Segment | BS21: 1 | BT21: 1 | BU21: 2 | BV21: 2 | BW21: 3 | BX21: 3 | BY21: 4 | BZ21: 4 | CA21: 5 | CB21: 5 | CC21: 6 | CD21: 6 | CE21: 7 | CF21: 7 | CG21: 8 | CH21: 8 | CI21: 9 | CJ21: 9 | CK21: 10 | CL21: 10
B22: Period | X22: Period | AU22: Period | BR22: Period
B23: Night | C23: 0.16 | D23: 0.16 | E23: 0.06 | F23: 0.06 | G23: 0.06 | H23: 0.06 | I23: 0.09 | J23: 0.09 | K23: 0.21 | L23: 0.08 | M23: 0.21 | N23: 0.06 | O23: 0.21 | P23: 0.02 | Q23: 0.16 | R23: 0.05 | S23: 0.01 | T23: 0.01 | U23: 0.06 | V23: 0.01 | X23: Night | Y23: 2675.86 | Z23: 2548.84 | AA23: 770.39 | AB23: 703.65 | AC23: 610.21 | AD23: 798.03 | AE23: 1478.86 | AF23: 1383.9 | AG23: 3568.6 | AH23: 1173.2 | AI23: 3623.2 | AJ23: 875.24 | AK23: 3383.1 | AL23: 353.5 | AM23: 2511.6 | AN23: 784.7 | AO23: 166.75 | AP23: 127.19 | AQ23: 965.86 | AR23: 134.74 | AU23: Night | AV23: 16800 | AW23: 16800 | AX23: 14477.71 | AY23: 13563.05 | AZ23: 13744.69 | BA23: 16325.05 | BB23: 16800 | BC23: 16800 | BD23: 16800 | BE23: 16800 | BF23: 16800 | BG23: 16777.36 | BH23: 16800 | BI23: 16800 | BJ23: 16800 | BK23: 16800 | BL23: 16666.15 | BM23: 12853.61 | BN23: 16284.24 | BO23: 13534.86 | BR23: Night | BS23: 19475.86 | BT23: 19348.84 | BU23: 15248.1 | BV23: 14266.7 | BW23: 14354.9 | BX23: 17123.08 | BY23: 18278.85 | BZ23: 18183.9 | CA23: 20368.6 | CB23: 17973.2 | CC23: 20423.2 | CD23: 17652.6 | CE23: 20183.1 | CF23: 17153.5 | CG23: 19311.6 | CH23: 17584.7 | CI23: 16832.9 | CJ23: 12980.8 | CK23: 17250.1 | CL23: 13669.6
B24: AM-Early | C24: 0.16 | D24: 0.17 | E24: 0.17 | F24: 0.18 | G24: 0.18 | H24: 0.18 | I24: 0.17 | J24: 0.17 | K24: 0.16 | L24: 0.16 | M24: 0.16 | N24: 0.16 | O24: 0.16 | P24: 0.16 | Q24: 0.16 | R24: 0.16 | S24: 0.16 | T24: 0.16 | U24: 0.16 | V24: 0.16 | X24: AM-Early | Y24: 1188.89 | Z24: 732.88 | AA24: 1222.62 | AB24: 786.75 | AC24: 803.72 | AD24: 993.85 | AE24: 1339.39 | AF24: 926.13 | AG24: 1250.33 | AH24: 854.99 | AI24: 1197.27 | AJ24: 861.09 | AK24: 1051.13 | AL24: 924.5 | AM24: 996.51 | AN24: 887.99 | AO24: 966.89 | AP24: 729.48 | AQ24: 1117.37 | AR24: 696 | AU24: AM-Early | AV24: 6759.19 | AW24: 4430.75 | AX24: 6155.08 | AY24: 4115.44 | AZ24: 4237.68 | BA24: 5204.05 | BB24: 6939.1 | BC24: 5058.67 | BD24: 7023.51 | BE24: 5025.81 | BF24: 6841.35 | BG24: 5118.31 | BH24: 6045.67 | BI24: 5448.2 | BJ24: 5787.14 | BK24: 5191.25 | BL24: 5609.78 | BM24: 4384.52 | BN24: 6723.55 | BO24: 4288.75 | BR24: AM-Early | BS24: 7948.08 | BT24: 5163.63 | BU24: 7377.7 | BV24: 4902.19 | BW24: 5041.4 | BX24: 6197.9 | BY24: 8278.49 | BZ24: 5984.8 | CA24: 8273.84 | CB24: 5880.8 | CC24: 8038.62 | CD24: 5979.4 | CE24: 7096.8 | CF24: 6372.7 | CG24: 6783.65 | CH24: 6079.24 | CI24: 6576.67 | CJ24: 5114 | CK24: 7840.92 | CL24: 4984.74
B25: AM-Peak | C25: 0.21 | D25: 0.17 | E25: 0.19 | F25: 0.06 | G25: 0.3 | H25: 0.24 | I25: 0.25 | J25: 0.17 | K25: 0.26 | L25: 0.16 | M25: 0.26 | N25: 0.16 | O25: 0.27 | P25: 0.16 | Q25: 0.27 | R25: 0.16 | S25: 0.17 | T25: 0.16 | U25: 0.16 | V25: 0.16 | X25: AM-Peak | Y25: 5701.98 | Z25: 1637.48 | AA25: 5397.13 | AB25: 606.93 | AC25: 6153.93 | AD25: 5685.53 | AE25: 6585.64 | AF25: 3172.64 | AG25: 6971.31 | AH25: 2817.8 | AI25: 7126.51 | AJ25: 2781.36 | AK25: 7102.38 | AL25: 2803.72 | AM25: 6943.72 | AN25: 2730.86 | AO25: 3102.75 | AP25: 2368.99 | AQ25: 2353.66 | AR25: 2098.39 | AU25: AM-Peak | AV25: 24778.02 | AW25: 10148.88 | AX25: 25057.21 | AY25: 9360 | AZ25: 17542.74 | BA25: 20954.47 | BB25: 22311.01 | BC25: 17975.41 | BD25: 23194.52 | BE25: 17376.43 | BF25: 23353.49 | BG25: 17455.63 | BH25: 23377.62 | BI25: 17698.6 | BJ25: 22506.06 | BK25: 16958.2 | BL25: 18470.2 | BM25: 15129.45 | BN25: 14793.63 | BO25: 13383.76 | BR25: AM-Peak | BS25: 30480 | BT25: 11786.35 | BU25: 30454.34 | BV25: 9966.93 | BW25: 23696.67 | BX25: 26640 | BY25: 28896.66 | BZ25: 21148.05 | CA25: 30165.83 | CB25: 20194.24 | CC25: 30480 | CD25: 20237 | CE25: 30480 | CF25: 20502.32 | CG25: 29449.79 | CH25: 19689.06 | CI25: 21572.95 | CJ25: 17498.45 | CK25: 17147.28 | CL25: 15482.16
B26: AM-Shoulder | C26: 0.23 | D26: 0.17 | E26: 0.21 | F26: 0.18 | G26: 0.17 | H26: 0.17 | I26: 0.21 | J26: 0.17 | K26: 0.2 | L26: 0.16 | M26: 0.2 | N26: 0.16 | O26: 0.2 | P26: 0.16 | Q26: 0.17 | R26: 0.16 | S26: 0.16 | T26: 0.16 | U26: 0.16 | V26: 0.16 | X26: AM-Shoulder | Y26: 1677.88 | Z26: 652.83 | AA26: 1747.91 | AB26: 643.18 | AC26: 1106.4 | AD26: 1327.14 | AE26: 1630.95 | AF26: 1061.78 | AG26: 1531.8 | AH26: 948 | AI26: 1530.81 | AJ26: 906.37 | AK26: 1525.81 | AL26: 907.52 | AM26: 1158.65 | AN26: 872.13 | AO26: 880.95 | AP26: 784.54 | AQ26: 791.05 | AR26: 740.11 | AU26: AM-Shoulder | AV26: 7202.12 | AW26: 4276.22 | AX26: 7132.09 | AY26: 3481.87 | AZ26: 6493.11 | BA26: 7552.86 | BB26: 7249.05 | BC26: 6259.19 | BD26: 7348.2 | BE26: 5982.96 | BF26: 7349.19 | BG26: 5843.02 | BH26: 7354.19 | BI26: 5881.31 | BJ26: 6974.39 | BK26: 5581.64 | BL26: 5553.48 | BM26: 5237.16 | BN26: 5160.11 | BO26: 4906.6 | BR26: AM-Shoulder | BS26: 8880 | BT26: 4929.06 | BU26: 8880 | BV26: 4125.05 | BW26: 7599.51 | BX26: 8880 | BY26: 8880 | BZ26: 7320.97 | CA26: 8880 | CB26: 6930.96 | CC26: 8880 | CD26: 6749.39 | CE26: 8880 | CF26: 6788.83 | CG26: 8133.05 | CH26: 6453.77 | CI26: 6434.42 | CJ26: 6021.7 | CK26: 5951.16 | CL26: 5646.71
B27: MD | C27: 0.22 | D27: 0.19 | E27: 0.2 | F27: 0.18 | G27: 0.23 | H27: 0.22 | I27: 0.18 | J27: 0.2 | K27: 0.16 | L27: 0.17 | M27: 0.16 | N27: 0.16 | O27: 0.16 | P27: 0.16 | Q27: 0.16 | R27: 0.16 | S27: 0.17 | T27: 0.17 | U27: 0.17 | V27: 0.16 | X27: MD | Y27: 5565.21 | Z27: 5942.97 | AA27: 7146.42 | AB27: 6365.73 | AC27: 5518.85 | AD27: 6063.78 | AE27: 5494.26 | AF27: 6192.04 | AG27: 5710.55 | AH27: 6135.72 | AI27: 5328.22 | AJ27: 5369.48 | AK27: 5041.81 | AL27: 5276 | AM27: 4734.55 | AN27: 4595.11 | AO27: 4379.48 | AP27: 4277.39 | AQ27: 4173.58 | AR27: 4657.85 | AU27: MD | AV27: 23548.8 | AW27: 31101.53 | AX27: 30445.42 | AY27: 32780.44 | AZ27: 22384.26 | BA27: 25048.64 | BB27: 29951.19 | BC27: 30280.96 | BD27: 33995.01 | BE27: 34312.78 | BF27: 32087 | BG27: 32339.35 | BH27: 30400.89 | BI27: 31679 | BJ27: 28892.82 | BK27: 27806.04 | BL27: 26929.02 | BM27: 26078.91 | BN27: 26214.07 | BO27: 29170.7 | BR27: MD | BS27: 29114.01 | BT27: 37044.5 | BU27: 37591.84 | BV27: 39146.18 | BW27: 27903.11 | BX27: 31112.41 | BY27: 35445.45 | BZ27: 36473 | CA27: 39705.56 | CB27: 40448.5 | CC27: 37415.22 | CD27: 37708.82 | CE27: 35442.7 | CF27: 36955 | CG27: 33627.37 | CH27: 32401.14 | CI27: 31308.5 | CJ27: 30356.3 | CK27: 30387.65 | CL27: 33828.55
B28: PM-Shoulder | C28: 0.24 | D28: 0.2 | E28: 0.21 | F28: 0.21 | G28: 0.25 | H28: 0.21 | I28: 0.21 | J28: 0.24 | K28: 0.2 | L28: 0.19 | M28: 0.2 | N28: 0.19 | O28: 0.2 | P28: 0.19 | Q28: 0.2 | R28: 0.19 | S28: 0.2 | T28: 0.19 | U28: 0.2 | V28: 0.2 | X28: PM-Shoulder | Y28: 1554 | Z28: 1324.88 | AA28: 1721.77 | AB28: 1757.53 | AC28: 1379.35 | AD28: 1366.59 | AE28: 1276.24 | AF28: 1277.5 | AG28: 1194.42 | AH28: 1535.52 | AI28: 1253.1 | AJ28: 1507.53 | AK28: 1250.2 | AL28: 1484.86 | AM28: 1223.64 | AN28: 1443.92 | AO28: 1165.94 | AP28: 1408.41 | AQ28: 1061.46 | AR28: 1044.48 | AU28: PM-Shoulder | AV28: 6010.61 | AW28: 6384.23 | AX28: 7158.23 | AY28: 7122.47 | AZ28: 4947.55 | BA28: 5813.77 | BB28: 5347.22 | BC28: 4822.89 | BD28: 5457.35 | BE28: 7344.48 | BF28: 5896.3 | BG28: 7372.47 | BH28: 5846.78 | BI28: 6987.25 | BJ28: 5813.23 | BK28: 6994.75 | BL28: 5599.51 | BM28: 6586.25 | BN28: 5205.58 | BO28: 4815.84 | BR28: PM-Shoulder | BS28: 7564.6 | BT28: 7709.11 | BU28: 8880 | BV28: 8880 | BW28: 6326.9 | BX28: 7180.36 | BY28: 6623.47 | BZ28: 6100.39 | CA28: 6651.77 | CB28: 8880 | CC28: 7149.41 | CD28: 8880 | CE28: 7096.99 | CF28: 8472.11 | CG28: 7036.87 | CH28: 8438.66 | CI28: 6765.44 | CJ28: 7994.66 | CK28: 6267.04 | CL28: 5860.32
B29: PM-Peak | C29: 0.23 | D29: 0.22 | E29: 0.21 | F29: 0.21 | G29: 0.27 | H29: 0.23 | I29: 0.21 | J29: 0.31 | K29: 0.2 | L29: 0.21 | M29: 0.19 | N29: 0.27 | O29: 0.2 | P29: 0.26 | Q29: 0.2 | R29: 0.19 | S29: 0.2 | T29: 0.2 | U29: 0.2 | V29: 0.2 | X29: PM-Peak | Y29: 5701.11 | Z29: 5805.03 | AA29: 4976.67 | AB29: 5866.23 | AC29: 4843.3 | AD29: 5598.84 | AE29: 4325.51 | AF29: 6336.8 | AG29: 3795.11 | AH29: 5539.35 | AI29: 3833.58 | AJ29: 7325.94 | AK29: 3859.44 | AL29: 6540.79 | AM29: 3995.35 | AN29: 4172.9 | AO29: 3491.19 | AP29: 3607.13 | AQ29: 3243.23 | AR29: 3227.1 | AU29: PM-Peak | AV29: 23106.9 | AW29: 24674.97 | AX29: 20816.03 | AY29: 24009.44 | AZ29: 15207.02 | BA29: 22824.11 | BB29: 18819.04 | BC29: 16943.96 | BD29: 17840.1 | BE29: 24940.65 | BF29: 18641.55 | BG29: 23154.06 | BH29: 18660.58 | BI29: 22395.26 | BJ29: 19523.27 | BK29: 21103.18 | BL29: 17296.87 | BM29: 17614.92 | BN29: 16251.19 | BO29: 15945.49 | BR29: PM-Peak | BS29: 28808.01 | BT29: 30480 | BU29: 25792.7 | BV29: 29875.67 | BW29: 20050.32 | BX29: 28422.95 | BY29: 23144.55 | BZ29: 23280.76 | CA29: 21635.2 | CB29: 30480 | CC29: 22475.13 | CD29: 30480 | CE29: 22520.02 | CF29: 28936.05 | CG29: 23518.62 | CH29: 25276.08 | CI29: 20788.05 | CJ29: 21222.05 | CK29: 19494.42 | CL29: 19172.59
B30: PM-Late | C30: 0.2 | D30: 0.2 | E30: 0.22 | F30: 0.22 | G30: 0.05 | H30: 0.21 | I30: 0.09 | J30: 0.22 | K30: 0.2 | L30: 0.2 | M30: 0.2 | N30: 0.2 | O30: 0.2 | P30: 0.2 | Q30: 0.2 | R30: 0.2 | S30: 0.2 | T30: 0.2 | U30: 0.2 | V30: 0.2 | X30: PM-Late | Y30: 2323.03 | Z30: 2934.3 | AA30: 2296.5 | AB30: 2449.87 | AC30: 430.28 | AD30: 2533.87 | AE30: 762.63 | AF30: 2702.35 | AG30: 1915.65 | AH30: 2591.53 | AI30: 1873.89 | AJ30: 2657.6 | AK30: 1855.12 | AL30: 2508.25 | AM30: 1772.15 | AN30: 1959.03 | AO30: 1667.31 | AP30: 1694.35 | AQ30: 1728.53 | AR30: 1777.77 | AU30: PM-Late | AV30: 11668.97 | AW30: 14199.3 | AX30: 9360 | AY30: 9975.27 | AZ30: 8423.24 | BA30: 11118.77 | BB30: 9360 | BC30: 11910.51 | BD30: 9849.45 | BE30: 12275.59 | BF30: 9612.51 | BG30: 12679.96 | BH30: 9619.58 | BI30: 12191.15 | BJ30: 9178.75 | BK30: 9866.07 | BL30: 8614.29 | BM30: 8779.85 | BN30: 9033.97 | BO30: 9559.23 | BR30: PM-Late | BS30: 13992 | BT30: 17133.6 | BU30: 11656.5 | BV30: 12425.14 | BW30: 8853.52 | BX30: 13652.64 | BY30: 10122.63 | BZ30: 14612.86 | CA30: 11765.1 | CB30: 14867.13 | CC30: 11486.4 | CD30: 15337.55 | CE30: 11474.7 | CF30: 14699.4 | CG30: 10950.9 | CH30: 11825.1 | CI30: 10281.6 | CJ30: 10474.2 | CK30: 10762.5 | CL30: 11337
