Workbook

Sheet Year_2025
B1: Lenght
C2: 11 | D2: 12 | E2: 13 | F2: 14 | G2: 15 | H2: 16 | I2: 17 | J2: 18
B3: Length | C3: 2.4 | D3: 2.5 | E3: 2.8 | F3: 3.3 | G3: 2.6 | H3: 2.6 | I3: 2.1 | J3: 0.8
B5: TollLights | T5: ML PCE.Miles | AM5: GP PCE.Miles | BF5: Highway PCE.Miles
B6: Direction | C6: NB | D6: SB | E6: NB | F6: SB | G6: NB | H6: SB | I6: NB | J6: SB | K6: NB | L6: SB | M6: NB | N6: SB | O6: NB | P6: SB | Q6: NB | R6: SB | T6: Direction | U6: NB | V6: SB | W6: NB | X6: SB | Y6: NB | Z6: SB | AA6: NB | AB6: SB | AC6: NB | AD6: SB | AE6: NB | AF6: SB | AG6: NB | AH6: SB | AI6: NB | AJ6: SB | AM6: Direction | AN6: NB | AO6: SB | AP6: NB | AQ6: SB | AR6: NB | AS6: SB | AT6: NB | AU6: SB | AV6: NB | AW6: SB | AX6: NB | AY6: SB | AZ6: NB | BA6: SB | BB6: NB | BC6: SB | BF6: Direction | BG6: NB | BH6: SB | BI6: NB | BJ6: SB | BK6: NB | BL6: SB | BM6: NB | BN6: SB | BO6: NB | BP6: SB | BQ6: NB | BR6: SB | BS6: NB | BT6: SB | BU6: NB | BV6: SB
B7: Segment | C7: 11 | D7: 11 | E7: 12 | F7: 12 | G7: 13 | H7: 13 | I7: 14 | J7: 14 | K7: 15 | L7: 15 | M7: 16 | N7: 16 | O7: 17 | P7: 17 | Q7: 18 | R7: 18 | T7: Segment | U7: 11 | V7: 11 | W7: 12 | X7: 12 | Y7: 13 | Z7: 13 | AA7: 14 | AB7: 14 | AC7: 15 | AD7: 15 | AE7: 16 | AF7: 16 | AG7: 17 | AH7: 17 | AI7: 18 | AJ7: 18 | AM7: Segment | AN7: 11 | AO7: 11 | AP7: 12 | AQ7: 12 | AR7: 13 | AS7: 13 | AT7: 14 | AU7: 14 | AV7: 15 | AW7: 15 | AX7: 16 | AY7: 16 | AZ7: 17 | BA7: 17 | BB7: 18 | BC7: 18 | BF7: Segment | BG7: 11 | BH7: 11 | BI7: 12 | BJ7: 12 | BK7: 13 | BL7: 13 | BM7: 14 | BN7: 14 | BO7: 15 | BP7: 15 | BQ7: 16 | BR7: 16 | BS7: 17 | BT7: 17 | BU7: 18 | BV7: 18
B8: Period | T8: Period | AM8: Period | BF8: Period
B9: Night | C9: 0.2 | D9: 0.2 | E9: 0.2 | F9: 0.2 | G9: 0.2 | H9: 0.2 | I9: 0.2 | J9: 0.2 | K9: 0.2 | L9: 0.2 | M9: 0.2 | N9: 0.2 | O9: 0.2 | P9: 0.2 | Q9: 0.2 | R9: 0.2 | T9: Night | U9: 2332.33 | V9: 2322.31 | W9: 2957.58 | X9: 2252.97 | Y9: 1803.05 | Z9: 1595.26 | AA9: 2162.97 | AB9: 1528.98 | AC9: 1515.84 | AD9: 1862.08 | AE9: 1515.84 | AF9: 1798.96 | AG9: 500.83 | AH9: 461.09 | AI9: 1804.93 | AJ9: 1445.71 | AM9: Night | AN9: 37517.27 | AO9: 37258.49 | AP9: 45972.42 | AQ9: 35354.53 | AR9: 32869.35 | AS9: 29255.14 | AT9: 33665.13 | AU9: 28939.92 | AV9: 28423.16 | AW9: 34810.92 | AX9: 28423.16 | AY9: 33636.44 | AZ9: 9362.87 | BA9: 8623.51 | BB9: 16417.47 | BC9: 13383.09 | BF9: Night | BG9: 39849.6 | BH9: 39580.8 | BI9: 48930 | BJ9: 37607.5 | BK9: 34672.4 | BL9: 30850.4 | BM9: 35828.1 | BN9: 30468.9 | BO9: 29939 | BP9: 36673 | BQ9: 29939 | BR9: 35435.4 | BS9: 9863.7 | BT9: 9084.6 | BU9: 18222.4 | BV9: 14828.8
B10: AM-Early | C10: 1.04 | D10: 0.5 | E10: 0.4 | F10: 1.56 | G10: 0.7 | H10: 0.75 | I10: 0.78 | J10: 0.59 | K10: 0.49 | L10: 0.36 | M10: 0.49 | N10: 0.37 | O10: 0.53 | P10: 0.53 | Q10: 1.26 | R10: 0.94 | T10: AM-Early | U10: 2406.79 | V10: 1538.21 | W10: 2871.94 | X10: 1593.07 | Y10: 3529.67 | Z10: 1754.67 | AA10: 3758.12 | AB10: 1914.55 | AC10: 1696.99 | AD10: 2365.19 | AE10: 1696.95 | AF10: 2337.48 | AG10: 1143.82 | AH10: 938.12 | AI10: 964.94 | AJ10: 763.32 | AM10: AM-Early | AN10: 13853.21 | AO10: 9026.59 | AP10: 17213.06 | AQ10: 9822.05 | AR10: 19007.53 | AS10: 9543.33 | AT10: 20189.98 | AU10: 10721.15 | AV10: 9904.21 | AW10: 12946.21 | AX10: 9904.25 | AY10: 12789.32 | AZ10: 6168.38 | BA10: 5055.28 | BB10: 5275.06 | BC10: 4507.08 | BF10: AM-Early | BG10: 16260 | BH10: 10564.8 | BI10: 20085 | BJ10: 11415.12 | BK10: 22537.2 | BL10: 11298 | BM10: 23948.1 | BN10: 12635.7 | BO10: 11601.2 | BP10: 15311.4 | BQ10: 11601.2 | BR10: 15126.8 | BS10: 7312.2 | BT10: 5993.4 | BU10: 6240 | BV10: 5270.4
B11: AM-Peak | C11: 1.6 | D11: 1.29 | E11: 0.82 | F11: 1.6 | G11: 1.6 | H11: 0.86 | I11: 1.22 | J11: 0.72 | K11: 0.44 | L11: 0.49 | M11: 0.5 | N11: 0.57 | O11: 0.67 | P11: 0.9 | Q11: 1.17 | R11: 1.6 | T11: AM-Peak | U11: 11132.91 | V11: 4416.75 | W11: 10513.25 | X11: 9835.31 | Y11: 13206.74 | Z11: 9313.28 | AA11: 13342.95 | AB11: 9903.27 | AC11: 4965.72 | AD11: 5774.95 | AE11: 4109.66 | AF11: 4694.78 | AG11: 2903.49 | AH11: 1384.11 | AI11: 1973.91 | AJ11: 2596.03 | AM11: AM-Peak | AN11: 50220.5 | AO11: 26575.29 | AP11: 67096.75 | AQ11: 37740.19 | AR11: 71717.96 | AS11: 52133.84 | AT11: 76880.87 | AU11: 57329.76 | AV11: 29305.17 | AW11: 33161.93 | AX11: 24188.74 | AY11: 26895.22 | AZ11: 16254.49 | BA11: 12513.69 | BB11: 11194.89 | BC11: 12965.57 | BF11: AM-Peak | BG11: 61353.41 | BH11: 30992.04 | BI11: 77610 | BJ11: 47575.5 | BK11: 84924.7 | BL11: 61447.12 | BM11: 90223.83 | BN11: 67233.02 | BO11: 34270.9 | BP11: 38936.88 | BQ11: 28298.4 | BR11: 31590 | BS11: 19157.98 | BT11: 13897.8 | BU11: 13168.8 | BV11: 15561.6
B12: AM-Shoulder | C12: 1.3 | D12: 0.86 | E12: 0.6 | F12: 1.42 | G12: 1.02 | H12: 0.75 | I12: 0.43 | J12: 0.46 | K12: 0.36 | L12: 0.9 | M12: 0.43 | N12: 0.37 | O12: 0.39 | P12: 0.4 | Q12: 1.04 | R12: 1.15 | T12: AM-Shoulder | U12: 2533.39 | V12: 1496.45 | W12: 3023 | X12: 3080.56 | Y12: 3752.48 | Z12: 3250.94 | AA12: 3698.55 | AB12: 3151.9 | AC12: 2063.77 | AD12: 884.26 | AE12: 1654.95 | AF12: 808.6 | AG12: 449.52 | AH12: 449.73 | AI12: 592.11 | AJ12: 608.98 | AM12: AM-Shoulder | AN12: 16294.61 | AO12: 9521.47 | AP12: 21112 | AQ12: 20241.44 | AR12: 21836.72 | AS12: 19135.06 | AT12: 21232.95 | AU12: 18496.1 | AV12: 12255.07 | AW12: 8036.34 | AX12: 9800.65 | AY12: 8112 | AZ12: 3780 | BA12: 3781.77 | BB12: 3763.09 | BC12: 3774.86 | BF12: AM-Shoulder | BG12: 18828 | BH12: 11017.92 | BI12: 24135 | BJ12: 23322 | BK12: 25589.2 | BL12: 22386 | BM12: 24931.5 | BN12: 21648 | BO12: 14318.84 | BP12: 8920.6 | BQ12: 11455.6 | BR12: 8920.6 | BS12: 4229.52 | BT12: 4231.5 | BU12: 4355.2 | BV12: 4383.84
B13: MD | C13: 1.4 | D13: 1.26 | E13: 0.9 | F13: 1.05 | G13: 0.72 | H13: 0.67 | I13: 0.38 | J13: 0.4 | K13: 0.33 | L13: 0.32 | M13: 0.35 | N13: 0.32 | O13: 0.44 | P13: 0.43 | Q13: 1.42 | R13: 1.47 | T13: MD | U13: 9021.33 | V13: 10345.83 | W13: 11445.31 | X13: 12128.17 | Y13: 12932.57 | Z13: 15215.44 | AA13: 12964.95 | AB13: 15897.9 | AC13: 12434.61 | AD13: 10492.18 | AE13: 12230.6 | AF13: 10275.37 | AG13: 3978.87 | AH13: 3835.98 | AI13: 4396.52 | AJ13: 4207.25 | AM13: MD | AN13: 55910.67 | AO13: 61654.17 | AP13: 76842.19 | AQ13: 77071.83 | AR13: 73727.43 | AS13: 82812.56 | AT13: 72307.05 | AU13: 87359.1 | AV13: 68971.39 | AW13: 59434.82 | AX13: 67758.4 | AY13: 58182.63 | AZ13: 21735.63 | BA13: 20954.52 | BB13: 27155.48 | BC13: 25530.72 | BF13: MD | BG13: 64932 | BH13: 72000 | BI13: 88287.5 | BJ13: 89200 | BK13: 86660 | BL13: 98028 | BM13: 85272 | BN13: 103257 | BO13: 81406 | BP13: 69927 | BQ13: 79989 | BR13: 68458 | BS13: 25714.5 | BT13: 24790.5 | BU13: 31552 | BV13: 29737.97
B14: PM-Shoulder | C14: 1.21 | D14: 1.2 | E14: 0.45 | F14: 0.53 | G14: 0.67 | H14: 1 | I14: 0.32 | J14: 0.55 | K14: 0.21 | L14: 0.2 | M14: 0.27 | N14: 0.25 | O14: 0.34 | P14: 0.3 | Q14: 0.58 | R14: 1.23 | T14: PM-Shoulder | U14: 2946.61 | V14: 2725.44 | W14: 3386.47 | X14: 4267.02 | Y14: 4491.75 | Z14: 5481.41 | AA14: 4171.02 | AB14: 5569.83 | AC14: 2831.23 | AD14: 2271.52 | AE14: 2393.27 | AF14: 1871.44 | AG14: 1278.12 | AH14: 1137.84 | AI14: 777.04 | AJ14: 758.78 | AM14: PM-Shoulder | AN14: 14620.88 | AO14: 12658.92 | AP14: 18497.15 | AQ14: 20777.98 | AR14: 20328.28 | AS14: 25083.82 | AT14: 18460.38 | AU14: 24004.77 | AV14: 11735.6 | AW14: 10091.86 | AX14: 9865.73 | AY14: 8019.27 | AZ14: 5308.63 | BA14: 4720.36 | BB14: 3837.92 | BC14: 3402.82 | BF14: PM-Shoulder | BG14: 17567.49 | BH14: 15384.36 | BI14: 21883.62 | BJ14: 25045 | BK14: 24820.03 | BL14: 30565.23 | BM14: 22631.4 | BN14: 29574.6 | BO14: 14566.83 | BP14: 12363.38 | BQ14: 12259 | BR14: 9890.71 | BS14: 6586.75 | BT14: 5858.21 | BU14: 4614.96 | BV14: 4161.6
B15: PM-Peak | C15: 1.55 | D15: 1.44 | E15: 1.07 | F15: 0.72 | G15: 0.75 | H15: 0.82 | I15: 0.48 | J15: 0.52 | K15: 0.36 | L15: 0.38 | M15: 0.48 | N15: 0.49 | O15: 0.9 | P15: 0.47 | Q15: 1.6 | R15: 1.42 | T15: PM-Peak | U15: 9597 | V15: 9715.69 | W15: 8368.8 | X15: 10537.48 | Y15: 12150.78 | Z15: 13393.05 | AA15: 11843 | AB15: 13628.06 | AC15: 8580.69 | AD15: 7716.54 | AE15: 6923.26 | AF15: 6209.95 | AG15: 1073.52 | AH15: 3423.95 | AI15: 2124.67 | AJ15: 2306.6 | AM15: PM-Peak | AN15: 47069.86 | AO15: 46321.91 | AP15: 44554.2 | AQ15: 54832.52 | AR15: 55688.31 | AS15: 59226.32 | AT15: 54050.48 | AU15: 59290.84 | AV15: 36658.04 | AW15: 35109.95 | AX15: 29267.72 | AY15: 28051.24 | AZ15: 9718.38 | BA15: 14150.67 | BB15: 9524.93 | BC15: 11184.28 | BF15: PM-Peak | BG15: 56666.86 | BH15: 56037.6 | BI15: 52923 | BJ15: 65370 | BK15: 67839.09 | BL15: 72619.37 | BM15: 65893.48 | BN15: 72918.89 | BO15: 45238.73 | BP15: 42826.49 | BQ15: 36190.98 | BR15: 34261.19 | BS15: 10791.9 | BT15: 17574.62 | BU15: 11649.6 | BV15: 13490.88
B16: PM-Late | C16: 0.5 | D16: 0.43 | E16: 0.6 | F16: 0.2 | G16: 0.67 | H16: 0.59 | I16: 0.5 | J16: 0.39 | K16: 0.48 | L16: 0.53 | M16: 0.48 | N16: 0.53 | O16: 0.38 | P16: 0.32 | Q16: 0.71 | R16: 1.14 | T16: PM-Late | U16: 4473.33 | V16: 5852.34 | W16: 4082.13 | X16: 4355.99 | Y16: 4207 | Z16: 5093.21 | AA16: 3921.81 | AB16: 5422.39 | AC16: 4622.71 | AD16: 3910.53 | AE16: 4622.71 | AF16: 3910.73 | AG16: 825.3 | AH16: 1297.59 | AI16: 1654.3 | AJ16: 1821.58 | AM16: PM-Late | AN16: 22721.07 | AO16: 27447.66 | AP16: 24545.37 | AQ16: 26851.51 | AR16: 19959.8 | AS16: 22643.59 | AT16: 18749.19 | AU16: 23525.21 | AV16: 21585.29 | AW16: 17344.47 | AX16: 21585.29 | AY16: 17344.27 | AZ16: 4536 | BA16: 4718.91 | BB16: 9181.7 | BC16: 9392.21 | BF16: PM-Late | BG16: 27194.4 | BH16: 33300 | BI16: 28627.5 | BJ16: 31207.5 | BK16: 24166.8 | BL16: 27736.8 | BM16: 22671 | BN16: 28947.6 | BO16: 26208 | BP16: 21255 | BQ16: 26208 | BR16: 21255 | BS16: 5361.3 | BT16: 6016.5 | BU16: 10836 | BV16: 11213.79
B19: CaptureRateLights | T19: ML Volume (PCE/Period) | AM19: GP Volume (PCE/Period) | BF19: Highway Volume
B20: Direction | C20: NB | D20: SB | E20: NB | F20: SB | G20: NB | H20: SB | I20: NB | J20: SB | K20: NB | L20: SB | M20: NB | N20: SB | O20: NB | P20: SB | Q20: NB | R20: SB | T20: Direction | U20: NB | V20: SB | W20: NB | X20: SB | Y20: NB | Z20: SB | AA20: NB | AB20: SB | AC20: NB | AD20: SB | AE20: NB | AF20: SB | AG20: NB | AH20: SB | AI20: NB | AJ20: SB | AM20: Direction | AN20: NB | AO20: SB | AP20: NB | AQ20: SB | AR20: NB | AS20: SB | AT20: NB | AU20: SB | AV20: NB | AW20: SB | AX20: NB | AY20: SB | AZ20: NB | BA20: SB | BB20: NB | BC20: SB | BF20: Direction | BG20: NB | BH20: SB | BI20: NB | BJ20: SB | BK20: NB | BL20: SB | BM20: NB | BN20: SB | BO20: NB | BP20: SB | BQ20: NB | BR20: SB | BS20: NB | BT20: SB | BU20: NB | BV20: SB
B21: Segment | C21: 11 | D21: 11 | E21: 12 | F21: 12 | G21: 13 | H21: 13 | I21: 14 | J21: 14 | K21: 15 | L21: 15 | M21: 16 | N21: 16 | O21: 17 | P21: 17 | Q21: 18 | R21: 18 | T21: Segment | U21: 11 | V21: 11 | W21: 12 | X21: 12 | Y21: 13 | Z21: 13 | AA21: 14 | AB21: 14 | AC21: 15 | AD21: 15 | AE21: 16 | AF21: 16 | AG21: 17 | AH21: 17 | AI21: 18 | AJ21: 18 | AM21: Segment | AN21: 11 | AO21: 11 | AP21: 12 | AQ21: 12 | AR21: 13 | AS21: 13 | AT21: 14 | AU21: 14 | AV21: 15 | AW21: 15 | AX21: 16 | AY21: 16 | AZ21: 17 | BA21: 17 | BB21: 18 | BC21: 18 | BF21: Segment | BG21: 11 | BH21: 11 | BI21: 12 | BJ21: 12 | BK21: 13 | BL21: 13 | BM21: 14 | BN21: 14 | BO21: 15 | BP21: 15 | BQ21: 16 | BR21: 16 | BS21: 17 | BT21: 17 | BU21: 18 | BV21: 18
B22: Period | T22: Period | AM22: Period | BF22: Period
B23: Night | C23: 0.06 | D23: 0.06 | E23: 0.06 | F23: 0.06 | G23: 0.05 | H23: 0.05 | I23: 0.06 | J23: 0.05 | K23: 0.05 | L23: 0.05 | M23: 0.05 | N23: 0.05 | O23: 0.05 | P23: 0.05 | Q23: 0.1 | R23: 0.1 | T23: Night | U23: 971.81 | V23: 967.63 | W23: 1183.03 | X23: 901.19 | Y23: 643.95 | Z23: 569.74 | AA23: 655.44 | AB23: 463.33 | AC23: 583.02 | AD23: 716.18 | AE23: 583.02 | AF23: 691.91 | AG23: 238.49 | AH23: 219.57 | AI23: 2256.16 | AJ23: 1807.14 | AM23: Night | AN23: 15632.19 | AO23: 15524.37 | AP23: 18388.97 | AQ23: 14141.81 | AR23: 11739.05 | AS23: 10448.26 | AT23: 10201.56 | AU23: 8769.67 | AV23: 10931.98 | AW23: 13388.82 | AX23: 10931.98 | AY23: 12937.09 | AZ23: 4458.51 | BA23: 4106.43 | BB23: 20521.84 | BC23: 16728.86 | BF23: Night | BG23: 16604 | BH23: 16492 | BI23: 19572 | BJ23: 15043 | BK23: 12383 | BL23: 11018 | BM23: 10857 | BN23: 9233 | BO23: 11515 | BP23: 14105 | BQ23: 11515 | BR23: 13629 | BS23: 4697 | BT23: 4326 | BU23: 22778 | BV23: 18536
B24: AM-Early | C24: 0.16 | D24: 0.17 | E24: 0.16 | F24: 0.17 | G24: 0.17 | H24: 0.17 | I24: 0.17 | J24: 0.17 | K24: 0.18 | L24: 0.17 | M24: 0.18 | N24: 0.17 | O24: 0.18 | P24: 0.18 | Q24: 0.17 | R24: 0.18 | T24: AM-Early | U24: 1002.83 | V24: 640.92 | W24: 1148.78 | X24: 637.23 | Y24: 1260.6 | Z24: 626.67 | AA24: 1138.82 | AB24: 580.17 | AC24: 652.69 | AD24: 909.69 | AE24: 652.67 | AF24: 899.03 | AG24: 544.68 | AH24: 446.73 | AI24: 1206.17 | AJ24: 954.15 | AM24: AM-Early | AN24: 5772.17 | AO24: 3761.08 | AP24: 6885.22 | AQ24: 3928.82 | AR24: 6788.4 | AS24: 3408.33 | AT24: 6118.18 | AU24: 3248.83 | AV24: 3809.31 | AW24: 4979.31 | AX24: 3809.33 | AY24: 4918.97 | AZ24: 2937.32 | BA24: 2407.27 | BB24: 6593.83 | BC24: 5633.85 | BF24: AM-Early | BG24: 6775 | BH24: 4402 | BI24: 8034 | BJ24: 4566.05 | BK24: 8049 | BL24: 4035 | BM24: 7257 | BN24: 3829 | BO24: 4462 | BP24: 5889 | BQ24: 4462 | BR24: 5818 | BS24: 3482 | BT24: 2854 | BU24: 7800 | BV24: 6588
B25: AM-Peak | C25: 0.21 | D25: 0.17 | E25: 0.16 | F25: 0.26 | G25: 0.17 | H25: 0.17 | I25: 0.16 | J25: 0.17 | K25: 0.18 | L25: 0.17 | M25: 0.18 | N25: 0.18 | O25: 0.18 | P25: 0.1 | Q25: 0.18 | R25: 0.2 | T25: AM-Peak | U25: 4638.71 | V25: 1840.31 | W25: 4205.3 | X25: 3934.12 | Y25: 4716.69 | Z25: 3326.17 | AA25: 4043.32 | AB25: 3000.99 | AC25: 1909.89 | AD25: 2221.13 | AE25: 1580.64 | AF25: 1805.69 | AG25: 1382.62 | AH25: 659.1 | AI25: 2467.39 | AJ25: 3245.03 | AM25: AM-Peak | AN25: 20925.21 | AO25: 11073.04 | AP25: 26838.7 | AQ25: 15096.08 | AR25: 25613.56 | AS25: 18619.23 | AT25: 23297.23 | AU25: 17372.65 | AV25: 11271.22 | AW25: 12754.59 | AX25: 9303.36 | AY25: 10344.31 | AZ25: 7740.23 | BA25: 5958.9 | BB25: 13993.61 | BC25: 16206.97 | BF25: AM-Peak | BG25: 25563.92 | BH25: 12913.35 | BI25: 31044 | BJ25: 19030.2 | BK25: 30330.25 | BL25: 21945.4 | BM25: 27340.55 | BN25: 20373.64 | BO25: 13181.11 | BP25: 14975.72 | BQ25: 10884 | BR25: 12150 | BS25: 9122.85 | BT25: 6618 | BU25: 16461 | BV25: 19452
B26: AM-Shoulder | C26: 0.16 | D26: 0.17 | E26: 0.16 | F26: 0.17 | G26: 0.16 | H26: 0.17 | I26: 0.17 | J26: 0.17 | K26: 0.18 | L26: 0.1 | M26: 0.18 | N26: 0.1 | O26: 0.12 | P26: 0.12 | Q26: 0.18 | R26: 0.18 | T26: AM-Shoulder | U26: 1055.58 | V26: 623.52 | W26: 1209.2 | X26: 1232.22 | Y26: 1340.17 | Z26: 1161.05 | AA26: 1120.77 | AB26: 955.12 | AC26: 793.76 | AD26: 340.1 | AE26: 636.52 | AF26: 311 | AG26: 214.06 | AH26: 214.16 | AI26: 740.13 | AJ26: 761.22 | AM26: AM-Shoulder | AN26: 6789.42 | AO26: 3967.28 | AP26: 8444.8 | AQ26: 8096.58 | AR26: 7798.83 | AS26: 6833.95 | AT26: 6434.23 | AU26: 5604.88 | AV26: 4713.49 | AW26: 3090.9 | AX26: 3769.48 | AY26: 3120 | AZ26: 1800 | BA26: 1800.84 | BB26: 4703.87 | BC26: 4718.58 | BF26: AM-Shoulder | BG26: 7845 | BH26: 4590.8 | BI26: 9654 | BJ26: 9328.8 | BK26: 9139 | BL26: 7995 | BM26: 7555 | BN26: 6560 | BO26: 5507.25 | BP26: 3431 | BQ26: 4406 | BR26: 3431 | BS26: 2014.06 | BT26: 2015 | BU26: 5444 | BV26: 5479.8
B27: MD | C27: 0.16 | D27: 0.17 | E27: 0.16 | F27: 0.17 | G27: 0.17 | H27: 0.17 | I27: 0.17 | J27: 0.17 | K27: 0.18 | L27: 0.18 | M27: 0.18 | N27: 0.18 | O27: 0.18 | P27: 0.18 | Q27: 0.18 | R27: 0.18 | T27: MD | U27: 3758.89 | V27: 4310.76 | W27: 4578.12 | X27: 4851.27 | Y27: 4618.77 | Z27: 5434.09 | AA27: 3928.77 | AB27: 4817.55 | AC27: 4782.54 | AD27: 4035.45 | AE27: 4704.08 | AF27: 3952.07 | AG27: 1894.7 | AH27: 1826.66 | AI27: 5495.65 | AJ27: 5259.06 | AM27: MD | AN27: 23296.11 | AO27: 25689.24 | AP27: 30736.88 | AQ27: 30828.73 | AR27: 26331.23 | AS27: 29575.91 | AT27: 21911.23 | AU27: 26472.45 | AV27: 26527.46 | AW27: 22859.55 | AX27: 26060.92 | AY27: 22377.93 | AZ27: 10350.3 | BA27: 9978.34 | BB27: 33944.35 | BC27: 31913.4 | BF27: MD | BG27: 27055 | BH27: 30000 | BI27: 35315 | BJ27: 35680 | BK27: 30950 | BL27: 35010 | BM27: 25840 | BN27: 31290 | BO27: 31310 | BP27: 26895 | BQ27: 30765 | BR27: 26330 | BS27: 12245 | BT27: 11805 | BU27: 39440 | BV27: 37172.46
B28: PM-Shoulder | C28: 0.2 | D28: 0.21 | E28: 0.2 | F28: 0.2 | G28: 0.2 | H28: 0.19 | I28: 0.2 | J28: 0.2 | K28: 0.21 | L28: 0.21 | M28: 0.22 | N28: 0.22 | O28: 0.22 | P28: 0.22 | Q28: 0.22 | R28: 0.22 | T28: PM-Shoulder | U28: 1227.76 | V28: 1135.6 | W28: 1354.59 | X28: 1706.81 | Y28: 1604.2 | Z28: 1957.65 | AA28: 1263.94 | AB28: 1687.83 | AC28: 1088.93 | AD28: 873.66 | AE28: 920.49 | AF28: 719.78 | AG28: 608.63 | AH28: 541.83 | AI28: 971.3 | AJ28: 948.47 | AM28: PM-Shoulder | AN28: 6092.03 | AO28: 5274.55 | AP28: 7398.86 | AQ28: 8311.19 | AR28: 7260.1 | AS28: 8958.51 | AT28: 5594.06 | AU28: 7274.17 | AV28: 4513.69 | AW28: 3881.48 | AX28: 3794.51 | AY28: 3084.34 | AZ28: 2527.92 | BA28: 2247.79 | BB28: 4797.4 | BC28: 4253.53 | BF28: PM-Shoulder | BG28: 7319.79 | BH28: 6410.15 | BI28: 8753.45 | BJ28: 10018 | BK28: 8864.3 | BL28: 10916.15 | BM28: 6858 | BN28: 8962 | BO28: 5602.63 | BP28: 4755.15 | BQ28: 4715 | BR28: 3804.12 | BS28: 3136.55 | BT28: 2789.62 | BU28: 5768.7 | BV28: 5202
B29: PM-Peak | C29: 0.2 | D29: 0.2 | E29: 0.2 | F29: 0.2 | G29: 0.2 | H29: 0.2 | I29: 0.2 | J29: 0.2 | K29: 0.21 | L29: 0.21 | M29: 0.21 | N29: 0.22 | O29: 0.1 | P29: 0.22 | Q29: 0.23 | R29: 0.22 | T29: PM-Peak | U29: 3998.75 | V29: 4048.2 | W29: 3347.52 | X29: 4214.99 | Y29: 4339.56 | Z29: 4783.23 | AA29: 3588.79 | AB29: 4129.71 | AC29: 3300.26 | AD29: 2967.9 | AE29: 2662.79 | AF29: 2388.44 | AG29: 511.2 | AH29: 1630.45 | AI29: 2655.84 | AJ29: 2883.25 | AM29: PM-Peak | AN29: 19612.44 | AO29: 19300.8 | AP29: 17821.68 | AQ29: 21933.01 | AR29: 19888.68 | AS29: 21152.26 | AT29: 16378.93 | AU29: 17966.92 | AV29: 14099.25 | AW29: 13503.83 | AX29: 11256.82 | AY29: 10788.94 | AZ29: 4627.8 | BA29: 6738.41 | BB29: 11906.16 | BC29: 13980.35 | BF29: PM-Peak | BG29: 23611.19 | BH29: 23349 | BI29: 21169.2 | BJ29: 26148 | BK29: 24228.25 | BL29: 25935.49 | BM29: 19967.72 | BN29: 22096.63 | BO29: 17399.51 | BP29: 16471.73 | BQ29: 13919.61 | BR29: 13177.38 | BS29: 5139 | BT29: 8368.87 | BU29: 14562 | BV29: 16863.6
B30: PM-Late | C30: 0.2 | D30: 0.21 | E30: 0.2 | F30: 0.18 | G30: 0.21 | H30: 0.21 | I30: 0.21 | J30: 0.21 | K30: 0.22 | L30: 0.22 | M30: 0.22 | N30: 0.22 | O30: 0.18 | P30: 0.25 | Q30: 0.22 | R30: 0.22 | T30: PM-Late | U30: 1863.89 | V30: 2438.48 | W30: 1632.85 | X30: 1742.4 | Y30: 1502.5 | Z30: 1819 | AA30: 1188.43 | AB30: 1643.15 | AC30: 1777.96 | AD30: 1504.05 | AE30: 1777.97 | AF30: 1504.13 | AG30: 393 | AH30: 617.9 | AI30: 2067.88 | AJ30: 2276.98 | AM30: PM-Late | AN30: 9467.11 | AO30: 11436.52 | AP30: 9818.15 | AQ30: 10740.6 | AR30: 7128.5 | AS30: 8087 | AT30: 5681.57 | AU30: 7128.85 | AV30: 8302.04 | AW30: 6670.95 | AX30: 8302.03 | AY30: 6670.87 | AZ30: 2160 | BA30: 2247.1 | BB30: 11477.12 | BC30: 11740.27 | BF30: PM-Late | BG30: 11331 | BH30: 13875 | BI30: 11451 | BJ30: 12483 | BK30: 8631 | BL30: 9906 | BM30: 6870 | BN30: 8772 | BO30: 10080 | BP30: 8175 | BQ30: 10080 | BR30: 8175 | BS30: 2553 | BT30: 2865 | BU30: 13545 | BV30: 14017.24
B33: Revenue Per Period | T33: ML Flow (PCE/hr) | AM33: GP Flow (PCE/hr) | BF33: Highway Flow
B34: Direction | C34: NB | D34: SB | E34: NB | F34: SB | G34: NB | H34: SB | I34: NB | J34: SB | K34: NB | L34: SB | M34: NB | N34: SB | O34: NB | P34: SB | Q34: NB | R34: SB | T34: Direction | U34: NB | V34: SB | W34: NB | X34: SB | Y34: NB | Z34: SB | AA34: NB | AB34: SB | AC34: NB | AD34: SB | AE34: NB | AF34: SB | AG34: NB | AH34: SB | AI34: NB | AJ34: SB | AM34: Direction | AN34: NB | AO34: SB | AP34: NB | AQ34: SB | AR34: NB | AS34: SB | AT34: NB | AU34: SB | AV34: NB | AW34: SB | AX34: NB | AY34: SB | AZ34: NB | BA34: SB | BB34: NB | BC34: SB | BF34: Direction | BG34: NB | BH34: SB | BI34: NB | BJ34: SB | BK34: NB | BL34: SB | BM34: NB | BN34: SB | BO34: NB | BP34: SB | BQ34: NB | BR34: SB | BS34: NB | BT34: SB | BU34: NB | BV34: SB
B35: Segment | C35: 11 | D35: 11 | E35: 12 | F35: 12 | G35: 13 | H35: 13 | I35: 14 | J35: 14 | K35: 15 | L35: 15 | M35: 16 | N35: 16 | O35: 17 | P35: 17 | Q35: 18 | R35: 18 | T35: Segment | U35: 11 | V35: 11 | W35: 12 | X35: 12 | Y35: 13 | Z35: 13 | AA35: 14 | AB35: 14 | AC35: 15 | AD35: 15 | AE35: 16 | AF35: 16 | AG35: 17 | AH35: 17 | AI35: 18 | AJ35: 18 | AM35: Segment | AN35: 11 | AO35: 11 | AP35: 12 | AQ35: 12 | AR35: 13 | AS35: 13 | AT35: 14 | AU35: 14 | AV35: 15 | AW35: 15 | AX35: 16 | AY35: 16 | AZ35: 17 | BA35: 17 | BB35: 18 | BC35: 18 | BF35: Segment | BG35: 11 | BH35: 11 | BI35: 12 | BJ35: 12 | BK35: 13 | BL35: 13 | BM35: 14 | BN35: 14 | BO35: 15 | BP35: 15 | BQ35: 16 | BR35: 16 | BS35: 17 | BT35: 17 | BU35: 18 | BV35: 18
B36: Period | T36: Period | AM36: Period | BF36: Period
B37: Night | C37: 466.47 | D37: 464.46 | E37: 591.52 | F37: 450.59 | G37: 360.61 | H37: 319.05 | I37: 432.59 | J37: 305.8 | K37: 303.17 | L37: 372.42 | M37: 303.17 | N37: 359.79 | O37: 100.17 | P37: 92.22 | Q37: 360.99 | R37: 289.14 | T37: Night | U37: 138.83 | V37: 138.23 | W37: 169 | X37: 128.74 | Y37: 91.99 | Z37: 81.39 | AA37: 93.63 | AB37: 66.19 | AC37: 83.29 | AD37: 102.31 | AE37: 83.29 | AF37: 98.84 | AG37: 34.07 | AH37: 31.37 | AI37: 322.31 | AJ37: 258.16 | AM37: Night | AN37: 2233.17 | AO37: 2217.77 | AP37: 2627 | AQ37: 2020.26 | AR37: 1677.01 | AS37: 1492.61 | AT37: 1457.37 | AU37: 1252.81 | AV37: 1561.71 | AW37: 1912.69 | AX37: 1561.71 | AY37: 1848.16 | AZ37: 636.93 | BA37: 586.63 | BB37: 2931.69 | BC37: 2389.84 | BF37: Night | BG37: 2372 | BH37: 2356 | BI37: 2796 | BJ37: 2149 | BK37: 1769 | BL37: 1574 | BM37: 1551 | BN37: 1319 | BO37: 1645 | BP37: 2015 | BQ37: 1645 | BR37: 1947 | BS37: 671 | BT37: 618 | BU37: 3254 | BV37: 2648
B38: AM-Early | C38: 2511.01 | D38: 763.19 | E38: 1160.57 | F38: 2479.66 | G38: 2472.74 | H38: 1314.62 | I38: 2922.02 | J38: 1137.49 | K38: 837.72 | L38: 857.53 | M38: 837.73 | N38: 856.99 | O38: 600.55 | P38: 500.97 | Q38: 1211.45 | R38: 721.26 | T38: AM-Early | U38: 1002.83 | V38: 640.92 | W38: 1148.78 | X38: 637.23 | Y38: 1260.6 | Z38: 626.67 | AA38: 1138.82 | AB38: 580.17 | AC38: 652.69 | AD38: 909.69 | AE38: 652.67 | AF38: 899.03 | AG38: 544.68 | AH38: 446.73 | AI38: 1206.17 | AJ38: 954.15 | AM38: AM-Early | AN38: 5772.17 | AO38: 3761.08 | AP38: 6885.22 | AQ38: 3928.82 | AR38: 6788.4 | AS38: 3408.33 | AT38: 6118.18 | AU38: 3248.83 | AV38: 3809.31 | AW38: 4979.31 | AX38: 3809.33 | AY38: 4918.97 | AZ38: 2937.32 | BA38: 2407.27 | BB38: 6593.83 | BC38: 5633.85 | BF38: AM-Early | BG38: 6775 | BH38: 4402 | BI38: 8034 | BJ38: 4566.05 | BK38: 8049 | BL38: 4035 | BM38: 7257 | BN38: 3829 | BO38: 4462 | BP38: 5889 | BQ38: 4462 | BR38: 5818 | BS38: 3482 | BT38: 2854 | BU38: 7800 | BV38: 6588
B39: AM-Peak | C39: 17812.64 | D39: 5687.49 | E39: 8588.65 | F39: 15736.5 | G39: 21130.78 | H39: 8010.06 | I39: 16319.12 | J39: 7110.63 | K39: 2175.78 | L39: 2816.07 | M39: 2070.99 | N39: 2678.64 | O39: 1936.13 | P39: 1245.7 | Q39: 2303.25 | R39: 4153.64 | T39: AM-Peak | U39: 1546.24 | V39: 613.44 | W39: 1401.77 | X39: 1311.37 | Y39: 1572.23 | Z39: 1108.72 | AA39: 1347.77 | AB39: 1000.33 | AC39: 636.63 | AD39: 740.38 | AE39: 526.88 | AF39: 601.9 | AG39: 460.87 | AH39: 219.7 | AI39: 822.46 | AJ39: 1081.68 | AM39: AM-Peak | AN39: 6975.07 | AO39: 3691.01 | AP39: 8946.23 | AQ39: 5032.03 | AR39: 8537.85 | AS39: 6206.41 | AT39: 7765.74 | AU39: 5790.88 | AV39: 3757.07 | AW39: 4251.53 | AX39: 3101.12 | AY39: 3448.1 | AZ39: 2580.08 | BA39: 1986.3 | BB39: 4664.54 | BC39: 5402.32 | BF39: AM-Peak | BG39: 8521.31 | BH39: 4304.45 | BI39: 10348 | BJ39: 6343.4 | BK39: 10110.08 | BL39: 7315.13 | BM39: 9113.52 | BN39: 6791.21 | BO39: 4393.7 | BP39: 4991.91 | BQ39: 3628 | BR39: 4050 | BS39: 3040.95 | BT39: 2206 | BU39: 5487 | BV39: 6484
B40: AM-Shoulder | C40: 3287.34 | D40: 1282.07 | E40: 1820.81 | F40: 4376.28 | G40: 3826.33 | H40: 2440.99 | I40: 1583.25 | J40: 1448.75 | K40: 752.75 | L40: 795.83 | M40: 703.52 | N40: 302.96 | O40: 177.38 | P40: 177.71 | Q40: 617.13 | R40: 702.45 | T40: AM-Shoulder | U40: 1055.58 | V40: 623.52 | W40: 1209.2 | X40: 1232.22 | Y40: 1340.17 | Z40: 1161.05 | AA40: 1120.77 | AB40: 955.12 | AC40: 793.76 | AD40: 340.1 | AE40: 636.52 | AF40: 311 | AG40: 214.06 | AH40: 214.16 | AI40: 740.13 | AJ40: 761.22 | AM40: AM-Shoulder | AN40: 6789.42 | AO40: 3967.28 | AP40: 8444.8 | AQ40: 8096.58 | AR40: 7798.83 | AS40: 6833.95 | AT40: 6434.23 | AU40: 5604.88 | AV40: 4713.49 | AW40: 3090.9 | AX40: 3769.48 | AY40: 3120 | AZ40: 1800 | BA40: 1800.84 | BB40: 4703.87 | BC40: 4718.58 | BF40: AM-Shoulder | BG40: 7845 | BH40: 4590.8 | BI40: 9654 | BJ40: 9328.8 | BK40: 9139 | BL40: 7995 | BM40: 7555 | BN40: 6560 | BO40: 5507.25 | BP40: 3431 | BQ40: 4406 | BR40: 3431 | BS40: 2014.06 | BT40: 2015 | BU40: 5444 | BV40: 5479.8
B41: MD | C41: 12634.66 | D41: 13067.49 | E41: 10295.66 | F41: 12753.01 | G41: 9300.54 | H41: 10163.58 | I41: 4948.15 | J41: 6300.76 | K41: 4058.85 | L41: 3339.1 | M41: 4316.15 | N41: 3335.32 | O41: 1745.04 | P41: 1642.82 | Q41: 6253.22 | R41: 6192.58 | T41: MD | U41: 751.78 | V41: 862.15 | W41: 915.62 | X41: 970.25 | Y41: 923.75 | Z41: 1086.82 | AA41: 785.75 | AB41: 963.51 | AC41: 956.51 | AD41: 807.09 | AE41: 940.82 | AF41: 790.41 | AG41: 378.94 | AH41: 365.33 | AI41: 1099.13 | AJ41: 1051.81 | AM41: MD | AN41: 4659.22 | AO41: 5137.85 | AP41: 6147.38 | AQ41: 6165.75 | AR41: 5266.25 | AS41: 5915.18 | AT41: 4382.25 | AU41: 5294.49 | AV41: 5305.49 | AW41: 4571.91 | AX41: 5212.18 | AY41: 4475.59 | AZ41: 2070.06 | BA41: 1995.67 | BB41: 6788.87 | BC41: 6382.68 | BF41: MD | BG41: 5411 | BH41: 6000 | BI41: 7063 | BJ41: 7136 | BK41: 6190 | BL41: 7002 | BM41: 5168 | BN41: 6258 | BO41: 6262 | BP41: 5379 | BQ41: 6153 | BR41: 5266 | BS41: 2449 | BT41: 2361 | BU41: 7888 | BV41: 7434.49
B42: PM-Shoulder | C42: 3562.96 | D42: 3257.85 | E42: 1540.54 | F42: 2247.47 | G42: 3029.88 | H42: 5467.7 | I42: 1338.36 | J42: 3080.63 | K42: 590.1 | L42: 454.31 | M42: 646.46 | N42: 469.59 | O42: 437.32 | P42: 342.81 | Q42: 450.76 | R42: 936.61 | T42: PM-Shoulder | U42: 1227.76 | V42: 1135.6 | W42: 1354.59 | X42: 1706.81 | Y42: 1604.2 | Z42: 1957.65 | AA42: 1263.94 | AB42: 1687.83 | AC42: 1088.93 | AD42: 873.66 | AE42: 920.49 | AF42: 719.78 | AG42: 608.63 | AH42: 541.83 | AI42: 971.3 | AJ42: 948.47 | AM42: PM-Shoulder | AN42: 6092.03 | AO42: 5274.55 | AP42: 7398.86 | AQ42: 8311.19 | AR42: 7260.1 | AS42: 8958.51 | AT42: 5594.06 | AU42: 7274.17 | AV42: 4513.69 | AW42: 3881.48 | AX42: 3794.51 | AY42: 3084.34 | AZ42: 2527.92 | BA42: 2247.79 | BB42: 4797.4 | BC42: 4253.53 | BF42: PM-Shoulder | BG42: 7319.79 | BH42: 6410.15 | BI42: 8753.45 | BJ42: 10018 | BK42: 8864.3 | BL42: 10916.15 | BM42: 6858 | BN42: 8962 | BO42: 5602.63 | BP42: 4755.15 | BQ42: 4715 | BR42: 3804.12 | BS42: 3136.55 | BT42: 2789.62 | BU42: 5768.7 | BV42: 5202
B43: PM-Peak | C43: 14865.7 | D43: 13970.06 | E43: 8921.19 | F43: 7548.29 | G43: 9173.31 | H43: 10951.54 | I43: 5743.55 | J43: 7088 | K43: 3057.31 | L43: 2899.18 | M43: 3299.14 | N43: 3014.29 | O43: 966.17 | P43: 1600.66 | Q43: 3399.47 | R43: 3285.74 | T43: PM-Peak | U43: 1332.92 | V43: 1349.4 | W43: 1115.84 | X43: 1405 | Y43: 1446.52 | Z43: 1594.41 | AA43: 1196.26 | AB43: 1376.57 | AC43: 1100.09 | AD43: 989.3 | AE43: 887.6 | AF43: 796.15 | AG43: 170.4 | AH43: 543.48 | AI43: 885.28 | AJ43: 961.08 | AM43: PM-Peak | AN43: 6537.48 | AO43: 6433.6 | AP43: 5940.56 | AQ43: 7311 | AR43: 6629.56 | AS43: 7050.75 | AT43: 5459.64 | AU43: 5988.97 | AV43: 4699.75 | AW43: 4501.28 | AX43: 3752.27 | AY43: 3596.31 | AZ43: 1542.6 | BA43: 2246.14 | BB43: 3968.72 | BC43: 4660.12 | BF43: PM-Peak | BG43: 7870.4 | BH43: 7783 | BI43: 7056.4 | BJ43: 8716 | BK43: 8076.08 | BL43: 8645.16 | BM43: 6655.91 | BN43: 7365.54 | BO43: 5799.84 | BP43: 5490.58 | BQ43: 4639.87 | BR43: 4392.46 | BS43: 1713 | BT43: 2789.62 | BU43: 4854 | BV43: 5621.2
B44: PM-Late | C44: 2242.92 | D44: 2526.16 | E44: 2434.7 | F44: 871.2 | G44: 2799.09 | H44: 3014.52 | I44: 1955.64 | J44: 2140.38 | K44: 2214.16 | L44: 2081.61 | M44: 2214.16 | N44: 2081.6 | O44: 315.89 | P44: 416.3 | Q44: 1171.21 | R44: 2068.08 | T44: PM-Late | U44: 621.3 | V44: 812.83 | W44: 544.28 | X44: 580.8 | Y44: 500.83 | Z44: 606.33 | AA44: 396.14 | AB44: 547.72 | AC44: 592.65 | AD44: 501.35 | AE44: 592.66 | AF44: 501.38 | AG44: 131 | AH44: 205.97 | AI44: 689.29 | AJ44: 758.99 | AM44: PM-Late | AN44: 3155.7 | AO44: 3812.17 | AP44: 3272.72 | AQ44: 3580.2 | AR44: 2376.17 | AS44: 2695.67 | AT44: 1893.86 | AU44: 2376.28 | AV44: 2767.35 | AW44: 2223.65 | AX44: 2767.34 | AY44: 2223.62 | AZ44: 720 | BA44: 749.03 | BB44: 3825.71 | BC44: 3913.42 | BF44: PM-Late | BG44: 3777 | BH44: 4625 | BI44: 3817 | BJ44: 4161 | BK44: 2877 | BL44: 3302 | BM44: 2290 | BN44: 2924 | BO44: 3360 | BP44: 2725 | BQ44: 3360 | BR44: 2725 | BS44: 851 | BT44: 955 | BU44: 4515 | BV44: 4672.41
B47: Revenue Per Period Lights | T47: ML V/C | AM47: GP V/C real | BF47: Highway Vol / GP Capacity
...

Sheet Year_2032
B1: Lenght
C2: 11 | D2: 12 | E2: 13 | F2: 14 | G2: 15 | H2: 16 | I2: 17 | J2: 18
B3: Length | C3: 2.4 | D3: 2.5 | E3: 2.8 | F3: 3.3 | G3: 2.6 | H3: 2.6 | I3: 2.1 | J3: 0.8
B5: TollLights | T5: ML PCE.Miles | AM5: GP PCE.Miles | BF5: Highway PCE.Miles
B6: Direction | C6: NB | D6: SB | E6: NB | F6: SB | G6: NB | H6: SB | I6: NB | J6: SB | K6: NB | L6: SB | M6: NB | N6: SB | O6: NB | P6: SB | Q6: NB | R6: SB | T6: Direction | U6: NB | V6: SB | W6: NB | X6: SB | Y6: NB | Z6: SB | AA6: NB | AB6: SB | AC6: NB | AD6: SB | AE6: NB | AF6: SB | AG6: NB | AH6: SB | AI6: NB | AJ6: SB | AM6: Direction | AN6: NB | AO6: SB | AP6: NB | AQ6: SB | AR6: NB | AS6: SB | AT6: NB | AU6: SB | AV6: NB | AW6: SB | AX6: NB | AY6: SB | AZ6: NB | BA6: SB | BB6: NB | BC6: SB | BF6: Direction | BG6: NB | BH6: SB | BI6: NB | BJ6: SB | BK6: NB | BL6: SB | BM6: NB | BN6: SB | BO6: NB | BP6: SB | BQ6: NB | BR6: SB | BS6: NB | BT6: SB | BU6: NB | BV6: SB
B7: Segment | C7: 11 | D7: 11 | E7: 12 | F7: 12 | G7: 13 | H7: 13 | I7: 14 | J7: 14 | K7: 15 | L7: 15 | M7: 16 | N7: 16 | O7: 17 | P7: 17 | Q7: 18 | R7: 18 | T7: Segment | U7: 11 | V7: 11 | W7: 12 | X7: 12 | Y7: 13 | Z7: 13 | AA7: 14 | AB7: 14 | AC7: 15 | AD7: 15 | AE7: 16 | AF7: 16 | AG7: 17 | AH7: 17 | AI7: 18 | AJ7: 18 | AM7: Segment | AN7: 11 | AO7: 11 | AP7: 12 | AQ7: 12 | AR7: 13 | AS7: 13 | AT7: 14 | AU7: 14 | AV7: 15 | AW7: 15 | AX7: 16 | AY7: 16 | AZ7: 17 | BA7: 17 | BB7: 18 | BC7: 18 | BF7: Segment | BG7: 11 | BH7: 11 | BI7: 12 | BJ7: 12 | BK7: 13 | BL7: 13 | BM7: 14 | BN7: 14 | BO7: 15 | BP7: 15 | BQ7: 16 | BR7: 16 | BS7: 17 | BT7: 17 | BU7: 18 | BV7: 18
B8: Period | T8: Period | AM8: Period | BF8: Period
B9: Night | C9: 0.2 | D9: 0.2 | E9: 0.2 | F9: 0.2 | G9: 0.2 | H9: 0.2 | I9: 0.2 | J9: 0.2 | K9: 0.2 | L9: 0.2 | M9: 0.2 | N9: 0.2 | O9: 0.2 | P9: 0.2 | Q9: 0.2 | R9: 0.2 | T9: Night | U9: 7593.6 | V9: 7269.36 | W9: 6329.75 | X9: 2274.08 | Y9: 2350.83 | Z9: 2121.07 | AA9: 2191.06 | AB9: 1855.79 | AC9: 1881.29 | AD9: 2311.06 | AE9: 1881.29 | AF9: 2232.65 | AG9: 621.48 | AH9: 572.53 | AI9: 6047.78 | AJ9: 4877.47 | AM9: Night | AN9: 40320 | AO9: 40320 | AP9: 52500 | AQ9: 42938.92 | AR9: 39651.97 | AS9: 35254.17 | AT9: 41216.15 | AU9: 35062.63 | AV9: 35334.07 | AW9: 43272.66 | AX9: 35334.07 | AY9: 41811.35 | AZ9: 11635.38 | BA9: 10722.95 | BB9: 16453.02 | BC9: 13435.09 | BF9: Night | BG9: 47913.6 | BH9: 47589.36 | BI9: 58829.75 | BJ9: 45213 | BK9: 42002.8 | BL9: 37375.24 | BM9: 43407.21 | BN9: 36918.42 | BO9: 37215.36 | BP9: 45583.72 | BQ9: 37215.36 | BR9: 44044 | BS9: 12256.86 | BT9: 11295.48 | BU9: 22500.8 | BV9: 18312.56
B10: AM-Early | C10: 1.8 | D10: 0.89 | E10: 0.82 | F10: 1.8 | G10: 1.66 | H10: 1.44 | I10: 1.8 | J10: 1.11 | K10: 0.93 | L10: 0.7 | M10: 0.93 | N10: 0.7 | O10: 0.98 | P10: 0.98 | Q10: 1.8 | R10: 1.8 | T10: AM-Early | U10: 2926.67 | V10: 1844.15 | W10: 3396.97 | X10: 1976.36 | Y10: 4120.83 | Z10: 2115.07 | AA10: 4559.13 | AB10: 2310.83 | AC10: 2102.02 | AD10: 2909.36 | AE10: 2102.02 | AF10: 2876.11 | AG10: 1418.76 | AH10: 1164.97 | AI10: 1030.22 | AJ10: 978.84 | AM10: AM-Early | AN10: 15334.55 | AO10: 10857.61 | AP10: 20750.78 | AQ10: 9781.21 | AR10: 23183.65 | AS10: 11572.45 | AT10: 24301.7 | AU10: 12997.54 | AV10: 12318.36 | AW10: 16123.42 | AX10: 12318.36 | AY10: 15926.83 | AZ10: 7670.88 | BA10: 6284.78 | BB10: 5396.98 | BC10: 5202.48 | BF10: AM-Early | BG10: 18261.22 | BH10: 12701.76 | BI10: 24147.75 | BJ10: 11757.57 | BK10: 27304.48 | BL10: 13687.52 | BM10: 28860.83 | BN10: 15308.37 | BO10: 14420.38 | BP10: 19032.78 | BQ10: 14420.38 | BR10: 18802.94 | BS10: 9089.64 | BT10: 7449.75 | BU10: 6427.2 | BV10: 6181.31
B11: AM-Peak | C11: 3.96 | D11: 1.8 | E11: 1.8 | F11: 1.8 | G11: 3.72 | H11: 1.73 | I11: 3.27 | J11: 1.4 | K11: 0.77 | L11: 0.87 | M11: 0.88 | N11: 1.01 | O11: 1.17 | P11: 0.9 | Q11: 1.8 | R11: 1.8 | T11: AM-Peak | U11: 13242.38 | V11: 6561.83 | W11: 12411.49 | X11: 13990.11 | Y11: 17271.67 | Z11: 10985.98 | AA11: 14976.18 | AB11: 11741.05 | AC11: 6138.46 | AD11: 7118.73 | AE11: 5093.28 | AF11: 5810 | AG11: 3604.97 | AH11: 1738.85 | AI11: 3021.66 | AJ11: 4864.94 | AM11: AM-Peak | AN11: 59909.62 | AO11: 30700.65 | AP11: 80899.01 | AQ11: 38986.05 | AR11: 85619.46 | AS11: 63459.07 | AT11: 94330.77 | AU11: 69714.3 | AV11: 36463.76 | AW11: 41280.44 | AX11: 30083.16 | AY11: 33456.76 | AZ11: 20211.76 | BA11: 15535.75 | BB11: 13240.02 | BC11: 14351.62 | BF11: AM-Peak | BG11: 73152 | BH11: 37262.48 | BI11: 93310.5 | BJ11: 52976.16 | BK11: 102891.13 | BL11: 74445.06 | BM11: 109306.96 | BN11: 81455.35 | BO11: 42602.23 | BP11: 48399.17 | BQ11: 35176.44 | BR11: 39266.76 | BS11: 23816.73 | BT11: 17274.6 | BU11: 16261.68 | BV11: 19216.56
B12: AM-Shoulder | C12: 1.8 | D12: 1.79 | E12: 1.36 | F12: 1.8 | G12: 2.29 | H12: 1.73 | I12: 0.89 | J12: 0.91 | K12: 0.68 | L12: 1.34 | M12: 0.78 | N12: 0.37 | O12: 0.49 | P12: 0.49 | Q12: 1.8 | R12: 1.8 | T12: AM-Shoulder | U12: 3228.47 | V12: 1793.52 | W12: 3582.79 | X12: 3710.07 | Y12: 4162.8 | Z12: 3847.95 | AA12: 4385.12 | AB12: 3769.6 | AC12: 2549.8 | AD12: 1099.1 | AE12: 2050.81 | AF12: 1542.27 | AG12: 783.38 | AH12: 782.83 | AI12: 880.51 | AJ12: 860.34 | AM12: AM-Shoulder | AN12: 17096.01 | AO12: 11452.82 | AP12: 25434.96 | AQ12: 20555.58 | AR12: 25237.2 | AS12: 23273.41 | AT12: 25819.45 | AU12: 22457.15 | AV12: 15249.81 | AW12: 9988.6 | AX12: 12188.35 | AY12: 9545.43 | AZ12: 4474.12 | BA12: 4476.83 | BB12: 4351.41 | BC12: 4179.66 | BF12: AM-Shoulder | BG12: 20324.48 | BH12: 13246.34 | BI12: 29017.75 | BJ12: 24265.65 | BK12: 29400 | BL12: 27121.36 | BM12: 30204.57 | BN12: 26226.75 | BO12: 17799.61 | BP12: 11087.7 | BQ12: 14239.16 | BR12: 11087.7 | BS12: 5257.5 | BT12: 5259.66 | BU12: 5231.92 | BV12: 5040
B13: MD | C13: 1.8 | D13: 1.8 | E13: 1.8 | F13: 1.8 | G13: 1.5 | H13: 1.44 | I13: 0.69 | J13: 0.77 | K13: 0.63 | L13: 0.59 | M13: 0.68 | N13: 0.6 | O13: 0.77 | P13: 0.75 | Q13: 1.8 | R13: 1.8 | T13: MD | U13: 12020.9 | V13: 13419.84 | W13: 15249.7 | X13: 16469.84 | Y13: 15469.37 | Z13: 18053.6 | AA13: 15582.78 | AB13: 18987.41 | AC13: 15283.01 | AD13: 12953.08 | AE13: 15038.79 | AF13: 12690.26 | AG13: 4944.42 | AH13: 4765.25 | AI13: 5271.93 | AJ13: 5014.24 | AM13: MD | AN13: 57722.49 | AO13: 65320.13 | AP13: 90902.8 | AQ13: 86881.7 | AR13: 89519.43 | AS13: 100711.2 | AT13: 87722.07 | AU13: 106110.64 | AV13: 85906.39 | AW13: 73967.52 | AX13: 84390.41 | AY13: 72402.54 | AZ13: 27020.73 | BA13: 26050.15 | BB13: 27488.07 | BC13: 25598.38 | BF13: MD | BG13: 69743.39 | BH13: 78739.96 | BI13: 106152.5 | BJ13: 103351.54 | BK13: 104988.8 | BL13: 118764.8 | BM13: 103304.85 | BN13: 125098.05 | BO13: 101189.4 | BP13: 86920.6 | BQ13: 99429.2 | BR13: 85092.8 | BS13: 31965.15 | BT13: 30815.4 | BU13: 32760 | BV13: 30612.62
B14: PM-Shoulder | C14: 1.8 | D14: 1.8 | E14: 1.06 | F14: 1.56 | G14: 1.78 | H14: 1.71 | I14: 0.7 | J14: 1.25 | K14: 0.41 | L14: 0.35 | M14: 0.51 | N14: 0.45 | O14: 0.62 | P14: 0.54 | Q14: 1.31 | R14: 1.8 | T14: PM-Shoulder | U14: 3096.67 | V14: 2837.22 | W14: 3989.43 | X14: 4839.95 | Y14: 5018.2 | Z14: 5395.58 | AA14: 4913.38 | AB14: 5866.64 | AC14: 3465.62 | AD14: 2871.62 | AE14: 2945.07 | AF14: 2314.27 | AG14: 1584.47 | AH14: 1411.5 | AI14: 956.13 | AJ14: 805.65 | AM14: PM-Shoulder | AN14: 14987.52 | AO14: 12999.62 | AP14: 22321.87 | AQ14: 25272.3 | AR14: 24381.8 | AS14: 26068.62 | AT14: 22505.33 | AU14: 27133.36 | AV14: 14640.72 | AW14: 12496.42 | AX14: 12292.49 | AY14: 9979.95 | AZ14: 6603.39 | BA14: 5870.17 | BB14: 4742.49 | BC14: 3478.35 | BF14: PM-Shoulder | BG14: 18084.19 | BH14: 15836.84 | BI14: 26311.3 | BJ14: 30112.25 | BK14: 29400 | BL14: 31464.21 | BM14: 27418.71 | BN14: 33000 | BO14: 18106.34 | BP14: 15368.04 | BQ14: 15237.56 | BR14: 12294.22 | BS14: 8187.86 | BT14: 7281.66 | BU14: 5698.62 | BV14: 4284
B15: PM-Peak | C15: 1.8 | D15: 1.8 | E15: 1.8 | F15: 1.63 | G15: 1.79 | H15: 1.8 | I15: 0.99 | J15: 1.2 | K15: 0.71 | L15: 0.71 | M15: 0.9 | N15: 0.89 | O15: 1.35 | P15: 0.83 | Q15: 1.8 | R15: 1.8 | T15: PM-Peak | U15: 15843.8 | V15: 15386.66 | W15: 11631.65 | X15: 12245.18 | Y15: 13938.37 | Z15: 16460.66 | AA15: 13879.31 | AB15: 15625.89 | AC15: 10419.24 | AD15: 9435.95 | AE15: 8490.79 | AF15: 7649.31 | AG15: 1334.47 | AH15: 4242.33 | AI15: 4026.18 | AJ15: 4107.9 | AM15: PM-Peak | AN15: 52285.27 | AO15: 51988.78 | AP15: 51994.97 | AQ15: 66351.07 | AR15: 68248.2 | AS15: 71519.49 | AT15: 65955.12 | AU15: 72716.65 | AV15: 45812.06 | AW15: 43795.29 | AX15: 36493.23 | AY15: 34936 | AZ15: 12080.12 | BA15: 17602.81 | BB15: 10359.13 | BC15: 12551.18 | BF15: PM-Peak | BG15: 68129.07 | BH15: 67375.44 | BI15: 63626.62 | BJ15: 78596.25 | BK15: 82186.57 | BL15: 87980.14 | BM15: 79834.43 | BN15: 88342.54 | BO15: 56231.3 | BP15: 53231.24 | BQ15: 44984.02 | BR15: 42585.31 | BS15: 13414.59 | BT15: 21845.14 | BU15: 14385.31 | BV15: 16659.08
B16: PM-Late | C16: 0.92 | D16: 0.81 | E16: 1.12 | F16: 0.27 | G16: 1.23 | H16: 1.08 | I16: 0.89 | J16: 0.7 | K16: 0.91 | L16: 1.01 | M16: 0.91 | N16: 1.01 | O16: 0.5 | P16: 0.57 | Q16: 1.56 | R16: 1.73 | T16: PM-Late | U16: 5366.77 | V16: 6997.66 | W16: 4893.82 | X16: 5857.56 | Y16: 5054.96 | Z16: 6150.82 | AA16: 4748.97 | AB16: 6550.68 | AC16: 5731.94 | AD16: 4851.61 | AE16: 5732.13 | AF16: 4851.66 | AG16: 1433.16 | AH16: 1601.38 | AI16: 2040.92 | AJ16: 1877.64 | AM16: PM-Late | AN16: 27329.15 | AO16: 33040.82 | AP16: 29524.43 | AQ16: 31662.69 | AR16: 24224.08 | AS16: 27450.86 | AT16: 22718.58 | AU16: 28517.1 | AV16: 26843.2 | AW16: 21566.99 | AX16: 26843.01 | AY16: 21566.94 | AZ16: 5232.24 | BA16: 5877.35 | BB16: 11340.04 | BC16: 9690.27 | BF16: PM-Late | BG16: 32695.92 | BH16: 40038.48 | BI16: 34418.25 | BJ16: 37520.25 | BK16: 29279.04 | BL16: 33601.68 | BM16: 27467.55 | BN16: 35067.78 | BO16: 32575.14 | BP16: 26418.6 | BQ16: 32575.14 | BR16: 26418.6 | BS16: 6665.4 | BT16: 7478.73 | BU16: 13380.96 | BV16: 11567.91
B19: CaptureRateLights | T19: ML Volume (PCE/Period) | AM19: GP Volume (PCE/Period) | BF19: Highway Volume
B20: Direction | C20: NB | D20: SB | E20: NB | F20: SB | G20: NB | H20: SB | I20: NB | J20: SB | K20: NB | L20: SB | M20: NB | N20: SB | O20: NB | P20: SB | Q20: NB | R20: SB | T20: Direction | U20: NB | V20: SB | W20: NB | X20: SB | Y20: NB | Z20: SB | AA20: NB | AB20: SB | AC20: NB | AD20: SB | AE20: NB | AF20: SB | AG20: NB | AH20: SB | AI20: NB | AJ20: SB | AM20: Direction | AN20: NB | AO20: SB | AP20: NB | AQ20: SB | AR20: NB | AS20: SB | AT20: NB | AU20: SB | AV20: NB | AW20: SB | AX20: NB | AY20: SB | AZ20: NB | BA20: SB | BB20: NB | BC20: SB | BF20: Direction | BG20: NB | BH20: SB | BI20: NB | BJ20: SB | BK20: NB | BL20: SB | BM20: NB | BN20: SB | BO20: NB | BP20: SB | BQ20: NB | BR20: SB | BS20: NB | BT20: SB | BU20: NB | BV20: SB
B21: Segment | C21: 11 | D21: 11 | E21: 12 | F21: 12 | G21: 13 | H21: 13 | I21: 14 | J21: 14 | K21: 15 | L21: 15 | M21: 16 | N21: 16 | O21: 17 | P21: 17 | Q21: 18 | R21: 18 | T21: Segment | U21: 11 | V21: 11 | W21: 12 | X21: 12 | Y21: 13 | Z21: 13 | AA21: 14 | AB21: 14 | AC21: 15 | AD21: 15 | AE21: 16 | AF21: 16 | AG21: 17 | AH21: 17 | AI21: 18 | AJ21: 18 | AM21: Segment | AN21: 11 | AO21: 11 | AP21: 12 | AQ21: 12 | AR21: 13 | AS21: 13 | AT21: 14 | AU21: 14 | AV21: 15 | AW21: 15 | AX21: 16 | AY21: 16 | AZ21: 17 | BA21: 17 | BB21: 18 | BC21: 18 | BF21: Segment | BG21: 11 | BH21: 11 | BI21: 12 | BJ21: 12 | BK21: 13 | BL21: 13 | BM21: 14 | BN21: 14 | BO21: 15 | BP21: 15 | BQ21: 16 | BR21: 16 | BS21: 17 | BT21: 17 | BU21: 18 | BV21: 18
B22: Period | T22: Period | AM22: Period | BF22: Period
B23: Night | C23: 0.19 | D23: 0.18 | E23: 0.12 | F23: 0.05 | G23: 0.06 | H23: 0.06 | I23: 0.05 | J23: 0.05 | K23: 0.05 | L23: 0.05 | M23: 0.05 | N23: 0.05 | O23: 0.05 | P23: 0.05 | Q23: 0.27 | R23: 0.27 | T23: Night | U23: 3164 | V23: 3028.9 | W23: 2531.9 | X23: 909.63 | Y23: 839.58 | Z23: 757.53 | AA23: 663.96 | AB23: 562.36 | AC23: 723.57 | AD23: 888.87 | AE23: 723.57 | AF23: 858.71 | AG23: 295.94 | AH23: 272.63 | AI23: 7559.73 | AJ23: 6096.84 | AM23: Night | AN23: 16800 | AO23: 16800 | AP23: 21000 | AQ23: 17175.57 | AR23: 14161.42 | AS23: 12590.77 | AT23: 12489.74 | AU23: 10625.04 | AV23: 13590.03 | AW23: 16643.33 | AX23: 13590.03 | AY23: 16081.29 | AZ23: 5540.66 | BA23: 5106.17 | BB23: 20566.27 | BC23: 16793.86 | BF23: Night | BG23: 19964 | BH23: 19828.9 | BI23: 23531.9 | BJ23: 18085.2 | BK23: 15001 | BL23: 13348.3 | BM23: 13153.7 | BN23: 11187.4 | BO23: 14313.6 | BP23: 17532.2 | BQ23: 14313.6 | BR23: 16940 | BS23: 5836.6 | BT23: 5378.8 | BU23: 28126 | BV23: 22890.7
B24: AM-Early | C24: 0.18 | D24: 0.17 | E24: 0.16 | F24: 0.19 | G24: 0.16 | H24: 0.17 | I24: 0.17 | J24: 0.17 | K24: 0.17 | L24: 0.17 | M24: 0.17 | N24: 0.17 | O24: 0.18 | P24: 0.18 | Q24: 0.18 | R24: 0.19 | T24: AM-Early | U24: 1219.45 | V24: 768.39 | W24: 1358.79 | X24: 790.54 | Y24: 1471.73 | Z24: 755.38 | AA24: 1381.56 | AB24: 700.25 | AC24: 808.47 | AD24: 1118.98 | AE24: 808.47 | AF24: 1106.2 | AG24: 675.6 | AH24: 554.75 | AI24: 1287.78 | AJ24: 1223.54 | AM24: AM-Early | AN24: 6389.4 | AO24: 4524.01 | AP24: 8300.31 | AQ24: 3912.48 | AR24: 8279.87 | AS24: 4133.02 | AT24: 7364.15 | AU24: 3938.65 | AV24: 4737.83 | AW24: 6201.32 | AX24: 4737.83 | AY24: 6125.7 | AZ24: 3652.8 | BA24: 2992.75 | BB24: 6746.22 | BC24: 6503.1 | BF24: AM-Early | BG24: 7608.84 | BH24: 5292.4 | BI24: 9659.1 | BJ24: 4703.03 | BK24: 9751.6 | BL24: 4888.4 | BM24: 8745.71 | BN24: 4638.9 | BO24: 5546.3 | BP24: 7320.3 | BQ24: 5546.3 | BR24: 7231.9 | BS24: 4328.4 | BT24: 3547.5 | BU24: 8034 | BV24: 7726.64
B25: AM-Peak | C25: 0.21 | D25: 0.21 | E25: 0.15 | F25: 0.32 | G25: 0.18 | H25: 0.16 | I25: 0.15 | J25: 0.16 | K25: 0.17 | L25: 0.17 | M25: 0.17 | N25: 0.17 | O25: 0.18 | P25: 0.1 | Q25: 0.22 | R25: 0.3 | T25: AM-Peak | U25: 5517.66 | V25: 2734.1 | W25: 4964.6 | X25: 5596.04 | Y25: 6168.45 | Z25: 3923.57 | AA25: 4538.24 | AB25: 3557.89 | AC25: 2360.95 | AD25: 2737.97 | AE25: 1958.95 | AF25: 2234.61 | AG25: 1716.65 | AH25: 828.02 | AI25: 3777.08 | AJ25: 6081.18 | AM25: AM-Peak | AN25: 24962.34 | AO25: 12791.94 | AP25: 32359.6 | AQ25: 15594.42 | AR25: 30578.38 | AS25: 22663.96 | AT25: 28585.08 | AU25: 21125.55 | AV25: 14024.52 | AW25: 15877.09 | AX25: 11570.45 | AY25: 12867.99 | AZ25: 9624.65 | BA25: 7397.98 | BB25: 16550.02 | BC25: 17939.52 | BF25: AM-Peak | BG25: 30480 | BH25: 15526.03 | BI25: 37324.2 | BJ25: 21190.46 | BK25: 36746.83 | BL25: 26587.52 | BM25: 33123.32 | BN25: 24683.44 | BO25: 16385.47 | BP25: 18615.07 | BQ25: 13529.4 | BR25: 15102.6 | BS25: 11341.3 | BT25: 8226 | BU25: 20327.1 | BV25: 24020.7
B26: AM-Shoulder | C26: 0.19 | D26: 0.17 | E26: 0.16 | F26: 0.19 | G26: 0.16 | H26: 0.17 | I26: 0.16 | J26: 0.17 | K26: 0.17 | L26: 0.1 | M26: 0.18 | N26: 0.17 | O26: 0.18 | P26: 0.18 | Q26: 0.22 | R26: 0.21 | T26: AM-Shoulder | U26: 1345.2 | V26: 747.3 | W26: 1433.12 | X26: 1484.03 | Y26: 1486.71 | Z26: 1374.27 | AA26: 1328.82 | AB26: 1142.3 | AC26: 980.69 | AD26: 422.73 | AE26: 788.77 | AF26: 593.18 | AG26: 373.04 | AH26: 372.78 | AI26: 1100.64 | AJ26: 1075.43 | AM26: AM-Shoulder | AN26: 7123.34 | AO26: 4772.01 | AP26: 10173.98 | AQ26: 8222.23 | AR26: 9013.29 | AS26: 8311.93 | AT26: 7824.08 | AU26: 6805.2 | AV26: 5865.31 | AW26: 3841.77 | AX26: 4687.83 | AY26: 3671.32 | AZ26: 2130.53 | BA26: 2131.82 | BB26: 5439.26 | BC26: 5224.57 | BF26: AM-Shoulder | BG26: 8468.53 | BH26: 5519.31 | BI26: 11607.1 | BJ26: 9706.26 | BK26: 10500 | BL26: 9686.2 | BM26: 9152.9 | BN26: 7947.5 | BO26: 6846 | BP26: 4264.5 | BQ26: 5476.6 | BR26: 4264.5 | BS26: 2503.57 | BT26: 2504.6 | BU26: 6539.9 | BV26: 6300
B27: MD | C27: 0.2 | D27: 0.2 | E27: 0.18 | F27: 0.2 | G27: 0.17 | H27: 0.17 | I27: 0.17 | J27: 0.17 | K27: 0.17 | L27: 0.18 | M27: 0.17 | N27: 0.18 | O27: 0.18 | P27: 0.18 | Q27: 0.2 | R27: 0.2 | T27: MD | U27: 5008.71 | V27: 5591.6 | W27: 6099.88 | X27: 6587.94 | Y27: 5524.77 | Z27: 6447.71 | AA27: 4722.06 | AB27: 5753.76 | AC27: 5878.08 | AD27: 4981.95 | AE27: 5784.15 | AF27: 4880.87 | AG27: 2354.49 | AH27: 2269.17 | AI27: 6589.92 | AJ27: 6267.79 | AM27: MD | AN27: 24051.04 | AO27: 27216.72 | AP27: 36361.12 | AQ27: 34752.68 | AR27: 31971.23 | AS27: 35968.29 | AT27: 26582.44 | AU27: 32154.74 | AV27: 33040.92 | AW27: 28449.05 | AX27: 32457.85 | AY27: 27847.13 | AZ27: 12867.01 | BA27: 12404.83 | BB27: 34360.08 | BC27: 31997.98 | BF27: MD | BG27: 29059.75 | BH27: 32808.32 | BI27: 42461 | BJ27: 41340.61 | BK27: 37496 | BL27: 42416 | BM27: 31304.5 | BN27: 37908.5 | BO27: 38919 | BP27: 33431 | BQ27: 38242 | BR27: 32728 | BS27: 15221.5 | BT27: 14674 | BU27: 40950 | BV27: 38265.77
B28: PM-Shoulder | C28: 0.2 | D28: 0.21 | E28: 0.19 | F28: 0.19 | G28: 0.19 | H28: 0.19 | I28: 0.2 | J28: 0.19 | K28: 0.21 | L28: 0.21 | M28: 0.21 | N28: 0.21 | O28: 0.22 | P28: 0.22 | Q28: 0.22 | R28: 0.22 | T28: PM-Shoulder | U28: 1290.28 | V28: 1182.18 | W28: 1595.77 | X28: 1935.98 | Y28: 1792.22 | Z28: 1926.99 | AA28: 1488.9 | AB28: 1777.77 | AC28: 1332.93 | AD28: 1104.47 | AE28: 1132.72 | AF28: 890.11 | AG28: 754.51 | AH28: 672.14 | AI28: 1195.16 | AJ28: 1007.06 | AM28: PM-Shoulder | AN28: 6244.8 | AO28: 5416.51 | AP28: 8928.75 | AQ28: 10108.92 | AR28: 8707.78 | AS28: 9310.22 | AT28: 6819.8 | AU28: 8222.23 | AV28: 5631.05 | AW28: 4806.32 | AX28: 4727.88 | AY28: 3838.44 | AZ28: 3144.47 | BA28: 2795.32 | BB28: 5928.11 | BC28: 4347.94 | BF28: PM-Shoulder | BG28: 7535.08 | BH28: 6598.68 | BI28: 10524.52 | BJ28: 12044.9 | BK28: 10500 | BL28: 11237.22 | BM28: 8308.7 | BN28: 10000 | BO28: 6963.98 | BP28: 5910.78 | BQ28: 5860.6 | BR28: 4728.55 | BS28: 3898.98 | BT28: 3467.46 | BU28: 7123.27 | BV28: 5355
B29: PM-Peak | C29: 0.27 | D29: 0.27 | E29: 0.23 | F29: 0.2 | G29: 0.19 | H29: 0.2 | I29: 0.2 | J29: 0.19 | K29: 0.21 | L29: 0.21 | M29: 0.21 | N29: 0.21 | O29: 0.1 | P29: 0.22 | Q29: 0.35 | R29: 0.31 | T29: PM-Peak | U29: 6601.58 | V29: 6411.11 | W29: 4652.66 | X29: 4898.07 | Y29: 4977.99 | Z29: 5878.81 | AA29: 4205.85 | AB29: 4735.12 | AC29: 4007.4 | AD29: 3629.21 | AE29: 3265.69 | AF29: 2942.04 | AG29: 635.46 | AH29: 2020.16 | AI29: 5032.73 | AJ29: 5134.88 | AM29: PM-Peak | AN29: 21785.53 | AO29: 21661.99 | AP29: 20797.99 | AQ29: 26540.43 | AR29: 24374.36 | AS29: 25542.67 | AT29: 19986.4 | AU29: 22035.35 | AV29: 17620.02 | AW29: 16844.34 | AX29: 14035.86 | AY29: 13436.92 | AZ29: 5752.44 | BA29: 8382.29 | BB29: 12948.91 | BC29: 15688.98 | BF29: PM-Peak | BG29: 28387.11 | BH29: 28073.1 | BI29: 25450.65 | BJ29: 31438.5 | BK29: 29352.35 | BL29: 31421.48 | BM29: 24192.25 | BN29: 26770.47 | BO29: 21627.42 | BP29: 20473.55 | BQ29: 17301.55 | BR29: 16378.97 | BS29: 6387.9 | BT29: 10402.45 | BU29: 17981.64 | BV29: 20823.85
B30: PM-Late | C30: 0.2 | D30: 0.21 | E30: 0.2 | F30: 0.21 | G30: 0.21 | H30: 0.21 | I30: 0.21 | J30: 0.21 | K30: 0.22 | L30: 0.22 | M30: 0.22 | N30: 0.22 | O30: 0.25 | P30: 0.24 | Q30: 0.22 | R30: 0.22 | T30: PM-Late | U30: 2236.15 | V30: 2915.69 | W30: 1957.53 | X30: 2343.02 | Y30: 1805.34 | Z30: 2196.72 | AA30: 1439.08 | AB30: 1985.06 | AC30: 2204.59 | AD30: 1866 | AE30: 2204.66 | AF30: 1866.02 | AG30: 682.46 | AH30: 762.56 | AI30: 2551.15 | AJ30: 2347.05 | AM30: PM-Late | AN30: 11387.15 | AO30: 13767.01 | AP30: 11809.77 | AQ30: 12665.08 | AR30: 8651.46 | AS30: 9803.88 | AT30: 6884.42 | AU30: 8641.54 | AV30: 10324.31 | AW30: 8295 | AX30: 10324.24 | AY30: 8294.98 | AZ30: 2491.54 | BA30: 2798.74 | BB30: 14175.05 | BC30: 12112.84 | BF30: PM-Late | BG30: 13623.3 | BH30: 16682.7 | BI30: 13767.3 | BJ30: 15008.1 | BK30: 10456.8 | BL30: 12000.6 | BM30: 8323.5 | BN30: 10626.6 | BO30: 12528.9 | BP30: 10161 | BQ30: 12528.9 | BR30: 10161 | BS30: 3174 | BT30: 3561.3 | BU30: 16726.2 | BV30: 14459.89
B33: Revenue Per Period | T33: ML Flow (PCE/hr) | AM33: GP Flow (PCE/hr) | BF33: Highway Flow
B34: Direction | C34: NB | D34: SB | E34: NB | F34: SB | G34: NB | H34: SB | I34: NB | J34: SB | K34: NB | L34: SB | M34: NB | N34: SB | O34: NB | P34: SB | Q34: NB | R34: SB | T34: Direction | U34: NB | V34: SB | W34: NB | X34: SB | Y34: NB | Z34: SB | AA34: NB | AB34: SB | AC34: NB | AD34: SB | AE34: NB | AF34: SB | AG34: NB | AH34: SB | AI34: NB | AJ34: SB | AM34: Direction | AN34: NB | AO34: SB | AP34: NB | AQ34: SB | AR34: NB | AS34: SB | AT34: NB | AU34: SB | AV34: NB | AW34: SB | AX34: NB | AY34: SB | AZ34: NB | BA34: SB | BB34: NB | BC34: SB | BF34: Direction | BG34: NB | BH34: SB | BI34: NB | BJ34: SB | BK34: NB | BL34: SB | BM34: NB | BN34: SB | BO34: NB | BP34: SB | BQ34: NB | BR34: SB | BS34: NB | BT34: SB | BU34: NB | BV34: SB
B35: Segment | C35: 11 | D35: 11 | E35: 12 | F35: 12 | G35: 13 | H35: 13 | I35: 14 | J35: 14 | K35: 15 | L35: 15 | M35: 16 | N35: 16 | O35: 17 | P35: 17 | Q35: 18 | R35: 18 | T35: Segment | U35: 11 | V35: 11 | W35: 12 | X35: 12 | Y35: 13 | Z35: 13 | AA35: 14 | AB35: 14 | AC35: 15 | AD35: 15 | AE35: 16 | AF35: 16 | AG35: 17 | AH35: 17 | AI35: 18 | AJ35: 18 | AM35: Segment | AN35: 11 | AO35: 11 | AP35: 12 | AQ35: 12 | AR35: 13 | AS35: 13 | AT35: 14 | AU35: 14 | AV35: 15 | AW35: 15 | AX35: 16 | AY35: 16 | AZ35: 17 | BA35: 17 | BB35: 18 | BC35: 18 | BF35: Segment | BG35: 11 | BH35: 11 | BI35: 12 | BJ35: 12 | BK35: 13 | BL35: 13 | BM35: 14 | BN35: 14 | BO35: 15 | BP35: 15 | BQ35: 16 | BR35: 16 | BS35: 17 | BT35: 17 | BU35: 18 | BV35: 18
B36: Period | T36: Period | AM36: Period | BF36: Period
B37: Night | C37: 1518.72 | D37: 1453.87 | E37: 1265.95 | F37: 454.82 | G37: 470.17 | H37: 424.21 | I37: 438.21 | J37: 371.16 | K37: 376.26 | L37: 462.21 | M37: 376.26 | N37: 446.53 | O37: 124.3 | P37: 114.51 | Q37: 1209.56 | R37: 975.49 | T37: Night | U37: 452 | V37: 432.7 | W37: 361.7 | X37: 129.95 | Y37: 119.94 | Z37: 108.22 | AA37: 94.85 | AB37: 80.34 | AC37: 103.37 | AD37: 126.98 | AE37: 103.37 | AF37: 122.67 | AG37: 42.28 | AH37: 38.95 | AI37: 1079.96 | AJ37: 870.98 | AM37: Night | AN37: 2400 | AO37: 2400 | AP37: 3000 | AQ37: 2453.65 | AR37: 2023.06 | AS37: 1798.68 | AT37: 1784.25 | AU37: 1517.86 | AV37: 1941.43 | AW37: 2377.62 | AX37: 1941.43 | AY37: 2297.33 | AZ37: 791.52 | BA37: 729.45 | BB37: 2938.04 | BC37: 2399.12 | BF37: Night | BG37: 2852 | BH37: 2832.7 | BI37: 3361.7 | BJ37: 2583.6 | BK37: 2143 | BL37: 1906.9 | BM37: 1879.1 | BN37: 1598.2 | BO37: 2044.8 | BP37: 2504.6 | BQ37: 2044.8 | BR37: 2420 | BS37: 833.8 | BT37: 768.4 | BU37: 4018 | BV37: 3270.1
B38: AM-Early | C38: 5268.01 | D38: 1646.12 | E38: 2787.46 | F38: 3557.45 | G38: 6856.87 | H38: 3039.04 | I38: 8206.44 | J38: 2570.97 | K38: 1956.6 | L38: 2030.99 | M38: 1956.6 | N38: 2026.55 | O38: 1386.67 | P38: 1137.86 | Q38: 1854.4 | R38: 1761.9 | T38: AM-Early | U38: 1219.45 | V38: 768.39 | W38: 1358.79 | X38: 790.54 | Y38: 1471.73 | Z38: 755.38 | AA38: 1381.56 | AB38: 700.25 | AC38: 808.47 | AD38: 1118.98 | AE38: 808.47 | AF38: 1106.2 | AG38: 675.6 | AH38: 554.75 | AI38: 1287.78 | AJ38: 1223.54 | AM38: AM-Early | AN38: 6389.4 | AO38: 4524.01 | AP38: 8300.31 | AQ38: 3912.48 | AR38: 8279.87 | AS38: 4133.02 | AT38: 7364.15 | AU38: 3938.65 | AV38: 4737.83 | AW38: 6201.32 | AX38: 4737.83 | AY38: 6125.7 | AZ38: 3652.8 | BA38: 2992.75 | BB38: 6746.22 | BC38: 6503.1 | BF38: AM-Early | BG38: 7608.84 | BH38: 5292.4 | BI38: 9659.1 | BJ38: 4703.03 | BK38: 9751.6 | BL38: 4888.4 | BM38: 8745.71 | BN38: 4638.9 | BO38: 5546.3 | BP38: 7320.3 | BQ38: 5546.3 | BR38: 7231.9 | BS38: 4328.4 | BT38: 3547.5 | BU38: 8034 | BV38: 7726.64
B39: AM-Peak | C39: 52382.27 | D39: 11811.29 | E39: 22340.68 | F39: 25182.2 | G39: 64187.4 | H39: 19017.35 | I39: 49041.26 | J39: 16390.01 | K39: 4720.33 | L39: 6207.24 | M39: 4472.02 | N39: 5854.78 | O39: 4218.17 | P39: 1564.97 | Q39: 5438.99 | R39: 8756.9 | T39: AM-Peak | U39: 1839.22 | V39: 911.37 | W39: 1654.87 | X39: 1865.35 | Y39: 2056.15 | Z39: 1307.86 | AA39: 1512.75 | AB39: 1185.96 | AC39: 786.98 | AD39: 912.66 | AE39: 652.98 | AF39: 744.87 | AG39: 572.22 | AH39: 276.01 | AI39: 1259.03 | AJ39: 2027.06 | AM39: AM-Peak | AN39: 8320.78 | AO39: 4263.98 | AP39: 10786.53 | AQ39: 5198.14 | AR39: 10192.79 | AS39: 7554.65 | AT39: 9528.36 | AU39: 7041.85 | AV39: 4674.84 | AW39: 5292.36 | AX39: 3856.82 | AY39: 4289.33 | AZ39: 3208.22 | BA39: 2465.99 | BB39: 5516.67 | BC39: 5979.84 | BF39: AM-Peak | BG39: 10160 | BH39: 5175.34 | BI39: 12441.4 | BJ39: 7063.49 | BK39: 12248.94 | BL39: 8862.51 | BM39: 11041.11 | BN39: 8227.81 | BO39: 5461.82 | BP39: 6205.02 | BQ39: 4509.8 | BR39: 5034.2 | BS39: 3780.43 | BT39: 2742 | BU39: 6775.7 | BV39: 8006.9
B40: AM-Shoulder | C40: 5811.25 | D40: 3217.71 | E40: 4876.71 | F40: 6678.12 | G40: 9528.72 | H40: 6653.53 | I40: 3922.37 | J40: 3424.04 | K40: 1727.95 | L40: 1477.41 | M40: 1594.28 | N40: 577.85 | O40: 381.41 | P40: 381.32 | Q40: 1584.92 | R40: 1548.61 | T40: AM-Shoulder | U40: 1345.2 | V40: 747.3 | W40: 1433.12 | X40: 1484.03 | Y40: 1486.71 | Z40: 1374.27 | AA40: 1328.82 | AB40: 1142.3 | AC40: 980.69 | AD40: 422.73 | AE40: 788.77 | AF40: 593.18 | AG40: 373.04 | AH40: 372.78 | AI40: 1100.64 | AJ40: 1075.43 | AM40: AM-Shoulder | AN40: 7123.34 | AO40: 4772.01 | AP40: 10173.98 | AQ40: 8222.23 | AR40: 9013.29 | AS40: 8311.93 | AT40: 7824.08 | AU40: 6805.2 | AV40: 5865.31 | AW40: 3841.77 | AX40: 4687.83 | AY40: 3671.32 | AZ40: 2130.53 | BA40: 2131.82 | BB40: 5439.26 | BC40: 5224.57 | BF40: AM-Shoulder | BG40: 8468.53 | BH40: 5519.31 | BI40: 11607.1 | BJ40: 9706.26 | BK40: 10500 | BL40: 9686.2 | BM40: 9152.9 | BN40: 7947.5 | BO40: 6846 | BP40: 4264.5 | BQ40: 5476.6 | BR40: 4264.5 | BS40: 2503.57 | BT40: 2504.6 | BU40: 6539.9 | BV40: 6300
B41: MD | C41: 21637.61 | D41: 24155.71 | E41: 27449.46 | F41: 29645.71 | G41: 23137.66 | H41: 26017.86 | I41: 10809.99 | J41: 14557.02 | K41: 9618.59 | L41: 7580.66 | M41: 10290.51 | N41: 7559.03 | O41: 3825.05 | P41: 3588.09 | Q41: 9489.48 | R41: 9025.62 | T41: MD | U41: 1001.74 | V41: 1118.32 | W41: 1219.98 | X41: 1317.59 | Y41: 1104.95 | Z41: 1289.54 | AA41: 944.41 | AB41: 1150.75 | AC41: 1175.62 | AD41: 996.39 | AE41: 1156.83 | AF41: 976.17 | AG41: 470.9 | AH41: 453.83 | AI41: 1317.98 | AJ41: 1253.56 | AM41: MD | AN41: 4810.21 | AO41: 5443.34 | AP41: 7272.22 | AQ41: 6950.54 | AR41: 6394.25 | AS41: 7193.66 | AT41: 5316.49 | AU41: 6430.95 | AV41: 6608.18 | AW41: 5689.81 | AX41: 6491.57 | AY41: 5569.43 | AZ41: 2573.4 | BA41: 2480.97 | BB41: 6872.02 | BC41: 6399.6 | BF41: MD | BG41: 5811.95 | BH41: 6561.66 | BI41: 8492.2 | BJ41: 8268.12 | BK41: 7499.2 | BL41: 8483.2 | BM41: 6260.9 | BN41: 7581.7 | BO41: 7783.8 | BP41: 6686.2 | BQ41: 7648.4 | BR41: 6545.6 | BS41: 3044.3 | BT41: 2934.8 | BU41: 8190 | BV41: 7653.15
B42: PM-Shoulder | C42: 5574.01 | D42: 5107 | E42: 4210.56 | F42: 7569.22 | G42: 8918.09 | H42: 9200.46 | I42: 3457.58 | J42: 7338.65 | K42: 1433.89 | L42: 991.44 | M42: 1516.66 | N42: 1051.19 | O42: 983.17 | P42: 757.68 | Q42: 1252.46 | R42: 1450.17 | T42: PM-Shoulder | U42: 1290.28 | V42: 1182.18 | W42: 1595.77 | X42: 1935.98 | Y42: 1792.22 | Z42: 1926.99 | AA42: 1488.9 | AB42: 1777.77 | AC42: 1332.93 | AD42: 1104.47 | AE42: 1132.72 | AF42: 890.11 | AG42: 754.51 | AH42: 672.14 | AI42: 1195.16 | AJ42: 1007.06 | AM42: PM-Shoulder | AN42: 6244.8 | AO42: 5416.51 | AP42: 8928.75 | AQ42: 10108.92 | AR42: 8707.78 | AS42: 9310.22 | AT42: 6819.8 | AU42: 8222.23 | AV42: 5631.05 | AW42: 4806.32 | AX42: 4727.88 | AY42: 3838.44 | AZ42: 3144.47 | BA42: 2795.32 | BB42: 5928.11 | BC42: 4347.94 | BF42: PM-Shoulder | BG42: 7535.08 | BH42: 6598.68 | BI42: 10524.52 | BJ42: 12044.9 | BK42: 10500 | BL42: 11237.22 | BM42: 8308.7 | BN42: 10000 | BO42: 6963.98 | BP42: 5910.78 | BQ42: 5860.6 | BR42: 4728.55 | BS42: 3898.98 | BT42: 3467.46 | BU42: 7123.27 | BV42: 5355
B43: PM-Peak | C43: 28518.82 | D43: 27695.97 | E43: 20936.86 | F43: 20012.03 | G43: 24996.31 | H43: 29629.18 | I43: 13807.81 | J43: 18806.56 | K43: 7355.79 | L43: 6741.24 | M43: 7601.33 | N43: 6823.2 | O43: 1801.53 | P43: 3512.6 | Q43: 7247.13 | R43: 7394.23 | T43: PM-Peak | U43: 2200.53 | V43: 2137.04 | W43: 1550.89 | X43: 1632.69 | Y43: 1659.33 | Z43: 1959.6 | AA43: 1401.95 | AB43: 1578.37 | AC43: 1335.8 | AD43: 1209.74 | AE43: 1088.56 | AF43: 980.68 | AG43: 211.82 | AH43: 673.39 | AI43: 1677.58 | AJ43: 1711.63 | AM43: PM-Peak | AN43: 7261.84 | AO43: 7220.66 | AP43: 6932.66 | AQ43: 8846.81 | AR43: 8124.79 | AS43: 8514.22 | AT43: 6662.13 | AU43: 7345.12 | AV43: 5873.34 | AW43: 5614.78 | AX43: 4678.62 | AY43: 4478.97 | AZ43: 1917.48 | BA43: 2794.1 | BB43: 4316.3 | BC43: 5229.66 | BF43: PM-Peak | BG43: 9462.37 | BH43: 9357.7 | BI43: 8483.55 | BJ43: 10479.5 | BK43: 9784.12 | BL43: 10473.83 | BM43: 8064.08 | BN43: 8923.49 | BO43: 7209.14 | BP43: 6824.52 | BQ43: 5767.18 | BR43: 5459.66 | BS43: 2129.3 | BT43: 3467.48 | BU43: 5993.88 | BV43: 6941.28
B44: PM-Late | C44: 4950.33 | D44: 5666.54 | E44: 5499.87 | F44: 1560.83 | G44: 6239.5 | H44: 6633.37 | I44: 4220.74 | J44: 4583.15 | K44: 5200.78 | L44: 4903.13 | M44: 5200.73 | N44: 4903.12 | O44: 715.49 | P44: 905.63 | Q44: 3179.74 | R44: 3241.93 | T44: PM-Late | U44: 745.38 | V44: 971.9 | W44: 652.51 | X44: 781.01 | Y44: 601.78 | Z44: 732.24 | AA44: 479.69 | AB44: 661.69 | AC44: 734.86 | AD44: 622 | AE44: 734.89 | AF44: 622.01 | AG44: 227.49 | AH44: 254.19 | AI44: 850.38 | AJ44: 782.35 | AM44: PM-Late | AN44: 3795.72 | AO44: 4589 | AP44: 3936.59 | AQ44: 4221.69 | AR44: 2883.82 | AS44: 3267.96 | AT44: 2294.81 | AU44: 2880.51 | AV44: 3441.44 | AW44: 2765 | AX44: 3441.41 | AY44: 2764.99 | AZ44: 830.51 | BA44: 932.91 | BB44: 4725.02 | BC44: 4037.61 | BF44: PM-Late | BG44: 4541.1 | BH44: 5560.9 | BI44: 4589.1 | BJ44: 5002.7 | BK44: 3485.6 | BL44: 4000.2 | BM44: 2774.5 | BN44: 3542.2 | BO44: 4176.3 | BP44: 3387 | BQ44: 4176.3 | BR44: 3387 | BS44: 1058 | BT44: 1187.1 | BU44: 5575.4 | BV44: 4819.96
B47: Revenue Per Period Lights | T47: ML V/C | AM47: GP V/C real | BF47: Highway Vol / GP Capacity
...

Sheet Year_2040
B1: Lenght
C2: 11 | D2: 12 | E2: 13 | F2: 14 | G2: 15 | H2: 16 | I2: 17 | J2: 18
B3: Length | C3: 2.4 | D3: 2.5 | E3: 2.8 | F3: 3.3 | G3: 2.6 | H3: 2.6 | I3: 2.1 | J3: 0.8
B5: TollLights | T5: ML PCE.Miles | AM5: GP PCE.Miles | BF5: Highway PCE.Miles
B6: Direction | C6: NB | D6: SB | E6: NB | F6: SB | G6: NB | H6: SB | I6: NB | J6: SB | K6: NB | L6: SB | M6: NB | N6: SB | O6: NB | P6: SB | Q6: NB | R6: SB | T6: Direction | U6: NB | V6: SB | W6: NB | X6: SB | Y6: NB | Z6: SB | AA6: NB | AB6: SB | AC6: NB | AD6: SB | AE6: NB | AF6: SB | AG6: NB | AH6: SB | AI6: NB | AJ6: SB | AM6: Direction | AN6: NB | AO6: SB | AP6: NB | AQ6: SB | AR6: NB | AS6: SB | AT6: NB | AU6: SB | AV6: NB | AW6: SB | AX6: NB | AY6: SB | AZ6: NB | BA6: SB | BB6: NB | BC6: SB | BF6: Direction | BG6: NB | BH6: SB | BI6: NB | BJ6: SB | BK6: NB | BL6: SB | BM6: NB | BN6: SB | BO6: NB | BP6: SB | BQ6: NB | BR6: SB | BS6: NB | BT6: SB | BU6: NB | BV6: SB
