Workbook

Sheet Year_2025
B1: Lenght
B3: Length
B5: TollLights | D5: ML PCE.Miles | G5: GP PCE.Miles | J5: Highway PCE.Miles
B6: Direction | D6: Direction | G6: Direction | J6: Direction
B7: Period | D7: Period | G7: Period | J7: Period
B8: Period | D8: Period | G8: Period | J8: Period
B11: CaptureRateLights | D11: ML Volume (PCE/Period) | G11: GP Volume (PCE/Period) | J11: Highway Volume
B12: Direction | D12: Direction | G12: Direction | J12: Direction
B13: Period | D13: Period | G13: Period | J13: Period
B14: Period | D14: Period | G14: Period | J14: Period
B17: Revenue Per Period | D17: ML Flow (PCE/hr) | G17: GP Flow (PCE/hr) | J17: Highway Flow
B18: Direction | D18: Direction | G18: Direction | J18: Direction
B19: Period | D19: Period | G19: Period | J19: Period
B20: Period | D20: Period | G20: Period | J20: Period
... B50: Period | D50: Period | G50: Period | J50: Period
D53: ML medium A veh.Miles | G53: GP medium A veh.Miles | J53: Implied VOT
D54: Direction | G54: Direction | J54: Direction
D55: Period | G55: Period | J55: Period
D56: Period | G56: Period | J56: Period
D59: ML medium A veh/period | G59: GP medium A veh/period
D60: Direction | G60: Direction
D61: Period | G61: Period
D62: Period | G62: Period
D65: ML medium B veh.Miles | G65: GP medium B veh.Miles
D66: Direction | G66: Direction
D67: Period | G67: Period
D68: Period | G68: Period
D71: ML medium B veh/period | G71: GP medium B veh/period
D72: Direction | G72: Direction
D73: Period | G73: Period
D74: Period | G74: Period
... D98: Period | G98: Period
D101: Bonus %
D102: Direction
D103: Period
D104: Period

Sheet Year_2032
B1: Lenght
C2: 1 | D2: 2 | E2: 3 | F2: 4 | G2: 5 | H2: 6 | I2: 7 | J2: 8 | K2: 9 | L2: 10
B3: Length | C3: 1.3 | D3: 1.3 | E3: 0.5 | F3: 1.6 | G3: 2 | H3: 3.6 | I3: 2.9 | J3: 3.8 | K3: 3.4 | L3: 4.5
B5: TollLights | X5: ML PCE.Miles | AU5: GP PCE.Miles | BR5: Highway PCE.Miles
B6: Direction | C6: NB | D6: SB | E6: NB | F6: SB | G6: NB | H6: SB | I6: NB | J6: SB | K6: NB | L6: SB | M6: NB | N6: SB | O6: NB | P6: SB | Q6: NB | R6: SB | S6: NB | T6: SB | U6: NB | V6: SB | X6: Direction | Y6: NB | Z6: SB | AA6: NB | AB6: SB | AC6: NB | AD6: SB | AE6: NB | AF6: SB | AG6: NB | AH6: SB | AI6: NB | AJ6: SB | AK6: NB | AL6: SB | AM6: NB | AN6: SB | AO6: NB | AP6: SB | AQ6: NB | AR6: SB | AU6: Direction | AV6: NB | AW6: SB | AX6: NB | AY6: SB | AZ6: NB | BA6: SB | BB6: NB | BC6: SB | BD6: NB | BE6: SB | BF6: NB | BG6: SB | BH6: NB | BI6: SB | BJ6: NB | BK6: SB | BL6: NB | BM6: SB | BN6: NB | BO6: SB | BR6: Direction | BS6: NB | BT6: SB | BU6: NB | BV6: SB | BW6: NB | BX6: SB | BY6: NB | BZ6: SB | CA6: NB | CB6: SB | CC6: NB | CD6: SB | CE6: NB | CF6: SB | CG6: NB | CH6: SB | CI6: NB | CJ6: SB | CK6: NB | CL6: SB
B7: Segment | C7: 1 | D7: 1 | E7: 2 | F7: 2 | G7: 3 | H7: 3 | I7: 4 | J7: 4 | K7: 5 | L7: 5 | M7: 6 | N7: 6 | O7: 7 | P7: 7 | Q7: 8 | R7: 8 | S7: 9 | T7: 9 | U7: 10 | V7: 10 | X7: Segment | Y7: 1 | Z7: 1 | AA7: 2 | AB7: 2 | AC7: 3 | AD7: 3 | AE7: 4 | AF7: 4 | AG7: 5 | AH7: 5 | AI7: 6 | AJ7: 6 | AK7: 7 | AL7: 7 | AM7: 8 | AN7: 8 | AO7: 9 | AP7: 9 | AQ7: 10 | AR7: 10 | AU7: Segment | AV7: 1 | AW7: 1 | AX7: 2 | AY7: 2 | AZ7: 3 | BA7: 3 | BB7: 4 | BC7: 4 | BD7: 5 | BE7: 5 | BF7: 6 | BG7: 6 | BH7: 7 | BI7: 7 | BJ7: 8 | BK7: 8 | BL7: 9 | BM7: 9 | BN7: 10 | BO7: 10 | BR7: Segment | BS7: 1 | BT7: 1 | BU7: 2 | BV7: 2 | BW7: 3 | BX7: 3 | BY7: 4 | BZ7: 4 | CA7: 5 | CB7: 5 | CC7: 6 | CD7: 6 | CE7: 7 | CF7: 7 | CG7: 8 | CH7: 8 | CI7: 9 | CJ7: 9 | CK7: 10 | CL7: 10
B8: Period | X8: Period | AU8: Period | BR8: Period
B9: Night | C9: 0.2 | D9: 0.2 | E9: 0.2 | F9: 0.2 | G9: 0.2 | H9: 0.2 | I9: 0.2 | J9: 0.54 | K9: 0.54 | L9: 0.54 | M9: 0.54 | N9: 0.54 | O9: 0.54 | P9: 0.54 | Q9: 0.54 | R9: 0.54 | S9: 0.54 | T9: 0.54 | U9: 0.54 | V9: 0.54 | X9: Night | Y9: 1353.17 | Z9: 1346.69 | AA9: 1160.75 | AB9: 1082.19 | AC9: 397.01 | AD9: 485.61 | AE9: 1386.03 | AF9: 2769.98 | AG9: 3877.16 | AH9: 3413.62 | AI9: 7063.56 | AJ9: 6056.32 | AK9: 5557.73 | AL9: 4777.81 | AM9: 7051.13 | AN9: 6424.43 | AO9: 5521.12 | AP9: 4211.41 | AQ9: 7445.02 | AR9: 5904.67 | AU9: Night | AV9: 23965.44 | AW9: 23806.8 | AX9: 18661.78 | AY9: 17464.52 | AZ9: 6780.44 | BA9: 8075.93 | BB9: 27860.14 | BC9: 26324.26 | BD9: 36860.04 | BE9: 32532.78 | BF9: 66459.96 | BG9: 57493.04 | BH9: 52973.26 | BI9: 44967.34 | BJ9: 66332.95 | BK9: 60397.43 | BL9: 51710.74 | BM9: 39923.31 | BN9: 70180.43 | BO9: 55608.53 | BR9: Night | BS9: 25318.61 | BT9: 25153.49 | BU9: 19822.53 | BV9: 18546.71 | BW9: 7177.45 | BX9: 8561.54 | BY9: 29246.17 | BZ9: 29094.24 | CA9: 40737.2 | CB9: 35946.4 | CC9: 73523.52 | CD9: 63549.36 | CE9: 58530.99 | CF9: 49745.15 | CG9: 73384.08 | CH9: 66821.86 | CI9: 57231.86 | CJ9: 44134.72 | CK9: 77625.45 | CL9: 61513.2
B10: AM-Early | C10: 0.89 | D10: 0.55 | E10: 0.69 | F10: 0.46 | G10: 0.81 | H10: 0.58 | I10: 0.82 | J10: 1.13 | K10: 0.91 | L10: 0.86 | M10: 1.18 | N10: 0.89 | O10: 1.23 | P10: 0.99 | Q10: 1.12 | R10: 0.78 | S10: 1.05 | T10: 0.71 | U10: 0.78 | V10: 0.47 | X10: AM-Early | Y10: 1545.55 | Z10: 952.77 | AA10: 1589.39 | AB10: 1022.77 | AC10: 401.84 | AD10: 496.88 | AE10: 2143.07 | AF10: 1481.81 | AG10: 2500.66 | AH10: 1709.98 | AI10: 4310.16 | AJ10: 3099.98 | AK10: 3048.28 | AL10: 2681.05 | AM10: 3786.73 | AN10: 3374.35 | AO10: 3287.41 | AP10: 2480.2 | AQ10: 5028.15 | AR10: 3132.01 | AU10: AM-Early | AV10: 8786.95 | AW10: 5759.95 | AX10: 8001.62 | AY10: 5350.07 | AZ10: 2118.86 | BA10: 2602.07 | BB10: 11102.51 | BC10: 8093.87 | BD10: 14047.01 | BE10: 10051.62 | BF10: 24628.86 | BG10: 18425.86 | BH10: 17532.44 | BI10: 15799.78 | BJ10: 21991.15 | BK10: 19726.76 | BL10: 19073.25 | BM10: 14907.38 | BN10: 30255.99 | BO10: 19299.35 | BR10: AM-Early | BS10: 10332.5 | BT10: 6712.72 | BU10: 9591.01 | BV10: 6372.85 | BW10: 2520.7 | BX10: 3098.95 | BY10: 13245.58 | BZ10: 9575.68 | CA10: 16547.67 | CB10: 11761.6 | CC10: 28939.01 | CD10: 21525.84 | CE10: 20580.72 | CF10: 18480.83 | CG10: 25777.87 | CH10: 23101.11 | CI10: 22360.66 | CJ10: 17387.59 | CK10: 35284.14 | CL10: 22431.35
B11: AM-Peak | C11: 3.6 | D11: 0.7 | E11: 4.09 | F11: 0.52 | G11: 1.8 | H11: 3.85 | I11: 1.8 | J11: 1.79 | K11: 1.8 | L11: 1.65 | M11: 1.8 | N11: 1.68 | O11: 1.8 | P11: 1.72 | Q11: 1.8 | R11: 1.59 | S11: 1.8 | T11: 1.35 | U11: 1.3 | V11: 1.15 | X11: AM-Peak | Y11: 7271.69 | Z11: 2377.84 | AA11: 6835.09 | AB11: 2313.36 | AC11: 2880.54 | AD11: 2741.78 | AE11: 10537.03 | AF11: 5076.23 | AG11: 13942.63 | AH11: 5635.59 | AI11: 25655.42 | AJ11: 10012.87 | AK11: 19604.9 | AL11: 8130.79 | AM11: 24818.8 | AN11: 10377.3 | AO11: 10549.37 | AP11: 8054.62 | AQ11: 10591.49 | AR11: 9442.81 | AU11: AM-Peak | AV11: 30333.12 | AW11: 14747.05 | AX11: 29312.89 | AY11: 12168 | AZ11: 7937.5 | BA11: 11584.92 | BB11: 35697.62 | BC11: 28760.65 | BD11: 46389.03 | BE11: 34752.88 | BF11: 84072.58 | BG11: 62840.33 | BH11: 62406.43 | BI11: 51325.95 | BJ11: 77359.15 | BK11: 64441.15 | BL11: 62798.66 | BM11: 51440.1 | BN11: 66571.29 | BO11: 60226.89 | BR11: AM-Peak | BS11: 37604.82 | BT11: 17124.88 | BU11: 36147.98 | BV11: 14481.36 | BW11: 10818.04 | BX11: 14326.7 | BY11: 46234.65 | BZ11: 33836.87 | CA11: 60331.66 | CB11: 40388.47 | CC11: 109728 | CD11: 72853.2 | CE11: 82011.34 | CF11: 59456.74 | CG11: 102177.96 | CH11: 74818.44 | CI11: 73348.03 | CJ11: 59494.71 | CK11: 77162.77 | CL11: 69669.7
B12: AM-Shoulder | C12: 1.8 | D12: 0.84 | E12: 1.8 | F12: 0.45 | G12: 1.8 | H12: 2.8 | I12: 1.8 | J12: 1.45 | K12: 1.8 | L12: 1.24 | M12: 1.8 | N12: 1.19 | O12: 1.8 | P12: 1.21 | Q12: 1.8 | R12: 1.08 | S12: 1.06 | T12: 0.98 | U12: 0.95 | V12: 0.88 | X12: AM-Shoulder | Y12: 2120.76 | Z12: 848.64 | AA12: 2123.88 | AB12: 933.9 | AC12: 704.15 | AD12: 663.57 | AE12: 2609.52 | AF12: 1698.86 | AG12: 3063.6 | AH12: 1896 | AI12: 5510.92 | AJ12: 3262.93 | AK12: 4424.85 | AL12: 2631.83 | AM12: 4402.89 | AN12: 3314.08 | AO12: 2995.22 | AP12: 2667.46 | AQ12: 3559.73 | AR12: 3330.49 | AU12: AM-Shoulder | AV12: 9006.83 | AW12: 5559.13 | AX12: 8431.31 | AY12: 5059.55 | AZ12: 2765.2 | BA12: 3776.43 | BB12: 11598.48 | BC12: 10014.7 | BD12: 14696.4 | BE12: 11965.93 | BF12: 26457.08 | BG12: 21034.87 | BH12: 21327.15 | BI12: 17055.78 | BJ12: 26502.69 | BK12: 21210.24 | BL12: 18881.82 | BM12: 17806.33 | BN12: 23220.49 | BO12: 22079.71 | BR12: AM-Shoulder | BS12: 11127.59 | BT12: 6407.78 | BU12: 10555.19 | BV12: 5993.46 | BW12: 3469.34 | BX12: 4440 | BY12: 14208 | BZ12: 11713.56 | CA12: 17760 | CB12: 13861.93 | CC12: 31968 | CD12: 24297.8 | CE12: 25752 | CF12: 19687.61 | CG12: 30905.58 | CH12: 24524.32 | CI12: 21877.04 | CJ12: 20473.79 | CK12: 26780.22 | CL12: 25410.19
B13: MD | C13: 1.8 | D13: 1.8 | E13: 1.8 | F13: 0.78 | G13: 1.8 | H13: 1.8 | I13: 0.8 | J13: 1.8 | K13: 1.68 | L13: 1.8 | M13: 1.44 | N13: 1.24 | O13: 1.26 | P13: 1.13 | Q13: 1.13 | R13: 1.04 | S13: 1.03 | T13: 0.84 | U13: 0.9 | V13: 0.63 | X13: MD | Y13: 7234.78 | Z13: 7725.89 | AA13: 9290.3 | AB13: 8275.63 | AC13: 2759.42 | AD13: 3031.89 | AE13: 8790.76 | AF13: 9907.37 | AG13: 11421.12 | AH13: 12271.42 | AI13: 19181.77 | AJ13: 19330.05 | AK13: 14621.34 | AL13: 15300.42 | AM13: 17991.24 | AN13: 17461.48 | AO13: 14890.23 | AP13: 14543.22 | AQ13: 18781.06 | AR13: 20960.65 | AU13: MD | AV13: 30613.43 | AW13: 40431.96 | AX13: 39579.08 | AY13: 42614.39 | AZ13: 11192.13 | BA13: 12524.32 | BB13: 47921.96 | BC13: 48449.43 | BD13: 67989.99 | BE13: 68625.58 | BF13: 115513.02 | BG13: 116421.72 | BH13: 88162.5 | BI13: 91869.08 | BJ13: 109792.77 | BK13: 105662.86 | BL13: 91558.67 | BM13: 88668.2 | BN13: 117963.36 | BO13: 131267.82 | BR13: MD | BS13: 37848.21 | BT13: 48157.85 | BU13: 48869.39 | BV13: 50890.03 | BW13: 13951.56 | BX13: 15556.21 | BY13: 56712.72 | BZ13: 58356.8 | CA13: 79411.12 | CB13: 80897 | CC13: 134694.79 | CD13: 135751.77 | CE13: 102783.84 | CF13: 107169.5 | CG13: 127784.01 | CH13: 123124.34 | CI13: 106448.9 | CJ13: 103211.42 | CK13: 136744.43 | CL13: 152228.48
B14: PM-Shoulder | C14: 1.8 | D14: 2.49 | E14: 2 | F14: 1.94 | G14: 1.8 | H14: 1.8 | I14: 0.82 | J14: 1.8 | K14: 0.82 | L14: 1.96 | M14: 1 | N14: 2.03 | O14: 0.98 | P14: 1.64 | Q14: 0.98 | R14: 1.67 | S14: 0.9 | T14: 1.35 | U14: 0.8 | V14: 0.67 | X14: PM-Shoulder | Y14: 1882.09 | Z14: 1577.81 | AA14: 2238.3 | AB14: 2284.79 | AC14: 641.16 | AD14: 713.26 | AE14: 2041.98 | AF14: 1900.57 | AG14: 2388.87 | AH14: 3001.23 | AI14: 4511.15 | AJ14: 5427.09 | AK14: 3625.59 | AL14: 4306.09 | AM14: 4649.78 | AN14: 5486.89 | AO14: 3964.21 | AP14: 4788.63 | AQ14: 4776.64 | AR14: 4700.18 | AU14: PM-Shoulder | AV14: 7096.76 | AW14: 7572.57 | AX14: 9305.7 | AY14: 9259.21 | AZ14: 2247.2 | BA14: 2564.73 | BB14: 8555.56 | BC14: 7011.3 | BD14: 10914.67 | BE14: 14316.76 | BF14: 21226.72 | BG14: 26540.91 | BH14: 16955.67 | BI14: 20263.02 | BJ14: 22090.32 | BK14: 26580.04 | BL14: 19038.3 | BM14: 22393.22 | BN14: 23425.06 | BO14: 21671.28 | BR14: PM-Shoulder | BS14: 8978.86 | BT14: 9150.38 | BU14: 11544 | BV14: 11544 | BW14: 2888.37 | BX14: 3277.99 | BY14: 10597.55 | BZ14: 8911.87 | CA14: 13303.53 | CB14: 17318 | CC14: 25737.86 | CD14: 31968 | CE14: 20581.26 | CF14: 24569.11 | CG14: 26740.1 | CH14: 32066.92 | CI14: 23002.51 | CJ14: 27181.85 | CK14: 28201.69 | CL14: 26371.46
B15: PM-Peak | C15: 3.6 | D15: 3.6 | E15: 2.26 | F15: 3.6 | G15: 1.8 | H15: 3.6 | I15: 1.66 | J15: 1.8 | K15: 1.44 | L15: 1.8 | M15: 1.62 | N15: 1.8 | O15: 1.62 | P15: 1.8 | Q15: 1.8 | R15: 2.27 | S15: 1.41 | T15: 1.44 | U15: 1.27 | V15: 1.22 | X15: PM-Peak | Y15: 7001.9 | Z15: 7314.86 | AA15: 6303.02 | AB15: 7626.07 | AC15: 3039.61 | AD15: 2709.59 | AE15: 6718.82 | AF15: 9509.27 | AG15: 7590.17 | AH15: 14643.69 | AI15: 13800.96 | AJ15: 26373.38 | AK15: 11192.45 | AL15: 18968.3 | AM15: 15182.38 | AN15: 15856.95 | AO15: 11870.1 | AP15: 12264.24 | AQ15: 14594.47 | AR15: 14521.96 | AU15: PM-Peak | AV15: 27191.95 | AW15: 28946.45 | AX15: 26262.88 | AY15: 31212.3 | AZ15: 7433.2 | BA15: 10266.1 | BB15: 29146.83 | BC15: 24500.88 | BD15: 35680.24 | BE15: 46316.31 | BF15: 67109.51 | BG15: 83354.62 | BH15: 54115.62 | BI15: 64946.25 | BJ15: 74188.36 | BK15: 80192.14 | BL15: 58809.28 | BM15: 59890.75 | BN15: 73130.39 | BO15: 71754.71 | BR15: PM-Peak | BS15: 34193.85 | BT15: 36261.3 | BU15: 32565.9 | BV15: 38838.37 | BW15: 10472.82 | BX15: 12975.7 | BY15: 35865.65 | BZ15: 34010.15 | CA15: 43270.41 | CB15: 60960 | CC15: 80910.47 | CD15: 109728 | CE15: 65308.07 | CF15: 83914.55 | CG15: 89370.74 | CH15: 96049.1 | CI15: 70679.38 | CJ15: 72154.98 | CK15: 87724.87 | CL15: 86276.67
B16: PM-Late | C16: 0.87 | D16: 1.14 | E16: 0.27 | F16: 0.28 | G16: 0.2 | H16: 0.33 | I16: 0.69 | J16: 1.57 | K16: 0.9 | L16: 1.54 | M16: 1.32 | N16: 1.53 | O16: 1.48 | P16: 1.35 | Q16: 1.3 | R16: 1.14 | S16: 1.19 | T16: 0.95 | U16: 1 | V16: 0.78 | X16: PM-Late | Y16: 3020.22 | Z16: 3814.59 | AA16: 2985.45 | AB16: 3184.83 | AC16: 215.14 | AD16: 1277.04 | AE16: 1220.21 | AF16: 4323.85 | AG16: 3831.67 | AH16: 5183.19 | AI16: 6746.02 | AJ16: 9567.34 | AK16: 5379.74 | AL16: 7273.93 | AM16: 6733.59 | AN16: 7444.06 | AO16: 5668.91 | AP16: 5760.79 | AQ16: 7778.2 | AR16: 7999.98 | AU16: PM-Late | AV16: 15169.38 | AW16: 18459.09 | AX16: 12168 | AY16: 12967.85 | AZ16: 4211.62 | BA16: 5549.28 | BB16: 14976 | BC16: 19056.72 | BD16: 19698.53 | BE16: 24551.06 | BF16: 34605.02 | BG16: 45647.86 | BH16: 27896.89 | BI16: 35354.33 | BJ16: 34879.83 | BK16: 37491.32 | BL16: 29288.53 | BM16: 29851.49 | BN16: 40653.05 | BO16: 43016.52 | BR16: PM-Late | BS16: 18189.6 | BT16: 22273.68 | BU16: 15153.45 | BV16: 16152.69 | BW16: 4426.76 | BX16: 6826.32 | BY16: 16196.21 | BZ16: 23380.57 | CA16: 23530.2 | CB16: 29734.25 | CC16: 41351.04 | CD16: 55215.2 | CE16: 33276.63 | CF16: 42628.26 | CG16: 41613.42 | CH16: 44935.38 | CI16: 34957.44 | CJ16: 35612.28 | CK16: 48431.25 | CL16: 51016.5
B19: CaptureRateLights | X19: ML Volume (PCE/Period) | AU19: GP Volume (PCE/Period) | BR19: Highway Volume
B20: Direction | C20: NB | D20: SB | E20: NB | F20: SB | G20: NB | H20: SB | I20: NB | J20: SB | K20: NB | L20: SB | M20: NB | N20: SB | O20: NB | P20: SB | Q20: NB | R20: SB | S20: NB | T20: SB | U20: NB | V20: SB | X20: Direction | Y20: NB | Z20: SB | AA20: NB | AB20: SB | AC20: NB | AD20: SB | AE20: NB | AF20: SB | AG20: NB | AH20: SB | AI20: NB | AJ20: SB | AK20: NB | AL20: SB | AM20: NB | AN20: SB | AO20: NB | AP20: SB | AQ20: NB | AR20: SB | AU20: Direction | AV20: NB | AW20: SB | AX20: NB | AY20: SB | AZ20: NB | BA20: SB | BB20: NB | BC20: SB | BD20: NB | BE20: SB | BF20: NB | BG20: SB | BH20: NB | BI20: SB | BJ20: NB | BK20: SB | BL20: NB | BM20: SB | BN20: NB | BO20: SB | BR20: Direction | BS20: NB | BT20: SB | BU20: NB | BV20: SB | BW20: NB | BX20: SB | BY20: NB | BZ20: SB | CA20: NB | CB20: SB | CC20: NB | CD20: SB | CE20: NB | CF20: SB | CG20: NB | CH20: SB | CI20: NB | CJ20: SB | CK20: NB | CL20: SB
B21: Segment | C21: 1 | D21: 1 | E21: 2 | F21: 2 | G21: 3 | H21: 3 | I21: 4 | J21: 4 | K21: 5 | L21: 5 | M21: 6 | N21: 6 | O21: 7 | P21: 7 | Q21: 8 | R21: 8 | S21: 9 | T21: 9 | U21: 10 | V21: 10 | X21: Segment | Y21: 1 | Z21: 1 | AA21: 2 | AB21: 2 | AC21: 3 | AD21: 3 | AE21: 4 | AF21: 4 | AG21: 5 | AH21: 5 | AI21: 6 | AJ21: 6 | AK21: 7 | AL21: 7 | AM21: 8 | AN21: 8 | AO21: 9 | AP21: 9 | AQ21: 10 | AR21: 10 | AU21: Segment | AV21: 1 | AW21: 1 | AX21: 2 | AY21: 2 | AZ21: 3 | BA21: 3 | BB21: 4 | BC21: 4 | BD21: 5 | BE21: 5 | BF21: 6 | BG21: 6 | BH21: 7 | BI21: 7 | BJ21: 8 | BK21: 8 | BL21: 9 | BM21: 9 | BN21: 10 | BO21: 10 | BR21: Segment | BS21: 1 | BT21: 1 | BU21: 2 | BV21: 2 | BW21: 3 | BX21: 3 | BY21: 4 | BZ21: 4 | CA21: 5 | CB21: 5 | CC21: 6 | CD21: 6 | CE21: 7 | CF21: 7 | CG21: 8 | CH21: 8 | CI21: 9 | CJ21: 9 | CK21: 10 | CL21: 10
B22: Period | X22: Period | AU22: Period | BR22: Period
B23: Night | C23: 0.06 | D23: 0.06 | E23: 0.06 | F23: 0.06 | G23: 0.06 | H23: 0.06 | I23: 0.05 | J23: 0.1 | K23: 0.1 | L23: 0.1 | M23: 0.1 | N23: 0.1 | O23: 0.1 | P23: 0.1 | Q23: 0.1 | R23: 0.1 | S23: 0.1 | T23: 0.1 | U23: 0.1 | V23: 0.1 | X23: Night | Y23: 1040.9 | Z23: 1035.92 | AA23: 892.88 | AB23: 832.45 | AC23: 794.02 | AD23: 971.22 | AE23: 866.27 | AF23: 1731.24 | AG23: 1938.58 | AH23: 1706.81 | AI23: 1962.1 | AJ23: 1682.31 | AK23: 1916.46 | AL23: 1647.52 | AM23: 1855.56 | AN23: 1690.64 | AO23: 1623.86 | AP23: 1238.65 | AQ23: 1654.45 | AR23: 1312.15 | AU23: Night | AV23: 18434.96 | AW23: 18312.92 | AX23: 14355.22 | AY23: 13434.25 | AZ23: 13560.88 | BA23: 16151.87 | BB23: 17412.59 | BC23: 16452.66 | BD23: 18430.02 | BE23: 16266.39 | BF23: 18461.1 | BG23: 15970.29 | BH23: 18266.64 | BI23: 15505.98 | BJ23: 17456.04 | BK23: 15894.06 | BL23: 15209.04 | BM23: 11742.15 | BN23: 15595.65 | BO23: 12357.45 | BR23: Night | BS23: 19475.85 | BT23: 19348.84 | BU23: 15248.1 | BV23: 14266.7 | BW23: 14354.9 | BX23: 17123.08 | BY23: 18278.86 | BZ23: 18183.9 | CA23: 20368.6 | CB23: 17973.2 | CC23: 20423.2 | CD23: 17652.6 | CE23: 20183.1 | CF23: 17153.5 | CG23: 19311.6 | CH23: 17584.7 | CI23: 16832.9 | CJ23: 12980.8 | CK23: 17250.1 | CL23: 13669.6
B24: AM-Early | C24: 0.16 | D24: 0.17 | E24: 0.17 | F24: 0.18 | G24: 0.18 | H24: 0.18 | I24: 0.17 | J24: 0.17 | K24: 0.16 | L24: 0.16 | M24: 0.16 | N24: 0.16 | O24: 0.16 | P24: 0.16 | Q24: 0.16 | R24: 0.16 | S24: 0.16 | T24: 0.16 | U24: 0.16 | V24: 0.16 | X24: AM-Early | Y24: 1188.89 | Z24: 732.9 | AA24: 1222.6 | AB24: 786.75 | AC24: 803.69 | AD24: 993.76 | AE24: 1339.42 | AF24: 926.13 | AG24: 1250.33 | AH24: 854.99 | AI24: 1197.27 | AJ24: 861.11 | AK24: 1051.13 | AL24: 924.5 | AM24: 996.51 | AN24: 887.99 | AO24: 966.89 | AP24: 729.47 | AQ24: 1117.37 | AR24: 696 | AU24: AM-Early | AV24: 6759.19 | AW24: 4430.73 | AX24: 6155.1 | AY24: 4115.44 | AZ24: 4237.71 | BA24: 5204.13 | BB24: 6939.07 | BC24: 5058.67 | BD24: 7023.51 | BE24: 5025.81 | BF24: 6841.35 | BG24: 5118.29 | BH24: 6045.67 | BI24: 5448.2 | BJ24: 5787.14 | BK24: 5191.25 | BL24: 5609.78 | BM24: 4384.52 | BN24: 6723.55 | BO24: 4288.74 | BR24: AM-Early | BS24: 7948.08 | BT24: 5163.63 | BU24: 7377.7 | BV24: 4902.19 | BW24: 5041.4 | BX24: 6197.9 | BY24: 8278.49 | BZ24: 5984.8 | CA24: 8273.83 | CB24: 5880.8 | CC24: 8038.62 | CD24: 5979.4 | CE24: 7096.8 | CF24: 6372.7 | CG24: 6783.65 | CH24: 6079.24 | CI24: 6576.67 | CJ24: 5114 | CK24: 7840.92 | CL24: 4984.74
B25: AM-Peak | C25: 0.22 | D25: 0.17 | E25: 0.2 | F25: 0.17 | G25: 0.3 | H25: 0.21 | I25: 0.25 | J25: 0.17 | K25: 0.26 | L25: 0.16 | M25: 0.26 | N25: 0.16 | O25: 0.27 | P25: 0.16 | Q25: 0.28 | R25: 0.16 | S25: 0.17 | T25: 0.16 | U25: 0.16 | V25: 0.16 | X25: AM-Peak | Y25: 5593.61 | Z25: 1829.1 | AA25: 5257.76 | AB25: 1779.51 | AC25: 5761.09 | AD25: 5483.55 | AE25: 6585.65 | AF25: 3172.64 | AG25: 6971.31 | AH25: 2817.8 | AI25: 7126.51 | AJ25: 2781.35 | AK25: 6760.31 | AL25: 2803.72 | AM25: 6531.26 | AN25: 2730.87 | AO25: 3102.75 | AP25: 2369 | AQ25: 2353.66 | AR25: 2098.4 | AU25: AM-Peak | AV25: 23333.17 | AW25: 11343.88 | AX25: 22548.38 | AY25: 9360 | AZ25: 15875 | BA25: 23169.85 | BB25: 22311.01 | BC25: 17975.4 | BD25: 23194.52 | BE25: 17376.44 | BF25: 23353.49 | BG25: 17455.65 | BH25: 21519.46 | BI25: 17698.6 | BJ25: 20357.67 | BK25: 16958.2 | BL25: 18470.19 | BM25: 15129.44 | BN25: 14793.62 | BO25: 13383.75 | BR25: AM-Peak | BS25: 28926.78 | BT25: 13172.98 | BU25: 27806.14 | BV25: 11139.51 | BW25: 21636.09 | BX25: 28653.4 | BY25: 28896.66 | BZ25: 21148.05 | CA25: 30165.83 | CB25: 20194.24 | CC25: 30480 | CD25: 20237 | CE25: 28279.77 | CF25: 20502.32 | CG25: 26888.94 | CH25: 19689.06 | CI25: 21572.95 | CJ25: 17498.45 | CK25: 17147.28 | CL25: 15482.16
B26: AM-Shoulder | C26: 0.23 | D26: 0.17 | E26: 0.22 | F26: 0.18 | G26: 0.24 | H26: 0.17 | I26: 0.21 | J26: 0.17 | K26: 0.2 | L26: 0.16 | M26: 0.2 | N26: 0.16 | O26: 0.2 | P26: 0.16 | Q26: 0.17 | R26: 0.16 | S26: 0.16 | T26: 0.16 | U26: 0.16 | V26: 0.16 | X26: AM-Shoulder | Y26: 1631.36 | Z26: 652.8 | AA26: 1633.75 | AB26: 718.39 | AC26: 1408.29 | AD26: 1327.14 | AE26: 1630.95 | AF26: 1061.78 | AG26: 1531.8 | AH26: 948 | AI26: 1530.81 | AJ26: 906.37 | AK26: 1525.81 | AL26: 907.53 | AM26: 1158.65 | AN26: 872.13 | AO26: 880.95 | AP26: 784.55 | AQ26: 791.05 | AR26: 740.11 | AU26: AM-Shoulder | AV26: 6928.33 | AW26: 4276.26 | AX26: 6485.63 | AY26: 3891.96 | AZ26: 5530.39 | BA26: 7552.86 | BB26: 7249.05 | BC26: 6259.19 | BD26: 7348.2 | BE26: 5982.96 | BF26: 7349.19 | BG26: 5843.02 | BH26: 7354.19 | BI26: 5881.3 | BJ26: 6974.39 | BK26: 5581.64 | BL26: 5553.48 | BM26: 5237.16 | BN26: 5160.11 | BO26: 4906.6 | BR26: AM-Shoulder | BS26: 8559.69 | BT26: 4929.06 | BU26: 8119.38 | BV26: 4610.35 | BW26: 6938.68 | BX26: 8880 | BY26: 8880 | BZ26: 7320.97 | CA26: 8880 | CB26: 6930.96 | CC26: 8880 | CD26: 6749.39 | CE26: 8880 | CF26: 6788.83 | CG26: 8133.05 | CH26: 6453.77 | CI26: 6434.42 | CJ26: 6021.7 | CK26: 5951.16 | CL26: 5646.71
B27: MD | C27: 0.22 | D27: 0.19 | E27: 0.2 | F27: 0.18 | G27: 0.23 | H27: 0.22 | I27: 0.18 | J27: 0.2 | K27: 0.16 | L27: 0.17 | M27: 0.16 | N27: 0.16 | O27: 0.16 | P27: 0.16 | Q27: 0.16 | R27: 0.16 | S27: 0.17 | T27: 0.17 | U27: 0.17 | V27: 0.16 | X27: MD | Y27: 5565.21 | Z27: 5942.99 | AA27: 7146.39 | AB27: 6365.87 | AC27: 5518.85 | AD27: 6063.78 | AE27: 5494.23 | AF27: 6192.1 | AG27: 5710.56 | AH27: 6135.71 | AI27: 5328.27 | AJ27: 5369.46 | AK27: 5041.84 | AL27: 5276.01 | AM27: 4734.54 | AN27: 4595.13 | AO27: 4379.48 | AP27: 4277.42 | AQ27: 4173.57 | AR27: 4657.92 | AU27: MD | AV27: 23548.8 | AW27: 31101.51 | AX27: 30445.45 | AY27: 32780.3 | AZ27: 22384.26 | BA27: 25048.64 | BB27: 29951.22 | BC27: 30280.9 | BD27: 33995 | BE27: 34312.79 | BF27: 32086.95 | BG27: 32339.37 | BH27: 30400.86 | BI27: 31678.99 | BJ27: 28892.83 | BK27: 27806.02 | BL27: 26929.02 | BM27: 26078.88 | BN27: 26214.08 | BO27: 29170.63 | BR27: MD | BS27: 29114.01 | BT27: 37044.5 | BU27: 37591.84 | BV27: 39146.17 | BW27: 27903.11 | BX27: 31112.41 | BY27: 35445.45 | BZ27: 36473 | CA27: 39705.56 | CB27: 40448.5 | CC27: 37415.22 | CD27: 37708.82 | CE27: 35442.7 | CF27: 36955 | CG27: 33627.37 | CH27: 32401.14 | CI27: 31308.5 | CJ27: 30356.3 | CK27: 30387.65 | CL27: 33828.55
B28: PM-Shoulder | C28: 0.25 | D28: 0.2 | E28: 0.21 | F28: 0.21 | G28: 0.26 | H28: 0.25 | I28: 0.21 | J28: 0.24 | K28: 0.2 | L28: 0.2 | M28: 0.2 | N28: 0.19 | O28: 0.2 | P28: 0.19 | Q28: 0.2 | R28: 0.19 | S28: 0.2 | T28: 0.19 | U28: 0.2 | V28: 0.2 | X28: PM-Shoulder | Y28: 1447.76 | Z28: 1213.7 | AA28: 1721.77 | AB28: 1757.53 | AC28: 1282.33 | AD28: 1426.53 | AE28: 1276.24 | AF28: 1187.86 | AG28: 1194.43 | AH28: 1500.62 | AI28: 1253.1 | AJ28: 1507.52 | AK28: 1250.2 | AL28: 1484.86 | AM28: 1223.63 | AN28: 1443.92 | AO28: 1165.94 | AP28: 1408.42 | AQ28: 1061.47 | AR28: 1044.48 | AU28: PM-Shoulder | AV28: 5459.05 | AW28: 5825.05 | AX28: 7158.23 | AY28: 7122.47 | AZ28: 4494.41 | BA28: 5129.45 | BB28: 5347.23 | BC28: 4382.06 | BD28: 5457.33 | BE28: 7158.38 | BF28: 5896.31 | BG28: 7372.48 | BH28: 5846.78 | BI28: 6987.25 | BJ28: 5813.24 | BK28: 6994.75 | BL28: 5599.5 | BM28: 6586.24 | BN28: 5205.57 | BO28: 4815.84 | BR28: PM-Shoulder | BS28: 6906.81 | BT28: 7038.75 | BU28: 8880 | BV28: 8880 | BW28: 5776.74 | BX28: 6555.98 | BY28: 6623.47 | BZ28: 5569.92 | CA28: 6651.77 | CB28: 8659 | CC28: 7149.41 | CD28: 8880 | CE28: 7096.99 | CF28: 8472.11 | CG28: 7036.87 | CH28: 8438.66 | CI28: 6765.44 | CJ28: 7994.66 | CK28: 6267.04 | CL28: 5860.32
B29: PM-Peak | C29: 0.24 | D29: 0.23 | E29: 0.21 | F29: 0.21 | G29: 0.33 | H29: 0.24 | I29: 0.21 | J29: 0.32 | K29: 0.2 | L29: 0.27 | M29: 0.19 | N29: 0.27 | O29: 0.2 | P29: 0.26 | Q29: 0.2 | R29: 0.19 | S29: 0.2 | T29: 0.2 | U29: 0.2 | V29: 0.2 | X29: PM-Peak | Y29: 5386.07 | Z29: 5626.81 | AA29: 4848.48 | AB29: 5866.21 | AC29: 6079.23 | AD29: 5419.18 | AE29: 4199.26 | AF29: 5943.29 | AG29: 3795.08 | AH29: 7321.84 | AI29: 3833.6 | AJ29: 7325.94 | AK29: 3859.47 | AL29: 6540.79 | AM29: 3995.36 | AN29: 4172.88 | AO29: 3491.21 | AP29: 3607.13 | AQ29: 3243.22 | AR29: 3227.1 | AU29: PM-Peak | AV29: 20916.89 | AW29: 22266.5 | AX29: 20202.21 | AY29: 24009.46 | AZ29: 14866.41 | BA29: 20532.21 | BB29: 18216.77 | BC29: 15313.05 | BD29: 17840.12 | BE29: 23158.16 | BF29: 18641.53 | BG29: 23154.06 | BH29: 18660.56 | BI29: 22395.26 | BJ29: 19523.25 | BK29: 21103.2 | BL29: 17296.85 | BM29: 17614.93 | BN29: 16251.2 | BO29: 15945.49 | BR29: PM-Peak | BS29: 26302.96 | BT29: 27893.31 | BU29: 25050.69 | BV29: 29875.67 | BW29: 20945.63 | BX29: 25951.39 | BY29: 22416.03 | BZ29: 21256.35 | CA29: 21635.2 | CB29: 30480 | CC29: 22475.13 | CD29: 30480 | CE29: 22520.02 | CF29: 28936.05 | CG29: 23518.62 | CH29: 25276.08 | CI29: 20788.05 | CJ29: 21222.05 | CK29: 19494.42 | CL29: 19172.59
B30: PM-Late | C30: 0.2 | D30: 0.2 | E30: 0.22 | F30: 0.22 | G30: 0.05 | H30: 0.22 | I30: 0.09 | J30: 0.22 | K30: 0.2 | L30: 0.2 | M30: 0.2 | N30: 0.2 | O30: 0.2 | P30: 0.2 | Q30: 0.2 | R30: 0.2 | S30: 0.2 | T30: 0.2 | U30: 0.2 | V30: 0.2 | X30: PM-Late | Y30: 2323.25 | Z30: 2934.3 | AA30: 2296.5 | AB30: 2449.87 | AC30: 430.28 | AD30: 2554.08 | AE30: 762.63 | AF30: 2702.41 | AG30: 1915.84 | AH30: 2591.59 | AI30: 1873.89 | AJ30: 2657.59 | AK30: 1855.08 | AL30: 2508.25 | AM30: 1772 | AN30: 1958.96 | AO30: 1667.33 | AP30: 1694.35 | AQ30: 1728.49 | AR30: 1777.77 | AU30: PM-Late | AV30: 11668.75 | AW30: 14199.3 | AX30: 9360 | AY30: 9975.27 | AZ30: 8423.24 | BA30: 11098.56 | BB30: 9360 | BC30: 11910.45 | BD30: 9849.26 | BE30: 12275.53 | BF30: 9612.51 | BG30: 12679.96 | BH30: 9619.62 | BI30: 12191.15 | BJ30: 9178.9 | BK30: 9866.14 | BL30: 8614.27 | BM30: 8779.85 | BN30: 9034.01 | BO30: 9559.23 | BR30: PM-Late | BS30: 13992 | BT30: 17133.6 | BU30: 11656.5 | BV30: 12425.14 | BW30: 8853.53 | BX30: 13652.64 | BY30: 10122.63 | BZ30: 14612.86 | CA30: 11765.1 | CB30: 14867.13 | CC30: 11486.4 | CD30: 15337.55 | CE30: 11474.7 | CF30: 14699.4 | CG30: 10950.9 | CH30: 11825.1 | CI30: 10281.6 | CJ30: 10474.2 | CK30: 10762.5 | CL30: 11337
B33: Revenue Per Period | X33: ML Flow (PCE/hr) | AU33: GP Flow (PCE/hr) | BR33: Highway Flow
B34: Direction | C34: NB | D34: SB | E34: NB | F34: SB | G34: NB | H34: SB | I34: NB | J34: SB | K34: NB | L34: SB | M34: NB | N34: SB | O34: NB | P34: SB | Q34: NB | R34: SB | S34: NB | T34: SB | U34: NB | V34: SB | X34: Direction | Y34: NB | Z34: SB | AA34: NB | AB34: SB | AC34: NB | AD34: SB | AE34: NB | AF34: SB | AG34: NB | AH34: SB | AI34: NB | AJ34: SB | AK34: NB | AL34: SB | AM34: NB | AN34: SB | AO34: NB | AP34: SB | AQ34: NB | AR34: SB | AU34: Direction | AV34: NB | AW34: SB | AX34: NB | AY34: SB | AZ34: NB | BA34: SB | BB34: NB | BC34: SB | BD34: NB | BE34: SB | BF34: NB | BG34: SB | BH34: NB | BI34: SB | BJ34: NB | BK34: SB | BL34: NB | BM34: SB | BN34: NB | BO34: SB | BR34: Direction | BS34: NB | BT34: SB | BU34: NB | BV34: SB | BW34: NB | BX34: SB | BY34: NB | BZ34: SB | CA34: NB | CB34: SB | CC34: NB | CD34: SB | CE34: NB | CF34: SB | CG34: NB | CH34: SB | CI34: NB | CJ34: SB | CK34: NB | CL34: SB
B35: Segment | C35: 1 | D35: 1 | E35: 2 | F35: 2 | G35: 3 | H35: 3 | I35: 4 | J35: 4 | K35: 5 | L35: 5 | M35: 6 | N35: 6 | O35: 7 | P35: 7 | Q35: 8 | R35: 8 | S35: 9 | T35: 9 | U35: 10 | V35: 10 | X35: Segment | Y35: 1 | Z35: 1 | AA35: 2 | AB35: 2 | AC35: 3 | AD35: 3 | AE35: 4 | AF35: 4 | AG35: 5 | AH35: 5 | AI35: 6 | AJ35: 6 | AK35: 7 | AL35: 7 | AM35: 8 | AN35: 8 | AO35: 9 | AP35: 9 | AQ35: 10 | AR35: 10 | AU35: Segment | AV35: 1 | AW35: 1 | AX35: 2 | AY35: 2 | AZ35: 3 | BA35: 3 | BB35: 4 | BC35: 4 | BD35: 5 | BE35: 5 | BF35: 6 | BG35: 6 | BH35: 7 | BI35: 7 | BJ35: 8 | BK35: 8 | BL35: 9 | BM35: 9 | BN35: 10 | BO35: 10 | BR35: Segment | BS35: 1 | BT35: 1 | BU35: 2 | BV35: 2 | BW35: 3 | BX35: 3 | BY35: 4 | BZ35: 4 | CA35: 5 | CB35: 5 | CC35: 6 | CD35: 6 | CE35: 7 | CF35: 7 | CG35: 8 | CH35: 8 | CI35: 9 | CJ35: 9 | CK35: 10 | CL35: 10
B36: Period | X36: Period | AU36: Period | BR36: Period
B37: Night | C37: 270.63 | D37: 269.34 | E37: 232.15 | F37: 216.44 | G37: 79.4 | H37: 97.12 | I37: 277.21 | J37: 1495.79 | K37: 2093.67 | L37: 1843.35 | M37: 3814.32 | N37: 3270.41 | O37: 3001.18 | P37: 2580.02 | Q37: 3807.61 | R37: 3469.19 | S37: 2981.41 | T37: 2274.16 | U37: 4020.31 | V37: 3188.52 | X37: Night | Y37: 148.7 | Z37: 147.99 | AA37: 127.55 | AB37: 118.92 | AC37: 113.43 | AD37: 138.75 | AE37: 123.75 | AF37: 247.32 | AG37: 276.94 | AH37: 243.83 | AI37: 280.3 | AJ37: 240.33 | AK37: 273.78 | AL37: 235.36 | AM37: 265.08 | AN37: 241.52 | AO37: 231.98 | AP37: 176.95 | AQ37: 236.35 | AR37: 187.45 | AU37: Night | AV37: 2633.57 | AW37: 2616.13 | AX37: 2050.75 | AY37: 1919.18 | AZ37: 1937.27 | BA37: 2307.41 | BB37: 2487.51 | BC37: 2350.38 | BD37: 2632.86 | BE37: 2323.77 | BF37: 2637.3 | BG37: 2281.47 | BH37: 2609.52 | BI37: 2215.14 | BJ37: 2493.72 | BK37: 2270.58 | BL37: 2172.72 | BM37: 1677.45 | BN37: 2227.95 | BO37: 1765.35 | BR37: Night | BS37: 2782.26 | BT37: 2764.12 | BU37: 2178.3 | BV37: 2038.1 | BW37: 2050.7 | BX37: 2446.16 | BY37: 2611.26 | BZ37: 2597.7 | CA37: 2909.8 | CB37: 2567.6 | CC37: 2917.6 | CD37: 2521.8 | CE37: 2883.3 | CF37: 2450.5 | CG37: 2758.8 | CH37: 2512.1 | CI37: 2404.7 | CJ37: 1854.4 | CK37: 2464.3 | CL37: 1952.8
B38: AM-Early | C38: 1380.94 | D38: 524.52 | E38: 1098.44 | F38: 469.34 | G38: 327.21 | H38: 285.91 | I38: 1749.02 | J38: 1671.16 | K38: 2278.48 | L38: 1471.76 | M38: 5072.35 | N38: 2773.95 | O38: 3736.4 | P38: 2665.26 | Q38: 4231.79 | R38: 2643.93 | S38: 3438.19 | T38: 1768.34 | U38: 3936.59 | V38: 1464.04 | X38: AM-Early | Y38: 1188.89 | Z38: 732.9 | AA38: 1222.6 | AB38: 786.75 | AC38: 803.69 | AD38: 993.76 | AE38: 1339.42 | AF38: 926.13 | AG38: 1250.33 | AH38: 854.99 | AI38: 1197.27 | AJ38: 861.11 | AK38: 1051.13 | AL38: 924.5 | AM38: 996.51 | AN38: 887.99 | AO38: 966.89 | AP38: 729.47 | AQ38: 1117.37 | AR38: 696 | AU38: AM-Early | AV38: 6759.19 | AW38: 4430.73 | AX38: 6155.1 | AY38: 4115.44 | AZ38: 4237.71 | BA38: 5204.13 | BB38: 6939.07 | BC38: 5058.67 | BD38: 7023.51 | BE38: 5025.81 | BF38: 6841.35 | BG38: 5118.29 | BH38: 6045.67 | BI38: 5448.2 | BJ38: 5787.14 | BK38: 5191.25 | BL38: 5609.78 | BM38: 4384.52 | BN38: 6723.55 | BO38: 4288.74 | BR38: AM-Early | BS38: 7948.08 | BT38: 5163.63 | BU38: 7377.7 | BV38: 4902.19 | BW38: 5041.4 | BX38: 6197.9 | BY38: 8278.49 | BZ38: 5984.8 | CA38: 8273.83 | CB38: 5880.8 | CC38: 8038.62 | CD38: 5979.4 | CE38: 7096.8 | CF38: 6372.7 | CG38: 6783.65 | CH38: 6079.24 | CI38: 6576.67 | CJ38: 5114 | CK38: 7840.92 | CL38: 4984.74
B39: AM-Peak | C39: 26178.1 | D39: 1660.48 | E39: 27923.87 | F39: 1198.99 | G39: 5184.98 | H39: 10566.08 | I39: 18966.64 | J39: 9071.96 | K39: 25096.73 | L39: 9292.22 | M39: 46179.75 | N39: 16823.02 | O39: 35288.82 | P39: 14023.35 | Q39: 44673.83 | R39: 16505.64 | S39: 18988.85 | T39: 10860.21 | U39: 13753.05 | V39: 10833.24 | X39: AM-Peak | Y39: 1864.54 | Z39: 609.7 | AA39: 1752.59 | AB39: 593.17 | AC39: 1920.36 | AD39: 1827.85 | AE39: 2195.22 | AF39: 1057.55 | AG39: 2323.77 | AH39: 939.27 | AI39: 2375.5 | AJ39: 927.12 | AK39: 2253.44 | AL39: 934.57 | AM39: 2177.09 | AN39: 910.29 | AO39: 1034.25 | AP39: 789.67 | AQ39: 784.55 | AR39: 699.47 | AU39: AM-Peak | AV39: 7777.72 | AW39: 3781.29 | AX39: 7516.13 | AY39: 3120 | AZ39: 5291.67 | BA39: 7723.28 | BB39: 7437 | BC39: 5991.8 | BD39: 7731.51 | BE39: 5792.15 | BF39: 7784.5 | BG39: 5818.55 | BH39: 7173.15 | BI39: 5899.53 | BJ39: 6785.89 | BK39: 5652.73 | BL39: 6156.73 | BM39: 5043.15 | BN39: 4931.21 | BO39: 4461.25 | BR39: AM-Peak | BS39: 9642.26 | BT39: 4391 | BU39: 9268.71 | BV39: 3713.17 | BW39: 7212.03 | BX39: 9551.13 | BY39: 9632.22 | BZ39: 7049.35 | CA39: 10055.28 | CB39: 6731.41 | CC39: 10160 | CD39: 6745.67 | CE39: 9426.59 | CF39: 6834.11 | CG39: 8962.98 | CH39: 6563.02 | CI39: 7190.98 | CJ39: 5832.82 | CK39: 5715.76 | CL39: 5160.72
B40: AM-Shoulder | C40: 3817.37 | D40: 712.89 | E40: 3822.98 | F40: 421.67 | G40: 1267.46 | H40: 1857.25 | I40: 4697.13 | J40: 2467.33 | K40: 5514.47 | L40: 2351.58 | M40: 9919.66 | N40: 3881.03 | O40: 7964.73 | P40: 3178.59 | Q40: 7925.2 | R40: 3581.25 | S40: 3184.21 | T40: 2609.72 | U40: 3365.92 | V40: 2924.73 | X40: AM-Shoulder | Y40: 1631.36 | Z40: 652.8 | AA40: 1633.75 | AB40: 718.39 | AC40: 1408.29 | AD40: 1327.14 | AE40: 1630.95 | AF40: 1061.78 | AG40: 1531.8 | AH40: 948 | AI40: 1530.81 | AJ40: 906.37 | AK40: 1525.81 | AL40: 907.53 | AM40: 1158.65 | AN40: 872.13 | AO40: 880.95 | AP40: 784.55 | AQ40: 791.05 | AR40: 740.11 | AU40: AM-Shoulder | AV40: 6928.33 | AW40: 4276.26 | AX40: 6485.63 | AY40: 3891.96 | AZ40: 5530.39 | BA40: 7552.86 | BB40: 7249.05 | BC40: 6259.19 | BD40: 7348.2 | BE40: 5982.96 | BF40: 7349.19 | BG40: 5843.02 | BH40: 7354.19 | BI40: 5881.3 | BJ40: 6974.39 | BK40: 5581.64 | BL40: 5553.48 | BM40: 5237.16 | BN40: 5160.11 | BO40: 4906.6 | BR40: AM-Shoulder | BS40: 8559.69 | BT40: 4929.06 | BU40: 8119.38 | BV40: 4610.35 | BW40: 6938.68 | BX40: 8880 | BY40: 8880 | BZ40: 7320.97 | CA40: 8880 | CB40: 6930.96 | CC40: 8880 | CD40: 6749.39 | CE40: 8880 | CF40: 6788.83 | CG40: 8133.05 | CH40: 6453.77 | CI40: 6434.42 | CJ40: 6021.7 | CK40: 5951.16 | CL40: 5646.71
B41: MD | C41: 13022.6 | D41: 13906.53 | E41: 16722.44 | F41: 6421.59 | G41: 4966.95 | H41: 5457.4 | I41: 7058.37 | J41: 17832.98 | K41: 19178.14 | L41: 22088.5 | M41: 27604.99 | N41: 24046.72 | O41: 18359.29 | P41: 17234.89 | Q41: 20290.2 | R41: 18146.67 | S41: 15351.76 | T41: 12155.74 | U41: 16891.84 | V41: 13293.56 | X41: MD | Y41: 1113.04 | Z41: 1188.6 | AA41: 1429.28 | AB41: 1273.17 | AC41: 1103.77 | AD41: 1212.76 | AE41: 1098.85 | AF41: 1238.42 | AG41: 1142.11 | AH41: 1227.14 | AI41: 1065.65 | AJ41: 1073.89 | AK41: 1008.37 | AL41: 1055.2 | AM41: 946.91 | AN41: 919.03 | AO41: 875.9 | AP41: 855.48 | AQ41: 834.71 | AR41: 931.58 | AU41: MD | AV41: 4709.76 | AW41: 6220.3 | AX41: 6089.09 | AY41: 6556.06 | AZ41: 4476.85 | BA41: 5009.73 | BB41: 5990.24 | BC41: 6056.18 | BD41: 6799 | BE41: 6862.56 | BF41: 6417.39 | BG41: 6467.87 | BH41: 6080.17 | BI41: 6335.8 | BJ41: 5778.57 | BK41: 5561.2 | BL41: 5385.8 | BM41: 5215.78 | BN41: 5242.82 | BO41: 5834.13 | BR41: MD | BS41: 5822.8 | BT41: 7408.9 | BU41: 7518.37 | BV41: 7829.23 | BW41: 5580.62 | BX41: 6222.48 | BY41: 7089.09 | BZ41: 7294.6 | CA41: 7941.11 | CB41: 8089.7 | CC41: 7483.04 | CD41: 7541.76 | CE41: 7088.54 | CF41: 7391 | CG41: 6725.47 | CH41: 6480.23 | CI41: 6261.7 | CJ41: 6071.26 | CK41: 6077.53 | CL41: 6765.71
B42: PM-Shoulder | C42: 3387.77 | D42: 3935.33 | E42: 4479.47 | F42: 4435.12 | G42: 1154.09 | H42: 1283.87 | I42: 1683.94 | J42: 3421.02 | K42: 1970.53 | L42: 5896.93 | M42: 4531.39 | N42: 10998.08 | O42: 3546.53 | P42: 7044.34 | Q42: 4546.46 | R42: 9177.5 | S42: 3585.51 | T42: 6472.02 | U42: 3800.72 | V42: 3127.41 | X42: PM-Shoulder | Y42: 1447.76 | Z42: 1213.7 | AA42: 1721.77 | AB42: 1757.53 | AC42: 1282.33 | AD42: 1426.53 | AE42: 1276.24 | AF42: 1187.86 | AG42: 1194.43 | AH42: 1500.62 | AI42: 1253.1 | AJ42: 1507.52 | AK42: 1250.2 | AL42: 1484.86 | AM42: 1223.63 | AN42: 1443.92 | AO42: 1165.94 | AP42: 1408.42 | AQ42: 1061.47 | AR42: 1044.48 | AU42: PM-Shoulder | AV42: 5459.05 | AW42: 5825.05 | AX42: 7158.23 | AY42: 7122.47 | AZ42: 4494.41 | BA42: 5129.45 | BB42: 5347.23 | BC42: 4382.06 | BD42: 5457.33 | BE42: 7158.38 | BF42: 5896.31 | BG42: 7372.48 | BH42: 5846.78 | BI42: 6987.25 | BJ42: 5813.24 | BK42: 6994.75 | BL42: 5599.5 | BM42: 6586.24 | BN42: 5205.57 | BO42: 4815.84 | BR42: PM-Shoulder | BS42: 6906.81 | BT42: 7038.75 | BU42: 8880 | BV42: 8880 | BW42: 5776.74 | BX42: 6555.98 | BY42: 6623.47 | BZ42: 5569.92 | CA42: 6651.77 | CB42: 8659 | CC42: 7149.41 | CD42: 8880 | CE42: 7096.99 | CF42: 8472.11 | CG42: 7036.87 | CH42: 8438.66 | CI42: 6765.44 | CJ42: 7994.66 | CK42: 6267.04 | CL42: 5860.32
B43: PM-Peak | C43: 25206.83 | D43: 26333.48 | E43: 14236.89 | F43: 27453.85 | G43: 5471.3 | H43: 9754.53 | I43: 11152.31 | J43: 17116.68 | K43: 10894.97 | L43: 26358.64 | M43: 22420.32 | N43: 47472.08 | O43: 18086.15 | P43: 34142.94 | Q43: 27328.1 | R43: 36052.94 | S43: 16700.75 | T43: 17716.69 | U43: 18575.37 | V43: 17750.78 | X43: PM-Peak | Y43: 1795.36 | Z43: 1875.6 | AA43: 1616.16 | AB43: 1955.4 | AC43: 2026.41 | AD43: 1806.39 | AE43: 1399.75 | AF43: 1981.1 | AG43: 1265.03 | AH43: 2440.61 | AI43: 1277.87 | AJ43: 2441.98 | AK43: 1286.49 | AL43: 2180.26 | AM43: 1331.79 | AN43: 1390.96 | AO43: 1163.74 | AP43: 1202.38 | AQ43: 1081.07 | AR43: 1075.7 | AU43: PM-Peak | AV43: 6972.3 | AW43: 7422.17 | AX43: 6734.07 | AY43: 8003.15 | AZ43: 4955.47 | BA43: 6844.07 | BB43: 6072.26 | BC43: 5104.35 | BD43: 5946.71 | BE43: 7719.39 | BF43: 6213.84 | BG43: 7718.02 | BH43: 6220.19 | BI43: 7465.09 | BJ43: 6507.75 | BK43: 7034.4 | BL43: 5765.62 | BM43: 5871.64 | BN43: 5417.07 | BO43: 5315.16 | BR43: PM-Peak | BS43: 8767.65 | BT43: 9297.77 | BU43: 8350.23 | BV43: 9958.56 | BW43: 6981.88 | BX43: 8650.46 | BY43: 7472.01 | BZ43: 7085.45 | CA43: 7211.73 | CB43: 10160 | CC43: 7491.71 | CD43: 10160 | CE43: 7506.67 | CF43: 9645.35 | CG43: 7839.54 | CH43: 8425.36 | CI43: 6929.35 | CJ43: 7074.02 | CK43: 6498.14 | CL43: 6390.86
B44: PM-Late | C44: 2615.7 | D44: 4340.33 | E44: 806.16 | F44: 894.24 | G44: 43.03 | H44: 423.37 | I44: 847.39 | J44: 6801.54 | K44: 3441.6 | L44: 7964.96 | M44: 8893.84 | N44: 14682.26 | O44: 7939.01 | P44: 9813.85 | Q44: 8732.81 | R44: 8516.76 | S44: 6736.11 | T44: 5500.58 | U44: 7750.78 | V44: 6217.5 | X44: PM-Late | Y44: 774.42 | Z44: 978.1 | AA44: 765.5 | AB44: 816.62 | AC44: 143.43 | AD44: 851.36 | AE44: 254.21 | AF44: 900.8 | AG44: 638.61 | AH44: 863.86 | AI44: 624.63 | AJ44: 885.86 | AK44: 618.36 | AL44: 836.08 | AM44: 590.67 | AN44: 652.99 | AO44: 555.78 | AP44: 564.78 | AQ44: 576.16 | AR44: 592.59 | AU44: PM-Late | AV44: 3889.58 | AW44: 4733.1 | AX44: 3120 | AY44: 3325.09 | AZ44: 2807.75 | BA44: 3699.52 | BB44: 3120 | BC44: 3970.15 | BD44: 3283.09 | BE44: 4091.84 | BF44: 3204.17 | BG44: 4226.65 | BH44: 3206.54 | BI44: 4063.72 | BJ44: 3059.63 | BK44: 3288.71 | BL44: 2871.42 | BM44: 2926.62 | BN44: 3011.34 | BO44: 3186.41 | BR44: PM-Late | BS44: 4664 | BT44: 5711.2 | BU44: 3885.5 | BV44: 4141.71 | BW44: 2951.18 | BX44: 4550.88 | BY44: 3374.21 | BZ44: 4870.95 | CA44: 3921.7 | CB44: 4955.71 | CC44: 3828.8 | CD44: 5112.52 | CE44: 3824.9 | CF44: 4899.8 | CG44: 3650.3 | CH44: 3941.7 | CI44: 3427.2 | CJ44: 3491.4 | CK44: 3587.5 | CL44: 3779
B47: Revenue Per Period Lights | X47: ML V/C | AU47: GP V/C real | BR47: Highway Vol / GP Capacity
...

Sheet Year_2040
B1: Lenght
C2: 1 | D2: 2 | E2: 3 | F2: 4 | G2: 5 | H2: 6 | I2: 7 | J2: 8 | K2: 9 | L2: 10
B3: Length | C3: 1.3 | D3: 1.3 | E3: 0.5 | F3: 1.6 | G3: 2 | H3: 3.6 | I3: 2.9 | J3: 3.8 | K3: 3.4 | L3: 4.5
B5: TollLights | X5: ML PCE.Miles | AU5: GP PCE.Miles | BR5: Highway PCE.Miles
B6: Direction | C6: NB | D6: SB | E6: NB | F6: SB | G6: NB | H6: SB | I6: NB | J6: SB | K6: NB | L6: SB | M6: NB | N6: SB | O6: NB | P6: SB | Q6: NB | R6: SB | S6: NB | T6: SB | U6: NB | V6: SB | X6: Direction | Y6: NB | Z6: SB | AA6: NB | AB6: SB | AC6: NB | AD6: SB | AE6: NB | AF6: SB | AG6: NB | AH6: SB | AI6: NB | AJ6: SB | AK6: NB | AL6: SB | AM6: NB | AN6: SB | AO6: NB | AP6: SB | AQ6: NB | AR6: SB | AU6: Direction | AV6: NB | AW6: SB | AX6: NB | AY6: SB | AZ6: NB | BA6: SB | BB6: NB | BC6: SB | BD6: NB | BE6: SB | BF6: NB | BG6: SB | BH6: NB | BI6: SB | BJ6: NB | BK6: SB | BL6: NB | BM6: SB | BN6: NB | BO6: SB | BR6: Direction | BS6: NB | BT6: SB | BU6: NB | BV6: SB | BW6: NB | BX6: SB | BY6: NB | BZ6: SB | CA6: NB | CB6: SB | CC6: NB | CD6: SB | CE6: NB | CF6: SB | CG6: NB | CH6: SB | CI6: NB | CJ6: SB | CK6: NB | CL6: SB
B7: Segment | C7: 1 | D7: 1 | E7: 2 | F7: 2 | G7: 3 | H7: 3 | I7: 4 | J7: 4 | K7: 5 | L7: 5 | M7: 6 | N7: 6 | O7: 7 | P7: 7 | Q7: 8 | R7: 8 | S7: 9 | T7: 9 | U7: 10 | V7: 10 | X7: Segment | Y7: 1 | Z7: 1 | AA7: 2 | AB7: 2 | AC7: 3 | AD7: 3 | AE7: 4 | AF7: 4 | AG7: 5 | AH7: 5 | AI7: 6 | AJ7: 6 | AK7: 7 | AL7: 7 | AM7: 8 | AN7: 8 | AO7: 9 | AP7: 9 | AQ7: 10 | AR7: 10 | AU7: Segment | AV7: 1 | AW7: 1 | AX7: 2 | AY7: 2 | AZ7: 3 | BA7: 3 | BB7: 4 | BC7: 4 | BD7: 5 | BE7: 5 | BF7: 6 | BG7: 6 | BH7: 7 | BI7: 7 | BJ7: 8 | BK7: 8 | BL7: 9 | BM7: 9 | BN7: 10 | BO7: 10 | BR7: Segment | BS7: 1 | BT7: 1 | BU7: 2 | BV7: 2 | BW7: 3 | BX7: 3 | BY7: 4 | BZ7: 4 | CA7: 5 | CB7: 5 | CC7: 6 | CD7: 6 | CE7: 7 | CF7: 7 | CG7: 8 | CH7: 8 | CI7: 9 | CJ7: 9 | CK7: 10 | CL7: 10
B8: Period | X8: Period | AU8: Period | BR8: Period
B9: Night | C9: 0.63 | D9: 0.63 | E9: 0.63 | F9: 0.63 | G9: 0.63 | H9: 0.63 | I9: 0.63 | J9: 0.63 | K9: 0.63 | L9: 0.63 | M9: 0.63 | N9: 0.63 | O9: 0.63 | P9: 0.63 | Q9: 0.63 | R9: 0.63 | S9: 0.63 | T9: 0.63 | U9: 0.63 | V9: 0.63 | X9: Night | Y9: 2797.78 | Z9: 2785.33 | AA9: 2323.14 | AB9: 2173.81 | AC9: 807.34 | AD9: 977.32 | AE9: 3258.18 | AF9: 3241.55 | AG9: 4447.52 | AH9: 3915.38 | AI9: 7524.33 | AJ9: 6961.5 | AK9: 5859.82 | AL9: 5546.37 | AM9: 8056.37 | AN9: 7442.68 | AO9: 6330.8 | AP9: 4829.97 | AQ9: 8618.4 | AR9: 6837.07 | AU9: Night | AV9: 26282.27 | AW9: 26097.61 | AX9: 21410.57 | AY9: 20022.91 | AZ9: 7673.51 | BA9: 9138 | BB9: 31117.53 | BC9: 30806.45 | BD9: 42283.08 | BE9: 37313.22 | BF9: 70794.55 | BG9: 66085.74 | BH9: 55852.18 | BI9: 52201.04 | BJ9: 75789.21 | BK9: 69968.64 | BL9: 59297.7 | BM9: 45790.25 | BN9: 81241.65 | BO9: 64387.58 | BR9: Night | BS9: 29080.05 | BT9: 28882.94 | BU9: 23733.71 | BV9: 22196.72 | BW9: 8480.85 | BX9: 10115.31 | BY9: 34375.71 | BZ9: 34048 | CA9: 46730.6 | CB9: 41228.6 | CC9: 78318.88 | CD9: 73047.24 | CE9: 61712 | CF9: 57747.41 | CG9: 83845.59 | CH9: 77411.32 | CI9: 65628.5 | CJ9: 50620.22 | CK9: 89860.05 | CL9: 71224.65
B10: AM-Early | C10: 1.68 | D10: 0.87 | E10: 1.37 | F10: 0.75 | G10: 1.43 | H10: 0.98 | I10: 1.7 | J10: 2.1 | K10: 1.84 | L10: 1.53 | M10: 2.1 | N10: 1.63 | O10: 2.1 | P10: 1.93 | Q10: 2.1 | R10: 1.42 | S10: 2.02 | T10: 1.2 | U10: 1.54 | V10: 0.77 | X10: AM-Early | Y10: 1754.12 | Z10: 1091.81 | AA10: 1871.1 | AB10: 1219.26 | AC10: 473.93 | AD10: 585.37 | AE10: 2455.82 | AF10: 1808.32 | AG10: 2801.49 | AH10: 1948.51 | AI10: 5362.91 | AJ10: 3519.85 | AK10: 3981.44 | AL10: 3066.56 | AM10: 4536.7 | AN10: 3851.61 | AO10: 3693.84 | AP10: 2827.01 | AQ10: 5633.54 | AR10: 3598.75 | AU10: AM-Early | AV10: 10111.27 | AW10: 6618.41 | AX10: 9609.96 | AY10: 6409.7 | AZ10: 2504.12 | BA10: 3075.51 | BB10: 13113.24 | BC10: 9446.72 | BD10: 16180.08 | BE10: 11543.09 | BF10: 27902.74 | BG10: 21224.39 | BH10: 19910.5 | BI10: 18387.64 | BJ10: 25324.35 | BK10: 22910.04 | BL10: 21947.14 | BM10: 17111.35 | BN10: 35214.94 | BO10: 22369.74 | BR10: AM-Early | BS10: 11865.39 | BT10: 7710.23 | BU10: 11481.05 | BV10: 7628.97 | BW10: 2978.05 | BX10: 3660.87 | BY10: 15569.06 | BZ10: 11255.04 | CA10: 18981.57 | CB10: 13491.6 | CC10: 33265.66 | CD10: 24744.24 | CE10: 23891.94 | CF10: 21454.2 | CG10: 29861.04 | CH10: 26761.65 | CI10: 25640.98 | CJ10: 19938.36 | CK10: 40848.48 | CL10: 25968.49
B11: AM-Peak | C11: 6.3 | D11: 1.09 | E11: 6.3 | F11: 0.83 | G11: 6.3 | H11: 6.3 | I11: 6.3 | J11: 2.1 | K11: 2.1 | L11: 2.1 | M11: 2.1 | N11: 2.1 | O11: 2.1 | P11: 2.1 | Q11: 2.1 | R11: 2.1 | S11: 3.65 | T11: 2.1 | U11: 2.1 | V11: 1.93 | X11: AM-Peak | Y11: 7234.43 | Z11: 2724.62 | AA11: 7251.71 | AB11: 2766.68 | AC11: 2261.56 | AD11: 2825.01 | AE11: 8925.63 | AF11: 8000.64 | AG11: 16095.06 | AH11: 8108.03 | AI11: 28953.81 | AJ11: 14691.2 | AK11: 22231.59 | AL11: 12442.13 | AM11: 28210.28 | AN11: 14867.8 | AO11: 11409.59 | AP11: 9852.16 | AQ11: 12800.32 | AR11: 10843.35 | AU11: AM-Peak | AV11: 31850.89 | AW11: 16941.89 | AX11: 30319.42 | AY11: 14568.64 | AZ11: 9297.57 | BA11: 12065.73 | BB11: 41762.37 | BC11: 31771.07 | BD11: 47264.94 | BE11: 38222.21 | BF11: 85094.19 | BG11: 69053.92 | BH11: 63008.54 | BI11: 56582.7 | BJ11: 77990.43 | BK11: 71802.33 | BL11: 72698.95 | BM11: 58367.92 | BN11: 76536.76 | BO11: 69815.12 | BR11: AM-Peak | BS11: 39085.32 | BT11: 19666.51 | BU11: 37571.13 | BV11: 17335.32 | BW11: 11559.13 | BX11: 14890.74 | BY11: 50688 | BZ11: 39771.72 | CA11: 63360 | CB11: 46330.23 | CC11: 114048 | CD11: 83745.12 | CE11: 85240.13 | CF11: 69024.83 | CG11: 106200.71 | CH11: 86670.13 | CI11: 84108.53 | CJ11: 68220.09 | CK11: 89337.08 | CL11: 80658.47
B12: AM-Shoulder | C12: 2.1 | D12: 1.38 | E12: 2.1 | F12: 0.73 | G12: 2.1 | H12: 4.2 | I12: 2.1 | J12: 2.1 | K12: 2.1 | L12: 2.1 | M12: 2.1 | N12: 2.1 | O12: 2.1 | P12: 2.1 | Q12: 2.1 | R12: 2.1 | S12: 2 | T12: 1.76 | U12: 1.73 | V12: 1.56 | X12: AM-Shoulder | Y12: 2569.25 | Z12: 973.64 | AA12: 2556.16 | AB12: 1114.47 | AC12: 855.54 | AD12: 732.3 | AE12: 3168.44 | AF12: 2576.21 | AG12: 3758.43 | AH12: 2408.08 | AI12: 6761.24 | AJ12: 4003.81 | AK12: 5432.65 | AL12: 3375.93 | AM12: 7118.69 | AN12: 3792.14 | AO12: 3396.17 | AP12: 3041.88 | AQ12: 4085.33 | AR12: 3832.26 | AU12: AM-Shoulder | AV12: 9059.58 | AW12: 6384.55 | AX12: 8474.49 | AY12: 6060.63 | AZ12: 2770.07 | BA12: 3907.7 | BB12: 11679.56 | BC12: 11192.05 | BD12: 14801.57 | BE12: 13492.51 | BF12: 26646.76 | BG12: 23924.56 | BH12: 21479.35 | BI12: 19479.58 | BJ12: 28145.31 | BK12: 24617.75 | BL12: 21689.99 | BM12: 20434.49 | BN12: 26917.73 | BO12: 25586.25 | BR12: AM-Shoulder | BS12: 11628.84 | BT12: 7358.19 | BU12: 11030.65 | BV12: 7175.1 | BW12: 3625.62 | BX12: 4640 | BY12: 14848 | BZ12: 13768.27 | CA12: 18560 | CB12: 15900.6 | CC12: 33408 | CD12: 27928.37 | CE12: 26912 | CF12: 22855.52 | CG12: 35264 | CH12: 28409.89 | CI12: 25086.16 | CJ12: 23476.37 | CK12: 31003.06 | CL12: 29418.52
B13: MD | C13: 2.1 | D13: 2.1 | E13: 3.49 | F13: 1.63 | G13: 2.1 | H13: 2.1 | I13: 1.53 | J13: 2.1 | K13: 2.1 | L13: 2.1 | M13: 2.1 | N13: 2.1 | O13: 2.1 | P13: 2.1 | Q13: 2.1 | R13: 2.03 | S13: 1.93 | T13: 1.49 | U13: 1.66 | V13: 1.13 | X13: MD | Y13: 8354.06 | Z13: 10550.79 | AA13: 7938.63 | AB13: 9721.58 | AC13: 3179.84 | AD13: 3484.51 | AE13: 10211.28 | AF13: 12176.11 | AG13: 15934.98 | AH13: 15605.33 | AI13: 27547.11 | AJ13: 24955.38 | AK13: 19499.66 | AL13: 18758.74 | AM13: 21659.5 | AN13: 19886.26 | AO13: 16879.65 | AP13: 16514.92 | AQ13: 21491.59 | AR13: 23893.49 | AU13: MD | AV13: 30201.59 | AW13: 41408.16 | AX13: 41844.2 | AY13: 51199.74 | AZ13: 11032.5 | BA13: 12362.46 | BB13: 56448.32 | BC13: 48557.87 | BD13: 71265.02 | BE13: 69302.17 | BF13: 127275.76 | BG13: 131099.22 | BH13: 99828.31 | BI13: 105652.93 | BJ13: 126382.72 | BK13: 122756.98 | BL13: 105180.35 | BM13: 101827.44 | BN13: 136822.35 | BO13: 152343.39 | BR13: MD | BS13: 38555.66 | BT13: 51958.95 | BU13: 49782.83 | BV13: 60921.31 | BW13: 14212.33 | BX13: 15846.98 | BY13: 66659.6 | BZ13: 60733.98 | CA13: 87200 | CB13: 84907.49 | CC13: 154822.87 | CD13: 156054.6 | CE13: 119327.97 | CF13: 124411.67 | CG13: 148042.22 | CH13: 142643.24 | CI13: 122060 | CJ13: 118342.36 | CK13: 158313.94 | CL13: 176236.88
B14: PM-Shoulder | C14: 2.1 | D14: 4.17 | E14: 2.1 | F14: 2.1 | G14: 2.1 | H14: 2.1 | I14: 1.72 | J14: 2.1 | K14: 1.63 | L14: 2.1 | M14: 2.1 | N14: 2.1 | O14: 2.1 | P14: 2.1 | Q14: 2.1 | R14: 2.1 | S14: 1.84 | T14: 2.1 | U14: 1.57 | V14: 1.27 | X14: PM-Shoulder | Y14: 2297.25 | Z14: 1626.01 | AA14: 2828.44 | AB14: 2838.86 | AC14: 782.99 | AD14: 867.55 | AE14: 2351.32 | AF14: 2340.18 | AG14: 2691.62 | AH14: 3878.06 | AI14: 5103.14 | AJ14: 7127.09 | AK14: 4139.87 | AL14: 5747.07 | AM14: 5250.34 | AN14: 7512.13 | AO14: 4421.58 | AP14: 6529.99 | AQ14: 5389.24 | AR14: 5304.26 | AU14: PM-Shoulder | AV14: 7086.06 | AW14: 7936.55 | AX14: 9235.56 | AY14: 9225.14 | AZ14: 2235.49 | BA14: 2558.1 | BB14: 10105.41 | BC14: 6973.13 | BD14: 12568.71 | BE14: 14220.03 | BF14: 24483.3 | BG14: 26280.91 | BH14: 19753.49 | BI14: 21164.93 | BJ14: 25726.55 | BK14: 27751.87 | BL14: 21955.23 | BM14: 24640.83 | BN14: 27261.39 | BO14: 25227.09 | BR14: PM-Shoulder | BS14: 9383.31 | BT14: 9562.56 | BU14: 12064 | BV14: 12064 | BW14: 3018.47 | BX14: 3425.65 | BY14: 12456.73 | BZ14: 9313.31 | CA14: 15260.32 | CB14: 18098.09 | CC14: 29586.43 | CD14: 33408 | CE14: 23893.37 | CF14: 26912 | CG14: 30976.89 | CH14: 35264 | CI14: 26376.81 | CJ14: 31170.82 | CK14: 32650.64 | CL14: 30531.35
B15: PM-Peak | C15: 6.3 | D15: 6.3 | E15: 5.72 | F15: 6.3 | G15: 6.3 | H15: 6.3 | I15: 2.1 | J15: 2.1 | K15: 2.1 | L15: 6.15 | M15: 2.1 | N15: 6.22 | O15: 2.1 | P15: 6.19 | Q15: 2.1 | R15: 4.2 | S15: 2.77 | T15: 2.91 | U15: 2.1 | V15: 2.1 | X15: PM-Peak | Y15: 7003.95 | Z15: 7329.69 | AA15: 7695.62 | AB15: 8133.74 | AC15: 2270.39 | AD15: 2711.79 | AE15: 9920.23 | AF15: 10813.23 | AG15: 9970.74 | AH15: 11188.33 | AI15: 19568.1 | AJ15: 19991.45 | AK15: 16164.02 | AL15: 16146.78 | AM15: 23098.52 | AN15: 20431.94 | AO15: 13138.49 | AP15: 13484.09 | AQ15: 17991.69 | AR15: 17391.44 | AU15: PM-Peak | AV15: 28536.12 | AW15: 30359.22 | AX15: 31287.55 | AY15: 33050.26 | AZ15: 8614.74 | BA15: 10774.76 | BB15: 32236.85 | BC15: 24535.91 | BD15: 39662.77 | BE15: 52171.67 | BF15: 73438.46 | BG15: 94056.55 | BH15: 59656.46 | BI15: 75725.22 | BJ15: 80437.57 | BK15: 90835.94 | BL15: 67904.09 | BM15: 69253.91 | BN15: 83568.76 | BO15: 82498.26 | BR15: PM-Peak | BS15: 35540.07 | BT15: 37688.91 | BU15: 38983.17 | BV15: 41184 | BW15: 10885.13 | BX15: 13486.55 | BY15: 42157.08 | BZ15: 35349.14 | CA15: 49633.51 | CB15: 63360 | CC15: 93006.56 | CD15: 114048 | CE15: 75820.49 | CF15: 91872 | CG15: 103536.1 | CH15: 111267.88 | CI15: 81042.58 | CJ15: 82738 | CK15: 101560.44 | CL15: 99889.7
B16: PM-Late | C16: 1.5 | D16: 2.1 | E16: 0.43 | F16: 0.45 | G16: 0.56 | H16: 0.53 | I16: 0.44 | J16: 2.1 | K16: 1.58 | L16: 2.1 | M16: 2.1 | N16: 2.1 | O16: 2.1 | P16: 2.1 | Q16: 2.1 | R16: 2.1 | S16: 2.1 | T16: 1.68 | U16: 1.81 | V16: 1.34 | X16: PM-Late | Y16: 3459.49 | Z16: 4500.42 | AA16: 3568.52 | AB16: 3795.7 | AC16: 812.05 | AD16: 1506.22 | AE16: 3260.87 | AF16: 4969.62 | AG16: 4385.38 | AH16: 5893.55 | AI16: 9005.95 | AJ16: 10866.42 | AK16: 7122.54 | AL16: 8789.95 | AM16: 9042.52 | AN16: 8879.67 | AO16: 6744.63 | AP16: 6590.5 | AQ16: 8972.85 | AR16: 9238.35 | AU16: PM-Late | AV16: 17429.3 | AW16: 21078.51 | AX16: 14571.9 | AY16: 15540.69 | AZ16: 4418.27 | BA16: 6558 | BB16: 15777.58 | BC16: 19365.26 | BD16: 22606.82 | BE16: 25054.35 | BF16: 38529.17 | BG16: 46602.46 | BH16: 29718.66 | BI16: 38128.33 | BJ16: 39162.38 | BK16: 43181.85 | BL16: 33345.45 | BM16: 34246.22 | BN16: 47099.4 | BO16: 49824.15 | BR16: PM-Late | BS16: 20888.79 | BT16: 25578.93 | BU16: 18140.42 | BV16: 19336.39 | BW16: 5230.32 | BX16: 8064.22 | BY16: 19038.46 | BZ16: 24334.88 | CA16: 26992.2 | CB16: 30947.9 | CC16: 47535.12 | CD16: 57468.88 | CE16: 36841.2 | CF16: 46918.29 | CG16: 48204.9 | CH16: 52061.52 | CI16: 40090.08 | CJ16: 40836.72 | CK16: 56072.25 | CL16: 59062.5
B19: CaptureRateLights | X19: ML Volume (PCE/Period) | AU19: GP Volume (PCE/Period) | BR19: Highway Volume
B20: Direction | C20: NB | D20: SB | E20: NB | F20: SB | G20: NB | H20: SB | I20: NB | J20: SB | K20: NB | L20: SB | M20: NB | N20: SB | O20: NB | P20: SB | Q20: NB | R20: SB | S20: NB | T20: SB | U20: NB | V20: SB | X20: Direction | Y20: NB | Z20: SB | AA20: NB | AB20: SB | AC20: NB | AD20: SB | AE20: NB | AF20: SB | AG20: NB | AH20: SB | AI20: NB | AJ20: SB | AK20: NB | AL20: SB | AM20: NB | AN20: SB | AO20: NB | AP20: SB | AQ20: NB | AR20: SB | AU20: Direction | AV20: NB | AW20: SB | AX20: NB | AY20: SB | AZ20: NB | BA20: SB | BB20: NB | BC20: SB | BD20: NB | BE20: SB | BF20: NB | BG20: SB | BH20: NB | BI20: SB | BJ20: NB | BK20: SB | BL20: NB | BM20: SB | BN20: NB | BO20: SB | BR20: Direction | BS20: NB | BT20: SB | BU20: NB | BV20: SB | BW20: NB | BX20: SB | BY20: NB | BZ20: SB | CA20: NB | CB20: SB | CC20: NB | CD20: SB | CE20: NB | CF20: SB | CG20: NB | CH20: SB | CI20: NB | CJ20: SB | CK20: NB | CL20: SB
B21: Segment | C21: 1 | D21: 1 | E21: 2 | F21: 2 | G21: 3 | H21: 3 | I21: 4 | J21: 4 | K21: 5 | L21: 5 | M21: 6 | N21: 6 | O21: 7 | P21: 7 | Q21: 8 | R21: 8 | S21: 9 | T21: 9 | U21: 10 | V21: 10 | X21: Segment | Y21: 1 | Z21: 1 | AA21: 2 | AB21: 2 | AC21: 3 | AD21: 3 | AE21: 4 | AF21: 4 | AG21: 5 | AH21: 5 | AI21: 6 | AJ21: 6 | AK21: 7 | AL21: 7 | AM21: 8 | AN21: 8 | AO21: 9 | AP21: 9 | AQ21: 10 | AR21: 10 | AU21: Segment | AV21: 1 | AW21: 1 | AX21: 2 | AY21: 2 | AZ21: 3 | BA21: 3 | BB21: 4 | BC21: 4 | BD21: 5 | BE21: 5 | BF21: 6 | BG21: 6 | BH21: 7 | BI21: 7 | BJ21: 8 | BK21: 8 | BL21: 9 | BM21: 9 | BN21: 10 | BO21: 10 | BR21: Segment | BS21: 1 | BT21: 1 | BU21: 2 | BV21: 2 | BW21: 3 | BX21: 3 | BY21: 4 | BZ21: 4 | CA21: 5 | CB21: 5 | CC21: 6 | CD21: 6 | CE21: 7 | CF21: 7 | CG21: 8 | CH21: 8 | CI21: 9 | CJ21: 9 | CK21: 10 | CL21: 10
B22: Period | X22: Period | AU22: Period | BR22: Period
B23: Night | C23: 0.1 | D23: 0.1 | E23: 0.1 | F23: 0.1 | G23: 0.1 | H23: 0.1 | I23: 0.1 | J23: 0.1 | K23: 0.1 | L23: 0.1 | M23: 0.1 | N23: 0.1 | O23: 0.1 | P23: 0.1 | Q23: 0.1 | R23: 0.1 | S23: 0.1 | T23: 0.1 | U23: 0.1 | V23: 0.1 | X23: Night | Y23: 2152.14 | Z23: 2142.56 | AA23: 1787.03 | AB23: 1672.16 | AC23: 1614.69 | AD23: 1954.63 | AE23: 2036.36 | AF23: 2025.97 | AG23: 2223.76 | AH23: 1957.69 | AI23: 2090.09 | AJ23: 1933.75 | AK23: 2020.63 | AL23: 1912.54 | AM23: 2120.1 | AN23: 1958.6 | AO23: 1862 | AP23: 1420.58 | AQ23: 1915.2 | AR23: 1519.35 | AU23: Night | AV23: 20217.13 | AW23: 20075.09 | AX23: 16469.67 | AY23: 15402.24 | AZ23: 15347.01 | BA23: 18276 | BB23: 19448.46 | BC23: 19254.03 | BD23: 21141.54 | BE23: 18656.61 | BF23: 19665.15 | BG23: 18357.15 | BH23: 19259.37 | BI23: 18000.36 | BJ23: 19944.53 | BK23: 18412.8 | BL23: 17440.5 | BM23: 13467.72 | BN23: 18053.7 | BO23: 14308.35 | BR23: Night | BS23: 22369.27 | BT23: 22217.65 | BU23: 18256.7 | BV23: 17074.4 | BW23: 16961.7 | BX23: 20230.63 | BY23: 21484.82 | BZ23: 21280 | CA23: 23365.3 | CB23: 20614.3 | CC23: 21755.24 | CD23: 20290.9 | CE23: 21280 | CF23: 19912.9 | CG23: 22064.63 | CH23: 20371.4 | CI23: 19302.5 | CJ23: 14888.3 | CK23: 19968.9 | CL23: 15827.7
B24: AM-Early | C24: 0.16 | D24: 0.16 | E24: 0.17 | F24: 0.17 | G24: 0.18 | H24: 0.18 | I24: 0.17 | J24: 0.18 | K24: 0.16 | L24: 0.16 | M24: 0.17 | N24: 0.16 | O24: 0.18 | P24: 0.16 | Q24: 0.17 | R24: 0.16 | S24: 0.16 | T24: 0.16 | U24: 0.15 | V24: 0.16 | X24: AM-Early | Y24: 1349.32 | Z24: 839.86 | AA24: 1439.31 | AB24: 937.89 | AC24: 947.87 | AD24: 1170.73 | AE24: 1534.89 | AF24: 1130.2 | AG24: 1400.75 | AH24: 974.26 | AI24: 1489.7 | AJ24: 977.74 | AK24: 1372.91 | AL24: 1057.43 | AM24: 1193.87 | AN24: 1013.58 | AO24: 1086.42 | AP24: 831.47 | AQ24: 1251.9 | AR24: 799.72 | AU24: AM-Early | AV24: 7777.9 | AW24: 5091.09 | AX24: 7392.27 | AY24: 4930.54 | AZ24: 5008.23 | BA24: 6151.01 | BB24: 8195.77 | BC24: 5904.2 | BD24: 8090.04 | BE24: 5771.54 | BF24: 7750.76 | BG24: 5895.66 | BH24: 6865.69 | BI24: 6340.57 | BJ24: 6664.3 | BK24: 6028.96 | BL24: 6455.04 | BM24: 5032.75 | BN24: 7825.54 | BO24: 4971.05 | BR24: AM-Early | BS24: 9127.22 | BT24: 5930.94 | BU24: 8831.58 | BV24: 5868.44 | BW24: 5956.1 | BX24: 7321.74 | BY24: 9730.66 | BZ24: 7034.4 | CA24: 9490.78 | CB24: 6745.8 | CC24: 9240.46 | CD24: 6873.4 | CE24: 8238.6 | CF24: 7398 | CG24: 7858.17 | CH24: 7042.54 | CI24: 7541.46 | CJ24: 5864.22 | CK24: 9077.44 | CL24: 5770.78
B25: AM-Peak | C25: 0.21 | D25: 0.16 | E25: 0.2 | F25: 0.17 | G25: 0.23 | H25: 0.21 | I25: 0.2 | J25: 0.23 | K25: 0.28 | L25: 0.2 | M25: 0.28 | N25: 0.21 | O25: 0.3 | P25: 0.21 | Q25: 0.3 | R25: 0.2 | S25: 0.16 | T25: 0.17 | U25: 0.17 | V25: 0.16 | X25: AM-Peak | Y25: 5564.94 | Z25: 2095.86 | AA25: 5578.24 | AB25: 2128.22 | AC25: 4523.12 | AD25: 5650.03 | AE25: 5578.52 | AF25: 5000.4 | AG25: 8047.53 | AH25: 4054.01 | AI25: 8042.73 | AJ25: 4080.89 | AK25: 7666.07 | AL25: 4290.39 | AM25: 7423.76 | AN25: 3912.58 | AO25: 3355.76 | AP25: 2897.7 | AQ25: 2844.52 | AR25: 2409.63 | AU25: AM-Peak | AV25: 24500.69 | AW25: 13032.22 | AX25: 23322.63 | AY25: 11206.65 | AZ25: 18595.14 | BA25: 24131.46 | BB25: 26101.48 | BC25: 19856.92 | BD25: 23632.47 | BE25: 19111.1 | BF25: 23637.27 | BG25: 19181.65 | BH25: 21727.08 | BI25: 19511.28 | BJ25: 20523.8 | BK25: 18895.35 | BL25: 21382.04 | BM25: 17167.04 | BN25: 17008.17 | BO25: 15514.47 | BR25: AM-Peak | BS25: 30065.63 | BT25: 15128.08 | BU25: 28900.87 | BV25: 13334.86 | BW25: 23118.26 | BX25: 29781.49 | BY25: 31680 | BZ25: 24857.32 | CA25: 31680 | CB25: 23165.12 | CC25: 31680 | CD25: 23262.53 | CE25: 29393.15 | CF25: 23801.67 | CG25: 27947.56 | CH25: 22807.93 | CI25: 24737.8 | CJ25: 20064.73 | CK25: 19852.68 | CL25: 17924.1
B26: AM-Shoulder | C26: 0.26 | D26: 0.17 | E26: 0.25 | F26: 0.17 | G26: 0.28 | H26: 0.18 | I26: 0.25 | J26: 0.22 | K26: 0.24 | L26: 0.18 | M26: 0.23 | N26: 0.17 | O26: 0.24 | P26: 0.18 | Q26: 0.24 | R26: 0.16 | S26: 0.16 | T26: 0.16 | U26: 0.16 | V26: 0.16 | X26: AM-Shoulder | Y26: 1976.35 | Z26: 748.95 | AA26: 1966.28 | AB26: 857.29 | AC26: 1711.09 | AD26: 1464.6 | AE26: 1980.28 | AF26: 1610.13 | AG26: 1879.22 | AH26: 1204.04 | AI26: 1878.12 | AJ26: 1112.17 | AK26: 1873.33 | AL26: 1164.12 | AM26: 1873.34 | AN26: 997.93 | AO26: 998.87 | AP26: 894.67 | AQ26: 907.85 | AR26: 851.61 | AU26: AM-Shoulder | AV26: 6968.91 | AW26: 4911.19 | AX26: 6518.84 | AY26: 4662.02 | AZ26: 5540.15 | BA26: 7815.4 | BB26: 7299.72 | BC26: 6995.03 | BD26: 7400.78 | BE26: 6746.26 | BF26: 7401.88 | BG26: 6645.71 | BH26: 7406.67 | BI26: 6717.1 | BJ26: 7406.66 | BK26: 6478.36 | BL26: 6379.41 | BM26: 6010.14 | BN26: 5981.72 | BO26: 5685.83 | BR26: AM-Shoulder | BS26: 8945.26 | BT26: 5660.15 | BU26: 8485.12 | BV26: 5519.31 | BW26: 7251.24 | BX26: 9280 | BY26: 9280 | BZ26: 8605.17 | CA26: 9280 | CB26: 7950.3 | CC26: 9280 | CD26: 7757.88 | CE26: 9280 | CF26: 7881.21 | CG26: 9280 | CH26: 7476.29 | CI26: 7378.28 | CJ26: 6904.81 | CK26: 6889.57 | CL26: 6537.45
B27: MD | C27: 0.25 | D27: 0.24 | E27: 0.17 | F27: 0.17 | G27: 0.26 | H27: 0.25 | I27: 0.17 | J27: 0.23 | K27: 0.21 | L27: 0.21 | M27: 0.2 | N27: 0.18 | O27: 0.19 | P27: 0.17 | Q27: 0.17 | R27: 0.16 | S27: 0.16 | T27: 0.16 | U27: 0.16 | V27: 0.16 | X27: MD | Y27: 6426.2 | Z27: 8115.99 | AA27: 6106.64 | AB27: 7478.14 | AC27: 6359.67 | AD27: 6969.03 | AE27: 6382.05 | AF27: 7610.07 | AG27: 7967.49 | AH27: 7802.66 | AI27: 7651.97 | AJ27: 6932.05 | AK27: 6724.02 | AL27: 6468.53 | AM27: 5699.87 | AN27: 5233.23 | AO27: 4964.6 | AP27: 4857.33 | AQ27: 4775.91 | AR27: 5309.66 | AU27: MD | AV27: 23231.99 | AW27: 31852.43 | AX27: 32187.85 | AY27: 39384.41 | AZ27: 22065 | BA27: 24724.93 | BB27: 35280.2 | BC27: 30348.67 | BD27: 35632.51 | BE27: 34651.08 | BF27: 35354.38 | BG27: 36416.45 | BH27: 34423.56 | BI27: 36432.05 | BJ27: 33258.61 | BK27: 32304.47 | BL27: 30935.4 | BM27: 29949.25 | BN27: 30404.97 | BO27: 33854.09 | BR27: MD | BS27: 29658.2 | BT27: 39968.42 | BU27: 38294.49 | BV27: 46862.55 | BW27: 28424.67 | BX27: 31693.95 | BY27: 41662.25 | BZ27: 37958.74 | CA27: 43600 | CB27: 42453.75 | CC27: 43006.35 | CD27: 43348.5 | CE27: 41147.58 | CF27: 42900.58 | CG27: 38958.48 | CH27: 37537.69 | CI27: 35900 | CJ27: 34806.57 | CK27: 35180.88 | CL27: 39163.75
B28: PM-Shoulder | C28: 0.29 | D28: 0.2 | E28: 0.25 | F28: 0.25 | G28: 0.3 | H28: 0.28 | I28: 0.21 | J28: 0.28 | K28: 0.2 | L28: 0.24 | M28: 0.19 | N28: 0.24 | O28: 0.2 | P28: 0.23 | Q28: 0.19 | R28: 0.24 | S28: 0.19 | T28: 0.23 | U28: 0.19 | V28: 0.19 | X28: PM-Shoulder | Y28: 1767.12 | Z28: 1250.78 | AA28: 2175.72 | AB28: 2183.74 | AC28: 1565.98 | AD28: 1735.1 | AE28: 1469.57 | AF28: 1462.61 | AG28: 1345.81 | AH28: 1939.03 | AI28: 1417.54 | AJ28: 1979.75 | AK28: 1427.54 | AL28: 1981.75 | AM28: 1381.67 | AN28: 1976.88 | AO28: 1300.46 | AP28: 1920.59 | AQ28: 1197.61 | AR28: 1178.72 | AU28: PM-Shoulder | AV28: 5450.82 | AW28: 6105.04 | AX28: 7104.28 | AY28: 7096.26 | AZ28: 4470.97 | BA28: 5116.2 | BB28: 6315.88 | BC28: 4358.21 | BD28: 6284.35 | BE28: 7110.01 | BF28: 6800.92 | BG28: 7300.25 | BH28: 6811.55 | BI28: 7298.25 | BJ28: 6770.15 | BK28: 7303.12 | BL28: 6457.42 | BM28: 7247.3 | BN28: 6058.09 | BO28: 5606.02 | BR28: PM-Shoulder | BS28: 7217.93 | BT28: 7355.81 | BU28: 9280 | BV28: 9280 | BW28: 6036.95 | BX28: 6851.29 | BY28: 7785.46 | BZ28: 5820.82 | CA28: 7630.16 | CB28: 9049.04 | CC28: 8218.45 | CD28: 9280 | CE28: 8239.09 | CF28: 9280 | CG28: 8151.81 | CH28: 9280 | CI28: 7757.89 | CJ28: 9167.89 | CK28: 7255.7 | CL28: 6784.74
